Workbook
Name Z_BD804FFF_0FA6_4DDB_B9D5_07B1854E6033_.wvu.PrintArea: '北段(八周檢核代碼'!$A$1:$AJ$68
Name Z_BD804FFF_0FA6_4DDB_B9D5_07B1854E6033_.wvu.PrintArea: '北段'!$A$1:$BL$65
Name Z_BD804FFF_0FA6_4DDB_B9D5_07B1854E6033_.wvu.PrintArea: '北段 (人資版)'!$A$1:$AC$70

Sheet 北段
B1: 員編 ID No. | C1: 日期 星期 姓名 | D1: 46201 | E1: 46202 | F1: 46203 | G1: 46204 | H1: 46205 | I1: 46206 | J1: 46207 | K1: 46208 | L1: 46209 | M1: 46210 | N1: 46211 | O1: 46212 | P1: 46213 | Q1: 46214 | R1: 46215 | S1: 46216 | T1: 46217 | U1: 46218 | V1: 46219 | W1: 46220 | X1: 46221 | Y1: 46222 | Z1: 46223 | AA1: 46224 | AB1: 46225 | AC1: 46226 | AD1: 46227 | AE1: 46228 | AF1: 46229 | AG1: 46230 | AH1: 46231 | AI1: 46232 | AJ1: 46233 | AK1: 46234 | AL1: 46235 | AM1: 1/1~7/4 P班天數 | AN1: 5/24~6/6 實際休假天數 | AP1: 6/7~7/4 實際休假天數 | AR1: 7/5~7/18 實際休假天數 | AT1: 7/5~7/18 剩餘休假天數 | AV1: 7/19~8/1 剩餘休假天數 | AX1: 7/19~8/1 實際休假天數 | AZ1: 7份班別小計 | BH1: 7月份 | BM1: 5/31~6/6 | BN1: 6/7~6/13 | BO1: 6/14~6/20 | BP1: 6/21~6/27 | BQ1: 6/28~7/4 | BR1: 6月天數 | BT1: 1/1~6/6 P班天數 | BU1: 6/7~7/4 P班天數
D2: =RIGHT(TEXT(D1,"[$-404]aaaa;@"),1) -> a | E2: =RIGHT(TEXT(E1,"[$-404]aaaa;@"),1) -> a | F2: =RIGHT(TEXT(F1,"[$-404]aaaa;@"),1) -> a | G2: =RIGHT(TEXT(G1,"[$-404]aaaa;@"),1) -> a | H2: =RIGHT(TEXT(H1,"[$-404]aaaa;@"),1) -> a | I2: =RIGHT(TEXT(I1,"[$-404]aaaa;@"),1) -> a | J2: =RIGHT(TEXT(J1,"[$-404]aaaa;@"),1) -> a | K2: =RIGHT(TEXT(K1,"[$-404]aaaa;@"),1) -> a | ... AL2: =RIGHT(TEXT(AL1,"[$-404]aaaa;@"),1) -> a | AN2: r | AO2: R | AP2: r | AQ2: R | AR2: r | AS2: R | AT2: r | AU2: R | AV2: r | AW2: R | AX2: r | AY2: R | AZ2: 早 | BA2: 早A | BB2: 中 | BC2: 午 | BD2: 午F | BE2: 夜 | BF2: T | BG2: 日 | BH2: L | BI2: R | BJ2: r | BK2: P | BL2: 休假 日數 | BM2: R | BN2: R | BO2: R | BP2: R | BQ2: R
A3: A1 | B3: T01028 | C3: 林金緗 | D3: 01午M | E3: 01午m | F3: R | G3: 01夜B2 | H3: 01夜B1 | I3: 01夜B2 | J3: 01夜B1 | K3: r' | L3: r' | M3: 01午M | N3: 01午m | O3: R | P3: 01午B1 | Q3: 01午m | R3: 01午M | S3: R | T3: 01午m | U3: 01午M | V3: 01午m | W3: 01午M | X3: 01午m | Y3: R | Z3: 01午M | AA3: 01午m | AB3: r' | AC3: 01午m | AD3: 01午M | AE3: 01午m | AF3: 01午M | AG3: R | AH3: L | AI3: L | AJ3: r' | AK3: 日 | AL3: 01午M | AM3: =BT3+BU3 -> 10 | AN3: 2 | AO3: 2 | AP3: 4 | AQ3: 4 | AR3: =COUNTIF(K3:X3,"r'*") -> 2 | AS3: =COUNTIF(K3:X3,"R") -> 2 | AT3: =8-AN3-AP3-AR3 -> 0 | AU3: =8-AO3-AQ3-AS3 -> 0 | AV3: =COUNTIF(Y3:AL3,"r'*") -> 2 | AW3: =COUNTIF(Y3:AL3,"R") -> 2 | AX3: =COUNTIF(Y3:AL3,"r'*") -> 2 | AY3: =COUNTIF(Y3:AL3,"R") -> 2 | AZ3: =COUNTIF(G3:AK3,"*早*")-BA3 -> 0 | BA3: =COUNTIF(G3:AK3,"*早A") -> 0 | BB3: =COUNTIF(G3:AK3,"*中*") -> 0 | BC3: =COUNTIF(G3:AK3,"*午*")-BD3 -> 16 | BD3: =COUNTIF(G3:AK3,"*午F") -> 0 | BE3: =COUNTIF(G3:AK3,"*夜*") -> 4 | BF3: =COUNTIF(G3:AK3,"*T*") -> 0 | BG3: =COUNTIF(G3:AK3,"*日*") -> 1 | BH3: =COUNTIF(G3:AK3,"L") -> 2 | BI3: {=SUMPRODUCT(1*ISNUMBER(FIND("R",G3:AK3)))} -> 4 | BJ3: {=SUMPRODUCT(1*ISNUMBER(FIND("r",G3:AK3)))} -> 4 | BK3: {=SUMPRODUCT(1*ISNUMBER(FIND("P",G3:AK3)))-SUMPRODUCT(1*ISNUMBER(FIND("午P",G3:AK3)))} -> 0 | BL3: =SUM(G3:AK3) -> 0 | BM3: {=SUMPRODUCT(1*ISNUMBER(FIND("R",D3:J3)))} -> 1 | BN3: {=SUMPRODUCT(1*ISNUMBER(FIND("R",K3:Q3)))} -> 1 | BO3: {=SUMPRODUCT(1*ISNUMBER(FIND("R",R3:X3)))} -> 1 | BP3: {=SUMPRODUCT(1*ISNUMBER(FIND("R",Y3:AE3)))} -> 1 | BQ3: {=SUMPRODUCT(1*ISNUMBER(FIND("R",AF3:AL3)))} -> 1 | BR3: =SUM(AZ3:BK3) -> 31 | BT3: 10 | BU3: {=SUMPRODUCT(1*ISNUMBER(FIND("P",K3:AL3)))-SUMPRODUCT(1*ISNUMBER(FIND("午P",K3:AL3)))} -> 0
B4: T00509 | C4: 郭秋儀 | D4: 01早M | E4: 01早M | F4: 01午m | G4: P | H4: R | I4: 01午M | J4: 01午m | K4: R | L4: 01早m | M4: r' | N4: 01早M | O4: 01早m | P4: 01早M | Q4: r' | R4: 01夜B1 | S4: 01夜B2 | T4: R | U4: L | V4: L | W4: 01早m | X4: 01早M | Y4: 01早m | Z4: 01早m | AA4: R | AB4: 01中A | AC4: 01夜B2 | AD4: 01夜B1 | AE4: r' | AF4: r' | AG4: 01早B1 | AH4: 01早m | AI4: 01早M(身心減壓) | AJ4: R | AK4: 01早M | AL4: 01早m | AM4: =BT4+BU4 -> 10 | AN4: 2 | AO4: 2 | AP4: 4 | AQ4: 4 | AR4: =COUNTIF(K4:X4,"r'*") -> 2 | AS4: =COUNTIF(K4:X4,"R") -> 2 | AT4: =8-AN4-AP4-AR4 -> 0 | AU4: =8-AO4-AQ4-AS4 -> 0 | AV4: =COUNTIF(Y4:AL4,"r'*") -> 2 | AW4: =COUNTIF(Y4:AL4,"R") -> 2 | AX4: =COUNTIF(Y4:AL4,"r'*") -> 2 | AY4: =COUNTIF(Y4:AL4,"R") -> 2 | AZ4: =COUNTIF(G4:AK4,"*早*")-BA4 -> 12 | BA4: =COUNTIF(G4:AK4,"*早A") -> 0 | BB4: =COUNTIF(G4:AK4,"*中*") -> 1 | BC4: =COUNTIF(G4:AK4,"*午*")-BD4 -> 2 | BD4: =COUNTIF(G4:AK4,"*午F") -> 0 | BE4: =COUNTIF(G4:AK4,"*夜*") -> 4 | BF4: =COUNTIF(G4:AK4,"*T*") -> 0 | BG4: =COUNTIF(G4:AK4,"*日*") -> 0 | BH4: =COUNTIF(G4:AK4,"L") -> 2 | BI4: {=SUMPRODUCT(1*ISNUMBER(FIND("R",G4:AK4)))} -> 5 | BJ4: {=SUMPRODUCT(1*ISNUMBER(FIND("r",G4:AK4)))} -> 4 | BK4: {=SUMPRODUCT(1*ISNUMBER(FIND("P",G4:AK4)))-SUMPRODUCT(1*ISNUMBER(FIND("午P",G4:AK4)))} -> 1 | BL4: =SUM(G4:AK4) -> 0 | BM4: {=SUMPRODUCT(1*ISNUMBER(FIND("R",D4:J4)))} -> 1 | BN4: {=SUMPRODUCT(1*ISNUMBER(FIND("R",K4:Q4)))} -> 1 | BO4: {=SUMPRODUCT(1*ISNUMBER(FIND("R",R4:X4)))} -> 1 | BP4: {=SUMPRODUCT(1*ISNUMBER(FIND("R",Y4:AE4)))} -> 1 | BQ4: {=SUMPRODUCT(1*ISNUMBER(FIND("R",AF4:AL4)))} -> 1 | BR4: =SUM(AZ4:BK4) -> 31 | BT4: 10 | BU4: {=SUMPRODUCT(1*ISNUMBER(FIND("P",K4:AL4)))-SUMPRODUCT(1*ISNUMBER(FIND("午P",K4:AL4)))} -> 0
B5: T01029 | C5: 林雯琳 | D5: 01午m | E5: 01午B1 | F5: R | G5: 01午M | H5: 01午M | I5: 01午B1 | J5: 01午M | K5: R | L5: 01午M | M5: 01午m | N5: 01午M | O5: r' | P5: r' | Q5: 01午M | R5: 01午m | S5: 01午M | T5: R | U5: L | V5: L | W5: 01夜B1 | X5: 01夜B2 | Y5: R | Z5: r' | AA5: 01午M | AB5: 01午m | AC5: 01午M | AD5: 01中A | AE5: L | AF5: L | AG5: R | AH5: 日 | AI5: 01午B1 | AJ5: r' | AK5: 01夜B1 | AL5: 01夜B2 | AM5: =BT5+BU5 -> 10 | AN5: 2 | AO5: 2 | AP5: 4 | AQ5: 4 | AR5: =COUNTIF(K5:X5,"r'*") -> 2 | AS5: =COUNTIF(K5:X5,"R") -> 2 | AT5: =8-AN5-AP5-AR5 -> 0 | AU5: =8-AO5-AQ5-AS5 -> 0 | AV5: =COUNTIF(Y5:AL5,"r'*") -> 2 | AW5: =COUNTIF(Y5:AL5,"R") -> 2 | AX5: =COUNTIF(Y5:AL5,"r'*") -> 2 | AY5: =COUNTIF(Y5:AL5,"R") -> 2 | AZ5: =COUNTIF(G5:AK5,"*早*")-BA5 -> 0 | BA5: =COUNTIF(G5:AK5,"*早A") -> 0 | BB5: =COUNTIF(G5:AK5,"*中*") -> 1 | BC5: =COUNTIF(G5:AK5,"*午*")-BD5 -> 14 | BD5: =COUNTIF(G5:AK5,"*午F") -> 0 | BE5: =COUNTIF(G5:AK5,"*夜*") -> 3 | BF5: =COUNTIF(G5:AK5,"*T*") -> 0 | BG5: =COUNTIF(G5:AK5,"*日*") -> 1 | BH5: =COUNTIF(G5:AK5,"L") -> 4 | BI5: {=SUMPRODUCT(1*ISNUMBER(FIND("R",G5:AK5)))} -> 4 | BJ5: {=SUMPRODUCT(1*ISNUMBER(FIND("r",G5:AK5)))} -> 4 | BK5: {=SUMPRODUCT(1*ISNUMBER(FIND("P",G5:AK5)))-SUMPRODUCT(1*ISNUMBER(FIND("午P",G5:AK5)))} -> 0 | BL5: =SUM(G5:AK5) -> 0 | BM5: {=SUMPRODUCT(1*ISNUMBER(FIND("R",D5:J5)))} -> 1 | BN5: {=SUMPRODUCT(1*ISNUMBER(FIND("R",K5:Q5)))} -> 1 | BO5: {=SUMPRODUCT(1*ISNUMBER(FIND("R",R5:X5)))} -> 1 | BP5: {=SUMPRODUCT(1*ISNUMBER(FIND("R",Y5:AE5)))} -> 1 | BQ5: {=SUMPRODUCT(1*ISNUMBER(FIND("R",AF5:AL5)))} -> 1 | BR5: =SUM(AZ5:BK5) -> 31 | BT5: 10 | BU5: {=SUMPRODUCT(1*ISNUMBER(FIND("P",K5:AL5)))-SUMPRODUCT(1*ISNUMBER(FIND("午P",K5:AL5)))} -> 0
B6: T01734 | C6: 黃冠銘 | D6: 01早m | E6: R | F6: 01早m | G6: 01早M | H6: 01早m | I6: 01早M | J6: 01早M | K6: r' | L6: R | M6: L | N6: L | O6: L | P6: 01早m | Q6: 01早M | R6: 01早m | S6: R | T6: 01早M | U6: 01早m | V6: 01夜B1 | W6: 01夜B2 | X6: r' | Y6: R | Z6: 01早M | AA6: 01早m | AB6: 01夜B2 | AC6: 01夜B1 | AD6: r' | AE6: r' | AF6: 01早m | AG6: 01早M | AH6: 日 | AI6: R | AJ6: 01早M | AK6: 01早m | AL6: 01早B1 | AM6: =BT6+BU6 -> 9 | AN6: 2 | AO6: 2 | AP6: 4 | AQ6: 4 | AR6: =COUNTIF(K6:X6,"r'*") -> 2 | AS6: =COUNTIF(K6:X6,"R") -> 2 | AT6: =8-AN6-AP6-AR6 -> 0 | AU6: =8-AO6-AQ6-AS6 -> 0 | AV6: =COUNTIF(Y6:AL6,"r'*") -> 2 | AW6: =COUNTIF(Y6:AL6,"R") -> 2 | AX6: =COUNTIF(Y6:AL6,"r'*") -> 2 | AY6: =COUNTIF(Y6:AL6,"R") -> 2 | AZ6: =COUNTIF(G6:AK6,"*早*")-BA6 -> 15 | BA6: =COUNTIF(G6:AK6,"*早A") -> 0 | BB6: =COUNTIF(G6:AK6,"*中*") -> 0 | BC6: =COUNTIF(G6:AK6,"*午*")-BD6 -> 0 | BD6: =COUNTIF(G6:AK6,"*午F") -> 0 | BE6: =COUNTIF(G6:AK6,"*夜*") -> 4 | BF6: =COUNTIF(G6:AK6,"*T*") -> 0 | BG6: =COUNTIF(G6:AK6,"*日*") -> 1 | BH6: =COUNTIF(G6:AK6,"L") -> 3 | BI6: {=SUMPRODUCT(1*ISNUMBER(FIND("R",G6:AK6)))} -> 4 | BJ6: {=SUMPRODUCT(1*ISNUMBER(FIND("r",G6:AK6)))} -> 4 | BK6: {=SUMPRODUCT(1*ISNUMBER(FIND("P",G6:AK6)))-SUMPRODUCT(1*ISNUMBER(FIND("午P",G6:AK6)))} -> 0 | BL6: =SUM(G6:AK6) -> 0 | BM6: {=SUMPRODUCT(1*ISNUMBER(FIND("R",D6:J6)))} -> 1 | BN6: {=SUMPRODUCT(1*ISNUMBER(FIND("R",K6:Q6)))} -> 1 | BO6: {=SUMPRODUCT(1*ISNUMBER(FIND("R",R6:X6)))} -> 1 | BP6: {=SUMPRODUCT(1*ISNUMBER(FIND("R",Y6:AE6)))} -> 1 | BQ6: {=SUMPRODUCT(1*ISNUMBER(FIND("R",AF6:AL6)))} -> 1 | BR6: =SUM(AZ6:BK6) -> 31 | BT6: 9 | BU6: {=SUMPRODUCT(1*ISNUMBER(FIND("P",K6:AL6)))-SUMPRODUCT(1*ISNUMBER(FIND("午P",K6:AL6)))} -> 0
B7: T02287 | C7: 林江玉 | D7: R | E7: P | F7: 01中A | G7: 01早B1 | H7: 01早M | I7: 01早m | J7: r' | K7: R | L7: L | M7: L | N7: L | O7: L | P7: L | Q7: r' | R7: R | S7: L | T7: L | U7: L | V7: L | W7: L | X7: r' | Y7: R | Z7: L | AA7: 日 | AB7: 01早M加(AFC訓) | AC7: 01中A | AD7: r' | AE7: 01早m | AF7: 01早M | AG7: 01夜B2 | AH7: 01夜B1 | AI7: 01夜B2 | AJ7: r' | AK7: R | AL7: 01夜B1 | AM7: =BT7+BU7 -> 11 | AN7: 2 | AO7: 2 | AP7: 4 | AQ7: 4 | AR7: =COUNTIF(K7:X7,"r'*") -> 2 | AS7: =COUNTIF(K7:X7,"R") -> 2 | AT7: =8-AN7-AP7-AR7 -> 0 | AU7: =8-AO7-AQ7-AS7 -> 0 | AV7: =COUNTIF(Y7:AL7,"r'*") -> 2 | AW7: =COUNTIF(Y7:AL7,"R") -> 2 | AX7: =COUNTIF(Y7:AL7,"r'*") -> 2 | AY7: =COUNTIF(Y7:AL7,"R") -> 2 | AZ7: =COUNTIF(G7:AK7,"*早*")-BA7 -> 6 | BA7: =COUNTIF(G7:AK7,"*早A") -> 0 | BB7: =COUNTIF(G7:AK7,"*中*") -> 1 | BC7: =COUNTIF(G7:AK7,"*午*")-BD7 -> 0 | BD7: =COUNTIF(G7:AK7,"*午F") -> 0 | BE7: =COUNTIF(G7:AK7,"*夜*") -> 3 | BF7: =COUNTIF(G7:AK7,"*T*") -> 0 | BG7: =COUNTIF(G7:AK7,"*日*") -> 1 | BH7: =COUNTIF(G7:AK7,"L") -> 11 | BI7: {=SUMPRODUCT(1*ISNUMBER(FIND("R",G7:AK7)))} -> 4 | BJ7: {=SUMPRODUCT(1*ISNUMBER(FIND("r",G7:AK7)))} -> 5 | BK7: {=SUMPRODUCT(1*ISNUMBER(FIND("P",G7:AK7)))-SUMPRODUCT(1*ISNUMBER(FIND("午P",G7:AK7)))} -> 0 | BL7: =SUM(G7:AK7) -> 0 | BM7: {=SUMPRODUCT(1*ISNUMBER(FIND("R",D7:J7)))} -> 1 | BN7: {=SUMPRODUCT(1*ISNUMBER(FIND("R",K7:Q7)))} -> 1 | BO7: {=SUMPRODUCT(1*ISNUMBER(FIND("R",R7:X7)))} -> 1 | BP7: {=SUMPRODUCT(1*ISNUMBER(FIND("R",Y7:AE7)))} -> 1 | BQ7: {=SUMPRODUCT(1*ISNUMBER(FIND("R",AF7:AL7)))} -> 1 | BR7: =SUM(AZ7:BK7) -> 31 | BT7: 11 | BU7: {=SUMPRODUCT(1*ISNUMBER(FIND("P",K7:AL7)))-SUMPRODUCT(1*ISNUMBER(FIND("午P",K7:AL7)))} -> 0
B8: T02359 | C8: 陳佳婷 | D8: R | E8: r' | F8: 01早M | G8: 01早m | H8: 01中A | I8: r' | J8: 01早m | K8: 01早m | L8: 01早M | M8: 01早m | N8: R | O8: 01早M | P8: r' | Q8: 01早m | R8: 01早M | S8: 01早m | T8: 01夜B1 | U8: 01夜B2 | V8: R | W8: r' | X8: 01早m | Y8: R | Z8: r' | AA8: 01早M | AB8: 日 | AC8: 01早M | AD8: 01早m | AE8: 01早M | AF8: R | AG8: 01早m | AH8: 01早M | AI8: 01早m(身心減壓) | AJ8: 01夜B1 | AK8: 01夜B2 | AL8: r' | AM8: =BT8+BU8 -> 9 | AN8: 2 | AO8: 2 | AP8: 4 | AQ8: 4 | AR8: =COUNTIF(K8:X8,"r'*") -> 2 | AS8: =COUNTIF(K8:X8,"R") -> 2 | AT8: =8-AN8-AP8-AR8 -> 0 | AU8: =8-AO8-AQ8-AS8 -> 0 | AV8: =COUNTIF(Y8:AL8,"r'*") -> 2 | AW8: =COUNTIF(Y8:AL8,"R") -> 2 | AX8: =COUNTIF(Y8:AL8,"r'*") -> 2 | AY8: =COUNTIF(Y8:AL8,"R") -> 2 | AZ8: =COUNTIF(G8:AK8,"*早*")-BA8 -> 17 | BA8: =COUNTIF(G8:AK8,"*早A") -> 0 | BB8: =COUNTIF(G8:AK8,"*中*") -> 1 | BC8: =COUNTIF(G8:AK8,"*午*")-BD8 -> 0 | BD8: =COUNTIF(G8:AK8,"*午F") -> 0 | BE8: =COUNTIF(G8:AK8,"*夜*") -> 4 | BF8: =COUNTIF(G8:AK8,"*T*") -> 0 | BG8: =COUNTIF(G8:AK8,"*日*") -> 1 | BH8: =COUNTIF(G8:AK8,"L") -> 0 | BI8: {=SUMPRODUCT(1*ISNUMBER(FIND("R",G8:AK8)))} -> 4 | BJ8: {=SUMPRODUCT(1*ISNUMBER(FIND("r",G8:AK8)))} -> 4 | BK8: {=SUMPRODUCT(1*ISNUMBER(FIND("P",G8:AK8)))-SUMPRODUCT(1*ISNUMBER(FIND("午P",G8:AK8)))} -> 0 | BL8: =SUM(G8:AK8) -> 0 | BM8: {=SUMPRODUCT(1*ISNUMBER(FIND("R",D8:J8)))} -> 1 | BN8: {=SUMPRODUCT(1*ISNUMBER(FIND("R",K8:Q8)))} -> 1 | BO8: {=SUMPRODUCT(1*ISNUMBER(FIND("R",R8:X8)))} -> 1 | BP8: {=SUMPRODUCT(1*ISNUMBER(FIND("R",Y8:AE8)))} -> 1 | BQ8: {=SUMPRODUCT(1*ISNUMBER(FIND("R",AF8:AL8)))} -> 1 | BR8: =SUM(AZ8:BK8) -> 31 | BT8: 9 | BU8: {=SUMPRODUCT(1*ISNUMBER(FIND("P",K8:AL8)))-SUMPRODUCT(1*ISNUMBER(FIND("午P",K8:AL8)))} -> 0
B9: T02363 | C9: 林孟錡 | D9: 01夜B1 | E9: 01夜B2 | F9: 01夜B1 | G9: R | H9: 01夜B2 | I9: 01夜B1 | J9: 01夜B2 | K9: 01夜B2 | L9: 01夜B1 | M9: 01夜B2 | N9: R | O9: r' | P9: r' | Q9: 01夜B1 | R9: 01夜B2 | S9: 01夜B1 | T9: 01夜B2 | U9: 01夜B1 | V9: 01夜B2 | W9: R | X9: 01夜B1 | Y9: 01夜B2 | Z9: 01夜B1 | AA9: 01夜B2 | AB9: 01夜B1 | AC9: R | AD9: 01夜B2 | AE9: 01夜B1 | AF9: 01夜B2 | AG9: R | AH9: 01夜B2 | AI9: 01夜B1 | AJ9: 01夜B2 | AK9: r' | AL9: r' | AM9: =BT9+BU9 -> 10 | AN9: 2 | AO9: 2 | AP9: 4 | AQ9: 4 | AR9: =COUNTIF(K9:X9,"r'*") -> 2 | AS9: =COUNTIF(K9:X9,"R") -> 2 | AT9: =8-AN9-AP9-AR9 -> 0 | AU9: =8-AO9-AQ9-AS9 -> 0 | AV9: =COUNTIF(Y9:AL9,"r'*") -> 2 | AW9: =COUNTIF(Y9:AL9,"R") -> 2 | AX9: =COUNTIF(Y9:AL9,"r'*") -> 2 | AY9: =COUNTIF(Y9:AL9,"R") -> 2 | AZ9: =COUNTIF(G9:AK9,"*早*")-BA9 -> 0 | BA9: =COUNTIF(G9:AK9,"*早A") -> 0 | BB9: =COUNTIF(G9:AK9,"*中*") -> 0 | BC9: =COUNTIF(G9:AK9,"*午*")-BD9 -> 0 | BD9: =COUNTIF(G9:AK9,"*午F") -> 0 | BE9: =COUNTIF(G9:AK9,"*夜*") -> 23 | BF9: =COUNTIF(G9:AK9,"*T*") -> 0 | BG9: =COUNTIF(G9:AK9,"*日*") -> 0 | BH9: =COUNTIF(G9:AK9,"L") -> 0 | BI9: {=SUMPRODUCT(1*ISNUMBER(FIND("R",G9:AK9)))} -> 5 | BJ9: {=SUMPRODUCT(1*ISNUMBER(FIND("r",G9:AK9)))} -> 3 | BK9: {=SUMPRODUCT(1*ISNUMBER(FIND("P",G9:AK9)))-SUMPRODUCT(1*ISNUMBER(FIND("午P",G9:AK9)))} -> 0 | BL9: =SUM(G9:AK9) -> 0 | BM9: {=SUMPRODUCT(1*ISNUMBER(FIND("R",D9:J9)))} -> 1 | BN9: {=SUMPRODUCT(1*ISNUMBER(FIND("R",K9:Q9)))} -> 1 | BO9: {=SUMPRODUCT(1*ISNUMBER(FIND("R",R9:X9)))} -> 1 | BP9: {=SUMPRODUCT(1*ISNUMBER(FIND("R",Y9:AE9)))} -> 1 | BQ9: {=SUMPRODUCT(1*ISNUMBER(FIND("R",AF9:AL9)))} -> 1 | BR9: =SUM(AZ9:BK9) -> 31 | BT9: 10 | BU9: {=SUMPRODUCT(1*ISNUMBER(FIND("P",K9:AL9)))-SUMPRODUCT(1*ISNUMBER(FIND("午P",K9:AL9)))} -> 0
B10: T02504 | C10: 潘元浩 | D10: 01午B1 | E10: 01午M | F10: 01午M | G10: r' | H10: R | I10: 01午m | J10: 01午B1 | K10: 01午m | L10: R | M10: 01夜B1 | N10: 01夜B2 | O10: 01夜B1 | P10: 01夜B2 | Q10: r' | R10: R | S10: 01午m | T10: 01午M | U10: r' | V10: 01午B1 | W10: 01午m | X10: 01午M | Y10: 01午m | Z10: r' | AA10: 日 | AB10: 01午M | AC10: R | AD10: L | AE10: L | AF10: r' | AG10: 01午m | AH10: 01午M | AI10: 01中A | AJ10: 01午M | AK10: 01午m | AL10: R | AM10: =BT10+BU10 -> 9 | AN10: 2 | AO10: 2 | AP10: 4 | AQ10: 4 | AR10: =COUNTIF(K10:X10,"r'*") -> 2 | AS10: =COUNTIF(K10:X10,"R") -> 2 | AT10: =8-AN10-AP10-AR10 -> 0 | AU10: =8-AO10-AQ10-AS10 -> 0 | AV10: =COUNTIF(Y10:AL10,"r'*") -> 2 | AW10: =COUNTIF(Y10:AL10,"R") -> 2 | AX10: =COUNTIF(Y10:AL10,"r'*") -> 2 | AY10: =COUNTIF(Y10:AL10,"R") -> 2 | AZ10: =COUNTIF(G10:AK10,"*早*")-BA10 -> 0 | BA10: =COUNTIF(G10:AK10,"*早A") -> 0 | BB10: =COUNTIF(G10:AK10,"*中*") -> 1 | BC10: =COUNTIF(G10:AK10,"*午*")-BD10 -> 14 | BD10: =COUNTIF(G10:AK10,"*午F") -> 0 | BE10: =COUNTIF(G10:AK10,"*夜*") -> 4 | BF10: =COUNTIF(G10:AK10,"*T*") -> 0 | BG10: =COUNTIF(G10:AK10,"*日*") -> 1 | BH10: =COUNTIF(G10:AK10,"L") -> 2 | BI10: {=SUMPRODUCT(1*ISNUMBER(FIND("R",G10:AK10)))} -> 4 | BJ10: {=SUMPRODUCT(1*ISNUMBER(FIND("r",G10:AK10)))} -> 5 | BK10: {=SUMPRODUCT(1*ISNUMBER(FIND("P",G10:AK10)))-SUMPRODUCT(1*ISNUMBER(FIND("午P",G10:AK10)))} -> 0 | BL10: =SUM(G10:AK10) -> 0 | BM10: {=SUMPRODUCT(1*ISNUMBER(FIND("R",D10:J10)))} -> 1 | BN10: {=SUMPRODUCT(1*ISNUMBER(FIND("R",K10:Q10)))} -> 1 | BO10: {=SUMPRODUCT(1*ISNUMBER(FIND("R",R10:X10)))} -> 1 | BP10: {=SUMPRODUCT(1*ISNUMBER(FIND("R",Y10:AE10)))} -> 1 | BQ10: {=SUMPRODUCT(1*ISNUMBER(FIND("R",AF10:AL10)))} -> 1 | BR10: =SUM(AZ10:BK10) -> 31 | BT10: 9 | BU10: {=SUMPRODUCT(1*ISNUMBER(FIND("P",K10:AL10)))-SUMPRODUCT(1*ISNUMBER(FIND("午P",K10:AL10)))} -> 0
B11: T02505 | C11: 李慧盺 | D11: 01夜B2 | E11: 01夜B1 | F11: 01夜B2 | G11: 01夜B1 | H11: R | I11: P | J11: r' | K11: 01午M | L11: 01午m | M11: R | N11: 01夜B1 | O11: 01夜B2 | P11: 01夜B1 | Q11: 01夜B2 | R11: r' | S11: r' | T11: 01中A | U11: 01午m | V11: 01午M | W11: R | X11: 01午B1 | Y11: 01午M | Z11: 01午m | AA11: r' | AB11: 日 | AC11: R | AD11: L | AE11: L | AF11: r' | AG11: 01午M | AH11: 01午m | AI11: 01午M | AJ11: 01午m | AK11: 01午B1 | AL11: R | AM11: =BT11+BU11 -> 10 | AN11: 2 | AO11: 2 | AP11: 4 | AQ11: 4 | AR11: =COUNTIF(K11:X11,"r'*") -> 2 | AS11: =COUNTIF(K11:X11,"R") -> 2 | AT11: =8-AN11-AP11-AR11 -> 0 | AU11: =8-AO11-AQ11-AS11 -> 0 | AV11: =COUNTIF(Y11:AL11,"r'*") -> 2 | AW11: =COUNTIF(Y11:AL11,"R") -> 2 | AX11: =COUNTIF(Y11:AL11,"r'*") -> 2 | AY11: =COUNTIF(Y11:AL11,"R") -> 2 | AZ11: =COUNTIF(G11:AK11,"*早*")-BA11 -> 0 | BA11: =COUNTIF(G11:AK11,"*早A") -> 0 | BB11: =COUNTIF(G11:AK11,"*中*") -> 1 | BC11: =COUNTIF(G11:AK11,"*午*")-BD11 -> 12 | BD11: =COUNTIF(G11:AK11,"*午F") -> 0 | BE11: =COUNTIF(G11:AK11,"*夜*") -> 5 | BF11: =COUNTIF(G11:AK11,"*T*") -> 0 | BG11: =COUNTIF(G11:AK11,"*日*") -> 1 | BH11: =COUNTIF(G11:AK11,"L") -> 2 | BI11: {=SUMPRODUCT(1*ISNUMBER(FIND("R",G11:AK11)))} -> 4 | BJ11: {=SUMPRODUCT(1*ISNUMBER(FIND("r",G11:AK11)))} -> 5 | BK11: {=SUMPRODUCT(1*ISNUMBER(FIND("P",G11:AK11)))-SUMPRODUCT(1*ISNUMBER(FIND("午P",G11:AK11)))} -> 1 | BL11: =SUM(G11:AK11) -> 0 | BM11: {=SUMPRODUCT(1*ISNUMBER(FIND("R",D11:J11)))} -> 1 | BN11: {=SUMPRODUCT(1*ISNUMBER(FIND("R",K11:Q11)))} -> 1 | BO11: {=SUMPRODUCT(1*ISNUMBER(FIND("R",R11:X11)))} -> 1 | BP11: {=SUMPRODUCT(1*ISNUMBER(FIND("R",Y11:AE11)))} -> 1 | BQ11: {=SUMPRODUCT(1*ISNUMBER(FIND("R",AF11:AL11)))} -> 1 | BR11: =SUM(AZ11:BK11) -> 31 | BT11: 10 | BU11: {=SUMPRODUCT(1*ISNUMBER(FIND("P",K11:AL11)))-SUMPRODUCT(1*ISNUMBER(FIND("午P",K11:AL11)))} -> 0
B12: T02776 | C12: 陳怡臻 | D12: 01早B2(跟) | E12: 01早B1(跟) | F12: 01午M | G12: 01午m | H12: 01午m | I12: R | J12: 01午B2 | K12: 01夜B1 | L12: 01夜B2 | M12: r' | N12: r' | O12: 01午m | P12: 01午M | Q12: R | R12: R | S12: r' | T12: 01早m | U12: 01早B2 | V12: 01早M | W12: 01早B2 | X12: 01中A | Y12: 01早M | Z12: R | AA12: r' | AB12: 01早m加(AFC訓) | AC12: 01早m | AD12: 01早M | AE12: 01夜B2 | AF12: 01夜B1 | AG12: r' | AH12: R | AI12: 01午m | AJ12: 01午B1 | AK12: 01午M | AL12: 01午m | AM12: =BT12+BU12 -> 10 | AN12: 2 | AO12: 2 | AP12: 3 | AQ12: 4 | AR12: =COUNTIF(K12:X12,"r'*") -> 3 | AS12: =COUNTIF(K12:X12,"R") -> 2 | AT12: =8-AN12-AP12-AR12 -> 0 | AU12: =8-AO12-AQ12-AS12 -> 0 | AV12: =COUNTIF(Y12:AL12,"r'*") -> 2 | AW12: =COUNTIF(Y12:AL12,"R") -> 2 | AX12: =COUNTIF(Y12:AL12,"r'*") -> 2 | AY12: =COUNTIF(Y12:AL12,"R") -> 2 | AZ12: =COUNTIF(G12:AK12,"*早*")-BA12 -> 8 | BA12: =COUNTIF(G12:AK12,"*早A") -> 0 | BB12: =COUNTIF(G12:AK12,"*中*") -> 1 | BC12: =COUNTIF(G12:AK12,"*午*")-BD12 -> 8 | BD12: =COUNTIF(G12:AK12,"*午F") -> 0 | BE12: =COUNTIF(G12:AK12,"*夜*") -> 4 | BF12: =COUNTIF(G12:AK12,"*T*") -> 0 | BG12: =COUNTIF(G12:AK12,"*日*") -> 0 | BH12: =COUNTIF(G12:AK12,"L") -> 0 | BI12: {=SUMPRODUCT(1*ISNUMBER(FIND("R",G12:AK12)))} -> 5 | BJ12: {=SUMPRODUCT(1*ISNUMBER(FIND("r",G12:AK12)))} -> 5 | BK12: {=SUMPRODUCT(1*ISNUMBER(FIND("P",G12:AK12)))-SUMPRODUCT(1*ISNUMBER(FIND("午P",G12:AK12)))} -> 0 | BL12: =SUM(G12:AK12) -> 0 | BM12: {=SUMPRODUCT(1*ISNUMBER(FIND("R",D12:J12)))} -> 1 | BN12: {=SUMPRODUCT(1*ISNUMBER(FIND("R",K12:Q12)))} -> 1 | BO12: {=SUMPRODUCT(1*ISNUMBER(FIND("R",R12:X12)))} -> 1 | BP12: {=SUMPRODUCT(1*ISNUMBER(FIND("R",Y12:AE12)))} -> 1 | BQ12: {=SUMPRODUCT(1*ISNUMBER(FIND("R",AF12:AL12)))} -> 1 | BR12: =SUM(AZ12:BK12) -> 31 | BT12: 10 | BU12: {=SUMPRODUCT(1*ISNUMBER(FIND("P",K12:AL12)))-SUMPRODUCT(1*ISNUMBER(FIND("午P",K12:AL12)))} -> 0
B13: T02777 | C13: 彭裕涵 | D13: 01午m | E13: 01午B1 | F13: r' | G13: R | H13: r' | I13: 01早B1(跟) | J13: 01早B2 | K13: 01早M | L13: r' | M13: 01早M | N13: 01早m | O13: 01午M | P13: 01午m | Q13: R | R13: R | S13: 01早M | T13: r' | U13: 01早M | V13: 01早m | W13: 01早M | X13: r' | Y13: 01夜B1 | Z13: 01夜B2 | AA13: 01夜B1 | AB13: r' | AC13: R | AD13: 01午m | AE13: 01午M | AF13: 01午m | AG13: 01夜B1 | AH13: r' | AI13: R | AJ13: 01早m | AK13: 01中A | AL13: 01早M | AM13: =BT13+BU13 -> 10 | AN13: 2 | AO13: 2 | AP13: 3 | AQ13: 4 | AR13: =COUNTIF(K13:X13,"r'*") -> 3 | AS13: =COUNTIF(K13:X13,"R") -> 2 | AT13: =8-AN13-AP13-AR13 -> 0 | AU13: =8-AO13-AQ13-AS13 -> 0 | AV13: =COUNTIF(Y13:AL13,"r'*") -> 2 | AW13: =COUNTIF(Y13:AL13,"R") -> 2 | AX13: =COUNTIF(Y13:AL13,"r'*") -> 2 | AY13: =COUNTIF(Y13:AL13,"R") -> 2 | AZ13: =COUNTIF(G13:AK13,"*早*")-BA13 -> 10 | BA13: =COUNTIF(G13:AK13,"*早A") -> 0 | BB13: =COUNTIF(G13:AK13,"*中*") -> 1 | BC13: =COUNTIF(G13:AK13,"*午*")-BD13 -> 5 | BD13: =COUNTIF(G13:AK13,"*午F") -> 0 | BE13: =COUNTIF(G13:AK13,"*夜*") -> 4 | BF13: =COUNTIF(G13:AK13,"*T*") -> 0 | BG13: =COUNTIF(G13:AK13,"*日*") -> 0 | BH13: =COUNTIF(G13:AK13,"L") -> 0 | BI13: {=SUMPRODUCT(1*ISNUMBER(FIND("R",G13:AK13)))} -> 5 | BJ13: {=SUMPRODUCT(1*ISNUMBER(FIND("r",G13:AK13)))} -> 6 | BK13: {=SUMPRODUCT(1*ISNUMBER(FIND("P",G13:AK13)))-SUMPRODUCT(1*ISNUMBER(FIND("午P",G13:AK13)))} -> 0 | BL13: =SUM(G13:AK13) -> 0 | BM13: {=SUMPRODUCT(1*ISNUMBER(FIND("R",D13:J13)))} -> 1 | BN13: {=SUMPRODUCT(1*ISNUMBER(FIND("R",K13:Q13)))} -> 1 | BO13: {=SUMPRODUCT(1*ISNUMBER(FIND("R",R13:X13)))} -> 1 | BP13: {=SUMPRODUCT(1*ISNUMBER(FIND("R",Y13:AE13)))} -> 1 | BQ13: {=SUMPRODUCT(1*ISNUMBER(FIND("R",AF13:AL13)))} -> 1 | BR13: =SUM(AZ13:BK13) -> 31 | BT13: 10 | BU13: {=SUMPRODUCT(1*ISNUMBER(FIND("P",K13:AL13)))-SUMPRODUCT(1*ISNUMBER(FIND("午P",K13:AL13)))} -> 0
B14: T00557 | C14: 陳志明 | D14: 01早B2 | E14: r' | F14: L | G14: R | H14: 01早B1 | I14: 01早B1 | J14: r' | K14: 01早B2 | L14: 01早B1 | M14: 01早B2 | N14: 01早B1 | O14: 01早B2 | P14: L | Q14: R | R14: R | S14: 01早B1 | T14: 01午B2 | U14: 01午B1 | V14: 01中A | W14: r' | X14: r' | Y14: 01午B1 | Z14: R | AA14: 01午B1 | AB14: 日 | AC14: r' | AD14: r' | AE14: 01午B2 | AF14: 01午B1 | AG14: 01中A | AH14: R | AI14: 01早B2(身心減壓) | AJ14: 01早B2 | AK14: P | AL14: 01午B2 | AM14: =BT14+BU14 -> 9 | AN14: 2 | AO14: 2 | AP14: 4 | AQ14: 4 | AR14: =COUNTIF(K14:X14,"r'*") -> 2 | AS14: =COUNTIF(K14:X14,"R") -> 2 | AT14: =8-AN14-AP14-AR14 -> 0 | AU14: =8-AO14-AQ14-AS14 -> 0 | AV14: =COUNTIF(Y14:AL14,"r'*") -> 2 | AW14: =COUNTIF(Y14:AL14,"R") -> 2 | AX14: =COUNTIF(Y14:AL14,"r'*") -> 2 | AY14: =COUNTIF(Y14:AL14,"R") -> 2 | AZ14: =COUNTIF(G14:AK14,"*早*")-BA14 -> 10 | BA14: =COUNTIF(G14:AK14,"*早A") -> 0 | BB14: =COUNTIF(G14:AK14,"*中*") -> 2 | BC14: =COUNTIF(G14:AK14,"*午*")-BD14 -> 6 | BD14: =COUNTIF(G14:AK14,"*午F") -> 0 | BE14: =COUNTIF(G14:AK14,"*夜*") -> 0 | BF14: =COUNTIF(G14:AK14,"*T*") -> 0 | BG14: =COUNTIF(G14:AK14,"*日*") -> 1 | BH14: =COUNTIF(G14:AK14,"L") -> 1 | BI14: {=SUMPRODUCT(1*ISNUMBER(FIND("R",G14:AK14)))} -> 5 | BJ14: {=SUMPRODUCT(1*ISNUMBER(FIND("r",G14:AK14)))} -> 5 | BK14: {=SUMPRODUCT(1*ISNUMBER(FIND("P",G14:AK14)))-SUMPRODUCT(1*ISNUMBER(FIND("午P",G14:AK14)))} -> 1 | BL14: =SUM(G14:AK14) -> 0 | BM14: {=SUMPRODUCT(1*ISNUMBER(FIND("R",D14:J14)))} -> 1 | BN14: {=SUMPRODUCT(1*ISNUMBER(FIND("R",K14:Q14)))} -> 1 | BO14: {=SUMPRODUCT(1*ISNUMBER(FIND("R",R14:X14)))} -> 1 | BP14: {=SUMPRODUCT(1*ISNUMBER(FIND("R",Y14:AE14)))} -> 1 | BQ14: {=SUMPRODUCT(1*ISNUMBER(FIND("R",AF14:AL14)))} -> 1 | BR14: =SUM(AZ14:BK14) -> 31 | BT14: 8 | BU14: {=SUMPRODUCT(1*ISNUMBER(FIND("P",K14:AL14)))-SUMPRODUCT(1*ISNUMBER(FIND("午P",K14:AL14)))} -> 1
B15: T00929 | C15: 簡婉蓁 | D15: 01午B1 | E15: 01午B2 | F15: R | G15: 01早B1 | H15: 01早B2 | I15: 01中A | J15: r' | K15: r' | L15: R | M15: P | N15: P | O15: P | P15: P | Q15: r' | R15: R | S15: 01早B2 | T15: 01早B1 | U15: 01早B2 | V15: 01早B1 | W15: 01中A | X15: 01早B1 | Y15: R | Z15: 01早B2 | AA15: 01早B1 | AB15: 01早B1加(AFC訓) | AC15: 日 | AD15: r' | AE15: r' | AF15: 01早B1 | AG15: 01早B2 | AH15: 01早B1 | AI15: 01早B2(身心減壓) | AJ15: 01早B1 | AK15: R | AL15: 01早B2 | AM15: =BT15+BU15 -> 10 | AN15: 2 | AO15: 2 | AP15: 4 | AQ15: 4 | AR15: =COUNTIF(K15:X15,"r'*") -> 2 | AS15: =COUNTIF(K15:X15,"R") -> 2 | AT15: =8-AN15-AP15-AR15 -> 0 | AU15: =8-AO15-AQ15-AS15 -> 0 | AV15: =COUNTIF(Y15:AL15,"r'*") -> 2 | AW15: =COUNTIF(Y15:AL15,"R") -> 2 | AX15: =COUNTIF(Y15:AL15,"r'*") -> 2 | AY15: =COUNTIF(Y15:AL15,"R") -> 2 | AZ15: =COUNTIF(G15:AK15,"*早*")-BA15 -> 15 | BA15: =COUNTIF(G15:AK15,"*早A") -> 0 | BB15: =COUNTIF(G15:AK15,"*中*") -> 2 | BC15: =COUNTIF(G15:AK15,"*午*")-BD15 -> 0 | BD15: =COUNTIF(G15:AK15,"*午F") -> 0 | BE15: =COUNTIF(G15:AK15,"*夜*") -> 0 | BF15: =COUNTIF(G15:AK15,"*T*") -> 0 | BG15: =COUNTIF(G15:AK15,"*日*") -> 1 | BH15: =COUNTIF(G15:AK15,"L") -> 0 | BI15: {=SUMPRODUCT(1*ISNUMBER(FIND("R",G15:AK15)))} -> 4 | BJ15: {=SUMPRODUCT(1*ISNUMBER(FIND("r",G15:AK15)))} -> 5 | BK15: {=SUMPRODUCT(1*ISNUMBER(FIND("P",G15:AK15)))-SUMPRODUCT(1*ISNUMBER(FIND("午P",G15:AK15)))} -> 4 | BL15: =SUM(G15:AK15) -> 0 | BM15: {=SUMPRODUCT(1*ISNUMBER(FIND("R",D15:J15)))} -> 1 | BN15: {=SUMPRODUCT(1*ISNUMBER(FIND("R",K15:Q15)))} -> 1 | BO15: {=SUMPRODUCT(1*ISNUMBER(FIND("R",R15:X15)))} -> 1 | BP15: {=SUMPRODUCT(1*ISNUMBER(FIND("R",Y15:AE15)))} -> 1 | BQ15: {=SUMPRODUCT(1*ISNUMBER(FIND("R",AF15:AL15)))} -> 1 | BR15: =SUM(AZ15:BK15) -> 31 | BT15: 6 | BU15: {=SUMPRODUCT(1*ISNUMBER(FIND("P",K15:AL15)))-SUMPRODUCT(1*ISNUMBER(FIND("午P",K15:AL15)))} -> 4
... B26: T02769 | C26: 吳東翰 | D26: r' | E26: r' | F26: 01午B2(跟) | G26: 01午B1(跟) | H26: 01午B2 | I26: 01午B1 | J26: R | K26: 01午B1 | L26: 01午B2 | M26: 01午B1 | N26: 01午B2 | O26: 01午B1 | P26: r' | Q26: R | R26: R | S26: r' | T26: 01早B2 | U26: 01早B1 | V26: r' | W26: 01早B1 | X26: 01早B2 | Y26: 01中A | Z26: 01早B2 | AA26: R | AB26: 01午B1 | AC26: R | AD26: 01早B2 | AE26: 01早B1 | AF26: 01早B2 | AG26: 01午B1 | AH26: r' | AI26: 01午B2 | AJ26: r' | AK26: 日 | AL26: 01午B2 | AM26: =BT26+BU26 -> 10 | AN26: 2 | AO26: 2 | AP26: 3 | AQ26: 4 | AR26: =COUNTIF(K26:X26,"r'*") -> 3 | AS26: =COUNTIF(K26:X26,"R") -> 2 | AT26: =8-AN26-AP26-AR26 -> 0 | AU26: =8-AO26-AQ26-AS26 -> 0 | AV26: =COUNTIF(Y26:AL26,"r'*") -> 2 | AW26: =COUNTIF(Y26:AL26,"R") -> 2 | AX26: =COUNTIF(Y26:AL26,"r'*") -> 2 | AY26: =COUNTIF(Y26:AL26,"R") -> 2 | AZ26: =COUNTIF(G26:AK26,"*早*")-BA26 -> 8 | BA26: =COUNTIF(G26:AK26,"*早A") -> 0 | BB26: =COUNTIF(G26:AK26,"*中*") -> 1 | BC26: =COUNTIF(G26:AK26,"*午*")-BD26 -> 11 | BD26: =COUNTIF(G26:AK26,"*午F") -> 0 | BE26: =COUNTIF(G26:AK26,"*夜*") -> 0 | BF26: =COUNTIF(G26:AK26,"*T*") -> 0 | BG26: =COUNTIF(G26:AK26,"*日*") -> 1 | BH26: =COUNTIF(G26:AK26,"L") -> 0 | BI26: {=SUMPRODUCT(1*ISNUMBER(FIND("R",G26:AK26)))} -> 5 | BJ26: {=SUMPRODUCT(1*ISNUMBER(FIND("r",G26:AK26)))} -> 5 | BK26: {=SUMPRODUCT(1*ISNUMBER(FIND("P",G26:AK26)))-SUMPRODUCT(1*ISNUMBER(FIND("午P",G26:AK26)))} -> 0 | BL26: =SUM(G26:AK26) -> 0 | BM26: {=SUMPRODUCT(1*ISNUMBER(FIND("R",D26:J26)))} -> 1 | BN26: {=SUMPRODUCT(1*ISNUMBER(FIND("R",K26:Q26)))} -> 1 | BO26: {=SUMPRODUCT(1*ISNUMBER(FIND("R",R26:X26)))} -> 1 | BP26: {=SUMPRODUCT(1*ISNUMBER(FIND("R",Y26:AE26)))} -> 2 | BQ26: {=SUMPRODUCT(1*ISNUMBER(FIND("R",AF26:AL26)))} -> 0 | BR26: =SUM(AZ26:BK26) -> 31 | BT26: 10 | BU26: {=SUMPRODUCT(1*ISNUMBER(FIND("P",K26:AL26)))-SUMPRODUCT(1*ISNUMBER(FIND("午P",K26:AL26)))} -> 0
C27: 班別代號: OO早A：0620~1520(9hr) OO早：0630~1430(8hr) OO早G：0730~1530(8hr) OO早Q：0930~1730(8hr) OO中A：1100~1900(8hr) OO午P：1400~2200(8hr) OO午：1410~2210(8hr) OO午F：1500~2400(9hr) OO夜：2150~0650(9hr) OO代表車站、段辦(例如：A17早班，代碼17早。A17正常班，代碼17日。中心正常班，代碼日。北段段辦正常班，代號41日。中段段辦正常班，代號42日。南段段辦正常班，代號43日。) T：訓練 0830~1730 日：0830~1730 R：例假 L：其他休假 r：休假 P：國定假日
A28: 備註
B34: 員編 ID No. | C34: 日期 星期 姓名 | D34: =D1 -> 46201 | E34: =E1 -> 46202 | F34: =F1 -> 46203 | G34: =G1 -> 46204 | H34: =H1 -> 46205 | I34: =I1 -> 46206 | J34: =J1 -> 46207 | K34: =K1 -> 46208 | ... AL34: =AL1 -> 46235
D35: =D2 -> a | E35: =E2 -> a | F35: =F2 -> a | G35: =G2 -> a | H35: =H2 -> a | I35: =I2 -> a | J35: =J2 -> a | K35: =K2 -> a | ... AL35: =AL2 -> a | AM35: 01早B2c
C36: 41早 | D36: =COUNTIF(D$3:D$26,"41早") -> 0 | E36: =COUNTIF(E$3:E$26,"41早") -> 0 | F36: =COUNTIF(F$3:F$26,"41早") -> 0 | G36: =COUNTIF(G$3:G$26,"41早") -> 0 | H36: =COUNTIF(H$3:H$26,"41早") -> 0 | I36: =COUNTIF(I$3:I$26,"41早") -> 0 | J36: =COUNTIF(J$3:J$26,"41早") -> 0 | K36: =COUNTIF(K$3:K$26,"41早") -> 0 | ... P36: =COUNTIF(P$3:P$26,"41早") -> 0 | Q36: =COUNTIF(Q$3:Q$26,"41早*") -> 0 | R36: =COUNTIF(R$3:R$26,"41早") -> 0 | S36: =COUNTIF(S$3:S$26,"41早") -> 0 | T36: =COUNTIF(T$3:T$26,"41早") -> 0 | U36: =COUNTIF(U$3:U$26,"41早") -> 0 | V36: =COUNTIF(V$3:V$26,"41早") -> 0 | W36: =COUNTIF(W$3:W$26,"41早") -> 0 | X36: =COUNTIF(X$3:X$26,"41早") -> 0 | Y36: =COUNTIF(Y$3:Y$26,"41早") -> 0 | ... AL36: =COUNTIF(AL$3:AL$26,"41早") -> 0
C37: 41午 | D37: =COUNTIF(D$3:D$26,"41午") -> 0 | E37: =COUNTIF(E$3:E$26,"41午") -> 0 | F37: =COUNTIF(F$3:F$26,"41午") -> 0 | G37: =COUNTIF(G$3:G$26,"41午") -> 0 | H37: =COUNTIF(H$3:H$26,"41午") -> 0 | I37: =COUNTIF(I$3:I$26,"41午") -> 0 | J37: =COUNTIF(J$3:J$26,"41午") -> 0 | K37: =COUNTIF(K$3:K$26,"41午") -> 0 | L37: =COUNTIF(L$3:L$26,"41午*") -> 0 | M37: =COUNTIF(M$3:M$26,"41午") -> 0 | N37: =COUNTIF(N$3:N$26,"41午") -> 0 | O37: =COUNTIF(O$3:O$26,"41午") -> 0 | P37: =COUNTIF(P$3:P$26,"41午") -> 0 | Q37: =COUNTIF(Q$3:Q$26,"41午") -> 0 | R37: =COUNTIF(R$3:R$26,"41午") -> 0 | S37: =COUNTIF(S$3:S$26,"41午") -> 0 | T37: =COUNTIF(T$3:T$26,"41午") -> 0 | ... AL37: =COUNTIF(AL$3:AL$26,"41午") -> 0
C38: 41夜 | D38: =COUNTIF(D$3:D$26,"41夜*") -> 0 | E38: =COUNTIF(E$3:E$26,"41夜*") -> 0 | F38: =COUNTIF(F$3:F$26,"41夜*") -> 0 | G38: =COUNTIF(G$3:G$26,"41夜*") -> 0 | H38: =COUNTIF(H$3:H$26,"41夜*") -> 0 | I38: =COUNTIF(I$3:I$26,"41夜*") -> 0 | J38: =COUNTIF(J$3:J$26,"41夜*") -> 0 | K38: =COUNTIF(K$3:K$26,"41夜*") -> 0 | ... AL38: =COUNTIF(AL$3:AL$26,"41夜*") -> 0
C39: A1早 | D39: =COUNTIF(D$3:D$26,"01早*") -> 8 | E39: =COUNTIF(E$3:E$26,"01早*") -> 7 | F39: =COUNTIF(F$3:F$26,"01早*") -> 6 | G39: =COUNTIF(G$3:G$26,"01早*") -> 6 | H39: =COUNTIF(H$3:H$26,"01早*") -> 6 | I39: =COUNTIF(I$3:I$26,"01早*") -> 7 | J39: =COUNTIF(J$3:J$26,"01早*") -> 6 | K39: =COUNTIF(K$3:K$26,"01早*") -> 6 | ... AL39: =COUNTIF(AL$3:AL$26,"01早*") -> 6
C40: A1中A | D40: =COUNTIF(D$3:D$26,"01中A*") -> 1 | E40: =COUNTIF(E$3:E$26,"01中A*") -> 1 | F40: =COUNTIF(F$3:F$26,"01中A*") -> 1 | G40: =COUNTIF(G$3:G$26,"01中A*") -> 1 | H40: =COUNTIF(H$3:H$26,"01中A*") -> 1 | I40: =COUNTIF(I$3:I$26,"01中A*") -> 1 | J40: =COUNTIF(J$3:J$26,"01中A*") -> 0 | K40: =COUNTIF(K$3:K$26,"01中A*") -> 0 | ... AL40: =COUNTIF(AL$3:AL$26,"01中A*") -> 1
C41: A1午 | D41: =COUNTIF(D$3:D$26,"01午*") -> 7 | E41: =COUNTIF(E$3:E$26,"01午*") -> 7 | F41: =COUNTIF(F$3:F$26,"01午*") -> 7 | G41: =COUNTIF(G$3:G$26,"01午*") -> 6 | H41: =COUNTIF(H$3:H$26,"01午*") -> 8 | I41: =COUNTIF(I$3:I$26,"01午*") -> 7 | J41: =COUNTIF(J$3:J$26,"01午*") -> 7 | K41: =COUNTIF(K$3:K$26,"01午*") -> 6 | ... AL41: =COUNTIF(AL$3:AL$26,"01午*") -> 6
C42: A1夜 | D42: =COUNTIF(D$3:D$26,"01夜*") -> 2 | E42: =COUNTIF(E$3:E$26,"01夜*") -> 2 | F42: =COUNTIF(F$3:F$26,"01夜*") -> 2 | G42: =COUNTIF(G$3:G$26,"01夜*") -> 2 | H42: =COUNTIF(H$3:H$26,"01夜*") -> 2 | I42: =COUNTIF(I$3:I$26,"01夜*") -> 2 | J42: =COUNTIF(J$3:J$26,"01夜*") -> 2 | K42: =COUNTIF(K$3:K$26,"01夜*") -> 2 | ... AL42: =COUNTIF(AL$3:AL$26,"01夜*") -> 2
C43: A2早 | D43: =COUNTIF(D$3:D$26,"**02早*") -> 0 | E43: =COUNTIF(E$3:E$26,"**02早*") -> 0 | F43: =COUNTIF(F$3:F$26,"**02早*") -> 0 | G43: =COUNTIF(G$3:G$26,"**02早*") -> 0 | H43: =COUNTIF(H$3:H$26,"**02早*") -> 0 | I43: =COUNTIF(I$3:I$26,"**02早*") -> 0 | J43: =COUNTIF(J$3:J$26,"**02早*") -> 0 | K43: =COUNTIF(K$3:K$26,"**02早*") -> 0 | ... AL43: =COUNTIF(AL$3:AL$26,"**02早*") -> 0
C44: A2中A | D44: =COUNTIF(D$3:D$26,"02中A*") -> 0 | E44: =COUNTIF(E$3:E$26,"02中A*") -> 0 | F44: =COUNTIF(F$3:F$26,"02中A*") -> 0 | G44: =COUNTIF(G$3:G$26,"02中A*") -> 0 | H44: =COUNTIF(H$3:H$26,"02中A*") -> 0 | I44: =COUNTIF(I$3:I$26,"02中A*") -> 0 | J44: =COUNTIF(J$3:J$26,"02中A*") -> 0 | K44: =COUNTIF(K$3:K$26,"02中A*") -> 0 | ... AL44: =COUNTIF(AL$3:AL$26,"02中A*") -> 0
C45: A2午 | D45: =COUNTIF(D$3:D$26,"*02午*") -> 0 | E45: =COUNTIF(E$3:E$26,"*02午*") -> 0 | F45: =COUNTIF(F$3:F$26,"*02午*") -> 0 | G45: =COUNTIF(G$3:G$26,"*02午*") -> 0 | H45: =COUNTIF(H$3:H$26,"*02午*") -> 0 | I45: =COUNTIF(I$3:I$26,"*02午*") -> 0 | J45: =COUNTIF(J$3:J$26,"*02午*") -> 0 | K45: =COUNTIF(K$3:K$26,"*02午*") -> 0 | ... AL45: =COUNTIF(AL$3:AL$26,"*02午*") -> 0
C46: A2夜 | D46: =COUNTIF(D$3:D$26,"02夜*") -> 0 | E46: =COUNTIF(E$3:E$26,"02夜*") -> 0 | F46: =COUNTIF(F$3:F$26,"02夜*") -> 0 | G46: =COUNTIF(G$3:G$26,"02夜*") -> 0 | H46: =COUNTIF(H$3:H$26,"02夜*") -> 0 | I46: =COUNTIF(I$3:I$26,"02夜*") -> 0 | J46: =COUNTIF(J$3:J$26,"02夜*") -> 0 | K46: =COUNTIF(K$3:K$26,"02夜*") -> 0 | ... AL46: =COUNTIF(AL$3:AL$26,"02夜*") -> 0
C47: A3早 | D47: =COUNTIF(D$3:D$26,"*03早*")-D48 -> 0 | E47: =COUNTIF(E$3:E$26,"*03早*")-E48 -> 0 | F47: =COUNTIF(F$3:F$26,"*03早*")-F48 -> 0 | G47: =COUNTIF(G$3:G$26,"*03早*")-G48 -> 0 | H47: =COUNTIF(H$3:H$26,"*03早*")-H48 -> 0 | I47: =COUNTIF(I$3:I$26,"*03早*")-I48 -> 0 | J47: =COUNTIF(J$3:J$26,"*03早*")-J48 -> 0 | K47: =COUNTIF(K$3:K$26,"*03早*")-K48 -> 0 | ... AL47: =COUNTIF(AL$3:AL$26,"*03早*")-AL48 -> 0
C48: A3早A | D48: =COUNTIF(D$3:D$26,"*03早A*") -> 0 | E48: =COUNTIF(E$3:E$26,"*03早A*") -> 0 | F48: =COUNTIF(F$3:F$26,"*03早A*") -> 0 | G48: =COUNTIF(G$3:G$26,"*03早A*") -> 0 | H48: =COUNTIF(H$3:H$26,"*03早A*") -> 0 | I48: =COUNTIF(I$3:I$26,"*03早A*") -> 0 | J48: =COUNTIF(J$3:J$26,"*03早A*") -> 0 | K48: =COUNTIF(K$3:K$26,"*03早A*") -> 0 | ... AL48: =COUNTIF(AL$3:AL$26,"*03早A*") -> 0
C49: A3中A | D49: =COUNTIF(D$3:D$26,"03中A*") -> 0 | E49: =COUNTIF(E$3:E$26,"03中A*") -> 0 | F49: =COUNTIF(F$3:F$26,"03中A*") -> 0 | G49: =COUNTIF(G$3:G$26,"03中A*") -> 0 | H49: =COUNTIF(H$3:H$26,"03中A*") -> 0 | I49: =COUNTIF(I$3:I$26,"03中A*") -> 0 | J49: =COUNTIF(J$3:J$26,"03中A*") -> 0 | K49: =COUNTIF(K$3:K$26,"03中A*") -> 0 | ... AL49: =COUNTIF(AL$3:AL$26,"03中A*") -> 0
C50: A3午 | D50: =COUNTIF(D$3:D$26,"*03午*")-D51 -> 0 | E50: =COUNTIF(E$3:E$26,"*03午*")-E51 -> 0 | F50: =COUNTIF(F$3:F$26,"*03午*")-F51 -> 0 | G50: =COUNTIF(G$3:G$26,"*03午*")-G51 -> 0 | H50: =COUNTIF(H$3:H$26,"*03午*")-H51 -> 0 | I50: =COUNTIF(I$3:I$26,"*03午*")-I51 -> 0 | J50: =COUNTIF(J$3:J$26,"*03午*")-J51 -> 0 | K50: =COUNTIF(K$3:K$26,"*03午*")-K51 -> 0 | ... AL50: =COUNTIF(AL$3:AL$26,"*03午*")-AL51 -> 0
C51: A3午F | D51: =COUNTIF(D$3:D$26,"*03午F*") -> 0 | E51: =COUNTIF(E$3:E$26,"*03午F*") -> 0 | F51: =COUNTIF(F$3:F$26,"*03午F*") -> 0 | G51: =COUNTIF(G$3:G$26,"*03午F*") -> 0 | H51: =COUNTIF(H$3:H$26,"*03午F*") -> 0 | I51: =COUNTIF(I$3:I$26,"*03午F*") -> 0 | J51: =COUNTIF(J$3:J$26,"*03午F*") -> 0 | K51: =COUNTIF(K$3:K$26,"*03午F*") -> 0 | ... AL51: =COUNTIF(AL$3:AL$26,"*03午F*") -> 0
C52: A3夜 | D52: =COUNTIF(D$3:D$26,"03夜") -> 0 | E52: =COUNTIF(E$3:E$26,"03夜") -> 0 | F52: =COUNTIF(F$3:F$26,"03夜") -> 0 | G52: =COUNTIF(G$3:G$26,"03夜") -> 0 | H52: =COUNTIF(H$3:H$26,"03夜") -> 0 | I52: =COUNTIF(I$3:I$26,"03夜") -> 0 | J52: =COUNTIF(J$3:J$26,"03夜") -> 0 | K52: =COUNTIF(K$3:K$26,"03夜") -> 0 | ... AL52: =COUNTIF(AL$3:AL$26,"03夜") -> 0
C53: A4早 | D53: =COUNTIF(D$3:D$26,"*04早*") -> 0 | E53: =COUNTIF(E$3:E$26,"*04早*") -> 0 | F53: =COUNTIF(F$3:F$26,"*04早*") -> 0 | G53: =COUNTIF(G$3:G$26,"*04早*") -> 0 | H53: =COUNTIF(H$3:H$26,"*04早*") -> 0 | I53: =COUNTIF(I$3:I$26,"*04早*") -> 0 | J53: =COUNTIF(J$3:J$26,"*04早*") -> 0 | K53: =COUNTIF(K$3:K$26,"*04早*") -> 0 | ... AL53: =COUNTIF(AL$3:AL$26,"*04早*") -> 0
C54: A4中A | D54: =COUNTIF(D$3:D$26,"*04中A*") -> 0 | E54: =COUNTIF(E$3:E$26,"*04中A*") -> 0 | F54: =COUNTIF(F$3:F$26,"*04中A*") -> 0 | G54: =COUNTIF(G$3:G$26,"*04中A*") -> 0 | H54: =COUNTIF(H$3:H$26,"*04中A*") -> 0 | I54: =COUNTIF(I$3:I$26,"*04中A*") -> 0 | J54: =COUNTIF(J$3:J$26,"*04中A*") -> 0 | K54: =COUNTIF(K$3:K$26,"*04中A*") -> 0 | ... AL54: =COUNTIF(AL$3:AL$26,"*04中A*") -> 0
C55: A4午 | D55: =COUNTIF(D$3:D$26,"*04午*") -> 0 | E55: =COUNTIF(E$3:E$26,"*04午*") -> 0 | F55: =COUNTIF(F$3:F$26,"*04午*") -> 0 | G55: =COUNTIF(G$3:G$26,"*04午*") -> 0 | H55: =COUNTIF(H$3:H$26,"*04午*") -> 0 | I55: =COUNTIF(I$3:I$26,"*04午*") -> 0 | J55: =COUNTIF(J$3:J$26,"*04午*") -> 0 | K55: =COUNTIF(K$3:K$26,"*04午*") -> 0 | ... AL55: =COUNTIF(AL$3:AL$26,"*04午*") -> 0
...

Sheet 北段 (人資版)
B1: 員編 ID No. | C1: 日期 星期 姓名 | D1: 46143 | E1: =D1+1 -> 46144 | F1: =E1+1 -> 46145 | G1: =F1+1 -> 46146 | H1: =G1+1 -> 46147 | I1: =H1+1 -> 46148 | J1: =I1+1 -> 46149 | K1: =J1+1 -> 46150 | L1: =K1+1 -> 46151 | ... AN1: =AM1+1 -> 46179
D2: =IFERROR(IF(WEEKDAY(D1,2)=7,"日",WEEKDAY(D1,2)),"") -> 5 | E2: =IFERROR(IF(WEEKDAY(E1,2)=7,"日",WEEKDAY(E1,2)),"") -> 6 | F2: =IFERROR(IF(WEEKDAY(F1,2)=7,"日",WEEKDAY(F1,2)),"") -> 日 | G2: =IFERROR(IF(WEEKDAY(G1,2)=7,"日",WEEKDAY(G1,2)),"") -> 1 | H2: =IFERROR(IF(WEEKDAY(H1,2)=7,"日",WEEKDAY(H1,2)),"") -> 2 | I2: =IFERROR(IF(WEEKDAY(I1,2)=7,"日",WEEKDAY(I1,2)),"") -> 3 | J2: =IFERROR(IF(WEEKDAY(J1,2)=7,"日",WEEKDAY(J1,2)),"") -> 4 | K2: =IFERROR(IF(WEEKDAY(K1,2)=7,"日",WEEKDAY(K1,2)),"") -> 5 | ... AN2: =IFERROR(IF(WEEKDAY(AN1,2)=7,"日",WEEKDAY(AN1,2)),"") -> 6
B3: =LEFT(#REF!,6) -> #REF! | C3: =VLOOKUP(B3,'北段'!B:C,2,FALSE) -> #REF! | D3: =LEFT(#REF!,4) -> #REF! | E3: =LEFT(#REF!,4) -> #REF! | F3: =LEFT(#REF!,4) -> #REF! | G3: =LEFT(#REF!,4) -> #REF! | H3: =LEFT(#REF!,4) -> #REF! | I3: =LEFT(#REF!,4) -> #REF! | J3: =LEFT(#REF!,4) -> #REF! | K3: =LEFT(#REF!,4) -> #REF! | ... AG3: =LEFT(#REF!,4) -> #REF! | AH3: =LEFT(北段!#REF!,4) -> #ERROR! | AI3: =LEFT(北段!#REF!,4) -> #ERROR! | AJ3: =LEFT(北段!#REF!,4) -> #ERROR! | AK3: =LEFT(北段!#REF!,4) -> #ERROR! | AL3: =LEFT(北段!#REF!,4) -> #ERROR! | AM3: =LEFT(北段!#REF!,4) -> #ERROR! | AN3: =LEFT(北段!#REF!,4) -> #ERROR!
B4: =LEFT(#REF!,6) -> #REF! | C4: =VLOOKUP(B4,'北段'!B:C,2,FALSE) -> #REF! | D4: =LEFT(#REF!,4) -> #REF! | E4: =LEFT(#REF!,4) -> #REF! | F4: =LEFT(#REF!,4) -> #REF! | G4: =LEFT(#REF!,4) -> #REF! | H4: =LEFT(#REF!,4) -> #REF! | I4: =LEFT(#REF!,4) -> #REF! | J4: =LEFT(#REF!,3) -> #REF! | K4: =LEFT(#REF!,4) -> #REF! | L4: =LEFT(#REF!,4) -> #REF! | M4: =LEFT(#REF!,4) -> #REF! | N4: =LEFT(#REF!,4) -> #REF! | O4: =LEFT(#REF!,4) -> #REF! | P4: =LEFT(#REF!,4) -> #REF! | Q4: =LEFT(#REF!,4) -> #REF! | R4: =LEFT(#REF!,4) -> #REF! | ... AG4: =LEFT(#REF!,4) -> #REF! | AH4: =LEFT(北段!#REF!,4) -> #ERROR! | AI4: =LEFT(北段!#REF!,4) -> #ERROR! | AJ4: =LEFT(北段!#REF!,4) -> #ERROR! | AK4: =LEFT(北段!#REF!,4) -> #ERROR! | AL4: =LEFT(北段!#REF!,4) -> #ERROR! | AM4: =LEFT(北段!#REF!,4) -> #ERROR! | AN4: =LEFT(北段!#REF!,4) -> #ERROR!
B5: =LEFT(#REF!,6) -> #REF! | C5: =VLOOKUP(B5,'北段'!B:C,2,FALSE) -> #REF! | D5: =LEFT(#REF!,4) -> #REF! | E5: =LEFT(#REF!,4) -> #REF! | F5: =LEFT(#REF!,4) -> #REF! | G5: =LEFT(#REF!,4) -> #REF! | H5: =LEFT(#REF!,4) -> #REF! | I5: =LEFT(#REF!,4) -> #REF! | J5: =LEFT(#REF!,4) -> #REF! | K5: =LEFT(#REF!,4) -> #REF! | ... X5: =LEFT(#REF!,4) -> #REF! | Y5: =LEFT(#REF!,3) -> #REF! | Z5: =LEFT(#REF!,4) -> #REF! | AA5: =LEFT(#REF!,4) -> #REF! | AB5: =LEFT(#REF!,4) -> #REF! | AC5: =LEFT(#REF!,4) -> #REF! | AD5: =LEFT(#REF!,4) -> #REF! | AE5: =LEFT(#REF!,4) -> #REF! | AF5: =LEFT(#REF!,4) -> #REF! | AG5: =LEFT(#REF!,4) -> #REF! | AH5: =LEFT(北段!#REF!,4) -> #ERROR! | AI5: =LEFT(北段!#REF!,4) -> #ERROR! | AJ5: =LEFT(北段!#REF!,4) -> #ERROR! | AK5: =LEFT(北段!#REF!,4) -> #ERROR! | AL5: =LEFT(北段!#REF!,4) -> #ERROR! | AM5: =LEFT(北段!#REF!,4) -> #ERROR! | AN5: =LEFT(北段!#REF!,4) -> #ERROR!
B6: =LEFT(#REF!,6) -> #REF! | C6: =VLOOKUP(B6,'北段'!B:C,2,FALSE) -> #REF! | D6: =LEFT(#REF!,4) -> #REF! | E6: =LEFT(#REF!,4) -> #REF! | F6: =LEFT(#REF!,4) -> #REF! | G6: =LEFT(#REF!,4) -> #REF! | H6: =LEFT(#REF!,4) -> #REF! | I6: =LEFT(#REF!,4) -> #REF! | J6: =LEFT(#REF!,4) -> #REF! | K6: =LEFT(#REF!,3) -> #REF! | L6: =LEFT(#REF!,4) -> #REF! | M6: =LEFT(#REF!,4) -> #REF! | N6: =LEFT(#REF!,4) -> #REF! | O6: =LEFT(#REF!,4) -> #REF! | P6: =LEFT(#REF!,4) -> #REF! | Q6: =LEFT(#REF!,3) -> #REF! | R6: =LEFT(#REF!,4) -> #REF! | S6: =LEFT(#REF!,4) -> #REF! | T6: =LEFT(#REF!,4) -> #REF! | U6: =LEFT(#REF!,4) -> #REF! | V6: =LEFT(#REF!,4) -> #REF! | W6: =LEFT(#REF!,4) -> #REF! | X6: =LEFT(#REF!,4) -> #REF! | Y6: =LEFT(#REF!,4) -> #REF! | ... AA6: =LEFT(#REF!,4) -> #REF! | AB6: =LEFT(#REF!,3) -> #REF! | AC6: =LEFT(#REF!,4) -> #REF! | AD6: =LEFT(#REF!,4) -> #REF! | AE6: =LEFT(#REF!,4) -> #REF! | AF6: =LEFT(#REF!,4) -> #REF! | AG6: =LEFT(#REF!,4) -> #REF! | AH6: =LEFT(北段!#REF!,4) -> #ERROR! | AI6: =LEFT(北段!#REF!,4) -> #ERROR! | AJ6: =LEFT(北段!#REF!,4) -> #ERROR! | AK6: =LEFT(北段!#REF!,4) -> #ERROR! | AL6: =LEFT(北段!#REF!,4) -> #ERROR! | AM6: =LEFT(北段!#REF!,4) -> #ERROR! | AN6: =LEFT(北段!#REF!,4) -> #ERROR!
B7: =LEFT(#REF!,6) -> #REF! | C7: =VLOOKUP(B7,'北段'!B:C,2,FALSE) -> #REF! | D7: =LEFT(#REF!,4) -> #REF! | E7: =LEFT(#REF!,4) -> #REF! | F7: =LEFT(#REF!,4) -> #REF! | G7: =LEFT(#REF!,4) -> #REF! | H7: =LEFT(#REF!,4) -> #REF! | I7: =LEFT(#REF!,4) -> #REF! | J7: =LEFT(#REF!,4) -> #REF! | K7: =LEFT(#REF!,4) -> #REF! | ... U7: =LEFT(#REF!,4) -> #REF! | V7: =LEFT(#REF!,3) -> #REF! | W7: =LEFT(#REF!,4) -> #REF! | X7: =LEFT(#REF!,4) -> #REF! | Y7: =LEFT(#REF!,4) -> #REF! | Z7: =LEFT(#REF!,4) -> #REF! | AA7: =LEFT(#REF!,4) -> #REF! | AB7: =LEFT(#REF!,4) -> #REF! | AC7: =LEFT(#REF!,4) -> #REF! | AD7: =LEFT(#REF!,4) -> #REF! | ... AG7: =LEFT(#REF!,4) -> #REF! | AH7: =LEFT(北段!#REF!,4) -> #ERROR! | AI7: =LEFT(北段!#REF!,4) -> #ERROR! | AJ7: =LEFT(北段!#REF!,4) -> #ERROR! | AK7: =LEFT(北段!#REF!,3) -> #ERROR! | AL7: =LEFT(北段!#REF!,4) -> #ERROR! | AM7: =LEFT(北段!#REF!,4) -> #ERROR! | AN7: =LEFT(北段!#REF!,4) -> #ERROR!
B8: =LEFT(#REF!,6) -> #REF! | C8: =VLOOKUP(B8,'北段'!B:C,2,FALSE) -> #REF! | D8: =LEFT(#REF!,4) -> #REF! | E8: =LEFT(#REF!,4) -> #REF! | F8: =LEFT(#REF!,4) -> #REF! | G8: =LEFT(#REF!,3) -> #REF! | H8: =LEFT(#REF!,4) -> #REF! | I8: =LEFT(#REF!,4) -> #REF! | J8: =LEFT(#REF!,4) -> #REF! | K8: =LEFT(#REF!,4) -> #REF! | L8: =LEFT(#REF!,4) -> #REF! | M8: =LEFT(#REF!,4) -> #REF! | N8: =LEFT(#REF!,4) -> #REF! | O8: =LEFT(#REF!,4) -> #REF! | ... W8: =LEFT(#REF!,4) -> #REF! | X8: =LEFT(#REF!,3) -> #REF! | Y8: =LEFT(#REF!,4) -> #REF! | Z8: =LEFT(#REF!,4) -> #REF! | AA8: =LEFT(#REF!,4) -> #REF! | AB8: =LEFT(#REF!,4) -> #REF! | AC8: =LEFT(#REF!,4) -> #REF! | AD8: =LEFT(#REF!,4) -> #REF! | AE8: =LEFT(#REF!,4) -> #REF! | AF8: =LEFT(#REF!,4) -> #REF! | AG8: =LEFT(#REF!,4) -> #REF! | AH8: =LEFT(北段!#REF!,4) -> #ERROR! | AI8: =LEFT(北段!#REF!,4) -> #ERROR! | AJ8: =LEFT(北段!#REF!,4) -> #ERROR! | AK8: =LEFT(北段!#REF!,4) -> #ERROR! | AL8: =LEFT(北段!#REF!,4) -> #ERROR! | AM8: =LEFT(北段!#REF!,4) -> #ERROR! | AN8: =LEFT(北段!#REF!,4) -> #ERROR!
B9: =LEFT(#REF!,6) -> #REF! | C9: =VLOOKUP(B9,'北段'!B:C,2,FALSE) -> #REF! | D9: =LEFT(#REF!,8) -> #REF! | E9: =LEFT(#REF!,8) -> #REF! | F9: =LEFT(#REF!,8) -> #REF! | G9: =LEFT(#REF!,8) -> #REF! | H9: =LEFT(#REF!,8) -> #REF! | I9: =LEFT(#REF!,8) -> #REF! | J9: =LEFT(#REF!,8) -> #REF! | K9: =LEFT(#REF!,8) -> #REF! | ... AG9: =LEFT(#REF!,8) -> #REF! | AH9: =LEFT(北段!#REF!,8) -> #ERROR! | AI9: =LEFT(北段!#REF!,8) -> #ERROR! | AJ9: =LEFT(北段!#REF!,8) -> #ERROR! | AK9: =LEFT(北段!#REF!,8) -> #ERROR! | AL9: =LEFT(北段!#REF!,8) -> #ERROR! | AM9: =LEFT(北段!#REF!,8) -> #ERROR! | AN9: =LEFT(北段!#REF!,8) -> #ERROR!
B10: =LEFT(#REF!,6) -> #REF! | C10: =VLOOKUP(B10,'北段'!B:C,2,FALSE) -> #REF! | D10: =LEFT(#REF!,4) -> #REF! | E10: =LEFT(#REF!,4) -> #REF! | F10: =LEFT(#REF!,4) -> #REF! | G10: =LEFT(#REF!,4) -> #REF! | H10: =LEFT(#REF!,4) -> #REF! | I10: =LEFT(#REF!,4) -> #REF! | J10: =LEFT(#REF!,4) -> #REF! | K10: =LEFT(#REF!,4) -> #REF! | ... U10: =LEFT(#REF!,4) -> #REF! | V10: =LEFT(#REF!,3) -> #REF! | W10: =LEFT(#REF!,4) -> #REF! | X10: =LEFT(#REF!,4) -> #REF! | Y10: =LEFT(#REF!,4) -> #REF! | Z10: =LEFT(#REF!,4) -> #REF! | AA10: =LEFT(#REF!,4) -> #REF! | AB10: =LEFT(#REF!,4) -> #REF! | AC10: =LEFT(#REF!,4) -> #REF! | AD10: =LEFT(#REF!,4) -> #REF! | ... AG10: =LEFT(#REF!,4) -> #REF! | AH10: =LEFT(北段!#REF!,4) -> #ERROR! | AI10: =LEFT(北段!#REF!,4) -> #ERROR! | AJ10: =LEFT(北段!#REF!,4) -> #ERROR! | AK10: =LEFT(北段!#REF!,4) -> #ERROR! | AL10: =LEFT(北段!#REF!,4) -> #ERROR! | AM10: =LEFT(北段!#REF!,4) -> #ERROR! | AN10: =LEFT(北段!#REF!,4) -> #ERROR!
B11: =LEFT(#REF!,6) -> #REF! | C11: =VLOOKUP(B11,'北段'!B:C,2,FALSE) -> #REF! | D11: =LEFT(#REF!,4) -> #REF! | E11: =LEFT(#REF!,4) -> #REF! | F11: =LEFT(#REF!,4) -> #REF! | G11: =LEFT(#REF!,4) -> #REF! | H11: =LEFT(#REF!,4) -> #REF! | I11: =LEFT(#REF!,4) -> #REF! | J11: =LEFT(#REF!,4) -> #REF! | K11: =LEFT(#REF!,4) -> #REF! | ... AG11: =LEFT(#REF!,4) -> #REF! | AH11: =LEFT(北段!#REF!,4) -> #ERROR! | AI11: =LEFT(北段!#REF!,4) -> #ERROR! | AJ11: =LEFT(北段!#REF!,4) -> #ERROR! | AK11: =LEFT(北段!#REF!,4) -> #ERROR! | AL11: =LEFT(北段!#REF!,4) -> #ERROR! | AM11: =LEFT(北段!#REF!,4) -> #ERROR! | AN11: =LEFT(北段!#REF!,4) -> #ERROR!
B12: =LEFT(#REF!,6) -> #REF! | C12: =VLOOKUP(B12,'北段'!B:C,2,FALSE) -> #REF! | D12: =LEFT(#REF!,4) -> #REF! | E12: =LEFT(#REF!,4) -> #REF! | F12: =LEFT(#REF!,4) -> #REF! | G12: =LEFT(#REF!,4) -> #REF! | H12: =LEFT(#REF!,4) -> #REF! | I12: =LEFT(#REF!,4) -> #REF! | J12: =LEFT(#REF!,4) -> #REF! | K12: =LEFT(#REF!,4) -> #REF! | ... AG12: =LEFT(#REF!,4) -> #REF! | AH12: =LEFT(北段!#REF!,4) -> #ERROR! | AI12: =LEFT(北段!#REF!,4) -> #ERROR! | AJ12: =LEFT(北段!#REF!,4) -> #ERROR! | AK12: =LEFT(北段!#REF!,4) -> #ERROR! | AL12: =LEFT(北段!#REF!,4) -> #ERROR! | AM12: =LEFT(北段!#REF!,4) -> #ERROR! | AN12: =LEFT(北段!#REF!,4) -> #ERROR!
B13: =LEFT(北段!#REF!,6) -> #ERROR! | C13: =VLOOKUP(B13,'北段'!B:C,2,FALSE) -> #ERROR! | D13: =LEFT(北段!#REF!,3) -> #ERROR! | E13: =LEFT(北段!#REF!,3) -> #ERROR! | F13: =LEFT(北段!#REF!,3) -> #ERROR! | G13: =LEFT(北段!#REF!,3) -> #ERROR! | H13: =LEFT(北段!#REF!,3) -> #ERROR! | I13: =LEFT(北段!#REF!,3) -> #ERROR! | J13: =LEFT(北段!#REF!,3) -> #ERROR! | K13: =LEFT(北段!#REF!,3) -> #ERROR! | ... AN13: =LEFT(北段!#REF!,3) -> #ERROR!
B14: =LEFT('北段'!B4,6) -> T00509 | C14: =VLOOKUP(B14,'北段'!B:C,2,FALSE) -> 郭秋儀 | D14: =LEFT('北段'!I4,3) -> 01午 | E14: =LEFT('北段'!J4,3) -> 01午 | F14: =LEFT('北段'!K4,3) -> R | G14: =LEFT('北段'!L4,4) -> 01早m | H14: =LEFT('北段'!M4,3) -> r' | I14: =LEFT('北段'!N4,3) -> 01早 | J14: =LEFT('北段'!O4,3) -> 01早 | K14: =LEFT('北段'!P4,3) -> 01早 | L14: =LEFT('北段'!Q4,3) -> r' | M14: =LEFT('北段'!R4,3) -> 01夜 | N14: =LEFT('北段'!S4,3) -> 01夜 | O14: =LEFT('北段'!T4,3) -> R | ... AD14: =LEFT('北段'!AI4,3) -> 01早 | AE14: =LEFT('北段'!AJ4,4) -> R | AF14: =LEFT('北段'!AK4,3) -> 01早 | AG14: =LEFT('北段'!AL4,3) -> 01早 | AH14: =LEFT(北段!#REF!,3) -> #ERROR! | AI14: =LEFT(北段!#REF!,3) -> #ERROR! | AJ14: =LEFT(北段!#REF!,3) -> #ERROR! | AK14: =LEFT(北段!#REF!,3) -> #ERROR! | AL14: =LEFT(北段!#REF!,3) -> #ERROR! | AM14: =LEFT(北段!#REF!,4) -> #ERROR! | AN14: =LEFT(北段!#REF!,3) -> #ERROR!
B15: =LEFT('北段'!B3,6) -> T01028 | C15: =VLOOKUP(B15,'北段'!B:C,2,FALSE) -> 林金緗 | D15: =LEFT('北段'!I3,3) -> 01夜 | E15: =LEFT('北段'!J3,3) -> 01夜 | F15: =LEFT('北段'!K3,3) -> r' | G15: =LEFT('北段'!L3,3) -> r' | H15: =LEFT('北段'!M3,4) -> 01午M | I15: =LEFT('北段'!N3,3) -> 01午 | J15: =LEFT('北段'!O3,3) -> R | K15: =LEFT('北段'!P3,3) -> 01午 | L15: =LEFT('北段'!Q3,3) -> 01午 | M15: =LEFT('北段'!R3,3) -> 01午 | N15: =LEFT('北段'!S3,3) -> R | O15: =LEFT('北段'!T3,3) -> 01午 | P15: =LEFT('北段'!U3,3) -> 01午 | Q15: =LEFT('北段'!V3,4) -> 01午m | R15: =LEFT('北段'!W3,3) -> 01午 | S15: =LEFT('北段'!X3,3) -> 01午 | T15: =LEFT('北段'!Y3,3) -> R | U15: =LEFT('北段'!Z3,3) -> 01午 | V15: =LEFT('北段'!AA3,3) -> 01午 | W15: =LEFT('北段'!AB3,3) -> r' | X15: =LEFT('北段'!AC3,4) -> 01午m | Y15: =LEFT('北段'!AD3,3) -> 01午 | Z15: =LEFT('北段'!AE3,3) -> 01午 | AA15: =LEFT('北段'!AF3,3) -> 01午 | AB15: =LEFT('北段'!AG3,3) -> R | AC15: =LEFT('北段'!AH3,3) -> L | AD15: =LEFT('北段'!AI3,3) -> L | AE15: =LEFT('北段'!AJ3,3) -> r' | AF15: =LEFT('北段'!AK3,3) -> 日 | AG15: =LEFT('北段'!AL3,3) -> 01午 | AH15: =LEFT(北段!#REF!,3) -> #ERROR! | AI15: =LEFT(北段!#REF!,3) -> #ERROR! | AJ15: =LEFT(北段!#REF!,3) -> #ERROR! | AK15: =LEFT(北段!#REF!,3) -> #ERROR! | AL15: =LEFT(北段!#REF!,3) -> #ERROR! | AM15: =LEFT(北段!#REF!,3) -> #ERROR! | AN15: =LEFT(北段!#REF!,3) -> #ERROR!
B16: =LEFT('北段'!B5,6) -> T01029 | C16: =VLOOKUP(B16,'北段'!B:C,2,FALSE) -> 林雯琳 | D16: =LEFT('北段'!I5,3) -> 01午 | E16: =LEFT('北段'!J5,3) -> 01午 | F16: =LEFT('北段'!K5,3) -> R | G16: =LEFT('北段'!L5,3) -> 01午 | H16: =LEFT('北段'!M5,3) -> 01午 | I16: =LEFT('北段'!N5,3) -> 01午 | J16: =LEFT('北段'!O5,3) -> r' | K16: =LEFT('北段'!P5,3) -> r' | ... P16: =LEFT('北段'!U5,3) -> L | Q16: =LEFT('北段'!V5,4) -> L | R16: =LEFT('北段'!W5,3) -> 01夜 | S16: =LEFT('北段'!X5,3) -> 01夜 | T16: =LEFT('北段'!Y5,3) -> R | U16: =LEFT('北段'!Z5,3) -> r' | V16: =LEFT('北段'!AA5,3) -> 01午 | W16: =LEFT('北段'!AB5,3) -> 01午 | X16: =LEFT('北段'!AC5,3) -> 01午 | Y16: =LEFT('北段'!AD5,3) -> 01中 | ... AG16: =LEFT('北段'!AL5,3) -> 01夜 | AH16: =LEFT(北段!#REF!,3) -> #ERROR! | AI16: =LEFT(北段!#REF!,3) -> #ERROR! | AJ16: =LEFT(北段!#REF!,3) -> #ERROR! | AK16: =LEFT(北段!#REF!,3) -> #ERROR! | AL16: =LEFT(北段!#REF!,3) -> #ERROR! | AM16: =LEFT(北段!#REF!,3) -> #ERROR! | AN16: =LEFT(北段!#REF!,3) -> #ERROR!
B17: =LEFT('北段'!B6,6) -> T01734 | C17: =VLOOKUP(B17,'北段'!B:C,2,FALSE) -> 黃冠銘 | D17: =LEFT('北段'!I6,3) -> 01早 | E17: =LEFT('北段'!J6,3) -> 01早 | F17: =LEFT('北段'!K6,3) -> r' | G17: =LEFT('北段'!L6,3) -> R | H17: =LEFT('北段'!M6,3) -> L | I17: =LEFT('北段'!N6,3) -> L | J17: =LEFT('北段'!O6,3) -> L | K17: =LEFT('北段'!P6,3) -> 01早 | ... AG17: =LEFT('北段'!AL6,3) -> 01早 | AH17: =LEFT(北段!#REF!,3) -> #ERROR! | AI17: =LEFT(北段!#REF!,3) -> #ERROR! | AJ17: =LEFT(北段!#REF!,3) -> #ERROR! | AK17: =LEFT(北段!#REF!,3) -> #ERROR! | AL17: =LEFT(北段!#REF!,3) -> #ERROR! | AM17: =LEFT(北段!#REF!,3) -> #ERROR! | AN17: =LEFT(北段!#REF!,3) -> #ERROR!
B18: =LEFT('北段'!B7,6) -> T02287 | C18: =VLOOKUP(B18,'北段'!B:C,2,FALSE) -> 林江玉 | D18: =LEFT('北段'!I7,3) -> 01早 | E18: =LEFT('北段'!J7,3) -> r' | F18: =LEFT('北段'!K7,3) -> R | G18: =LEFT('北段'!L7,3) -> L | H18: =LEFT('北段'!M7,3) -> L | I18: =LEFT('北段'!N7,3) -> L | J18: =LEFT('北段'!O7,3) -> L | K18: =LEFT('北段'!P7,3) -> L | ... AG18: =LEFT('北段'!AL7,3) -> 01夜 | AH18: =LEFT(北段!#REF!,3) -> #ERROR! | AI18: =LEFT(北段!#REF!,3) -> #ERROR! | AJ18: =LEFT(北段!#REF!,3) -> #ERROR! | AK18: =LEFT(北段!#REF!,3) -> #ERROR! | AL18: =LEFT(北段!#REF!,3) -> #ERROR! | AM18: =LEFT(北段!#REF!,3) -> #ERROR! | AN18: =LEFT(北段!#REF!,3) -> #ERROR!
B19: =LEFT('北段'!B8,6) -> T02359 | C19: =VLOOKUP(B19,'北段'!B:C,2,FALSE) -> 陳佳婷 | D19: =LEFT('北段'!I8,3) -> r' | E19: =LEFT('北段'!J8,3) -> 01早 | F19: =LEFT('北段'!K8,3) -> 01早 | G19: =LEFT('北段'!L8,3) -> 01早 | H19: =LEFT('北段'!M8,3) -> 01早 | I19: =LEFT('北段'!N8,3) -> R | J19: =LEFT('北段'!O8,3) -> 01早 | K19: =LEFT('北段'!P8,3) -> r' | ... AC19: =LEFT('北段'!AH8,3) -> 01早 | AD19: =LEFT('北段'!AI8,4) -> 01早m | AE19: =LEFT('北段'!AJ8,3) -> 01夜 | AF19: =LEFT('北段'!AK8,3) -> 01夜 | AG19: =LEFT('北段'!AL8,3) -> r' | AH19: =LEFT(北段!#REF!,3) -> #ERROR! | AI19: =LEFT(北段!#REF!,3) -> #ERROR! | AJ19: =LEFT(北段!#REF!,3) -> #ERROR! | AK19: =LEFT(北段!#REF!,3) -> #ERROR! | AL19: =LEFT(北段!#REF!,3) -> #ERROR! | AM19: =LEFT(北段!#REF!,3) -> #ERROR! | AN19: =LEFT(北段!#REF!,3) -> #ERROR!
B20: =LEFT('北段'!B9,6) -> T02363 | C20: =VLOOKUP(B20,'北段'!B:C,2,FALSE) -> 林孟錡 | D20: =LEFT('北段'!I9,3) -> 01夜 | E20: =LEFT('北段'!J9,3) -> 01夜 | F20: =LEFT('北段'!K9,3) -> 01夜 | G20: =LEFT('北段'!L9,3) -> 01夜 | H20: =LEFT('北段'!M9,3) -> 01夜 | I20: =LEFT('北段'!N9,3) -> R | J20: =LEFT('北段'!O9,3) -> r' | K20: =LEFT('北段'!P9,3) -> r' | ... AG20: =LEFT('北段'!AL9,3) -> r' | AH20: =LEFT(北段!#REF!,3) -> #ERROR! | AI20: =LEFT(北段!#REF!,3) -> #ERROR! | AJ20: =LEFT(北段!#REF!,3) -> #ERROR! | AK20: =LEFT(北段!#REF!,3) -> #ERROR! | AL20: =LEFT(北段!#REF!,3) -> #ERROR! | AM20: =LEFT(北段!#REF!,3) -> #ERROR! | AN20: =LEFT(北段!#REF!,3) -> #ERROR!
B21: =LEFT('北段'!B10,6) -> T02504 | C21: =VLOOKUP(B21,'北段'!B:C,2,FALSE) -> 潘元浩 | D21: =LEFT('北段'!I10,3) -> 01午 | E21: =LEFT('北段'!J10,3) -> 01午 | F21: =LEFT('北段'!K10,3) -> 01午 | G21: =LEFT('北段'!L10,3) -> R | H21: =LEFT('北段'!M10,3) -> 01夜 | I21: =LEFT('北段'!N10,3) -> 01夜 | J21: =LEFT('北段'!O10,3) -> 01夜 | K21: =LEFT('北段'!P10,3) -> 01夜 | ... AG21: =LEFT('北段'!AL10,3) -> R | AH21: =LEFT(北段!#REF!,4) -> #ERROR! | AI21: =LEFT(北段!#REF!,3) -> #ERROR! | AJ21: =LEFT(北段!#REF!,3) -> #ERROR! | AK21: =LEFT(北段!#REF!,3) -> #ERROR! | AL21: =LEFT(北段!#REF!,3) -> #ERROR! | AM21: =LEFT(北段!#REF!,3) -> #ERROR! | AN21: =LEFT(北段!#REF!,3) -> #ERROR!
B22: =LEFT('北段'!B11,6) -> T02505 | C22: =VLOOKUP(B22,'北段'!B:C,2,FALSE) -> 李慧盺 | D22: =LEFT('北段'!I11,3) -> P | E22: =LEFT('北段'!J11,3) -> r' | F22: =LEFT('北段'!K11,3) -> 01午 | G22: =LEFT('北段'!L11,3) -> 01午 | H22: =LEFT('北段'!M11,3) -> R | I22: =LEFT('北段'!N11,3) -> 01夜 | J22: =LEFT('北段'!O11,3) -> 01夜 | K22: =LEFT('北段'!P11,3) -> 01夜 | ... AE22: =LEFT('北段'!AJ11,3) -> 01午 | AF22: =LEFT('北段'!AK11,4) -> 01午B | AG22: =LEFT('北段'!AL11,3) -> R | AH22: =LEFT(北段!#REF!,3) -> #ERROR! | AI22: =LEFT(北段!#REF!,3) -> #ERROR! | AJ22: =LEFT(北段!#REF!,3) -> #ERROR! | AK22: =LEFT(北段!#REF!,3) -> #ERROR! | AL22: =LEFT(北段!#REF!,3) -> #ERROR! | AM22: =LEFT(北段!#REF!,3) -> #ERROR! | AN22: =LEFT(北段!#REF!,3) -> #ERROR!
B23: =LEFT('北段'!B14,6) -> T00557 | C23: =VLOOKUP(B23,'北段'!B:C,2,FALSE) -> 陳志明 | D23: =LEFT('北段'!I14,3) -> 01早 | E23: =LEFT('北段'!J14,3) -> r' | F23: =LEFT('北段'!K14,3) -> 01早 | G23: =LEFT('北段'!L14,4) -> 01早B | H23: =LEFT('北段'!M14,3) -> 01早 | I23: =LEFT('北段'!N14,3) -> 01早 | J23: =LEFT('北段'!O14,3) -> 01早 | K23: =LEFT('北段'!P14,3) -> L | L23: =LEFT('北段'!Q14,3) -> R | M23: =LEFT('北段'!R14,3) -> R | N23: =LEFT('北段'!S14,3) -> 01早 | O23: =LEFT('北段'!T14,3) -> 01午 | ... AF23: =LEFT('北段'!AK14,3) -> P | AG23: =LEFT('北段'!AL14,4) -> 01午B | AH23: =LEFT(北段!#REF!,3) -> #ERROR! | AI23: =LEFT(北段!#REF!,3) -> #ERROR! | AJ23: =LEFT(北段!#REF!,3) -> #ERROR! | AK23: =LEFT(北段!#REF!,3) -> #ERROR! | AL23: =LEFT(北段!#REF!,3) -> #ERROR! | AM23: =LEFT(北段!#REF!,3) -> #ERROR! | AN23: =LEFT(北段!#REF!,3) -> #ERROR!
B24: =LEFT('北段'!B15,6) -> T00929 | C24: =VLOOKUP(B24,'北段'!B:C,2,FALSE) -> 簡婉蓁 | D24: =LEFT('北段'!I15,3) -> 01中 | E24: =LEFT('北段'!J15,3) -> r' | F24: =LEFT('北段'!K15,3) -> r' | G24: =LEFT('北段'!L15,3) -> R | H24: =LEFT('北段'!M15,3) -> P | I24: =LEFT('北段'!N15,3) -> P | J24: =LEFT('北段'!O15,3) -> P | K24: =LEFT('北段'!P15,3) -> P | ... AG24: =LEFT('北段'!AL15,3) -> 01早 | AH24: =LEFT(北段!#REF!,3) -> #ERROR! | AI24: =LEFT(北段!#REF!,3) -> #ERROR! | AJ24: =LEFT(北段!#REF!,3) -> #ERROR! | AK24: =LEFT(北段!#REF!,3) -> #ERROR! | AL24: =LEFT(北段!#REF!,3) -> #ERROR! | AM24: =LEFT(北段!#REF!,3) -> #ERROR! | AN24: =LEFT(北段!#REF!,3) -> #ERROR!
B25: =LEFT('北段'!B16,6) -> T01459 | C25: =VLOOKUP(B25,'北段'!B:C,2,FALSE) -> 林禹丞 | D25: =LEFT('北段'!I16,3) -> 01午 | E25: =LEFT('北段'!J16,3) -> 01午 | F25: =LEFT('北段'!K16,3) -> R | G25: =LEFT('北段'!L16,3) -> r' | H25: =LEFT('北段'!M16,3) -> 01早 | I25: =LEFT('北段'!N16,3) -> 01早 | J25: =LEFT('北段'!O16,3) -> 01早 | K25: =LEFT('北段'!P16,3) -> 01早 | ... O25: =LEFT('北段'!T16,3) -> 01早 | P25: =LEFT('北段'!U16,4) -> 01中A | Q25: =LEFT('北段'!V16,3) -> 01早 | R25: =LEFT('北段'!W16,3) -> r' | S25: =LEFT('北段'!X16,3) -> 01早 | T25: =LEFT('北段'!Y16,3) -> R | U25: =LEFT('北段'!Z16,3) -> r' | V25: =LEFT('北段'!AA16,4) -> 01早B | W25: =LEFT('北段'!AB16,3) -> 日 | X25: =LEFT('北段'!AC16,3) -> 01早 | Y25: =LEFT('北段'!AD16,3) -> 01早 | Z25: =LEFT('北段'!AE16,3) -> 01早 | AA25: =LEFT('北段'!AF16,3) -> R | AB25: =LEFT('北段'!AG16,3) -> L | AC25: =LEFT('北段'!AH16,3) -> 01早 | AD25: =LEFT('北段'!AI16,3) -> r' | ... AG25: =LEFT('北段'!AL16,3) -> 01早 | AH25: =LEFT(北段!#REF!,3) -> #ERROR! | AI25: =LEFT(北段!#REF!,3) -> #ERROR! | AJ25: =LEFT(北段!#REF!,4) -> #ERROR! | AK25: =LEFT(北段!#REF!,3) -> #ERROR! | AL25: =LEFT(北段!#REF!,3) -> #ERROR! | AM25: =LEFT(北段!#REF!,3) -> #ERROR! | AN25: =LEFT(北段!#REF!,3) -> #ERROR!
B26: =LEFT('北段'!B17,6) -> T01600 | C26: =VLOOKUP(B26,'北段'!B:C,2,FALSE) -> 陳奎羽 | D26: =LEFT('北段'!I17,3) -> 01早 | E26: =LEFT('北段'!J17,3) -> r' | F26: =LEFT('北段'!K17,3) -> 01早 | G26: =LEFT('北段'!L17,3) -> 01早 | H26: =LEFT('北段'!M17,4) -> 01早B | I26: =LEFT('北段'!N17,3) -> 01早 | J26: =LEFT('北段'!O17,3) -> 01早 | K26: =LEFT('北段'!P17,3) -> R | L26: =LEFT('北段'!Q17,3) -> 01早 | M26: =LEFT('北段'!R17,3) -> 01早 | N26: =LEFT('北段'!S17,3) -> 01早 | O26: =LEFT('北段'!T17,3) -> 01早 | P26: =LEFT('北段'!U17,3) -> r' | ... AG26: =LEFT('北段'!AL17,3) -> L | AH26: =LEFT(北段!#REF!,3) -> #ERROR! | AI26: =LEFT(北段!#REF!,3) -> #ERROR! | AJ26: =LEFT(北段!#REF!,3) -> #ERROR! | AK26: =LEFT(北段!#REF!,3) -> #ERROR! | AL26: =LEFT(北段!#REF!,3) -> #ERROR! | AM26: =LEFT(北段!#REF!,3) -> #ERROR! | AN26: =LEFT(北段!#REF!,3) -> #ERROR!
B27: =LEFT('北段'!B18,6) -> T01795 | C27: =VLOOKUP(B27,'北段'!B:C,2,FALSE) -> 黃羿綾 | D27: =LEFT('北段'!I18,3) -> R | E27: =LEFT('北段'!J18,3) -> r' | F27: =LEFT('北段'!K18,3) -> r' | G27: =LEFT('北段'!L18,3) -> R | H27: =LEFT('北段'!M18,3) -> 01午 | I27: =LEFT('北段'!N18,3) -> 01午 | J27: =LEFT('北段'!O18,3) -> 01午 | K27: =LEFT('北段'!P18,3) -> r' | ... T27: =LEFT('北段'!Y18,3) -> R | U27: =LEFT('北段'!Z18,4) -> 01午B | V27: =LEFT('北段'!AA18,3) -> 01午 | W27: =LEFT('北段'!AB18,3) -> 01午 | X27: =LEFT('北段'!AC18,3) -> 01午 | Y27: =LEFT('北段'!AD18,3) -> 01午 | Z27: =LEFT('北段'!AE18,3) -> 01午 | AA27: =LEFT('北段'!AF18,3) -> r' | AB27: =LEFT('北段'!AG18,3) -> 日 | AC27: =LEFT('北段'!AH18,4) -> 01午B | AD27: =LEFT('北段'!AI18,3) -> 01午 | AE27: =LEFT('北段'!AJ18,3) -> 01中 | AF27: =LEFT('北段'!AK18,3) -> R | AG27: =LEFT('北段'!AL18,3) -> r' | AH27: =LEFT(北段!#REF!,3) -> #ERROR! | AI27: =LEFT(北段!#REF!,3) -> #ERROR! | AJ27: =LEFT(北段!#REF!,3) -> #ERROR! | AK27: =LEFT(北段!#REF!,3) -> #ERROR! | AL27: =LEFT(北段!#REF!,3) -> #ERROR! | AM27: =LEFT(北段!#REF!,3) -> #ERROR! | AN27: =LEFT(北段!#REF!,3) -> #ERROR!
B28: =LEFT('北段'!B19,6) -> T02222 | C28: =VLOOKUP(B28,'北段'!B:C,2,FALSE) -> 𡍼文妤 | D28: =LEFT('北段'!I19,3) -> R | E28: =LEFT('北段'!J19,3) -> 01早 | F28: =LEFT('北段'!K19,3) -> 01早 | G28: =LEFT('北段'!L19,3) -> 01早 | H28: =LEFT('北段'!M19,3) -> R | I28: =LEFT('北段'!N19,3) -> r' | J28: =LEFT('北段'!O19,3) -> 01早 | K28: =LEFT('北段'!P19,3) -> 01早 | ... V28: =LEFT('北段'!AA19,3) -> 01中 | W28: =LEFT('北段'!AB19,4) -> 01早B | X28: =LEFT('北段'!AC19,3) -> 01早 | Y28: =LEFT('北段'!AD19,3) -> 01早 | Z28: =LEFT('北段'!AE19,3) -> 01早 | AA28: =LEFT('北段'!AF19,3) -> R | AB28: =LEFT('北段'!AG19,3) -> r' | AC28: =LEFT('北段'!AH19,3) -> 01早 | AD28: =LEFT('北段'!AI19,3) -> r' | AE28: =LEFT('北段'!AJ19,3) -> 01早 | ... AG28: =LEFT('北段'!AL19,3) -> 日 | AH28: =LEFT(北段!#REF!,3) -> #ERROR! | AI28: =LEFT(北段!#REF!,3) -> #ERROR! | AJ28: =LEFT(北段!#REF!,3) -> #ERROR! | AK28: =LEFT(北段!#REF!,3) -> #ERROR! | AL28: =LEFT(北段!#REF!,4) -> #ERROR! | AM28: =LEFT(北段!#REF!,3) -> #ERROR! | AN28: =LEFT(北段!#REF!,3) -> #ERROR!
B29: =LEFT('北段'!B20,6) -> T02233 | C29: =VLOOKUP(B29,'北段'!B:C,2,FALSE) -> 簡悅如 | D29: =LEFT('北段'!I20,3) -> 01早 | E29: =LEFT('北段'!J20,3) -> 01早 | F29: =LEFT('北段'!K20,3) -> 01早 | G29: =LEFT('北段'!L20,3) -> r' | H29: =LEFT('北段'!M20,3) -> L | I29: =LEFT('北段'!N20,3) -> 01早 | J29: =LEFT('北段'!O20,3) -> R | K29: =LEFT('北段'!P20,3) -> 01早 | ... Y29: =LEFT('北段'!AD20,3) -> r' | Z29: =LEFT('北段'!AE20,4) -> 01早B | AA29: =LEFT('北段'!AF20,3) -> 01早 | AB29: =LEFT('北段'!AG20,3) -> 01早 | AC29: =LEFT('北段'!AH20,3) -> R | AD29: =LEFT('北段'!AI20,3) -> 01早 | AE29: =LEFT('北段'!AJ20,3) -> 日 | AF29: =LEFT('北段'!AK20,1) -> 0 | AG29: =LEFT('北段'!AL20,3) -> 01早 | AH29: =LEFT(北段!#REF!,3) -> #ERROR! | AI29: =LEFT(北段!#REF!,3) -> #ERROR! | AJ29: =LEFT(北段!#REF!,3) -> #ERROR! | AK29: =LEFT(北段!#REF!,3) -> #ERROR! | AL29: =LEFT(北段!#REF!,4) -> #ERROR! | AM29: =LEFT(北段!#REF!,1) -> #ERROR! | AN29: =LEFT(北段!#REF!,3) -> #ERROR!
B30: =LEFT('北段'!B21,6) -> T02498 | C30: =VLOOKUP(B30,'北段'!B:C,2,FALSE) -> 張芯瑜 | D30: =LEFT('北段'!I21,3) -> 01午 | E30: =LEFT('北段'!J21,3) -> R | F30: =LEFT('北段'!K21,3) -> R | G30: =LEFT('北段'!L21,3) -> r' | H30: =LEFT('北段'!M21,3) -> L | I30: =LEFT('北段'!N21,3) -> L | J30: =LEFT('北段'!O21,3) -> P | K30: =LEFT('北段'!P21,3) -> r' | ... M30: =LEFT('北段'!R21,3) -> 01午 | N30: =LEFT('北段'!S21,4) -> 01午B | O30: =LEFT('北段'!T21,3) -> 01午 | P30: =LEFT('北段'!U21,3) -> 01午 | Q30: =LEFT('北段'!V21,3) -> R | R30: =LEFT('北段'!W21,3) -> 01午 | S30: =LEFT('北段'!X21,3) -> 01午 | T30: =LEFT('北段'!Y21,3) -> 01午 | U30: =LEFT('北段'!Z21,3) -> R | V30: =LEFT('北段'!AA21,3) -> 01早 | ... X30: =LEFT('北段'!AC21,3) -> 01午 | Y30: =LEFT('北段'!AD21,4) -> 01午B | Z30: =LEFT('北段'!AE21,3) -> 01午 | AA30: =LEFT('北段'!AF21,3) -> r' | AB30: =LEFT('北段'!AG21,3) -> 日 | AC30: =LEFT('北段'!AH21,3) -> 01午 | AD30: =LEFT('北段'!AI21,3) -> r' | AE30: =LEFT('北段'!AJ21,3) -> 01午 | AF30: =LEFT('北段'!AK21,3) -> 01午 | AG30: =LEFT('北段'!AL21,3) -> R | AH30: =LEFT(北段!#REF!,3) -> #ERROR! | AI30: =LEFT(北段!#REF!,3) -> #ERROR! | AJ30: =LEFT(北段!#REF!,3) -> #ERROR! | AK30: =LEFT(北段!#REF!,3) -> #ERROR! | AL30: =LEFT(北段!#REF!,3) -> #ERROR! | AM30: =LEFT(北段!#REF!,3) -> #ERROR! | AN30: =LEFT(北段!#REF!,3) -> #ERROR!
