Workbook

Sheet 北段
B1: 員編 ID No. | C1: 日期 星期 姓名 | D1: 46201 | E1: 46202 | F1: 46203 | G1: 46204 | H1: 46205 | I1: 46206 | J1: 46207 | K1: 46208 | L1: 46209 | M1: 46210 | N1: 46211 | O1: 46212 | P1: 46213 | Q1: 46214 | R1: 46215 | S1: 46216 | T1: 46217 | U1: 46218 | V1: 46219 | W1: 46220 | X1: 46221 | Y1: 46222 | Z1: 46223 | AA1: 46224 | AB1: 46225 | AC1: 46226 | AD1: 46227 | AE1: 46228 | AF1: 46229 | AG1: 46230 | AH1: 46231 | AI1: 46232 | AJ1: 46233 | AK1: 46234 | AL1: 46235 | AM1: 1/1~7/4 P班天數 | AN1: 5/23~6/6 實際休假天數 | AP1: 6/7~7/4 實際休假天數 | AR1: 7/5~7/18 實際休假天數 | AT1: 7/5~7/18 剩餘休假天數 | AV1: 7份班別小計 | BD1: 7月份 | BI1: 5/31~6/6 | BJ1: 6/7~6/13 | BK1: 6/14~6/20 | BL1: 6/21~6/27 | BM1: 6/28~7/4 | BN1: 6月天數 | BP1: 1/1~6/6 P班天數 | BQ1: 6/7~7/4 P班天數
D2: =RIGHT(TEXT(D1,"[$-404]aaaa;@"),1) -> 日 | E2: =RIGHT(TEXT(E1,"[$-404]aaaa;@"),1) -> 一 | F2: =RIGHT(TEXT(F1,"[$-404]aaaa;@"),1) -> 二 | G2: =RIGHT(TEXT(G1,"[$-404]aaaa;@"),1) -> 三 | H2: =RIGHT(TEXT(H1,"[$-404]aaaa;@"),1) -> 四 | I2: =RIGHT(TEXT(I1,"[$-404]aaaa;@"),1) -> 五 | J2: =RIGHT(TEXT(J1,"[$-404]aaaa;@"),1) -> 六 | K2: =RIGHT(TEXT(K1,"[$-404]aaaa;@"),1) -> 日 | ... AL2: =RIGHT(TEXT(AL1,"[$-404]aaaa;@"),1) -> 六 | AN2: r | AO2: R | AP2: r | AQ2: R | AR2: r | AS2: R | AT2: r | AU2: R | AV2: 早 | AW2: 早A | AX2: 中 | AY2: 午 | AZ2: 午F | BA2: 夜 | BB2: T | BC2: 日 | BD2: L | BE2: R | BF2: r | BG2: P | BH2: 休假 日數 | BI2: R | BJ2: R | BK2: R | BL2: R | BM2: R
A3: 北 段 辦 | B3: T00082 | C3: 梁仲煒 | D3: R | E3: 41日 | F3: 41日 | G3: 41日 | H3: 41日 | I3: 41日 | J3: r' | AM3: =BP3+BQ3 -> 11 | AN3: 2 | AO3: 2 | AP3: 4 | AQ3: 4 | AR3: =COUNTIF(K3:X3,"r'*") -> 0 | AS3: =COUNTIF(K3:X3,"R") -> 0 | AT3: =8-AN3-AP3-AR3 -> 2 | AU3: =8-AO3-AQ3-AS3 -> 2 | AV3: =COUNTIF(G3:AK3,"*早*")-AW3 -> 0 | AW3: =COUNTIF(G3:AK3,"*早A") -> 0 | AX3: =COUNTIF(G3:AK3,"*中*") -> 0 | AY3: =COUNTIF(G3:AK3,"*午*")-AZ3 -> 0 | AZ3: =COUNTIF(G3:AK3,"*午F") -> 0 | BA3: =COUNTIF(G3:AK3,"*夜*") -> 0 | BB3: =COUNTIF(G3:AK3,"*T*") -> 0 | BC3: =COUNTIF(G3:AK3,"*日*") -> 3 | BD3: =COUNTIF(G3:AK3,"L") -> 0 | BE3: {=SUMPRODUCT(1*ISNUMBER(FIND("R",G3:AK3)))} -> 0 | BF3: {=SUMPRODUCT(1*ISNUMBER(FIND("r",G3:AK3)))} -> 1 | BG3: {=SUMPRODUCT(1*ISNUMBER(FIND("P",G3:AK3)))-SUMPRODUCT(1*ISNUMBER(FIND("午P",G3:AK3)))} -> 0 | BH3: =SUM(BE3:BG3) -> 1 | BI3: {=SUMPRODUCT(1*ISNUMBER(FIND("R",D3:J3)))} -> 1 | BJ3: {=SUMPRODUCT(1*ISNUMBER(FIND("R",K3:Q3)))} -> 0 | BK3: {=SUMPRODUCT(1*ISNUMBER(FIND("R",R3:X3)))} -> 0 | BL3: {=SUMPRODUCT(1*ISNUMBER(FIND("R",Y3:AE3)))} -> 0 | BM3: {=SUMPRODUCT(1*ISNUMBER(FIND("R",AF3:AL3)))} -> 0 | BN3: =SUM(AV3:BG3) -> 4 | BP3: 11 | BQ3: {=SUMPRODUCT(1*ISNUMBER(FIND("P",K3:AL3)))-SUMPRODUCT(1*ISNUMBER(FIND("午P",K3:AL3)))} -> 0
B4: T00178 | C4: 何旺宗 | D4: 06午 | E4: 41午 | F4: 41午 | G4: 41午 | H4: R | I4: 41早 | J4: 41早 | AM4: =BP4+BQ4 -> 9 | AN4: 2 | AO4: 2 | AP4: 4 | AQ4: 4 | AR4: =COUNTIF(K4:X4,"r'*") -> 0 | AS4: =COUNTIF(K4:X4,"R") -> 0 | AT4: =8-AN4-AP4-AR4 -> 2 | AU4: =8-AO4-AQ4-AS4 -> 2 | AV4: =COUNTIF(E4:AH4,"*早*")-AW4 -> 2 | AW4: =COUNTIF(E4:AH4,"*早A") -> 0 | AX4: =COUNTIF(E4:AH4,"*中*") -> 0 | AY4: =COUNTIF(E4:AH4,"*午*")-AZ4 -> 3 | AZ4: =COUNTIF(E4:AH4,"*午F") -> 0 | BA4: =COUNTIF(E4:AH4,"*夜*") -> 0 | BB4: =COUNTIF(E4:AH4,"*T*") -> 0 | BC4: =COUNTIF(E4:AH4,"*日*") -> 0 | BD4: =COUNTIF(E4:AH4,"L") -> 0 | BE4: {=SUMPRODUCT(1*ISNUMBER(FIND("R",E4:AH4)))} -> 1 | BF4: {=SUMPRODUCT(1*ISNUMBER(FIND("r",E4:AH4)))} -> 0 | BG4: {=SUMPRODUCT(1*ISNUMBER(FIND("P",E4:AH4)))-SUMPRODUCT(1*ISNUMBER(FIND("午P",E4:AH4)))} -> 0 | BH4: =SUM(BE4:BG4) -> 1 | BI4: {=SUMPRODUCT(1*ISNUMBER(FIND("R",D4:J4)))} -> 1 | BJ4: {=SUMPRODUCT(1*ISNUMBER(FIND("R",K4:Q4)))} -> 0 | BK4: {=SUMPRODUCT(1*ISNUMBER(FIND("R",R4:X4)))} -> 0 | BL4: {=SUMPRODUCT(1*ISNUMBER(FIND("R",Y4:AE4)))} -> 0 | BM4: {=SUMPRODUCT(1*ISNUMBER(FIND("R",AF4:AL4)))} -> 0 | BN4: =SUM(AV4:BG4) -> 6 | BP4: 9 | BQ4: {=SUMPRODUCT(1*ISNUMBER(FIND("P",K4:AL4)))-SUMPRODUCT(1*ISNUMBER(FIND("午P",K4:AL4)))} -> 0
B5: T00252 | C5: 馮炫強 | D5: R | E5: 41夜 | F5: 41夜 | G5: 41夜 | H5: 41夜 | I5: 41夜 | J5: 41夜 | AM5: =BP5+BQ5 -> 9 | AN5: 2 | AO5: 2 | AP5: 3 | AQ5: 4 | AR5: =COUNTIF(K5:X5,"r'*") -> 0 | AS5: =COUNTIF(K5:X5,"R") -> 0 | AT5: =8-AN5-AP5-AR5 -> 3 | AU5: =8-AO5-AQ5-AS5 -> 2 | AV5: =COUNTIF(E5:AH5,"*早*")-AW5 -> 0 | AW5: =COUNTIF(E5:AH5,"*早A") -> 0 | AX5: =COUNTIF(E5:AH5,"*中*") -> 0 | AY5: =COUNTIF(E5:AH5,"*午*")-AZ5 -> 0 | AZ5: =COUNTIF(E5:AH5,"*午F") -> 0 | BA5: =COUNTIF(E5:AH5,"*夜*") -> 6 | BB5: =COUNTIF(E5:AH5,"*T*") -> 0 | BC5: =COUNTIF(E5:AH5,"*日*") -> 0 | BD5: =COUNTIF(E5:AH5,"L") -> 0 | BE5: {=SUMPRODUCT(1*ISNUMBER(FIND("R",E5:AH5)))} -> 0 | BF5: {=SUMPRODUCT(1*ISNUMBER(FIND("r",E5:AH5)))} -> 0 | BG5: {=SUMPRODUCT(1*ISNUMBER(FIND("P",E5:AH5)))-SUMPRODUCT(1*ISNUMBER(FIND("午P",E5:AH5)))} -> 0 | BH5: =SUM(BE5:BG5) -> 0 | BI5: {=SUMPRODUCT(1*ISNUMBER(FIND("R",D5:J5)))} -> 1 | BJ5: {=SUMPRODUCT(1*ISNUMBER(FIND("R",K5:Q5)))} -> 0 | BK5: {=SUMPRODUCT(1*ISNUMBER(FIND("R",R5:X5)))} -> 0 | BL5: {=SUMPRODUCT(1*ISNUMBER(FIND("R",Y5:AE5)))} -> 0 | BM5: {=SUMPRODUCT(1*ISNUMBER(FIND("R",AF5:AL5)))} -> 0 | BN5: =SUM(AV5:BG5) -> 6 | BP5: 9 | BQ5: {=SUMPRODUCT(1*ISNUMBER(FIND("P",K5:AL5)))-SUMPRODUCT(1*ISNUMBER(FIND("午P",K5:AL5)))} -> 0
B6: T00343 | C6: 劉哲宇 | D6: R | E6: 41早 | F6: 41早 | G6: 41早 | H6: 41早 | I6: 41日(講師) | J6: 06早 | AA6: 勞安訓 | AM6: =BP6+BQ6 -> 8 | AN6: 2 | AO6: 2 | AP6: 3 | AQ6: 4 | AR6: =COUNTIF(K6:X6,"r'*") -> 0 | AS6: =COUNTIF(K6:X6,"R") -> 0 | AT6: =8-AN6-AP6-AR6 -> 3 | AU6: =8-AO6-AQ6-AS6 -> 2 | AV6: =COUNTIF(E6:AH6,"*早*")-AW6 -> 5 | AW6: =COUNTIF(E6:AH6,"*早A") -> 0 | AX6: =COUNTIF(E6:AH6,"*中*") -> 0 | AY6: =COUNTIF(E6:AH6,"*午*")-AZ6 -> 0 | AZ6: =COUNTIF(E6:AH6,"*午F") -> 0 | BA6: =COUNTIF(E6:AH6,"*夜*") -> 0 | BB6: =COUNTIF(E6:AH6,"*T*") -> 0 | BC6: =COUNTIF(E6:AH6,"*日*") -> 1 | BD6: =COUNTIF(E6:AH6,"L") -> 0 | BE6: {=SUMPRODUCT(1*ISNUMBER(FIND("R",E6:AH6)))} -> 0 | BF6: {=SUMPRODUCT(1*ISNUMBER(FIND("r",E6:AH6)))} -> 0 | BG6: {=SUMPRODUCT(1*ISNUMBER(FIND("P",E6:AH6)))-SUMPRODUCT(1*ISNUMBER(FIND("午P",E6:AH6)))} -> 0 | BH6: =SUM(BE6:BG6) -> 0 | BI6: {=SUMPRODUCT(1*ISNUMBER(FIND("R",D6:J6)))} -> 1 | BJ6: {=SUMPRODUCT(1*ISNUMBER(FIND("R",K6:Q6)))} -> 0 | BK6: {=SUMPRODUCT(1*ISNUMBER(FIND("R",R6:X6)))} -> 0 | BL6: {=SUMPRODUCT(1*ISNUMBER(FIND("R",Y6:AE6)))} -> 0 | BM6: {=SUMPRODUCT(1*ISNUMBER(FIND("R",AF6:AL6)))} -> 0 | BN6: =SUM(AV6:BG6) -> 6 | BP6: 8 | BQ6: {=SUMPRODUCT(1*ISNUMBER(FIND("P",K6:AL6)))-SUMPRODUCT(1*ISNUMBER(FIND("午P",K6:AL6)))} -> 0
B7: T00356 | C7: 吳國強 | D7: 41早 | E7: 03早 | F7: R | G7: 41日(講師) | H7: 41午 | I7: 41午 | J7: 41午 | AM7: =BP7+BQ7 -> 7 | AN7: 2 | AO7: 2 | AP7: 3 | AQ7: 4 | AR7: =COUNTIF(K7:X7,"r'*") -> 0 | AS7: =COUNTIF(K7:X7,"R") -> 0 | AT7: =8-AN7-AP7-AR7 -> 3 | AU7: =8-AO7-AQ7-AS7 -> 2 | AV7: =COUNTIF(E7:AH7,"*早*")-AW7 -> 1 | AW7: =COUNTIF(E7:AH7,"*早A") -> 0 | AX7: =COUNTIF(E7:AH7,"*中*") -> 0 | AY7: =COUNTIF(E7:AH7,"*午*")-AZ7 -> 3 | AZ7: =COUNTIF(E7:AH7,"*午F") -> 0 | BA7: =COUNTIF(E7:AH7,"*夜*") -> 0 | BB7: =COUNTIF(E7:AH7,"*T*") -> 0 | BC7: =COUNTIF(E7:AH7,"*日*") -> 1 | BD7: =COUNTIF(E7:AH7,"L") -> 0 | BE7: {=SUMPRODUCT(1*ISNUMBER(FIND("R",E7:AH7)))} -> 1 | BF7: {=SUMPRODUCT(1*ISNUMBER(FIND("r",E7:AH7)))} -> 0 | BG7: {=SUMPRODUCT(1*ISNUMBER(FIND("P",E7:AH7)))-SUMPRODUCT(1*ISNUMBER(FIND("午P",E7:AH7)))} -> 0 | BH7: =SUM(BE7:BG7) -> 1 | BI7: {=SUMPRODUCT(1*ISNUMBER(FIND("R",D7:J7)))} -> 1 | BJ7: {=SUMPRODUCT(1*ISNUMBER(FIND("R",K7:Q7)))} -> 0 | BK7: {=SUMPRODUCT(1*ISNUMBER(FIND("R",R7:X7)))} -> 0 | BL7: {=SUMPRODUCT(1*ISNUMBER(FIND("R",Y7:AE7)))} -> 0 | BM7: {=SUMPRODUCT(1*ISNUMBER(FIND("R",AF7:AL7)))} -> 0 | BN7: =SUM(AV7:BG7) -> 6 | BP7: 7 | BQ7: {=SUMPRODUCT(1*ISNUMBER(FIND("P",K7:AL7)))-SUMPRODUCT(1*ISNUMBER(FIND("午P",K7:AL7)))} -> 0
B8: T00492 | C8: 李尉羽 | D8: 41午 | E8: R | F8: L | G8: L | H8: L | I8: P | J8: r' | K8: 長假 | L8: 長假 | AM8: =BP8+BQ8 -> 10 | AN8: 2 | AO8: 2 | AP8: 4 | AQ8: 4 | AR8: =COUNTIF(K8:X8,"r'*") -> 0 | AS8: =COUNTIF(K8:X8,"R") -> 0 | AT8: =8-AN8-AP8-AR8 -> 2 | AU8: =8-AO8-AQ8-AS8 -> 2 | AV8: =COUNTIF(E8:AH8,"*早*")-AW8 -> 0 | AW8: =COUNTIF(E8:AH8,"*早A") -> 0 | AX8: =COUNTIF(E8:AH8,"*中*") -> 0 | AY8: =COUNTIF(E8:AH8,"*午*")-AZ8 -> 0 | AZ8: =COUNTIF(E8:AH8,"*午F") -> 0 | BA8: =COUNTIF(E8:AH8,"*夜*") -> 0 | BB8: =COUNTIF(E8:AH8,"*T*") -> 0 | BC8: =COUNTIF(E8:AH8,"*日*") -> 0 | BD8: =COUNTIF(E8:AH8,"L") -> 3 | BE8: {=SUMPRODUCT(1*ISNUMBER(FIND("R",E8:AH8)))} -> 1 | BF8: {=SUMPRODUCT(1*ISNUMBER(FIND("r",E8:AH8)))} -> 1 | BG8: {=SUMPRODUCT(1*ISNUMBER(FIND("P",E8:AH8)))-SUMPRODUCT(1*ISNUMBER(FIND("午P",E8:AH8)))} -> 1 | BH8: =SUM(BE8:BG8) -> 3 | BI8: {=SUMPRODUCT(1*ISNUMBER(FIND("R",D8:J8)))} -> 1 | BJ8: {=SUMPRODUCT(1*ISNUMBER(FIND("R",K8:Q8)))} -> 0 | BK8: {=SUMPRODUCT(1*ISNUMBER(FIND("R",R8:X8)))} -> 0 | BL8: {=SUMPRODUCT(1*ISNUMBER(FIND("R",Y8:AE8)))} -> 0 | BM8: {=SUMPRODUCT(1*ISNUMBER(FIND("R",AF8:AL8)))} -> 0 | BN8: =SUM(AV8:BG8) -> 6 | BP8: 10 | BQ8: {=SUMPRODUCT(1*ISNUMBER(FIND("P",K8:AL8)))-SUMPRODUCT(1*ISNUMBER(FIND("午P",K8:AL8)))} -> 0
B9: T00586 | C9: 江冠滿 | D9: r'(05早) | E9: 05早 | F9: 41日 | G9: 41日 | H9: 41日 | I9: 41日 | J9: R | K9: 長假 | L9: 長假 | M9: 長假 | N9: 長假 | O9: 長假 | P9: 長假 | Q9: 長假 | R9: 長假 | AM9: =BP9+BQ9 -> 11 | AN9: 2 | AO9: 2 | AP9: 4 | AQ9: 4 | AR9: =COUNTIF(K9:X9,"r'*") -> 0 | AS9: =COUNTIF(K9:X9,"R") -> 0 | AT9: =8-AN9-AP9-AR9 -> 2 | AU9: =8-AO9-AQ9-AS9 -> 2 | AV9: =COUNTIF(E9:AH9,"*早*")-AW9 -> 1 | AW9: =COUNTIF(E9:AH9,"*早A") -> 0 | AX9: =COUNTIF(E9:AH9,"*中*") -> 0 | AY9: =COUNTIF(E9:AH9,"*午*")-AZ9 -> 0 | AZ9: =COUNTIF(E9:AH9,"*午F") -> 0 | BA9: =COUNTIF(E9:AH9,"*夜*") -> 0 | BB9: =COUNTIF(E9:AH9,"*T*") -> 0 | BC9: =COUNTIF(E9:AH9,"*日*") -> 4 | BD9: =COUNTIF(E9:AH9,"L") -> 0 | BE9: {=SUMPRODUCT(1*ISNUMBER(FIND("R",E9:AH9)))} -> 1 | BF9: {=SUMPRODUCT(1*ISNUMBER(FIND("r",E9:AH9)))} -> 0 | BG9: {=SUMPRODUCT(1*ISNUMBER(FIND("P",E9:AH9)))-SUMPRODUCT(1*ISNUMBER(FIND("午P",E9:AH9)))} -> 0 | BH9: =SUM(BE9:BG9) -> 1 | BI9: {=SUMPRODUCT(1*ISNUMBER(FIND("R",D9:J9)))} -> 1 | BJ9: {=SUMPRODUCT(1*ISNUMBER(FIND("R",K9:Q9)))} -> 0 | BK9: {=SUMPRODUCT(1*ISNUMBER(FIND("R",R9:X9)))} -> 0 | BL9: {=SUMPRODUCT(1*ISNUMBER(FIND("R",Y9:AE9)))} -> 0 | BM9: {=SUMPRODUCT(1*ISNUMBER(FIND("R",AF9:AL9)))} -> 0 | BN9: =SUM(AV9:BG9) -> 6 | BP9: 11 | BQ9: {=SUMPRODUCT(1*ISNUMBER(FIND("P",K9:AL9)))-SUMPRODUCT(1*ISNUMBER(FIND("午P",K9:AL9)))} -> 0
B10: T00605 | C10: 謝蕙芸 | D10: R | E10: 41日 | F10: 41日 | G10: 41日 | H10: 41日 | I10: 41日 | J10: r' | AM10: =BP10+BQ10 -> 11 | AN10: 2 | AO10: 2 | AP10: 4 | AQ10: 4 | AR10: =COUNTIF(K10:X10,"r'*") -> 0 | AS10: =COUNTIF(K10:X10,"R") -> 0 | AT10: =8-AN10-AP10-AR10 -> 2 | AU10: =8-AO10-AQ10-AS10 -> 2 | AV10: =COUNTIF(E10:AH10,"*早*")-AW10 -> 0 | AW10: =COUNTIF(E10:AH10,"*早A") -> 0 | AX10: =COUNTIF(E10:AH10,"*中*") -> 0 | AY10: =COUNTIF(E10:AH10,"*午*")-AZ10 -> 0 | AZ10: =COUNTIF(E10:AH10,"*午F") -> 0 | BA10: =COUNTIF(E10:AH10,"*夜*") -> 0 | BB10: =COUNTIF(E10:AH10,"*T*") -> 0 | BC10: =COUNTIF(E10:AH10,"*日*") -> 5 | BD10: =COUNTIF(E10:AH10,"L") -> 0 | BE10: {=SUMPRODUCT(1*ISNUMBER(FIND("R",E10:AH10)))} -> 0 | BF10: {=SUMPRODUCT(1*ISNUMBER(FIND("r",E10:AH10)))} -> 1 | BG10: {=SUMPRODUCT(1*ISNUMBER(FIND("P",E10:AH10)))-SUMPRODUCT(1*ISNUMBER(FIND("午P",E10:AH10)))} -> 0 | BH10: =SUM(BE10:BG10) -> 1 | BI10: {=SUMPRODUCT(1*ISNUMBER(FIND("R",D10:J10)))} -> 1 | BJ10: {=SUMPRODUCT(1*ISNUMBER(FIND("R",K10:Q10)))} -> 0 | BK10: {=SUMPRODUCT(1*ISNUMBER(FIND("R",R10:X10)))} -> 0 | BL10: {=SUMPRODUCT(1*ISNUMBER(FIND("R",Y10:AE10)))} -> 0 | BM10: {=SUMPRODUCT(1*ISNUMBER(FIND("R",AF10:AL10)))} -> 0 | BN10: =SUM(AV10:BG10) -> 6 | BP10: 11 | BQ10: {=SUMPRODUCT(1*ISNUMBER(FIND("P",K10:AL10)))-SUMPRODUCT(1*ISNUMBER(FIND("午P",K10:AL10)))} -> 0
B11: T00912 | C11: 詹雅惠 | D11: R | E11: 41日 | F11: 41日 | G11: L | H11: L | I11: L | J11: r' | K11: 長假 | L11: 長假 | M11: 長假 | N11: 長假 | O11: 長假 | P11: 長假 | Q11: 長假 | R11: 長假 | AM11: =BP11+BQ11 -> 11 | AN11: 2 | AO11: 2 | AP11: 4 | AQ11: 4 | AR11: =COUNTIF(K11:X11,"r'*") -> 0 | AS11: =COUNTIF(K11:X11,"R") -> 0 | AT11: =8-AN11-AP11-AR11 -> 2 | AU11: =8-AO11-AQ11-AS11 -> 2 | AV11: =COUNTIF(E11:AH11,"*早*")-AW11 -> 0 | AW11: =COUNTIF(E11:AH11,"*早A") -> 0 | AX11: =COUNTIF(E11:AH11,"*中*") -> 0 | AY11: =COUNTIF(E11:AH11,"*午*")-AZ11 -> 0 | AZ11: =COUNTIF(E11:AH11,"*午F") -> 0 | BA11: =COUNTIF(E11:AH11,"*夜*") -> 0 | BB11: =COUNTIF(E11:AH11,"*T*") -> 0 | BC11: =COUNTIF(E11:AH11,"*日*") -> 2 | BD11: =COUNTIF(E11:AH11,"L") -> 3 | BE11: {=SUMPRODUCT(1*ISNUMBER(FIND("R",E11:AH11)))} -> 0 | BF11: {=SUMPRODUCT(1*ISNUMBER(FIND("r",E11:AH11)))} -> 1 | BG11: {=SUMPRODUCT(1*ISNUMBER(FIND("P",E11:AH11)))-SUMPRODUCT(1*ISNUMBER(FIND("午P",E11:AH11)))} -> 0 | BH11: =SUM(BE11:BG11) -> 1 | BI11: {=SUMPRODUCT(1*ISNUMBER(FIND("R",D11:J11)))} -> 1 | BJ11: {=SUMPRODUCT(1*ISNUMBER(FIND("R",K11:Q11)))} -> 0 | BK11: {=SUMPRODUCT(1*ISNUMBER(FIND("R",R11:X11)))} -> 0 | BL11: {=SUMPRODUCT(1*ISNUMBER(FIND("R",Y11:AE11)))} -> 0 | BM11: {=SUMPRODUCT(1*ISNUMBER(FIND("R",AF11:AL11)))} -> 0 | BN11: =SUM(AV11:BG11) -> 6 | BP11: 11 | BQ11: {=SUMPRODUCT(1*ISNUMBER(FIND("P",K11:AL11)))-SUMPRODUCT(1*ISNUMBER(FIND("午P",K11:AL11)))} -> 0
B12: T00860 | C12: 陳家瑋 | D12: R | E12: 41日 | F12: 41日 | G12: 41日 | H12: 41日 | I12: 41日 | J12: r' | AM12: =BP12+BQ12 -> 10 | AN12: 2 | AO12: 2 | AP12: 4 | AQ12: 4 | AR12: =COUNTIF(K12:X12,"r'*") -> 0 | AS12: =COUNTIF(K12:X12,"R") -> 0 | AT12: =8-AN12-AP12-AR12 -> 2 | AU12: =8-AO12-AQ12-AS12 -> 2 | AV12: =COUNTIF(E12:AH12,"*早*")-AW12 -> 0 | AW12: =COUNTIF(E12:AH12,"*早A") -> 0 | AX12: =COUNTIF(E12:AH12,"*中*") -> 0 | AY12: =COUNTIF(E12:AH12,"*午*")-AZ12 -> 0 | AZ12: =COUNTIF(E12:AH12,"*午F") -> 0 | BA12: =COUNTIF(E12:AH12,"*夜*") -> 0 | BB12: =COUNTIF(E12:AH12,"*T*") -> 0 | BC12: =COUNTIF(E12:AH12,"*日*") -> 5 | BD12: =COUNTIF(E12:AH12,"L") -> 0 | BE12: {=SUMPRODUCT(1*ISNUMBER(FIND("R",E12:AH12)))} -> 0 | BF12: {=SUMPRODUCT(1*ISNUMBER(FIND("r",E12:AH12)))} -> 1 | BG12: {=SUMPRODUCT(1*ISNUMBER(FIND("P",E12:AH12)))-SUMPRODUCT(1*ISNUMBER(FIND("午P",E12:AH12)))} -> 0 | BH12: =SUM(BE12:BG12) -> 1 | BI12: {=SUMPRODUCT(1*ISNUMBER(FIND("R",D12:J12)))} -> 1 | BJ12: {=SUMPRODUCT(1*ISNUMBER(FIND("R",K12:Q12)))} -> 0 | BK12: {=SUMPRODUCT(1*ISNUMBER(FIND("R",R12:X12)))} -> 0 | BL12: {=SUMPRODUCT(1*ISNUMBER(FIND("R",Y12:AE12)))} -> 0 | BM12: {=SUMPRODUCT(1*ISNUMBER(FIND("R",AF12:AL12)))} -> 0 | BN12: =SUM(AV12:BG12) -> 6 | BP12: 10 | BQ12: {=SUMPRODUCT(1*ISNUMBER(FIND("P",K12:AL12)))-SUMPRODUCT(1*ISNUMBER(FIND("午P",K12:AL12)))} -> 0
B13: T00509 | C13: 郭秋儀 | D13: 01午M | E13: 01午m | F13: R | G13: 01夜B2 | H13: 01夜B1 | I13: 01夜B2 | J13: 01夜B1 | U13: L | V13: L | AE13: R | AF13: R | AM13: =BP13+BQ13 -> 10 | AN13: 2 | AO13: 2 | AP13: 4 | AQ13: 4 | AR13: =COUNTIF(K13:X13,"r'*") -> 0 | AS13: =COUNTIF(K13:X13,"R") -> 0 | AT13: =8-AN13-AP13-AR13 -> 2 | AU13: =8-AO13-AQ13-AS13 -> 2 | AV13: =COUNTIF(E13:AH13,"*早*")-AW13 -> 0 | AW13: =COUNTIF(E13:AH13,"*早A") -> 0 | AX13: =COUNTIF(E13:AH13,"*中*") -> 0 | AY13: =COUNTIF(E13:AH13,"*午*")-AZ13 -> 1 | AZ13: =COUNTIF(E13:AH13,"*午F") -> 0 | BA13: =COUNTIF(E13:AH13,"*夜*") -> 4 | BB13: =COUNTIF(E13:AH13,"*T*") -> 0 | BC13: =COUNTIF(E13:AH13,"*日*") -> 0 | BD13: =COUNTIF(E13:AL13,"L") -> 2 | BE13: {=SUMPRODUCT(1*ISNUMBER(FIND("R",E13:AH13)))} -> 3 | BF13: {=SUMPRODUCT(1*ISNUMBER(FIND("r",E13:AH13)))} -> 0 | BG13: {=SUMPRODUCT(1*ISNUMBER(FIND("P",E13:AH13)))-SUMPRODUCT(1*ISNUMBER(FIND("午P",E13:AH13)))} -> 0 | BH13: =SUM(BE13:BG13) -> 3 | BI13: {=SUMPRODUCT(1*ISNUMBER(FIND("R",D13:J13)))} -> 1 | BJ13: {=SUMPRODUCT(1*ISNUMBER(FIND("R",K13:Q13)))} -> 0 | BK13: {=SUMPRODUCT(1*ISNUMBER(FIND("R",R13:X13)))} -> 0 | BL13: {=SUMPRODUCT(1*ISNUMBER(FIND("R",Y13:AE13)))} -> 1 | BM13: {=SUMPRODUCT(1*ISNUMBER(FIND("R",AF13:AL13)))} -> 1 | BN13: =SUM(AV13:BG13) -> 10 | BP13: 10 | BQ13: {=SUMPRODUCT(1*ISNUMBER(FIND("P",K13:AL13)))-SUMPRODUCT(1*ISNUMBER(FIND("午P",K13:AL13)))} -> 0
B14: T01028 | C14: 林金緗 | D14: 01早M | E14: 01早M | F14: 01午m | G14: P | H14: R | I14: 01午M | J14: 01午m | AG14: R | AH14: L | AI14: L | AJ14: r' | AM14: =BP14+BQ14 -> 10 | AN14: 2 | AO14: 2 | AP14: 4 | AQ14: 4 | AR14: =COUNTIF(K14:X14,"r'*") -> 0 | AS14: =COUNTIF(K14:X14,"R") -> 0 | AT14: =8-AN14-AP14-AR14 -> 2 | AU14: =8-AO14-AQ14-AS14 -> 2 | AV14: =COUNTIF(E14:AH14,"*早*")-AW14 -> 1 | AW14: =COUNTIF(E14:AH14,"*早A") -> 0 | AX14: =COUNTIF(E14:AH14,"*中*") -> 0 | AY14: =COUNTIF(E14:AH14,"*午*")-AZ14 -> 3 | AZ14: =COUNTIF(E14:AH14,"*午F") -> 0 | BA14: =COUNTIF(E14:AH14,"*夜*") -> 0 | BB14: =COUNTIF(E14:AH14,"*T*") -> 0 | BC14: =COUNTIF(E14:AH14,"*日*") -> 0 | BD14: =COUNTIF(E14:AH14,"L") -> 1 | BE14: {=SUMPRODUCT(1*ISNUMBER(FIND("R",E14:AH14)))} -> 2 | BF14: {=SUMPRODUCT(1*ISNUMBER(FIND("r",E14:AH14)))} -> 0 | BG14: {=SUMPRODUCT(1*ISNUMBER(FIND("P",E14:AH14)))-SUMPRODUCT(1*ISNUMBER(FIND("午P",E14:AH14)))} -> 1 | BH14: =SUM(BE14:BG14) -> 3 | BI14: {=SUMPRODUCT(1*ISNUMBER(FIND("R",D14:J14)))} -> 1 | BJ14: {=SUMPRODUCT(1*ISNUMBER(FIND("R",K14:Q14)))} -> 0 | BK14: {=SUMPRODUCT(1*ISNUMBER(FIND("R",R14:X14)))} -> 0 | BL14: {=SUMPRODUCT(1*ISNUMBER(FIND("R",Y14:AE14)))} -> 0 | BM14: {=SUMPRODUCT(1*ISNUMBER(FIND("R",AF14:AL14)))} -> 1 | BN14: =SUM(AV14:BG14) -> 8 | BP14: 10 | BQ14: {=SUMPRODUCT(1*ISNUMBER(FIND("P",K14:AL14)))-SUMPRODUCT(1*ISNUMBER(FIND("午P",K14:AL14)))} -> 0
B15: T01029 | C15: 林雯琳 | D15: 01午m | E15: 01午B1 | F15: R | G15: 01午M | H15: 01午M | I15: 01午B1 | J15: 01午M | U15: L | V15: L | AE15: L | AF15: L | AM15: =BP15+BQ15 -> 10 | AN15: 2 | AO15: 2 | AP15: 4 | AQ15: 4 | AR15: =COUNTIF(K15:X15,"r'*") -> 0 | AS15: =COUNTIF(K15:X15,"R") -> 0 | AT15: =8-AN15-AP15-AR15 -> 2 | AU15: =8-AO15-AQ15-AS15 -> 2 | AV15: =COUNTIF(E15:AH15,"*早*")-AW15 -> 0 | AW15: =COUNTIF(E15:AH15,"*早A") -> 0 | AX15: =COUNTIF(E15:AH15,"*中*") -> 0 | AY15: =COUNTIF(E15:AH15,"*午*")-AZ15 -> 5 | AZ15: =COUNTIF(E15:AH15,"*午F") -> 0 | BA15: =COUNTIF(E15:AH15,"*夜*") -> 0 | BB15: =COUNTIF(E15:AH15,"*T*") -> 0 | BC15: =COUNTIF(E15:AH15,"*日*") -> 0 | BD15: =COUNTIF(E15:AH15,"L") -> 4 | BE15: {=SUMPRODUCT(1*ISNUMBER(FIND("R",E15:AH15)))} -> 1 | BF15: {=SUMPRODUCT(1*ISNUMBER(FIND("r",E15:AH15)))} -> 0 | BG15: {=SUMPRODUCT(1*ISNUMBER(FIND("P",E15:AH15)))-SUMPRODUCT(1*ISNUMBER(FIND("午P",E15:AH15)))} -> 0 | BH15: =SUM(BE15:BG15) -> 1 | BI15: {=SUMPRODUCT(1*ISNUMBER(FIND("R",D15:J15)))} -> 1 | BJ15: {=SUMPRODUCT(1*ISNUMBER(FIND("R",K15:Q15)))} -> 0 | BK15: {=SUMPRODUCT(1*ISNUMBER(FIND("R",R15:X15)))} -> 0 | BL15: {=SUMPRODUCT(1*ISNUMBER(FIND("R",Y15:AE15)))} -> 0 | BM15: {=SUMPRODUCT(1*ISNUMBER(FIND("R",AF15:AL15)))} -> 0 | BN15: =SUM(AV15:BG15) -> 10 | BP15: 10 | BQ15: {=SUMPRODUCT(1*ISNUMBER(FIND("P",K15:AL15)))-SUMPRODUCT(1*ISNUMBER(FIND("午P",K15:AL15)))} -> 0
B16: T01734 | C16: 黃冠銘 | D16: 01早m | E16: R | F16: 01早m | G16: 01早M | H16: 01早m | I16: 01早M | J16: 01早M | K16: 長假 | L16: 長假 | M16: 長假(L) | N16: 長假(L) | O16: 長假(L) | AM16: =BP16+BQ16 -> 9 | AN16: 2 | AO16: 2 | AP16: 4 | AQ16: 4 | AR16: =COUNTIF(K16:X16,"r'*") -> 0 | AS16: =COUNTIF(K16:X16,"R") -> 0 | AT16: =8-AN16-AP16-AR16 -> 2 | AU16: =8-AO16-AQ16-AS16 -> 2 | AV16: =COUNTIF(E16:AH16,"*早*")-AW16 -> 5 | AW16: =COUNTIF(E16:AH16,"*早A") -> 0 | AX16: =COUNTIF(E16:AH16,"*中*") -> 0 | AY16: =COUNTIF(E16:AH16,"*午*")-AZ16 -> 0 | AZ16: =COUNTIF(E16:AH16,"*午F") -> 0 | BA16: =COUNTIF(E16:AH16,"*夜*") -> 0 | BB16: =COUNTIF(E16:AH16,"*T*") -> 0 | BC16: =COUNTIF(E16:AH16,"*日*") -> 0 | BD16: =COUNTIF(E16:AH16,"L") -> 0 | BE16: {=SUMPRODUCT(1*ISNUMBER(FIND("R",E16:AH16)))} -> 1 | BF16: {=SUMPRODUCT(1*ISNUMBER(FIND("r",E16:AH16)))} -> 0 | BG16: {=SUMPRODUCT(1*ISNUMBER(FIND("P",E16:AH16)))-SUMPRODUCT(1*ISNUMBER(FIND("午P",E16:AH16)))} -> 0 | BH16: =SUM(BE16:BG16) -> 1 | BI16: {=SUMPRODUCT(1*ISNUMBER(FIND("R",D16:J16)))} -> 1 | BJ16: {=SUMPRODUCT(1*ISNUMBER(FIND("R",K16:Q16)))} -> 0 | BK16: {=SUMPRODUCT(1*ISNUMBER(FIND("R",R16:X16)))} -> 0 | BL16: {=SUMPRODUCT(1*ISNUMBER(FIND("R",Y16:AE16)))} -> 0 | BM16: {=SUMPRODUCT(1*ISNUMBER(FIND("R",AF16:AL16)))} -> 0 | BN16: =SUM(AV16:BG16) -> 6 | BP16: 9 | BQ16: {=SUMPRODUCT(1*ISNUMBER(FIND("P",K16:AL16)))-SUMPRODUCT(1*ISNUMBER(FIND("午P",K16:AL16)))} -> 0
B17: T02287 | C17: 林江玉 | D17: R | E17: P | F17: 01中A | G17: 01早B1 | H17: 01早M | I17: 01早m | J17: r' | K17: 長假 | L17: 長假(L) | M17: 長假(L) | N17: 長假(L) | O17: 長假(L) | P17: 長假(L) | Q17: 長假 | R17: 長假 | S17: 長假(L) | T17: 長假(L) | U17: 長假(L) | V17: 長假(L) | W17: 長假(L) | X17: 長假 | Y17: 長假 | Z17: 長假 | AM17: =BP17+BQ17 -> 11 | AN17: 2 | AO17: 2 | AP17: 4 | AQ17: 4 | AR17: =COUNTIF(K17:X17,"r'*") -> 0 | AS17: =COUNTIF(K17:X17,"R") -> 0 | AT17: =8-AN17-AP17-AR17 -> 2 | AU17: =8-AO17-AQ17-AS17 -> 2 | AV17: =COUNTIF(E17:AH17,"*早*")-AW17 -> 3 | AW17: =COUNTIF(E17:AH17,"*早A") -> 0 | AX17: =COUNTIF(E17:AH17,"*中*") -> 1 | AY17: =COUNTIF(E17:AH17,"*午*")-AZ17 -> 0 | AZ17: =COUNTIF(E17:AH17,"*午F") -> 0 | BA17: =COUNTIF(E17:AH17,"*夜*") -> 0 | BB17: =COUNTIF(E17:AH17,"*T*") -> 0 | BC17: =COUNTIF(E17:AH17,"*日*") -> 0 | BD17: =COUNTIF(E17:AH17,"L") -> 0 | BE17: {=SUMPRODUCT(1*ISNUMBER(FIND("R",E17:AH17)))} -> 0 | BF17: {=SUMPRODUCT(1*ISNUMBER(FIND("r",E17:AH17)))} -> 1 | BG17: {=SUMPRODUCT(1*ISNUMBER(FIND("P",E17:AH17)))-SUMPRODUCT(1*ISNUMBER(FIND("午P",E17:AH17)))} -> 1 | BH17: =SUM(BE17:BG17) -> 2 | BI17: {=SUMPRODUCT(1*ISNUMBER(FIND("R",D17:J17)))} -> 1 | BJ17: {=SUMPRODUCT(1*ISNUMBER(FIND("R",K17:Q17)))} -> 0 | BK17: {=SUMPRODUCT(1*ISNUMBER(FIND("R",R17:X17)))} -> 0 | BL17: {=SUMPRODUCT(1*ISNUMBER(FIND("R",Y17:AE17)))} -> 0 | BM17: {=SUMPRODUCT(1*ISNUMBER(FIND("R",AF17:AL17)))} -> 0 | BN17: =SUM(AV17:BG17) -> 6 | BP17: 11 | BQ17: {=SUMPRODUCT(1*ISNUMBER(FIND("P",K17:AL17)))-SUMPRODUCT(1*ISNUMBER(FIND("午P",K17:AL17)))} -> 0
B18: T02359 | C18: 陳佳婷 | D18: R | E18: r' | F18: 01早M | G18: 01早m | H18: 01中A | I18: r' | J18: 01早m | Y18: R | Z18: r' | AM18: =BP18+BQ18 -> 9 | AN18: 2 | AO18: 2 | AP18: 4 | AQ18: 4 | AR18: =COUNTIF(K18:X18,"r'*") -> 0 | AS18: =COUNTIF(K18:X18,"R") -> 0 | AT18: =8-AN18-AP18-AR18 -> 2 | AU18: =8-AO18-AQ18-AS18 -> 2 | AV18: =COUNTIF(E18:AH18,"*早*")-AW18 -> 3 | AW18: =COUNTIF(E18:AH18,"*早A") -> 0 | AX18: =COUNTIF(E18:AH18,"*中*") -> 1 | AY18: =COUNTIF(E18:AH18,"*午*")-AZ18 -> 0 | AZ18: =COUNTIF(E18:AH18,"*午F") -> 0 | BA18: =COUNTIF(E18:AH18,"*夜*") -> 0 | BB18: =COUNTIF(E18:AH18,"*T*") -> 0 | BC18: =COUNTIF(E18:AH18,"*日*") -> 0 | BD18: =COUNTIF(E18:AH18,"L") -> 0 | BE18: {=SUMPRODUCT(1*ISNUMBER(FIND("R",E18:AH18)))} -> 1 | BF18: {=SUMPRODUCT(1*ISNUMBER(FIND("r",E18:AH18)))} -> 3 | BG18: {=SUMPRODUCT(1*ISNUMBER(FIND("P",E18:AH18)))-SUMPRODUCT(1*ISNUMBER(FIND("午P",E18:AH18)))} -> 0 | BH18: =SUM(BE18:BG18) -> 4 | BI18: {=SUMPRODUCT(1*ISNUMBER(FIND("R",D18:J18)))} -> 1 | BJ18: {=SUMPRODUCT(1*ISNUMBER(FIND("R",K18:Q18)))} -> 0 | BK18: {=SUMPRODUCT(1*ISNUMBER(FIND("R",R18:X18)))} -> 0 | BL18: {=SUMPRODUCT(1*ISNUMBER(FIND("R",Y18:AE18)))} -> 1 | BM18: {=SUMPRODUCT(1*ISNUMBER(FIND("R",AF18:AL18)))} -> 0 | BN18: =SUM(AV18:BG18) -> 8 | BP18: 9 | BQ18: {=SUMPRODUCT(1*ISNUMBER(FIND("P",K18:AL18)))-SUMPRODUCT(1*ISNUMBER(FIND("午P",K18:AL18)))} -> 0
B19: T02363 | C19: 林孟錡 | D19: 01夜B1 | E19: 01夜B2 | F19: 01夜B1 | G19: R | H19: 01夜B2 | I19: 01夜B1 | J19: 01夜B2 | AM19: =BP19+BQ19 -> 10 | AN19: 2 | AO19: 2 | AP19: 4 | AQ19: 4 | AR19: =COUNTIF(K19:X19,"r'*") -> 0 | AS19: =COUNTIF(K19:X19,"R") -> 0 | AT19: =8-AN19-AP19-AR19 -> 2 | AU19: =8-AO19-AQ19-AS19 -> 2 | AV19: =COUNTIF(E19:AH19,"*早*")-AW19 -> 0 | AW19: =COUNTIF(E19:AH19,"*早A") -> 0 | AX19: =COUNTIF(E19:AH19,"*中*") -> 0 | AY19: =COUNTIF(E19:AH19,"*午*")-AZ19 -> 0 | AZ19: =COUNTIF(E19:AH19,"*午F") -> 0 | BA19: =COUNTIF(E19:AH19,"*夜*") -> 5 | BB19: =COUNTIF(E19:AH19,"*T*") -> 0 | BC19: =COUNTIF(E19:AH19,"*日*") -> 0 | BD19: =COUNTIF(E19:AH19,"L") -> 0 | BE19: {=SUMPRODUCT(1*ISNUMBER(FIND("R",E19:AH19)))} -> 1 | BF19: {=SUMPRODUCT(1*ISNUMBER(FIND("r",E19:AH19)))} -> 0 | BG19: {=SUMPRODUCT(1*ISNUMBER(FIND("P",E19:AH19)))-SUMPRODUCT(1*ISNUMBER(FIND("午P",E19:AH19)))} -> 0 | BH19: =SUM(BE19:BG19) -> 1 | BI19: {=SUMPRODUCT(1*ISNUMBER(FIND("R",D19:J19)))} -> 1 | BJ19: {=SUMPRODUCT(1*ISNUMBER(FIND("R",K19:Q19)))} -> 0 | BK19: {=SUMPRODUCT(1*ISNUMBER(FIND("R",R19:X19)))} -> 0 | BL19: {=SUMPRODUCT(1*ISNUMBER(FIND("R",Y19:AE19)))} -> 0 | BM19: {=SUMPRODUCT(1*ISNUMBER(FIND("R",AF19:AL19)))} -> 0 | BN19: =SUM(AV19:BG19) -> 6 | BP19: 10 | BQ19: {=SUMPRODUCT(1*ISNUMBER(FIND("P",K19:AL19)))-SUMPRODUCT(1*ISNUMBER(FIND("午P",K19:AL19)))} -> 0
B20: T02504 | C20: 潘元浩 | D20: 01午B1 | E20: 01午M | F20: 01午M | G20: r' | H20: R | I20: 01午m | J20: 01午B1 | AC20: R | AD20: r' | AE20: L | AF20: L | AM20: =BP20+BQ20 -> 9 | AN20: 2 | AO20: 2 | AP20: 4 | AQ20: 4 | AR20: =COUNTIF(K20:X20,"r'*") -> 0 | AS20: =COUNTIF(K20:X20,"R") -> 0 | AT20: =8-AN20-AP20-AR20 -> 2 | AU20: =8-AO20-AQ20-AS20 -> 2 | AV20: =COUNTIF(E20:AH20,"*早*")-AW20 -> 0 | AW20: =COUNTIF(E20:AH20,"*早A") -> 0 | AX20: =COUNTIF(E20:AH20,"*中*") -> 0 | AY20: =COUNTIF(E20:AH20,"*午*")-AZ20 -> 4 | AZ20: =COUNTIF(E20:AH20,"*午F") -> 0 | BA20: =COUNTIF(E20:AH20,"*夜*") -> 0 | BB20: =COUNTIF(E20:AH20,"*T*") -> 0 | BC20: =COUNTIF(E20:AH20,"*日*") -> 0 | BD20: =COUNTIF(E20:AH20,"L") -> 2 | BE20: {=SUMPRODUCT(1*ISNUMBER(FIND("R",E20:AH20)))} -> 2 | BF20: {=SUMPRODUCT(1*ISNUMBER(FIND("r",E20:AH20)))} -> 2 | BG20: {=SUMPRODUCT(1*ISNUMBER(FIND("P",E20:AH20)))-SUMPRODUCT(1*ISNUMBER(FIND("午P",E20:AH20)))} -> 0 | BH20: =SUM(BE20:BG20) -> 4 | BI20: {=SUMPRODUCT(1*ISNUMBER(FIND("R",D20:J20)))} -> 1 | BJ20: {=SUMPRODUCT(1*ISNUMBER(FIND("R",K20:Q20)))} -> 0 | BK20: {=SUMPRODUCT(1*ISNUMBER(FIND("R",R20:X20)))} -> 0 | BL20: {=SUMPRODUCT(1*ISNUMBER(FIND("R",Y20:AE20)))} -> 1 | BM20: {=SUMPRODUCT(1*ISNUMBER(FIND("R",AF20:AL20)))} -> 0 | BN20: =SUM(AV20:BG20) -> 10 | BP20: 9 | BQ20: {=SUMPRODUCT(1*ISNUMBER(FIND("P",K20:AL20)))-SUMPRODUCT(1*ISNUMBER(FIND("午P",K20:AL20)))} -> 0
B21: T02505 | C21: 李慧盺 | D21: 01夜B2 | E21: 01夜B1 | F21: 01夜B2 | G21: 01夜B1 | H21: R | I21: P | J21: r' | AC21: R | AD21: r' | AE21: L | AF21: L | AM21: =BP21+BQ21 -> 10 | AN21: 2 | AO21: 2 | AP21: 4 | AQ21: 4 | AR21: =COUNTIF(K21:X21,"r'*") -> 0 | AS21: =COUNTIF(K21:X21,"R") -> 0 | AT21: =8-AN21-AP21-AR21 -> 2 | AU21: =8-AO21-AQ21-AS21 -> 2 | AV21: =COUNTIF(E21:AH21,"*早*")-AW21 -> 0 | AW21: =COUNTIF(E21:AH21,"*早A") -> 0 | AX21: =COUNTIF(E21:AH21,"*中*") -> 0 | AY21: =COUNTIF(E21:AH21,"*午*")-AZ21 -> 0 | AZ21: =COUNTIF(E21:AH21,"*午F") -> 0 | BA21: =COUNTIF(E21:AH21,"*夜*") -> 3 | BB21: =COUNTIF(E21:AH21,"*T*") -> 0 | BC21: =COUNTIF(E21:AH21,"*日*") -> 0 | BD21: =COUNTIF(E21:AH21,"L") -> 2 | BE21: {=SUMPRODUCT(1*ISNUMBER(FIND("R",E21:AH21)))} -> 2 | BF21: {=SUMPRODUCT(1*ISNUMBER(FIND("r",E21:AH21)))} -> 2 | BG21: {=SUMPRODUCT(1*ISNUMBER(FIND("P",E21:AH21)))-SUMPRODUCT(1*ISNUMBER(FIND("午P",E21:AH21)))} -> 1 | BH21: =SUM(BE21:BG21) -> 5 | BI21: {=SUMPRODUCT(1*ISNUMBER(FIND("R",D21:J21)))} -> 1 | BJ21: {=SUMPRODUCT(1*ISNUMBER(FIND("R",K21:Q21)))} -> 0 | BK21: {=SUMPRODUCT(1*ISNUMBER(FIND("R",R21:X21)))} -> 0 | BL21: {=SUMPRODUCT(1*ISNUMBER(FIND("R",Y21:AE21)))} -> 1 | BM21: {=SUMPRODUCT(1*ISNUMBER(FIND("R",AF21:AL21)))} -> 0 | BN21: =SUM(AV21:BG21) -> 10 | BP21: 10 | BQ21: {=SUMPRODUCT(1*ISNUMBER(FIND("P",K21:AL21)))-SUMPRODUCT(1*ISNUMBER(FIND("午P",K21:AL21)))} -> 0
B22: T00557 | C22: 陳志明 | D22: 01早B2 | E22: r' | F22: L | G22: R | H22: 01早B1 | I22: 01早B1 | J22: r' | P22: L | Q22: R | R22: R | Z22: R | AM22: =BP22+BQ22 -> 8 | AN22: 2 | AO22: 2 | AP22: 4 | AQ22: 4 | AR22: =COUNTIF(K22:X22,"r'*") -> 0 | AS22: =COUNTIF(K22:X22,"R") -> 2 | AT22: =8-AN22-AP22-AR22 -> 2 | AU22: =8-AO22-AQ22-AS22 -> 0 | AV22: =COUNTIF(E22:AH22,"*早*")-AW22 -> 2 | AW22: =COUNTIF(E22:AH22,"*早A") -> 0 | AX22: =COUNTIF(E22:AH22,"*中*") -> 0 | AY22: =COUNTIF(E22:AH22,"*午*")-AZ22 -> 0 | AZ22: =COUNTIF(E22:AH22,"*午F") -> 0 | BA22: =COUNTIF(E22:AH22,"*夜*") -> 0 | BB22: =COUNTIF(E22:AH22,"*T*") -> 0 | BC22: =COUNTIF(E22:AH22,"*日*") -> 0 | BD22: =COUNTIF(E22:AH22,"L") -> 2 | BE22: {=SUMPRODUCT(1*ISNUMBER(FIND("R",E22:AH22)))} -> 4 | BF22: {=SUMPRODUCT(1*ISNUMBER(FIND("r",E22:AH22)))} -> 2 | BG22: {=SUMPRODUCT(1*ISNUMBER(FIND("P",E22:AH22)))-SUMPRODUCT(1*ISNUMBER(FIND("午P",E22:AH22)))} -> 0 | BH22: =SUM(BE22:BG22) -> 6 | BI22: {=SUMPRODUCT(1*ISNUMBER(FIND("R",D22:J22)))} -> 1 | BJ22: {=SUMPRODUCT(1*ISNUMBER(FIND("R",K22:Q22)))} -> 1 | BK22: {=SUMPRODUCT(1*ISNUMBER(FIND("R",R22:X22)))} -> 1 | BL22: {=SUMPRODUCT(1*ISNUMBER(FIND("R",Y22:AE22)))} -> 1 | BM22: {=SUMPRODUCT(1*ISNUMBER(FIND("R",AF22:AL22)))} -> 0 | BN22: =SUM(AV22:BG22) -> 10 | BP22: 8 | BQ22: {=SUMPRODUCT(1*ISNUMBER(FIND("P",K22:AL22)))-SUMPRODUCT(1*ISNUMBER(FIND("午P",K22:AL22)))} -> 0
B23: T00929 | C23: 簡婉蓁 | D23: 01午B1 | E23: 01午B2 | F23: R | G23: 01早B1 | H23: 01早B2 | I23: 01中A | J23: r' | K23: 長假 | L23: 長假 | M23: 長假(P) | N23: 長假(P) | O23: 長假(P) | P23: 長假(P) | Q23: 長假 | R23: 長假 | AM23: =BP23+BQ23 -> 10 | AN23: 2 | AO23: 2 | AP23: 4 | AQ23: 4 | AR23: =COUNTIF(K23:X23,"r'*") -> 0 | AS23: =COUNTIF(K23:X23,"R") -> 0 | AT23: =8-AN23-AP23-AR23 -> 2 | AU23: =8-AO23-AQ23-AS23 -> 2 | AV23: =COUNTIF(E23:AH23,"*早*")-AW23 -> 2 | AW23: =COUNTIF(E23:AH23,"*早A") -> 0 | AX23: =COUNTIF(E23:AH23,"*中*") -> 1 | AY23: =COUNTIF(E23:AH23,"*午*")-AZ23 -> 1 | AZ23: =COUNTIF(E23:AH23,"*午F") -> 0 | BA23: =COUNTIF(E23:AH23,"*夜*") -> 0 | BB23: =COUNTIF(E23:AH23,"*T*") -> 0 | BC23: =COUNTIF(E23:AH23,"*日*") -> 0 | BD23: =COUNTIF(E23:AH23,"L") -> 0 | BE23: {=SUMPRODUCT(1*ISNUMBER(FIND("R",E23:AH23)))} -> 1 | BF23: {=SUMPRODUCT(1*ISNUMBER(FIND("r",E23:AH23)))} -> 1 | BG23: {=SUMPRODUCT(1*ISNUMBER(FIND("P",E23:AH23)))-SUMPRODUCT(1*ISNUMBER(FIND("午P",E23:AH23)))} -> 4 | BH23: =SUM(BE23:BG23) -> 6 | BI23: {=SUMPRODUCT(1*ISNUMBER(FIND("R",D23:J23)))} -> 1 | BJ23: {=SUMPRODUCT(1*ISNUMBER(FIND("R",K23:Q23)))} -> 0 | BK23: {=SUMPRODUCT(1*ISNUMBER(FIND("R",R23:X23)))} -> 0 | BL23: {=SUMPRODUCT(1*ISNUMBER(FIND("R",Y23:AE23)))} -> 0 | BM23: {=SUMPRODUCT(1*ISNUMBER(FIND("R",AF23:AL23)))} -> 0 | BN23: =SUM(AV23:BG23) -> 10 | BP23: 6 | BQ23: {=SUMPRODUCT(1*ISNUMBER(FIND("P",K23:AL23)))-SUMPRODUCT(1*ISNUMBER(FIND("午P",K23:AL23)))} -> 4
B24: T01459 | C24: 林禹丞 | D24: R | E24: r' | F24: 01午B1 | G24: 01午B2 | H24: 01午B1 | I24: 01午B2 | J24: 01午B1 | R24: R | S24: L | AF24: R | AG24: L | AM24: =BP24+BQ24 -> 9 | AN24: 2 | AO24: 2 | AP24: 4 | AQ24: 4 | AR24: =COUNTIF(K24:X24,"r'*") -> 0 | AS24: =COUNTIF(K24:X24,"R") -> 1 | AT24: =8-AN24-AP24-AR24 -> 2 | AU24: =8-AO24-AQ24-AS24 -> 1 | AV24: =COUNTIF(E24:AH24,"*早*")-AW24 -> 0 | AW24: =COUNTIF(E24:AH24,"*早A") -> 0 | AX24: =COUNTIF(E24:AH24,"*中*") -> 0 | AY24: =COUNTIF(E24:AH24,"*午*")-AZ24 -> 5 | AZ24: =COUNTIF(E24:AH24,"*午F") -> 0 | BA24: =COUNTIF(E24:AH24,"*夜*") -> 0 | BB24: =COUNTIF(E24:AH24,"*T*") -> 0 | BC24: =COUNTIF(E24:AH24,"*日*") -> 0 | BD24: =COUNTIF(E24:AH24,"L") -> 2 | BE24: {=SUMPRODUCT(1*ISNUMBER(FIND("R",E24:AH24)))} -> 2 | BF24: {=SUMPRODUCT(1*ISNUMBER(FIND("r",E24:AH24)))} -> 1 | BG24: {=SUMPRODUCT(1*ISNUMBER(FIND("P",E24:AH24)))-SUMPRODUCT(1*ISNUMBER(FIND("午P",E24:AH24)))} -> 0 | BH24: =SUM(BE24:BG24) -> 3 | BI24: {=SUMPRODUCT(1*ISNUMBER(FIND("R",D24:J24)))} -> 1 | BJ24: {=SUMPRODUCT(1*ISNUMBER(FIND("R",K24:Q24)))} -> 0 | BK24: {=SUMPRODUCT(1*ISNUMBER(FIND("R",R24:X24)))} -> 1 | BL24: {=SUMPRODUCT(1*ISNUMBER(FIND("R",Y24:AE24)))} -> 0 | BM24: {=SUMPRODUCT(1*ISNUMBER(FIND("R",AF24:AL24)))} -> 1 | BN24: =SUM(AV24:BG24) -> 10 | BP24: 9 | BQ24: {=SUMPRODUCT(1*ISNUMBER(FIND("P",K24:AL24)))-SUMPRODUCT(1*ISNUMBER(FIND("午P",K24:AL24)))} -> 0
B25: T01600 | C25: 陳奎羽 | D25: R | E25: P | F25: r' | G25: 01早B2 | H25: 01早B1 | I25: 01早B1 | J25: r' | AE25: R | AF25: L | AG25: R | AM25: =BP25+BQ25 -> 10 | AN25: 2 | AO25: 2 | AP25: 4 | AQ25: 4 | AR25: =COUNTIF(K25:X25,"r'*") -> 0 | AS25: =COUNTIF(K25:X25,"R") -> 0 | AT25: =8-AN25-AP25-AR25 -> 2 | AU25: =8-AO25-AQ25-AS25 -> 2 | AV25: =COUNTIF(E25:AH25,"*早*")-AW25 -> 3 | AW25: =COUNTIF(E25:AH25,"*早A") -> 0 | AX25: =COUNTIF(E25:AH25,"*中*") -> 0 | AY25: =COUNTIF(E25:AH25,"*午*")-AZ25 -> 0 | AZ25: =COUNTIF(E25:AH25,"*午F") -> 0 | BA25: =COUNTIF(E25:AH25,"*夜*") -> 0 | BB25: =COUNTIF(E25:AH25,"*T*") -> 0 | BC25: =COUNTIF(E25:AH25,"*日*") -> 0 | BD25: =COUNTIF(E25:AH25,"L") -> 1 | BE25: {=SUMPRODUCT(1*ISNUMBER(FIND("R",E25:AH25)))} -> 2 | BF25: {=SUMPRODUCT(1*ISNUMBER(FIND("r",E25:AH25)))} -> 2 | BG25: {=SUMPRODUCT(1*ISNUMBER(FIND("P",E25:AH25)))-SUMPRODUCT(1*ISNUMBER(FIND("午P",E25:AH25)))} -> 1 | BH25: =SUM(BE25:BG25) -> 5 | BI25: {=SUMPRODUCT(1*ISNUMBER(FIND("R",D25:J25)))} -> 1 | BJ25: {=SUMPRODUCT(1*ISNUMBER(FIND("R",K25:Q25)))} -> 0 | BK25: {=SUMPRODUCT(1*ISNUMBER(FIND("R",R25:X25)))} -> 0 | BL25: {=SUMPRODUCT(1*ISNUMBER(FIND("R",Y25:AE25)))} -> 1 | BM25: {=SUMPRODUCT(1*ISNUMBER(FIND("R",AF25:AL25)))} -> 1 | BN25: =SUM(AV25:BG25) -> 9 | BP25: 10 | BQ25: {=SUMPRODUCT(1*ISNUMBER(FIND("P",K25:AL25)))-SUMPRODUCT(1*ISNUMBER(FIND("午P",K25:AL25)))} -> 0
B26: T01795 | C26: 黃羿綾 | D26: 01早B1 | E26: 01早B1 | F26: 01午B2 | G26: 01午B2 | H26: 01午B1 | I26: R | J26: r' | K26: r' | L26: R | P26: R | R26: r' | AM26: =BP26+BQ26 -> 9 | AN26: 2 | AO26: 2 | AP26: 4 | AQ26: 4 | AR26: =COUNTIF(K26:X26,"r'*") -> 2 | AS26: =COUNTIF(K26:X26,"R") -> 2 | AT26: =8-AN26-AP26-AR26 -> 0 | AU26: =8-AO26-AQ26-AS26 -> 0 | AV26: =COUNTIF(E26:AH26,"*早*")-AW26 -> 1 | AW26: =COUNTIF(E26:AH26,"*早A") -> 0 | AX26: =COUNTIF(E26:AH26,"*中*") -> 0 | AY26: =COUNTIF(E26:AH26,"*午*")-AZ26 -> 3 | AZ26: =COUNTIF(E26:AH26,"*午F") -> 0 | BA26: =COUNTIF(E26:AH26,"*夜*") -> 0 | BB26: =COUNTIF(E26:AH26,"*T*") -> 0 | BC26: =COUNTIF(E26:AH26,"*日*") -> 0 | BD26: =COUNTIF(E26:AH26,"L") -> 0 | BE26: {=SUMPRODUCT(1*ISNUMBER(FIND("R",E26:AH26)))} -> 3 | BF26: {=SUMPRODUCT(1*ISNUMBER(FIND("r",E26:AH26)))} -> 3 | BG26: {=SUMPRODUCT(1*ISNUMBER(FIND("P",E26:AH26)))-SUMPRODUCT(1*ISNUMBER(FIND("午P",E26:AH26)))} -> 0 | BH26: =SUM(BE26:BG26) -> 6 | BI26: {=SUMPRODUCT(1*ISNUMBER(FIND("R",D26:J26)))} -> 1 | BJ26: {=SUMPRODUCT(1*ISNUMBER(FIND("R",K26:Q26)))} -> 2 | BK26: {=SUMPRODUCT(1*ISNUMBER(FIND("R",R26:X26)))} -> 0 | BL26: {=SUMPRODUCT(1*ISNUMBER(FIND("R",Y26:AE26)))} -> 0 | BM26: {=SUMPRODUCT(1*ISNUMBER(FIND("R",AF26:AL26)))} -> 0 | BN26: =SUM(AV26:BG26) -> 10 | BP26: 9 | BQ26: {=SUMPRODUCT(1*ISNUMBER(FIND("P",K26:AL26)))-SUMPRODUCT(1*ISNUMBER(FIND("午P",K26:AL26)))} -> 0
B27: T02222 | C27: 𡍼文妤 | D27: 01早B1 | E27: 01早B2 | F27: 01早B1 | G27: 01中A | H27: r' | I27: R | J27: 01早B2 | AA27: 勞安訓 | AF27: R | AG27: r' | AM27: =BP27+BQ27 -> 10 | AN27: 2 | AO27: 2 | AP27: 4 | AQ27: 4 | AR27: =COUNTIF(K27:X27,"r'*") -> 0 | AS27: =COUNTIF(K27:X27,"R") -> 0 | AT27: =8-AN27-AP27-AR27 -> 2 | AU27: =8-AO27-AQ27-AS27 -> 2 | AV27: =COUNTIF(E27:AH27,"*早*")-AW27 -> 3 | AW27: =COUNTIF(E27:AH27,"*早A") -> 0 | AX27: =COUNTIF(E27:AH27,"*中*") -> 1 | AY27: =COUNTIF(E27:AH27,"*午*")-AZ27 -> 0 | AZ27: =COUNTIF(E27:AH27,"*午F") -> 0 | BA27: =COUNTIF(E27:AH27,"*夜*") -> 0 | BB27: =COUNTIF(E27:AH27,"*T*") -> 0 | BC27: =COUNTIF(E27:AH27,"*日*") -> 0 | BD27: =COUNTIF(E27:AH27,"L") -> 0 | BE27: {=SUMPRODUCT(1*ISNUMBER(FIND("R",E27:AH27)))} -> 2 | BF27: {=SUMPRODUCT(1*ISNUMBER(FIND("r",E27:AH27)))} -> 2 | BG27: {=SUMPRODUCT(1*ISNUMBER(FIND("P",E27:AH27)))-SUMPRODUCT(1*ISNUMBER(FIND("午P",E27:AH27)))} -> 0 | BH27: =SUM(BE27:BG27) -> 4 | BI27: {=SUMPRODUCT(1*ISNUMBER(FIND("R",D27:J27)))} -> 1 | BJ27: {=SUMPRODUCT(1*ISNUMBER(FIND("R",K27:Q27)))} -> 0 | BK27: {=SUMPRODUCT(1*ISNUMBER(FIND("R",R27:X27)))} -> 0 | BL27: {=SUMPRODUCT(1*ISNUMBER(FIND("R",Y27:AE27)))} -> 0 | BM27: {=SUMPRODUCT(1*ISNUMBER(FIND("R",AF27:AL27)))} -> 1 | BN27: =SUM(AV27:BG27) -> 8 | BP27: 10 | BQ27: {=SUMPRODUCT(1*ISNUMBER(FIND("P",K27:AL27)))-SUMPRODUCT(1*ISNUMBER(FIND("午P",K27:AL27)))} -> 0
B28: T02233 | C28: 簡悅如 | D28: P | E28: 01早B2 | F28: 01早B1 | G28: r' | H28: R | I28: 01早B2 | J28: 01早B1 | M28: L | W28: L | X28: L | Y28: L | AM28: =BP28+BQ28 -> 10 | AN28: 1 | AO28: 2 | AP28: 4 | AQ28: 4 | AR28: =COUNTIF(K28:X28,"r'*") -> 0 | AS28: =COUNTIF(K28:X28,"R") -> 0 | AT28: =8-AN28-AP28-AR28 -> 3 | AU28: =8-AO28-AQ28-AS28 -> 2 | AV28: =COUNTIF(E28:AH28,"*早*")-AW28 -> 4 | AW28: =COUNTIF(E28:AH28,"*早A") -> 0 | AX28: =COUNTIF(E28:AH28,"*中*") -> 0 | AY28: =COUNTIF(E28:AH28,"*午*")-AZ28 -> 0 | AZ28: =COUNTIF(E28:AH28,"*午F") -> 0 | BA28: =COUNTIF(E28:AH28,"*夜*") -> 0 | BB28: =COUNTIF(E28:AH28,"*T*") -> 0 | BC28: =COUNTIF(E28:AH28,"*日*") -> 0 | BD28: =COUNTIF(E28:AH28,"L") -> 4 | BE28: {=SUMPRODUCT(1*ISNUMBER(FIND("R",E28:AH28)))} -> 1 | BF28: {=SUMPRODUCT(1*ISNUMBER(FIND("r",E28:AH28)))} -> 1 | BG28: {=SUMPRODUCT(1*ISNUMBER(FIND("P",E28:AH28)))-SUMPRODUCT(1*ISNUMBER(FIND("午P",E28:AH28)))} -> 0 | BH28: =SUM(BE28:BG28) -> 2 | BI28: {=SUMPRODUCT(1*ISNUMBER(FIND("R",D28:J28)))} -> 1 | BJ28: {=SUMPRODUCT(1*ISNUMBER(FIND("R",K28:Q28)))} -> 0 | BK28: {=SUMPRODUCT(1*ISNUMBER(FIND("R",R28:X28)))} -> 0 | BL28: {=SUMPRODUCT(1*ISNUMBER(FIND("R",Y28:AE28)))} -> 0 | BM28: {=SUMPRODUCT(1*ISNUMBER(FIND("R",AF28:AL28)))} -> 0 | BN28: =SUM(AV28:BG28) -> 10 | BP28: 10 | BQ28: {=SUMPRODUCT(1*ISNUMBER(FIND("P",K28:AL28)))-SUMPRODUCT(1*ISNUMBER(FIND("午P",K28:AL28)))} -> 0
B29: T02498 | C29: 張芯瑜 | D29: 01中A | E29: 01午B1 | F29: 01午B1 | G29: r' | H29: 01午B2 | I29: 01午B1 | J29: R | K29: 長假 | L29: 長假 | M29: 長假 | N29: 長假 | O29: 長假 | P29: 長假 | AM29: =BP29+BQ29 -> 9 | AN29: 2 | AO29: 2 | AP29: 4 | AQ29: 4 | AR29: =COUNTIF(K29:X29,"r'*") -> 0 | AS29: =COUNTIF(K29:X29,"R") -> 0 | AT29: =8-AN29-AP29-AR29 -> 2 | AU29: =8-AO29-AQ29-AS29 -> 2 | AV29: =COUNTIF(E29:AH29,"*早*")-AW29 -> 0 | AW29: =COUNTIF(E29:AH29,"*早A") -> 0 | AX29: =COUNTIF(E29:AH29,"*中*") -> 0 | AY29: =COUNTIF(E29:AH29,"*午*")-AZ29 -> 4 | AZ29: =COUNTIF(E29:AH29,"*午F") -> 0 | BA29: =COUNTIF(E29:AH29,"*夜*") -> 0 | BB29: =COUNTIF(E29:AH29,"*T*") -> 0 | BC29: =COUNTIF(E29:AH29,"*日*") -> 0 | BD29: =COUNTIF(E29:AH29,"L") -> 0 | BE29: {=SUMPRODUCT(1*ISNUMBER(FIND("R",E29:AH29)))} -> 1 | BF29: {=SUMPRODUCT(1*ISNUMBER(FIND("r",E29:AH29)))} -> 1 | BG29: {=SUMPRODUCT(1*ISNUMBER(FIND("P",E29:AH29)))-SUMPRODUCT(1*ISNUMBER(FIND("午P",E29:AH29)))} -> 0 | BH29: =SUM(BE29:BG29) -> 2 | BI29: {=SUMPRODUCT(1*ISNUMBER(FIND("R",D29:J29)))} -> 1 | BJ29: {=SUMPRODUCT(1*ISNUMBER(FIND("R",K29:Q29)))} -> 0 | BK29: {=SUMPRODUCT(1*ISNUMBER(FIND("R",R29:X29)))} -> 0 | BL29: {=SUMPRODUCT(1*ISNUMBER(FIND("R",Y29:AE29)))} -> 0 | BM29: {=SUMPRODUCT(1*ISNUMBER(FIND("R",AF29:AL29)))} -> 0 | BN29: =SUM(AV29:BG29) -> 6 | BP29: 9 | BQ29: {=SUMPRODUCT(1*ISNUMBER(FIND("P",K29:AL29)))-SUMPRODUCT(1*ISNUMBER(FIND("午P",K29:AL29)))} -> 0
B30: T02612 | C30: 蕭曉琦 | D30: R | E30: 01早B1 | F30: 01早B2 | G30: 01午B1 | H30: r' | I30: r' | J30: 01早B1 | R30: R | AF30: R | AM30: =BP30+BQ30 -> 8 | AN30: 2 | AO30: 2 | AP30: 4 | AQ30: 4 | AR30: =COUNTIF(K30:X30,"r'*") -> 0 | AS30: =COUNTIF(K30:X30,"R") -> 1 | AT30: =8-AN30-AP30-AR30 -> 2 | AU30: =8-AO30-AQ30-AS30 -> 1 | AV30: =COUNTIF(E30:AH30,"*早*")-AW30 -> 3 | AW30: =COUNTIF(E30:AH30,"*早A") -> 0 | AX30: =COUNTIF(E30:AH30,"*中*") -> 0 | AY30: =COUNTIF(E30:AH30,"*午*")-AZ30 -> 1 | AZ30: =COUNTIF(E30:AH30,"*午F") -> 0 | BA30: =COUNTIF(E30:AH30,"*夜*") -> 0 | BB30: =COUNTIF(E30:AH30,"*T*") -> 0 | BC30: =COUNTIF(E30:AH30,"*日*") -> 0 | BD30: =COUNTIF(E30:AH30,"L") -> 0 | BE30: {=SUMPRODUCT(1*ISNUMBER(FIND("R",E30:AH30)))} -> 2 | BF30: {=SUMPRODUCT(1*ISNUMBER(FIND("r",E30:AH30)))} -> 2 | BG30: {=SUMPRODUCT(1*ISNUMBER(FIND("P",E30:AH30)))-SUMPRODUCT(1*ISNUMBER(FIND("午P",E30:AH30)))} -> 0 | BH30: =SUM(BE30:BG30) -> 4 | BI30: {=SUMPRODUCT(1*ISNUMBER(FIND("R",D30:J30)))} -> 1 | BJ30: {=SUMPRODUCT(1*ISNUMBER(FIND("R",K30:Q30)))} -> 0 | BK30: {=SUMPRODUCT(1*ISNUMBER(FIND("R",R30:X30)))} -> 1 | BL30: {=SUMPRODUCT(1*ISNUMBER(FIND("R",Y30:AE30)))} -> 0 | BM30: {=SUMPRODUCT(1*ISNUMBER(FIND("R",AF30:AL30)))} -> 1 | BN30: =SUM(AV30:BG30) -> 8 | BP30: 8 | BQ30: {=SUMPRODUCT(1*ISNUMBER(FIND("P",K30:AL30)))-SUMPRODUCT(1*ISNUMBER(FIND("午P",K30:AL30)))} -> 0
B31: T02613 | C31: 張雅荃 | D31: 01午B2 | E31: 01中A | F31: R | G31: 01午B1 | H31: 01午B2 | I31: r' | J31: 01午B2 | U31: R | AE31: R | AF31: r' | AK31: r' | AM31: =BP31+BQ31 -> 8 | AN31: 2 | AO31: 2 | AP31: 4 | AQ31: 4 | AR31: =COUNTIF(K31:X31,"r'*") -> 0 | AS31: =COUNTIF(K31:X31,"R") -> 1 | AT31: =8-AN31-AP31-AR31 -> 2 | AU31: =8-AO31-AQ31-AS31 -> 1 | AV31: =COUNTIF(E31:AH31,"*早*")-AW31 -> 0 | AW31: =COUNTIF(E31:AH31,"*早A") -> 0 | AX31: =COUNTIF(E31:AH31,"*中*") -> 1 | AY31: =COUNTIF(E31:AH31,"*午*")-AZ31 -> 3 | AZ31: =COUNTIF(E31:AH31,"*午F") -> 0 | BA31: =COUNTIF(E31:AH31,"*夜*") -> 0 | BB31: =COUNTIF(E31:AH31,"*T*") -> 0 | BC31: =COUNTIF(E31:AH31,"*日*") -> 0 | BD31: =COUNTIF(E31:AH31,"L") -> 0 | BE31: {=SUMPRODUCT(1*ISNUMBER(FIND("R",E31:AH31)))} -> 3 | BF31: {=SUMPRODUCT(1*ISNUMBER(FIND("r",E31:AH31)))} -> 2 | BG31: {=SUMPRODUCT(1*ISNUMBER(FIND("P",E31:AH31)))-SUMPRODUCT(1*ISNUMBER(FIND("午P",E31:AH31)))} -> 0 | BH31: =SUM(BE31:BG31) -> 5 | BI31: {=SUMPRODUCT(1*ISNUMBER(FIND("R",D31:J31)))} -> 1 | BJ31: {=SUMPRODUCT(1*ISNUMBER(FIND("R",K31:Q31)))} -> 0 | BK31: {=SUMPRODUCT(1*ISNUMBER(FIND("R",R31:X31)))} -> 1 | BL31: {=SUMPRODUCT(1*ISNUMBER(FIND("R",Y31:AE31)))} -> 1 | BM31: {=SUMPRODUCT(1*ISNUMBER(FIND("R",AF31:AL31)))} -> 0 | BN31: =SUM(AV31:BG31) -> 9 | BP31: 8 | BQ31: {=SUMPRODUCT(1*ISNUMBER(FIND("P",K31:AL31)))-SUMPRODUCT(1*ISNUMBER(FIND("午P",K31:AL31)))} -> 0
A32: A2 | B32: T00489 | C32: 吳珮伃 | D32: L | E32: R | F32: 02午 | G32: 02午 | H32: 02午 | I32: r' | J32: 02午 | V32: 長假 | W32: 長假 | X32: 長假 | Y32: 長假 | Z32: 長假 | AA32: 長假 | AB32: 長假 | AC32: 長假 | AD32: 長假 | AM32: =BP32+BQ32 -> 10 | AN32: 2 | AO32: 2 | AP32: 5 | AQ32: 4 | AR32: =COUNTIF(K32:X32,"r'*") -> 0 | AS32: =COUNTIF(K32:X32,"R") -> 0 | AT32: =8-AN32-AP32-AR32 -> 1 | AU32: =8-AO32-AQ32-AS32 -> 2 | AV32: =COUNTIF(E32:AH32,"*早*")-AW32 -> 0 | AW32: =COUNTIF(E32:AH32,"*早A") -> 0 | AX32: =COUNTIF(E32:AH32,"*中*") -> 0 | AY32: =COUNTIF(E32:AH32,"*午*")-AZ32 -> 4 | AZ32: =COUNTIF(E32:AH32,"*午F") -> 0 | BA32: =COUNTIF(E32:AH32,"*夜*") -> 0 | BB32: =COUNTIF(E32:AH32,"*T*") -> 0 | BC32: =COUNTIF(E32:AH32,"*日*") -> 0 | BD32: =COUNTIF(E32:AH32,"L") -> 0 | BE32: {=SUMPRODUCT(1*ISNUMBER(FIND("R",E32:AH32)))} -> 1 | BF32: {=SUMPRODUCT(1*ISNUMBER(FIND("r",E32:AH32)))} -> 1 | BG32: {=SUMPRODUCT(1*ISNUMBER(FIND("P",E32:AH32)))-SUMPRODUCT(1*ISNUMBER(FIND("午P",E32:AH32)))} -> 0 | BH32: =SUM(BE32:BG32) -> 2 | BI32: {=SUMPRODUCT(1*ISNUMBER(FIND("R",D32:J32)))} -> 1 | BJ32: {=SUMPRODUCT(1*ISNUMBER(FIND("R",K32:Q32)))} -> 0 | BK32: {=SUMPRODUCT(1*ISNUMBER(FIND("R",R32:X32)))} -> 0 | BL32: {=SUMPRODUCT(1*ISNUMBER(FIND("R",Y32:AE32)))} -> 0 | BM32: {=SUMPRODUCT(1*ISNUMBER(FIND("R",AF32:AL32)))} -> 0 | BN32: =SUM(AV32:BG32) -> 6 | BP32: 10 | BQ32: {=SUMPRODUCT(1*ISNUMBER(FIND("P",K32:AL32)))-SUMPRODUCT(1*ISNUMBER(FIND("午P",K32:AL32)))} -> 0
B33: T00523 | C33: 鄭翰鴻 | D33: 02午 | E33: 02午 | F33: P | G33: R | H33: 02早 | I33: 02早 | J33: 02早 | AM33: =BP33+BQ33 -> 10 | AN33: 3 | AO33: 2 | AP33: 5 | AQ33: 4 | AR33: =COUNTIF(K33:X33,"r'*") -> 0 | AS33: =COUNTIF(K33:X33,"R") -> 0 | AT33: =8-AN33-AP33-AR33 -> 0 | AU33: =8-AO33-AQ33-AS33 -> 2 | AV33: =COUNTIF(E33:AH33,"*早*")-AW33 -> 3 | AW33: =COUNTIF(E33:AH33,"*早A") -> 0 | AX33: =COUNTIF(E33:AH33,"*中*") -> 0 | AY33: =COUNTIF(E33:AH33,"*午*")-AZ33 -> 1 | AZ33: =COUNTIF(E33:AH33,"*午F") -> 0 | BA33: =COUNTIF(E33:AH33,"*夜*") -> 0 | BB33: =COUNTIF(E33:AH33,"*T*") -> 0 | BC33: =COUNTIF(E33:AH33,"*日*") -> 0 | BD33: =COUNTIF(E33:AH33,"L") -> 0 | BE33: {=SUMPRODUCT(1*ISNUMBER(FIND("R",E33:AH33)))} -> 1 | BF33: {=SUMPRODUCT(1*ISNUMBER(FIND("r",E33:AH33)))} -> 0 | BG33: {=SUMPRODUCT(1*ISNUMBER(FIND("P",E33:AH33)))-SUMPRODUCT(1*ISNUMBER(FIND("午P",E33:AH33)))} -> 1 | BH33: =SUM(BE33:BG33) -> 2 | BI33: {=SUMPRODUCT(1*ISNUMBER(FIND("R",D33:J33)))} -> 1 | BJ33: {=SUMPRODUCT(1*ISNUMBER(FIND("R",K33:Q33)))} -> 0 | BK33: {=SUMPRODUCT(1*ISNUMBER(FIND("R",R33:X33)))} -> 0 | BL33: {=SUMPRODUCT(1*ISNUMBER(FIND("R",Y33:AE33)))} -> 0 | BM33: {=SUMPRODUCT(1*ISNUMBER(FIND("R",AF33:AL33)))} -> 0 | BN33: =SUM(AV33:BG33) -> 6 | BP33: 10 | BQ33: {=SUMPRODUCT(1*ISNUMBER(FIND("P",K33:AL33)))-SUMPRODUCT(1*ISNUMBER(FIND("午P",K33:AL33)))} -> 0
B34: T00899 | C34: 陳炘玉 | D34: r' | E34: R | F34: r' | G34: 02夜 | H34: 02夜 | I34: 02夜 | J34: 02夜 | AI34: 長假 | AJ34: 長假 | AK34: 長假 | AL34: 長假 | AM34: =BP34+BQ34 -> 9 | AN34: 2 | AO34: 2 | AP34: 4 | AQ34: 4 | AR34: =COUNTIF(K34:X34,"r'*") -> 0 | AS34: =COUNTIF(K34:X34,"R") -> 0 | AT34: =8-AN34-AP34-AR34 -> 2 | AU34: =8-AO34-AQ34-AS34 -> 2 | AV34: =COUNTIF(E34:AH34,"*早*")-AW34 -> 0 | AW34: =COUNTIF(E34:AH34,"*早A") -> 0 | AX34: =COUNTIF(E34:AH34,"*中*") -> 0 | AY34: =COUNTIF(E34:AH34,"*午*")-AZ34 -> 0 | AZ34: =COUNTIF(E34:AH34,"*午F") -> 0 | BA34: =COUNTIF(E34:AH34,"*夜*") -> 4 | BB34: =COUNTIF(E34:AH34,"*T*") -> 0 | BC34: =COUNTIF(E34:AH34,"*日*") -> 0 | BD34: =COUNTIF(E34:AH34,"L") -> 0 | BE34: {=SUMPRODUCT(1*ISNUMBER(FIND("R",E34:AH34)))} -> 1 | BF34: {=SUMPRODUCT(1*ISNUMBER(FIND("r",E34:AH34)))} -> 1 | BG34: {=SUMPRODUCT(1*ISNUMBER(FIND("P",E34:AH34)))-SUMPRODUCT(1*ISNUMBER(FIND("午P",E34:AH34)))} -> 0 | BH34: =SUM(BE34:BG34) -> 2 | BI34: {=SUMPRODUCT(1*ISNUMBER(FIND("R",D34:J34)))} -> 1 | BJ34: {=SUMPRODUCT(1*ISNUMBER(FIND("R",K34:Q34)))} -> 0 | BK34: {=SUMPRODUCT(1*ISNUMBER(FIND("R",R34:X34)))} -> 0 | BL34: {=SUMPRODUCT(1*ISNUMBER(FIND("R",Y34:AE34)))} -> 0 | BM34: {=SUMPRODUCT(1*ISNUMBER(FIND("R",AF34:AL34)))} -> 0 | BN34: =SUM(AV34:BG34) -> 6 | BP34: 9 | BQ34: {=SUMPRODUCT(1*ISNUMBER(FIND("P",K34:AL34)))-SUMPRODUCT(1*ISNUMBER(FIND("午P",K34:AL34)))} -> 0
B35: T01025 | C35: 卓子揚 | D35: 02早 | E35: 02早 | F35: 02早 | G35: 02早 | H35: 01日(講師) | I35: r' | J35: R | N35: 長假 | O35: 長假 | P35: 長假 | Q35: 長假 | R35: 長假 | AM35: =BP35+BQ35 -> 10 | AN35: 2 | AO35: 2 | AP35: 4 | AQ35: 4 | AR35: =COUNTIF(K35:X35,"r'*") -> 0 | AS35: =COUNTIF(K35:X35,"R") -> 0 | AT35: =8-AN35-AP35-AR35 -> 2 | AU35: =8-AO35-AQ35-AS35 -> 2 | AV35: =COUNTIF(E35:AH35,"*早*")-AW35 -> 3 | AW35: =COUNTIF(E35:AH35,"*早A") -> 0 | AX35: =COUNTIF(E35:AH35,"*中*") -> 0 | AY35: =COUNTIF(E35:AH35,"*午*")-AZ35 -> 0 | AZ35: =COUNTIF(E35:AH35,"*午F") -> 0 | BA35: =COUNTIF(E35:AH35,"*夜*") -> 0 | BB35: =COUNTIF(E35:AH35,"*T*") -> 0 | BC35: =COUNTIF(E35:AH35,"*日*") -> 1 | BD35: =COUNTIF(E35:AH35,"L") -> 0 | BE35: {=SUMPRODUCT(1*ISNUMBER(FIND("R",E35:AH35)))} -> 1 | BF35: {=SUMPRODUCT(1*ISNUMBER(FIND("r",E35:AH35)))} -> 1 | BG35: {=SUMPRODUCT(1*ISNUMBER(FIND("P",E35:AH35)))-SUMPRODUCT(1*ISNUMBER(FIND("午P",E35:AH35)))} -> 0 | BH35: =SUM(BE35:BG35) -> 2 | BI35: {=SUMPRODUCT(1*ISNUMBER(FIND("R",D35:J35)))} -> 1 | BJ35: {=SUMPRODUCT(1*ISNUMBER(FIND("R",K35:Q35)))} -> 0 | BK35: {=SUMPRODUCT(1*ISNUMBER(FIND("R",R35:X35)))} -> 0 | BL35: {=SUMPRODUCT(1*ISNUMBER(FIND("R",Y35:AE35)))} -> 0 | BM35: {=SUMPRODUCT(1*ISNUMBER(FIND("R",AF35:AL35)))} -> 0 | BN35: =SUM(AV35:BG35) -> 6 | BP35: 10 | BQ35: {=SUMPRODUCT(1*ISNUMBER(FIND("P",K35:AL35)))-SUMPRODUCT(1*ISNUMBER(FIND("午P",K35:AL35)))} -> 0
B36: T02510 | C36: 張詠迎 | D36: 02夜 | E36: 02夜 | F36: 02夜 | G36: R | H36: P | I36: 02午 | J36: r' | K36: 長假 | L36: 長假 | M36: 長假 | N36: 長假 | O36: 長假 | AM36: =BP36+BQ36 -> 9 | AN36: 2 | AO36: 2 | AP36: 5 | AQ36: 4 | AR36: =COUNTIF(K36:X36,"r'*") -> 0 | AS36: =COUNTIF(K36:X36,"R") -> 0 | AT36: =8-AN36-AP36-AR36 -> 1 | AU36: =8-AO36-AQ36-AS36 -> 2 | AV36: =COUNTIF(E36:AH36,"*早*")-AW36 -> 0 | AW36: =COUNTIF(E36:AH36,"*早A") -> 0 | AX36: =COUNTIF(E36:AH36,"*中*") -> 0 | AY36: =COUNTIF(E36:AH36,"*午*")-AZ36 -> 1 | AZ36: =COUNTIF(E36:AH36,"*午F") -> 0 | BA36: =COUNTIF(E36:AH36,"*夜*") -> 2 | BB36: =COUNTIF(E36:AH36,"*T*") -> 0 | BC36: =COUNTIF(E36:AH36,"*日*") -> 0 | BD36: =COUNTIF(E36:AH36,"L") -> 0 | BE36: {=SUMPRODUCT(1*ISNUMBER(FIND("R",E36:AH36)))} -> 1 | BF36: {=SUMPRODUCT(1*ISNUMBER(FIND("r",E36:AH36)))} -> 1 | BG36: {=SUMPRODUCT(1*ISNUMBER(FIND("P",E36:AH36)))-SUMPRODUCT(1*ISNUMBER(FIND("午P",E36:AH36)))} -> 1 | BH36: =SUM(BE36:BG36) -> 3 | BI36: {=SUMPRODUCT(1*ISNUMBER(FIND("R",D36:J36)))} -> 1 | BJ36: {=SUMPRODUCT(1*ISNUMBER(FIND("R",K36:Q36)))} -> 0 | BK36: {=SUMPRODUCT(1*ISNUMBER(FIND("R",R36:X36)))} -> 0 | BL36: {=SUMPRODUCT(1*ISNUMBER(FIND("R",Y36:AE36)))} -> 0 | BM36: {=SUMPRODUCT(1*ISNUMBER(FIND("R",AF36:AL36)))} -> 0 | BN36: =SUM(AV36:BG36) -> 6 | BP36: 9 | BQ36: {=SUMPRODUCT(1*ISNUMBER(FIND("P",K36:AL36)))-SUMPRODUCT(1*ISNUMBER(FIND("午P",K36:AL36)))} -> 0
B37: T00510 | C37: 郭凌毓 | D37: R | E37: L | F37: L | G37: L | H37: L | I37: L | J37: r' | AM37: =BP37+BQ37 -> 11 | AN37: 2 | AO37: 2 | AP37: 4 | AQ37: 4 | AR37: =COUNTIF(K37:X37,"r'*") -> 0 | AS37: =COUNTIF(K37:X37,"R") -> 0 | AT37: =8-AN37-AP37-AR37 -> 2 | AU37: =8-AO37-AQ37-AS37 -> 2 | AV37: =COUNTIF(E37:AH37,"*早*")-AW37 -> 0 | AW37: =COUNTIF(E37:AH37,"*早A") -> 0 | AX37: =COUNTIF(E37:AH37,"*中*") -> 0 | AY37: =COUNTIF(E37:AH37,"*午*")-AZ37 -> 0 | AZ37: =COUNTIF(E37:AH37,"*午F") -> 0 | BA37: =COUNTIF(E37:AH37,"*夜*") -> 0 | BB37: =COUNTIF(E37:AH37,"*T*") -> 0 | BC37: =COUNTIF(E37:AH37,"*日*") -> 0 | BD37: =COUNTIF(E37:AH37,"L") -> 5 | BE37: {=SUMPRODUCT(1*ISNUMBER(FIND("R",E37:AH37)))} -> 0 | BF37: {=SUMPRODUCT(1*ISNUMBER(FIND("r",E37:AH37)))} -> 1 | BG37: {=SUMPRODUCT(1*ISNUMBER(FIND("P",E37:AH37)))-SUMPRODUCT(1*ISNUMBER(FIND("午P",E37:AH37)))} -> 0 | BH37: =SUM(BE37:BG37) -> 1 | BI37: {=SUMPRODUCT(1*ISNUMBER(FIND("R",D37:J37)))} -> 1 | BJ37: {=SUMPRODUCT(1*ISNUMBER(FIND("R",K37:Q37)))} -> 0 | BK37: {=SUMPRODUCT(1*ISNUMBER(FIND("R",R37:X37)))} -> 0 | BL37: {=SUMPRODUCT(1*ISNUMBER(FIND("R",Y37:AE37)))} -> 0 | BM37: {=SUMPRODUCT(1*ISNUMBER(FIND("R",AF37:AL37)))} -> 0 | BN37: =SUM(AV37:BG37) -> 6 | BP37: 11 | BQ37: {=SUMPRODUCT(1*ISNUMBER(FIND("P",K37:AL37)))-SUMPRODUCT(1*ISNUMBER(FIND("午P",K37:AL37)))} -> 0
B38: T01264 | C38: 高子翔 | D38: R | E38: r' | F38: 02早 | G38: 02早 | H38: r' | I38: P | J38: 02早 | AA38: 勞安訓 | AM38: =BP38+BQ38 -> 7 | AN38: 2 | AO38: 2 | AP38: 4 | AQ38: 4 | AR38: =COUNTIF(K38:X38,"r'*") -> 0 | AS38: =COUNTIF(K38:X38,"R") -> 0 | AT38: =8-AN38-AP38-AR38 -> 2 | AU38: =8-AO38-AQ38-AS38 -> 2 | AV38: =COUNTIF(E38:AH38,"*早*")-AW38 -> 3 | AW38: =COUNTIF(E38:AH38,"*早A") -> 0 | AX38: =COUNTIF(E38:AH38,"*中*") -> 0 | AY38: =COUNTIF(E38:AH38,"*午*")-AZ38 -> 0 | AZ38: =COUNTIF(E38:AH38,"*午F") -> 0 | BA38: =COUNTIF(E38:AH38,"*夜*") -> 0 | BB38: =COUNTIF(E38:AH38,"*T*") -> 0 | BC38: =COUNTIF(E38:AH38,"*日*") -> 0 | BD38: =COUNTIF(E38:AH38,"L") -> 0 | BE38: {=SUMPRODUCT(1*ISNUMBER(FIND("R",E38:AH38)))} -> 0 | BF38: {=SUMPRODUCT(1*ISNUMBER(FIND("r",E38:AH38)))} -> 2 | BG38: {=SUMPRODUCT(1*ISNUMBER(FIND("P",E38:AH38)))-SUMPRODUCT(1*ISNUMBER(FIND("午P",E38:AH38)))} -> 1 | BH38: =SUM(BE38:BG38) -> 3 | BI38: {=SUMPRODUCT(1*ISNUMBER(FIND("R",D38:J38)))} -> 1 | BJ38: {=SUMPRODUCT(1*ISNUMBER(FIND("R",K38:Q38)))} -> 0 | BK38: {=SUMPRODUCT(1*ISNUMBER(FIND("R",R38:X38)))} -> 0 | BL38: {=SUMPRODUCT(1*ISNUMBER(FIND("R",Y38:AE38)))} -> 0 | BM38: {=SUMPRODUCT(1*ISNUMBER(FIND("R",AF38:AL38)))} -> 0 | BN38: =SUM(AV38:BG38) -> 6 | BP38: 7 | BQ38: {=SUMPRODUCT(1*ISNUMBER(FIND("P",K38:AL38)))-SUMPRODUCT(1*ISNUMBER(FIND("午P",K38:AL38)))} -> 0
B39: T01746 | C39: 古佩宜 | D39: 02午 | E39: P | F39: r' | G39: 02午 | H39: 02午 | I39: R | J39: r' | AL39: 長假 | AM39: =BP39+BQ39 -> 8 | AN39: 2 | AO39: 2 | AP39: 4 | AQ39: 4 | AR39: =COUNTIF(K39:X39,"r'*") -> 0 | AS39: =COUNTIF(K39:X39,"R") -> 0 | AT39: =8-AN39-AP39-AR39 -> 2 | AU39: =8-AO39-AQ39-AS39 -> 2 | AV39: =COUNTIF(E39:AH39,"*早*")-AW39 -> 0 | AW39: =COUNTIF(E39:AH39,"*早A") -> 0 | AX39: =COUNTIF(E39:AH39,"*中*") -> 0 | AY39: =COUNTIF(E39:AH39,"*午*")-AZ39 -> 2 | AZ39: =COUNTIF(E39:AH39,"*午F") -> 0 | BA39: =COUNTIF(E39:AH39,"*夜*") -> 0 | BB39: =COUNTIF(E39:AH39,"*T*") -> 0 | BC39: =COUNTIF(E39:AH39,"*日*") -> 0 | BD39: =COUNTIF(E39:AH39,"L") -> 0 | BE39: {=SUMPRODUCT(1*ISNUMBER(FIND("R",E39:AH39)))} -> 1 | BF39: {=SUMPRODUCT(1*ISNUMBER(FIND("r",E39:AH39)))} -> 2 | BG39: {=SUMPRODUCT(1*ISNUMBER(FIND("P",E39:AH39)))-SUMPRODUCT(1*ISNUMBER(FIND("午P",E39:AH39)))} -> 1 | BH39: =SUM(BE39:BG39) -> 4 | BI39: {=SUMPRODUCT(1*ISNUMBER(FIND("R",D39:J39)))} -> 1 | BJ39: {=SUMPRODUCT(1*ISNUMBER(FIND("R",K39:Q39)))} -> 0 | BK39: {=SUMPRODUCT(1*ISNUMBER(FIND("R",R39:X39)))} -> 0 | BL39: {=SUMPRODUCT(1*ISNUMBER(FIND("R",Y39:AE39)))} -> 0 | BM39: {=SUMPRODUCT(1*ISNUMBER(FIND("R",AF39:AL39)))} -> 0 | BN39: =SUM(AV39:BG39) -> 6 | BP39: 8 | BQ39: {=SUMPRODUCT(1*ISNUMBER(FIND("P",K39:AL39)))-SUMPRODUCT(1*ISNUMBER(FIND("午P",K39:AL39)))} -> 0
B40: T01865 | C40: 顏志宇 | D40: 02早 | E40: 02早 | F40: 02午 | G40: R | H40: 02早 | I40: 02午 | J40: 02午 | AM40: =BP40+BQ40 -> 8 | AN40: 2 | AO40: 2 | AP40: 5 | AQ40: 4 | AR40: =COUNTIF(K40:X40,"r'*") -> 0 | AS40: =COUNTIF(K40:X40,"R") -> 0 | AT40: =8-AN40-AP40-AR40 -> 1 | AU40: =8-AO40-AQ40-AS40 -> 2 | AV40: =COUNTIF(E40:AH40,"*早*")-AW40 -> 2 | AW40: =COUNTIF(E40:AH40,"*早A") -> 0 | AX40: =COUNTIF(E40:AH40,"*中*") -> 0 | AY40: =COUNTIF(E40:AH40,"*午*")-AZ40 -> 3 | AZ40: =COUNTIF(E40:AH40,"*午F") -> 0 | BA40: =COUNTIF(E40:AH40,"*夜*") -> 0 | BB40: =COUNTIF(E40:AH40,"*T*") -> 0 | BC40: =COUNTIF(E40:AH40,"*日*") -> 0 | BD40: =COUNTIF(E40:AH40,"L") -> 0 | BE40: {=SUMPRODUCT(1*ISNUMBER(FIND("R",E40:AH40)))} -> 1 | BF40: {=SUMPRODUCT(1*ISNUMBER(FIND("r",E40:AH40)))} -> 0 | BG40: {=SUMPRODUCT(1*ISNUMBER(FIND("P",E40:AH40)))-SUMPRODUCT(1*ISNUMBER(FIND("午P",E40:AH40)))} -> 0 | BH40: =SUM(BE40:BG40) -> 1 | BI40: {=SUMPRODUCT(1*ISNUMBER(FIND("R",D40:J40)))} -> 1 | BJ40: {=SUMPRODUCT(1*ISNUMBER(FIND("R",K40:Q40)))} -> 0 | BK40: {=SUMPRODUCT(1*ISNUMBER(FIND("R",R40:X40)))} -> 0 | BL40: {=SUMPRODUCT(1*ISNUMBER(FIND("R",Y40:AE40)))} -> 0 | BM40: {=SUMPRODUCT(1*ISNUMBER(FIND("R",AF40:AL40)))} -> 0 | BN40: =SUM(AV40:BG40) -> 6 | BP40: 8 | BQ40: {=SUMPRODUCT(1*ISNUMBER(FIND("P",K40:AL40)))-SUMPRODUCT(1*ISNUMBER(FIND("午P",K40:AL40)))} -> 0
...

Sheet 北段 (人資版)
B1: 員編 ID No. | C1: 日期 星期 姓名 | D1: 46143 | E1: =D1+1 -> 46144 | F1: =E1+1 -> 46145 | G1: =F1+1 -> 46146 | H1: =G1+1 -> 46147 | I1: =H1+1 -> 46148 | J1: =I1+1 -> 46149 | K1: =J1+1 -> 46150 | L1: =K1+1 -> 46151 | ... AN1: =AM1+1 -> 46179
D2: =IFERROR(IF(WEEKDAY(D1,2)=7,"日",WEEKDAY(D1,2)),"") -> 5 | E2: =IFERROR(IF(WEEKDAY(E1,2)=7,"日",WEEKDAY(E1,2)),"") -> 6 | F2: =IFERROR(IF(WEEKDAY(F1,2)=7,"日",WEEKDAY(F1,2)),"") -> 日 | G2: =IFERROR(IF(WEEKDAY(G1,2)=7,"日",WEEKDAY(G1,2)),"") -> 1 | H2: =IFERROR(IF(WEEKDAY(H1,2)=7,"日",WEEKDAY(H1,2)),"") -> 2 | I2: =IFERROR(IF(WEEKDAY(I1,2)=7,"日",WEEKDAY(I1,2)),"") -> 3 | J2: =IFERROR(IF(WEEKDAY(J1,2)=7,"日",WEEKDAY(J1,2)),"") -> 4 | K2: =IFERROR(IF(WEEKDAY(K1,2)=7,"日",WEEKDAY(K1,2)),"") -> 5 | ... AN2: =IFERROR(IF(WEEKDAY(AN1,2)=7,"日",WEEKDAY(AN1,2)),"") -> 6
B3: =LEFT(北段!B3,6) -> T00082 | C3: =VLOOKUP(B3,北段!B:C,2,FALSE) -> 梁仲煒 | D3: =LEFT(北段!I3,4) -> 41日 | E3: =LEFT(北段!J3,4) -> r' | F3: =LEFT(北段!K3,4) | G3: =LEFT(北段!L3,4) | H3: =LEFT(北段!M3,4) | I3: =LEFT(北段!N3,4) | J3: =LEFT(北段!O3,4) | K3: =LEFT(北段!P3,4) | ... AG3: =LEFT(北段!AL3,4) | AH3: =LEFT(北段!#REF!,4) -> #REF! | AI3: =LEFT(北段!#REF!,4) -> #REF! | AJ3: =LEFT(北段!#REF!,4) -> #REF! | AK3: =LEFT(北段!#REF!,4) -> #REF! | AL3: =LEFT(北段!#REF!,4) -> #REF! | AM3: =LEFT(北段!#REF!,4) -> #REF! | AN3: =LEFT(北段!#REF!,4) -> #REF!
B4: =LEFT(北段!B4,6) -> T00178 | C4: =VLOOKUP(B4,北段!B:C,2,FALSE) -> 何旺宗 | D4: =LEFT(北段!I4,4) -> 41早 | E4: =LEFT(北段!J4,4) -> 41早 | F4: =LEFT(北段!K4,4) | G4: =LEFT(北段!L4,4) | H4: =LEFT(北段!M4,4) | I4: =LEFT(北段!N4,4) | J4: =LEFT(北段!O4,3) | K4: =LEFT(北段!P4,4) | L4: =LEFT(北段!Q4,4) | M4: =LEFT(北段!R4,4) | N4: =LEFT(北段!S4,4) | O4: =LEFT(北段!T4,4) | P4: =LEFT(北段!U4,4) | Q4: =LEFT(北段!V4,4) | R4: =LEFT(北段!W4,4) | ... AG4: =LEFT(北段!AL4,4) | AH4: =LEFT(北段!#REF!,4) -> #REF! | AI4: =LEFT(北段!#REF!,4) -> #REF! | AJ4: =LEFT(北段!#REF!,4) -> #REF! | AK4: =LEFT(北段!#REF!,4) -> #REF! | AL4: =LEFT(北段!#REF!,4) -> #REF! | AM4: =LEFT(北段!#REF!,4) -> #REF! | AN4: =LEFT(北段!#REF!,4) -> #REF!
B5: =LEFT(北段!B5,6) -> T00252 | C5: =VLOOKUP(B5,北段!B:C,2,FALSE) -> 馮炫強 | D5: =LEFT(北段!I5,4) -> 41夜 | E5: =LEFT(北段!J5,4) -> 41夜 | F5: =LEFT(北段!K5,4) | G5: =LEFT(北段!L5,4) | H5: =LEFT(北段!M5,4) | I5: =LEFT(北段!N5,4) | J5: =LEFT(北段!O5,4) | K5: =LEFT(北段!P5,4) | ... X5: =LEFT(北段!AC5,4) | Y5: =LEFT(北段!AD5,3) | Z5: =LEFT(北段!AE5,4) | AA5: =LEFT(北段!AF5,4) | AB5: =LEFT(北段!AG5,4) | AC5: =LEFT(北段!AH5,4) | AD5: =LEFT(北段!AI5,4) | AE5: =LEFT(北段!AJ5,4) | AF5: =LEFT(北段!AK5,4) | AG5: =LEFT(北段!AL5,4) | AH5: =LEFT(北段!#REF!,4) -> #REF! | AI5: =LEFT(北段!#REF!,4) -> #REF! | AJ5: =LEFT(北段!#REF!,4) -> #REF! | AK5: =LEFT(北段!#REF!,4) -> #REF! | AL5: =LEFT(北段!#REF!,4) -> #REF! | AM5: =LEFT(北段!#REF!,4) -> #REF! | AN5: =LEFT(北段!#REF!,4) -> #REF!
B6: =LEFT(北段!B6,6) -> T00343 | C6: =VLOOKUP(B6,北段!B:C,2,FALSE) -> 劉哲宇 | D6: =LEFT(北段!I6,4) -> 41日( | E6: =LEFT(北段!J6,4) -> 06早 | F6: =LEFT(北段!K6,4) | G6: =LEFT(北段!L6,4) | H6: =LEFT(北段!M6,4) | I6: =LEFT(北段!N6,4) | J6: =LEFT(北段!O6,4) | K6: =LEFT(北段!P6,3) | L6: =LEFT(北段!Q6,4) | M6: =LEFT(北段!R6,4) | N6: =LEFT(北段!S6,4) | O6: =LEFT(北段!T6,4) | P6: =LEFT(北段!U6,4) | Q6: =LEFT(北段!V6,3) | R6: =LEFT(北段!W6,4) | S6: =LEFT(北段!X6,4) | T6: =LEFT(北段!Y6,4) | U6: =LEFT(北段!Z6,4) | V6: =LEFT(北段!AA6,4) -> 勞安訓 | W6: =LEFT(北段!AB6,4) | X6: =LEFT(北段!AC6,4) | Y6: =LEFT(北段!AD6,4) | ... AA6: =LEFT(北段!AF6,4) | AB6: =LEFT(北段!AG6,3) | AC6: =LEFT(北段!AH6,4) | AD6: =LEFT(北段!AI6,4) | AE6: =LEFT(北段!AJ6,4) | AF6: =LEFT(北段!AK6,4) | AG6: =LEFT(北段!AL6,4) | AH6: =LEFT(北段!#REF!,4) -> #REF! | AI6: =LEFT(北段!#REF!,4) -> #REF! | AJ6: =LEFT(北段!#REF!,4) -> #REF! | AK6: =LEFT(北段!#REF!,4) -> #REF! | AL6: =LEFT(北段!#REF!,4) -> #REF! | AM6: =LEFT(北段!#REF!,4) -> #REF! | AN6: =LEFT(北段!#REF!,4) -> #REF!
B7: =LEFT(北段!B7,6) -> T00356 | C7: =VLOOKUP(B7,北段!B:C,2,FALSE) -> 吳國強 | D7: =LEFT(北段!I7,4) -> 41午 | E7: =LEFT(北段!J7,4) -> 41午 | F7: =LEFT(北段!K7,4) | G7: =LEFT(北段!L7,4) | H7: =LEFT(北段!M7,4) | I7: =LEFT(北段!N7,4) | J7: =LEFT(北段!O7,4) | K7: =LEFT(北段!P7,4) | ... U7: =LEFT(北段!Z7,4) | V7: =LEFT(北段!AA7,3) | W7: =LEFT(北段!AB7,4) | X7: =LEFT(北段!AC7,4) | Y7: =LEFT(北段!AD7,4) | Z7: =LEFT(北段!AE7,4) | AA7: =LEFT(北段!AF7,4) | AB7: =LEFT(北段!AG7,4) | AC7: =LEFT(北段!AH7,4) | AD7: =LEFT(北段!AI7,4) | ... AG7: =LEFT(北段!AL7,4) | AH7: =LEFT(北段!#REF!,4) -> #REF! | AI7: =LEFT(北段!#REF!,4) -> #REF! | AJ7: =LEFT(北段!#REF!,4) -> #REF! | AK7: =LEFT(北段!#REF!,3) -> #REF! | AL7: =LEFT(北段!#REF!,4) -> #REF! | AM7: =LEFT(北段!#REF!,4) -> #REF! | AN7: =LEFT(北段!#REF!,4) -> #REF!
B8: =LEFT(北段!B8,6) -> T00492 | C8: =VLOOKUP(B8,北段!B:C,2,FALSE) -> 李尉羽 | D8: =LEFT(北段!I8,4) -> P | E8: =LEFT(北段!J8,4) -> r' | F8: =LEFT(北段!K8,4) -> 長假 | G8: =LEFT(北段!L8,3) -> 長假 | H8: =LEFT(北段!M8,4) | I8: =LEFT(北段!N8,4) | J8: =LEFT(北段!O8,4) | K8: =LEFT(北段!P8,4) | L8: =LEFT(北段!Q8,4) | M8: =LEFT(北段!R8,4) | N8: =LEFT(北段!S8,4) | O8: =LEFT(北段!T8,4) | ... W8: =LEFT(北段!AB8,4) | X8: =LEFT(北段!AC8,3) | Y8: =LEFT(北段!AD8,4) | Z8: =LEFT(北段!AE8,4) | AA8: =LEFT(北段!AF8,4) | AB8: =LEFT(北段!AG8,4) | AC8: =LEFT(北段!AH8,4) | AD8: =LEFT(北段!AI8,4) | AE8: =LEFT(北段!AJ8,4) | AF8: =LEFT(北段!AK8,4) | AG8: =LEFT(北段!AL8,4) | AH8: =LEFT(北段!#REF!,4) -> #REF! | AI8: =LEFT(北段!#REF!,4) -> #REF! | AJ8: =LEFT(北段!#REF!,4) -> #REF! | AK8: =LEFT(北段!#REF!,4) -> #REF! | AL8: =LEFT(北段!#REF!,4) -> #REF! | AM8: =LEFT(北段!#REF!,4) -> #REF! | AN8: =LEFT(北段!#REF!,4) -> #REF!
B9: =LEFT(北段!B9,6) -> T00586 | C9: =VLOOKUP(B9,北段!B:C,2,FALSE) -> 江冠滿 | D9: =LEFT(北段!I9,8) -> 41日 | E9: =LEFT(北段!J9,8) -> R | F9: =LEFT(北段!K9,8) -> 長假 | G9: =LEFT(北段!L9,8) -> 長假 | H9: =LEFT(北段!M9,8) -> 長假 | I9: =LEFT(北段!N9,8) -> 長假 | J9: =LEFT(北段!O9,8) -> 長假 | K9: =LEFT(北段!P9,8) -> 長假 | ... AG9: =LEFT(北段!AL9,8) | AH9: =LEFT(北段!#REF!,8) -> #REF! | AI9: =LEFT(北段!#REF!,8) -> #REF! | AJ9: =LEFT(北段!#REF!,8) -> #REF! | AK9: =LEFT(北段!#REF!,8) -> #REF! | AL9: =LEFT(北段!#REF!,8) -> #REF! | AM9: =LEFT(北段!#REF!,8) -> #REF! | AN9: =LEFT(北段!#REF!,8) -> #REF!
B10: =LEFT(北段!B10,6) -> T00605 | C10: =VLOOKUP(B10,北段!B:C,2,FALSE) -> 謝蕙芸 | D10: =LEFT(北段!I10,4) -> 41日 | E10: =LEFT(北段!J10,4) -> r' | F10: =LEFT(北段!K10,4) | G10: =LEFT(北段!L10,4) | H10: =LEFT(北段!M10,4) | I10: =LEFT(北段!N10,4) | J10: =LEFT(北段!O10,4) | K10: =LEFT(北段!P10,4) | ... U10: =LEFT(北段!Z10,4) | V10: =LEFT(北段!AA10,3) | W10: =LEFT(北段!AB10,4) | X10: =LEFT(北段!AC10,4) | Y10: =LEFT(北段!AD10,4) | Z10: =LEFT(北段!AE10,4) | AA10: =LEFT(北段!AF10,4) | AB10: =LEFT(北段!AG10,4) | AC10: =LEFT(北段!AH10,4) | AD10: =LEFT(北段!AI10,4) | ... AG10: =LEFT(北段!AL10,4) | AH10: =LEFT(北段!#REF!,4) -> #REF! | AI10: =LEFT(北段!#REF!,4) -> #REF! | AJ10: =LEFT(北段!#REF!,4) -> #REF! | AK10: =LEFT(北段!#REF!,4) -> #REF! | AL10: =LEFT(北段!#REF!,4) -> #REF! | AM10: =LEFT(北段!#REF!,4) -> #REF! | AN10: =LEFT(北段!#REF!,4) -> #REF!
B11: =LEFT(北段!B11,6) -> T00912 | C11: =VLOOKUP(B11,北段!B:C,2,FALSE) -> 詹雅惠 | D11: =LEFT(北段!I11,4) -> L | E11: =LEFT(北段!J11,4) -> r' | F11: =LEFT(北段!K11,4) -> 長假 | G11: =LEFT(北段!L11,4) -> 長假 | H11: =LEFT(北段!M11,4) -> 長假 | I11: =LEFT(北段!N11,4) -> 長假 | J11: =LEFT(北段!O11,4) -> 長假 | K11: =LEFT(北段!P11,4) -> 長假 | ... AG11: =LEFT(北段!AL11,4) | AH11: =LEFT(北段!#REF!,4) -> #REF! | AI11: =LEFT(北段!#REF!,4) -> #REF! | AJ11: =LEFT(北段!#REF!,4) -> #REF! | AK11: =LEFT(北段!#REF!,4) -> #REF! | AL11: =LEFT(北段!#REF!,4) -> #REF! | AM11: =LEFT(北段!#REF!,4) -> #REF! | AN11: =LEFT(北段!#REF!,4) -> #REF!
