Workbook

Sheet 北段
B1: 員編 ID No. | C1: 日期 星期 姓名 | D1: 46229 | E1: =D1+1 -> 46230 | F1: =E1+1 -> 46231 | G1: =F1+1 -> 46232 | H1: =G1+1 -> 46233 | I1: =H1+1 -> 46234 | J1: 46235 | K1: 46236 | L1: =K1+1 -> 46237 | M1: =L1+1 -> 46238 | N1: =M1+1 -> 46239 | O1: =N1+1 -> 46240 | P1: =O1+1 -> 46241 | Q1: =P1+1 -> 46242 | R1: =Q1+1 -> 46243 | S1: =R1+1 -> 46244 | ... AS1: =AR1+1 -> 46270 | AT1: 1/1~9/5 P班天數 | AU1: 7/19~8/1 實際休假天數 | AW1: 8/2~9/5 實際休假天數 | AY1: 9/6~9/12 剩餘休假天數 | BA1: 8份班別小計 | BI1: 8月份 | BN1: 7/26~8/1 | BO1: 8/2~8/8 | BP1: 8/9~8/15 | BQ1: 8/16~8/22 | BR1: 8/23~8/29 | BS1: 8/30~9/5 | BT1: 8月天數 | BV1: 1/1~8/1 P班天數 | BW1: 8/2~9/5 P班天數
D2: =RIGHT(TEXT(D1,"[$-404]aaaa;@"),1) -> 日 | E2: =RIGHT(TEXT(E1,"[$-404]aaaa;@"),1) -> 一 | F2: =RIGHT(TEXT(F1,"[$-404]aaaa;@"),1) -> 二 | G2: =RIGHT(TEXT(G1,"[$-404]aaaa;@"),1) -> 三 | H2: =RIGHT(TEXT(H1,"[$-404]aaaa;@"),1) -> 四 | I2: =RIGHT(TEXT(I1,"[$-404]aaaa;@"),1) -> 五 | J2: =RIGHT(TEXT(J1,"[$-404]aaaa;@"),1) -> 六 | K2: =RIGHT(TEXT(K1,"[$-404]aaaa;@"),1) -> 日 | ... AS2: =RIGHT(TEXT(AS1,"[$-404]aaaa;@"),1) -> 六 | AU2: r | AV2: R | AW2: r | AX2: R | AY2: r | AZ2: R | BA2: 早 | BB2: 早A | BC2: 中 | BD2: 午 | BE2: 午F | BF2: 夜 | BG2: T | BH2: 日 | BI2: L | BJ2: R | BK2: r | BL2: P | BM2: 休假 日數 | BN2: R | BO2: R | BP2: R | BQ2: R | BR2: R | BS2: R
A3: A1 | B3: T01028 | C3: 林金緗 | D3: 01午M | E3: L | F3: L | G3: L | H3: R | I3: 01午m | J3: 01午M | M3: R | X3: R | AI3: r' | AL3: R | AT3: =BV3+BW3 -> 11 | AU3: 2 | AV3: 2 | AW3: =COUNTIF(K3:AS3,"r'*") -> 1 | AX3: =COUNTIF(K3:AS3,"R") -> 3 | AY3: =8-AU3-AW3 -> 5 | AZ3: =8-AV3-AX3 -> 3 | BA3: =COUNTIF(J3:AN3,"*早*")-BB3 -> 0 | BB3: =COUNTIF(J3:AN3,"*早A") -> 0 | BC3: =COUNTIF(J3:AN3,"*中*") -> 0 | BD3: =COUNTIF(J3:AN3,"*午*")-BE3 -> 1 | BE3: =COUNTIF(J3:AN3,"*午F") -> 0 | BF3: =COUNTIF(J3:AN3,"*夜*") -> 0 | BG3: =COUNTIF(J3:AN3,"*T*") -> 0 | BH3: =COUNTIF(J3:AN3,"*日*") -> 0 | BI3: =COUNTIF(J3:AN3,"L") -> 0 | BJ3: {=SUMPRODUCT(1*ISNUMBER(FIND("R",J3:AN3)))} -> 3 | BK3: {=SUMPRODUCT(1*ISNUMBER(FIND("r",J3:AN3)))} -> 1 | BL3: {=SUMPRODUCT(1*ISNUMBER(FIND("P",J3:AN3)))-SUMPRODUCT(1*ISNUMBER(FIND("午P",G3:AK3)))} -> 0 | BM3: =SUM(BJ3:BL3) -> 4 | BN3: {=SUMPRODUCT(1*ISNUMBER(FIND("R",D3:J3)))} -> 1 | BO3: {=SUMPRODUCT(1*ISNUMBER(FIND("R",K3:Q3)))} -> 1 | BP3: {=SUMPRODUCT(1*ISNUMBER(FIND("R",R3:X3)))} -> 1 | BQ3: {=SUMPRODUCT(1*ISNUMBER(FIND("R",Y3:AE3)))} -> 0 | BR3: {=SUMPRODUCT(1*ISNUMBER(FIND("R",AF3:AL3)))} -> 1 | BS3: {=SUMPRODUCT(1*ISNUMBER(FIND("R",AM3:AS3)))} -> 0 | BT3: =SUM(BA3:BL3) -> 5 | BV3: 11 | BW3: {=SUMPRODUCT(1*ISNUMBER(FIND("P",K3:AL3)))-SUMPRODUCT(1*ISNUMBER(FIND("午P",K3:AL3)))} -> 0
B4: T00509 | C4: 郭秋儀 | D4: r' | E4: 01早M | F4: 01早m | G4: 01早M(減壓課) | H4: R | I4: 01早M | J4: 01午m | N4: L | AA4: r' | AB4: L | AC4: r' | AD4: r' | AE4: R | AF4: R | AT4: =BV4+BW4 -> 11 | AU4: 2 | AV4: 2 | AW4: =COUNTIF(K4:AS4,"r'*") -> 3 | AX4: =COUNTIF(K4:AS4,"R") -> 2 | AY4: =8-AU4-AW4 -> 3 | AZ4: =8-AV4-AX4 -> 4 | BA4: =COUNTIF(J4:AN4,"*早*")-BB4 -> 0 | BB4: =COUNTIF(J4:AN4,"*早A") -> 0 | BC4: =COUNTIF(J4:AN4,"*中*") -> 0 | BD4: =COUNTIF(J4:AN4,"*午*")-BE4 -> 1 | BE4: =COUNTIF(J4:AN4,"*午F") -> 0 | BF4: =COUNTIF(J4:AN4,"*夜*") -> 0 | BG4: =COUNTIF(J4:AN4,"*T*") -> 0 | BH4: =COUNTIF(J4:AN4,"*日*") -> 0 | BI4: =COUNTIF(J4:AN4,"L") -> 2 | BJ4: {=SUMPRODUCT(1*ISNUMBER(FIND("R",J4:AN4)))} -> 2 | BK4: {=SUMPRODUCT(1*ISNUMBER(FIND("r",J4:AN4)))} -> 3 | BL4: {=SUMPRODUCT(1*ISNUMBER(FIND("P",J4:AN4)))-SUMPRODUCT(1*ISNUMBER(FIND("午P",G4:AK4)))} -> 0 | BM4: =SUM(BJ4:BL4) -> 5 | BN4: {=SUMPRODUCT(1*ISNUMBER(FIND("R",D4:J4)))} -> 1 | BO4: {=SUMPRODUCT(1*ISNUMBER(FIND("R",K4:Q4)))} -> 0 | BP4: {=SUMPRODUCT(1*ISNUMBER(FIND("R",R4:X4)))} -> 0 | BQ4: {=SUMPRODUCT(1*ISNUMBER(FIND("R",Y4:AE4)))} -> 1 | BR4: {=SUMPRODUCT(1*ISNUMBER(FIND("R",AF4:AL4)))} -> 1 | BS4: {=SUMPRODUCT(1*ISNUMBER(FIND("R",AM4:AS4)))} -> 0 | BT4: =SUM(BA4:BL4) -> 8 | BV4: 11 | BW4: {=SUMPRODUCT(1*ISNUMBER(FIND("P",K4:AL4)))-SUMPRODUCT(1*ISNUMBER(FIND("午P",K4:AL4)))} -> 0
B5: T01029 | C5: 林雯琳 | D5: L | E5: r' | F5: P | G5: R | H5: 01夜B2 | I5: 01夜B1 | J5: 01夜B2 | AA5: L | AB5: L | AC5: r' | AD5: R | AE5: L | AF5: L | AK5: R | AT5: =BV5+BW5 -> 11 | AU5: 2 | AV5: 2 | AW5: =COUNTIF(K5:AS5,"r'*") -> 1 | AX5: =COUNTIF(K5:AS5,"R") -> 2 | AY5: =8-AU5-AW5 -> 5 | AZ5: =8-AV5-AX5 -> 4 | BA5: =COUNTIF(J5:AN5,"*早*")-BB5 -> 0 | BB5: =COUNTIF(J5:AN5,"*早A") -> 0 | BC5: =COUNTIF(J5:AN5,"*中*") -> 0 | BD5: =COUNTIF(J5:AN5,"*午*")-BE5 -> 0 | BE5: =COUNTIF(J5:AN5,"*午F") -> 0 | BF5: =COUNTIF(J5:AN5,"*夜*") -> 1 | BG5: =COUNTIF(J5:AN5,"*T*") -> 0 | BH5: =COUNTIF(J5:AN5,"*日*") -> 0 | BI5: =COUNTIF(J5:AN5,"L") -> 4 | BJ5: {=SUMPRODUCT(1*ISNUMBER(FIND("R",J5:AN5)))} -> 2 | BK5: {=SUMPRODUCT(1*ISNUMBER(FIND("r",J5:AN5)))} -> 1 | BL5: {=SUMPRODUCT(1*ISNUMBER(FIND("P",J5:AN5)))-SUMPRODUCT(1*ISNUMBER(FIND("午P",G5:AK5)))} -> 0 | BM5: =SUM(BJ5:BL5) -> 3 | BN5: {=SUMPRODUCT(1*ISNUMBER(FIND("R",D5:J5)))} -> 1 | BO5: {=SUMPRODUCT(1*ISNUMBER(FIND("R",K5:Q5)))} -> 0 | BP5: {=SUMPRODUCT(1*ISNUMBER(FIND("R",R5:X5)))} -> 0 | BQ5: {=SUMPRODUCT(1*ISNUMBER(FIND("R",Y5:AE5)))} -> 1 | BR5: {=SUMPRODUCT(1*ISNUMBER(FIND("R",AF5:AL5)))} -> 1 | BS5: {=SUMPRODUCT(1*ISNUMBER(FIND("R",AM5:AS5)))} -> 0 | BT5: =SUM(BA5:BL5) -> 8 | BV5: 11 | BW5: {=SUMPRODUCT(1*ISNUMBER(FIND("P",K5:AL5)))-SUMPRODUCT(1*ISNUMBER(FIND("午P",K5:AL5)))} -> 0
B6: T01734 | C6: 黃冠銘 | D6: r' | E6: r' | F6: P | G6: P | H6: R | I6: 01早m | J6: 01早M | AO6: r' | AP6: r' | AQ6: R | AR6: L | AS6: L | AT6: =BV6+BW6 -> 11 | AU6: 2 | AV6: 2 | AW6: =COUNTIF(K6:AS6,"r'*") -> 2 | AX6: =COUNTIF(K6:AS6,"R") -> 1 | AY6: =8-AU6-AW6 -> 4 | AZ6: =8-AV6-AX6 -> 5 | BA6: =COUNTIF(J6:AN6,"*早*")-BB6 -> 1 | BB6: =COUNTIF(J6:AN6,"*早A") -> 0 | BC6: =COUNTIF(J6:AN6,"*中*") -> 0 | BD6: =COUNTIF(J6:AN6,"*午*")-BE6 -> 0 | BE6: =COUNTIF(J6:AN6,"*午F") -> 0 | BF6: =COUNTIF(J6:AN6,"*夜*") -> 0 | BG6: =COUNTIF(J6:AN6,"*T*") -> 0 | BH6: =COUNTIF(J6:AN6,"*日*") -> 0 | BI6: =COUNTIF(J6:AN6,"L") -> 0 | BJ6: {=SUMPRODUCT(1*ISNUMBER(FIND("R",J6:AN6)))} -> 0 | BK6: {=SUMPRODUCT(1*ISNUMBER(FIND("r",J6:AN6)))} -> 0 | BL6: {=SUMPRODUCT(1*ISNUMBER(FIND("P",J6:AN6)))-SUMPRODUCT(1*ISNUMBER(FIND("午P",G6:AK6)))} -> 0 | BM6: =SUM(BJ6:BL6) -> 0 | BN6: {=SUMPRODUCT(1*ISNUMBER(FIND("R",D6:J6)))} -> 1 | BO6: {=SUMPRODUCT(1*ISNUMBER(FIND("R",K6:Q6)))} -> 0 | BP6: {=SUMPRODUCT(1*ISNUMBER(FIND("R",R6:X6)))} -> 0 | BQ6: {=SUMPRODUCT(1*ISNUMBER(FIND("R",Y6:AE6)))} -> 0 | BR6: {=SUMPRODUCT(1*ISNUMBER(FIND("R",AF6:AL6)))} -> 0 | BS6: {=SUMPRODUCT(1*ISNUMBER(FIND("R",AM6:AS6)))} -> 1 | BT6: =SUM(BA6:BL6) -> 1 | BV6: 11 | BW6: {=SUMPRODUCT(1*ISNUMBER(FIND("P",K6:AL6)))-SUMPRODUCT(1*ISNUMBER(FIND("午P",K6:AL6)))} -> 0
B7: T02287 | C7: 林江玉 | D7: 01夜B2 | E7: 01夜B1 | F7: 01夜B2 | G7: 01夜B1 | H7: R | I7: r' | J7: 01早B1 | M7: L | N7: L | O7: L | P7: L | Q7: R | R7: R | S7: L | T7: L | AF7: R | AG7: r' | AM7: R | AN7: r' | AT7: =BV7+BW7 -> 11 | AU7: 2 | AV7: 2 | AW7: =COUNTIF(K7:AS7,"r'*") -> 2 | AX7: =COUNTIF(K7:AS7,"R") -> 4 | AY7: =8-AU7-AW7 -> 4 | AZ7: =8-AV7-AX7 -> 2 | BA7: =COUNTIF(J7:AN7,"*早*")-BB7 -> 1 | BB7: =COUNTIF(J7:AN7,"*早A") -> 0 | BC7: =COUNTIF(J7:AN7,"*中*") -> 0 | BD7: =COUNTIF(J7:AN7,"*午*")-BE7 -> 0 | BE7: =COUNTIF(J7:AN7,"*午F") -> 0 | BF7: =COUNTIF(J7:AN7,"*夜*") -> 0 | BG7: =COUNTIF(J7:AN7,"*T*") -> 0 | BH7: =COUNTIF(J7:AN7,"*日*") -> 0 | BI7: =COUNTIF(J7:AN7,"L") -> 6 | BJ7: {=SUMPRODUCT(1*ISNUMBER(FIND("R",J7:AN7)))} -> 4 | BK7: {=SUMPRODUCT(1*ISNUMBER(FIND("r",J7:AN7)))} -> 2 | BL7: {=SUMPRODUCT(1*ISNUMBER(FIND("P",J7:AN7)))-SUMPRODUCT(1*ISNUMBER(FIND("午P",G7:AK7)))} -> 0 | BM7: =SUM(BJ7:BL7) -> 6 | BN7: {=SUMPRODUCT(1*ISNUMBER(FIND("R",D7:J7)))} -> 1 | BO7: {=SUMPRODUCT(1*ISNUMBER(FIND("R",K7:Q7)))} -> 1 | BP7: {=SUMPRODUCT(1*ISNUMBER(FIND("R",R7:X7)))} -> 1 | BQ7: {=SUMPRODUCT(1*ISNUMBER(FIND("R",Y7:AE7)))} -> 0 | BR7: {=SUMPRODUCT(1*ISNUMBER(FIND("R",AF7:AL7)))} -> 1 | BS7: {=SUMPRODUCT(1*ISNUMBER(FIND("R",AM7:AS7)))} -> 1 | BT7: =SUM(BA7:BL7) -> 13 | BV7: 11 | BW7: {=SUMPRODUCT(1*ISNUMBER(FIND("P",K7:AL7)))-SUMPRODUCT(1*ISNUMBER(FIND("午P",K7:AL7)))} -> 0
B8: T02359 | C8: 陳佳婷 | D8: 06早 | E8: 06早 | F8: R | G8: 01早m(減壓課) | H8: 01早M | I8: 01早B1 | J8: 01早m | Q8: R | R8: R | AP8: R | AT8: =BV8+BW8 -> 11 | AU8: 2 | AV8: 2 | AW8: =COUNTIF(K8:AS8,"r'*") -> 0 | AX8: =COUNTIF(K8:AS8,"R") -> 3 | AY8: =8-AU8-AW8 -> 6 | AZ8: =8-AV8-AX8 -> 3 | BA8: =COUNTIF(J8:AN8,"*早*")-BB8 -> 1 | BB8: =COUNTIF(J8:AN8,"*早A") -> 0 | BC8: =COUNTIF(J8:AN8,"*中*") -> 0 | BD8: =COUNTIF(J8:AN8,"*午*")-BE8 -> 0 | BE8: =COUNTIF(J8:AN8,"*午F") -> 0 | BF8: =COUNTIF(J8:AN8,"*夜*") -> 0 | BG8: =COUNTIF(J8:AN8,"*T*") -> 0 | BH8: =COUNTIF(J8:AN8,"*日*") -> 0 | BI8: =COUNTIF(J8:AN8,"L") -> 0 | BJ8: {=SUMPRODUCT(1*ISNUMBER(FIND("R",J8:AN8)))} -> 2 | BK8: {=SUMPRODUCT(1*ISNUMBER(FIND("r",J8:AN8)))} -> 0 | BL8: {=SUMPRODUCT(1*ISNUMBER(FIND("P",J8:AN8)))-SUMPRODUCT(1*ISNUMBER(FIND("午P",G8:AK8)))} -> 0 | BM8: =SUM(BJ8:BL8) -> 2 | BN8: {=SUMPRODUCT(1*ISNUMBER(FIND("R",D8:J8)))} -> 1 | BO8: {=SUMPRODUCT(1*ISNUMBER(FIND("R",K8:Q8)))} -> 1 | BP8: {=SUMPRODUCT(1*ISNUMBER(FIND("R",R8:X8)))} -> 1 | BQ8: {=SUMPRODUCT(1*ISNUMBER(FIND("R",Y8:AE8)))} -> 0 | BR8: {=SUMPRODUCT(1*ISNUMBER(FIND("R",AF8:AL8)))} -> 0 | BS8: {=SUMPRODUCT(1*ISNUMBER(FIND("R",AM8:AS8)))} -> 1 | BT8: =SUM(BA8:BL8) -> 3 | BV8: 11 | BW8: {=SUMPRODUCT(1*ISNUMBER(FIND("P",K8:AL8)))-SUMPRODUCT(1*ISNUMBER(FIND("午P",K8:AL8)))} -> 0
B9: T02363 | C9: 林孟錡 | D9: 01夜B1 | E9: 01夜B2 | F9: 01夜B1 | G9: r' | H9: P | I9: r' | J9: R | K9: r' | L9: R | M9: L | N9: L | O9: L | P9: r' | Q9: 01夜B2 | R9: 01夜B1 | S9: 01夜B2 | T9: 01夜B1 | U9: 01夜B2 | V9: 01夜B1 | W9: R | X9: L | Y9: R | Z9: 01夜B2 | AA9: 01夜B1 | AB9: 01夜B2 | AC9: 01夜B1 | AD9: 01夜B2 | AE9: 01夜B1 | AF9: 01夜B2 | AG9: R | AH9: 01夜B1 | AI9: 01夜B2 | AJ9: 01夜B1 | AK9: 01夜B2 | AL9: 01夜B1 | AM9: 01夜B2 | AT9: =BV9+BW9 -> 11 | AU9: 2 | AV9: 2 | AW9: =COUNTIF(K9:AS9,"r'*") -> 2 | AX9: =COUNTIF(K9:AS9,"R") -> 4 | AY9: =8-AU9-AW9 -> 4 | AZ9: =8-AV9-AX9 -> 2 | BA9: =COUNTIF(J9:AN9,"*早*")-BB9 -> 0 | BB9: =COUNTIF(J9:AN9,"*早A") -> 0 | BC9: =COUNTIF(J9:AN9,"*中*") -> 0 | BD9: =COUNTIF(J9:AN9,"*午*")-BE9 -> 0 | BE9: =COUNTIF(J9:AN9,"*午F") -> 0 | BF9: =COUNTIF(J9:AN9,"*夜*") -> 19 | BG9: =COUNTIF(J9:AN9,"*T*") -> 0 | BH9: =COUNTIF(J9:AN9,"*日*") -> 0 | BI9: =COUNTIF(J9:AN9,"L") -> 4 | BJ9: {=SUMPRODUCT(1*ISNUMBER(FIND("R",J9:AN9)))} -> 5 | BK9: {=SUMPRODUCT(1*ISNUMBER(FIND("r",J9:AN9)))} -> 2 | BL9: {=SUMPRODUCT(1*ISNUMBER(FIND("P",J9:AN9)))-SUMPRODUCT(1*ISNUMBER(FIND("午P",G9:AK9)))} -> 0 | BM9: =SUM(BJ9:BL9) -> 7 | BN9: {=SUMPRODUCT(1*ISNUMBER(FIND("R",D9:J9)))} -> 1 | BO9: {=SUMPRODUCT(1*ISNUMBER(FIND("R",K9:Q9)))} -> 1 | BP9: {=SUMPRODUCT(1*ISNUMBER(FIND("R",R9:X9)))} -> 1 | BQ9: {=SUMPRODUCT(1*ISNUMBER(FIND("R",Y9:AE9)))} -> 1 | BR9: {=SUMPRODUCT(1*ISNUMBER(FIND("R",AF9:AL9)))} -> 1 | BS9: {=SUMPRODUCT(1*ISNUMBER(FIND("R",AM9:AS9)))} -> 0 | BT9: =SUM(BA9:BL9) -> 30 | BV9: 11 | BW9: {=SUMPRODUCT(1*ISNUMBER(FIND("P",K9:AL9)))-SUMPRODUCT(1*ISNUMBER(FIND("午P",K9:AL9)))} -> 0
B10: T02505 | C10: 李慧盺 | D10: r' | E10: 01午M | F10: 01午m | G10: r' | H10: 01午M | I10: 01午B1 | J10: R | AC10: r' | AD10: r' | AE10: R | AF10: R | AT10: =BV10+BW10 -> 11 | AU10: 2 | AV10: 2 | AW10: =COUNTIF(K10:AS10,"r'*") -> 2 | AX10: =COUNTIF(K10:AS10,"R") -> 2 | AY10: =8-AU10-AW10 -> 4 | AZ10: =8-AV10-AX10 -> 4 | BA10: =COUNTIF(J10:AN10,"*早*")-BB10 -> 0 | BB10: =COUNTIF(J10:AN10,"*早A") -> 0 | BC10: =COUNTIF(J10:AN10,"*中*") -> 0 | BD10: =COUNTIF(J10:AN10,"*午*")-BE10 -> 0 | BE10: =COUNTIF(J10:AN10,"*午F") -> 0 | BF10: =COUNTIF(J10:AN10,"*夜*") -> 0 | BG10: =COUNTIF(J10:AN10,"*T*") -> 0 | BH10: =COUNTIF(J10:AN10,"*日*") -> 0 | BI10: =COUNTIF(J10:AN10,"L") -> 0 | BJ10: {=SUMPRODUCT(1*ISNUMBER(FIND("R",J10:AN10)))} -> 3 | BK10: {=SUMPRODUCT(1*ISNUMBER(FIND("r",J10:AN10)))} -> 2 | BL10: {=SUMPRODUCT(1*ISNUMBER(FIND("P",J10:AN10)))-SUMPRODUCT(1*ISNUMBER(FIND("午P",G10:AK10)))} -> 0 | BM10: =SUM(BJ10:BL10) -> 5 | BN10: {=SUMPRODUCT(1*ISNUMBER(FIND("R",D10:J10)))} -> 1 | BO10: {=SUMPRODUCT(1*ISNUMBER(FIND("R",K10:Q10)))} -> 0 | BP10: {=SUMPRODUCT(1*ISNUMBER(FIND("R",R10:X10)))} -> 0 | BQ10: {=SUMPRODUCT(1*ISNUMBER(FIND("R",Y10:AE10)))} -> 1 | BR10: {=SUMPRODUCT(1*ISNUMBER(FIND("R",AF10:AL10)))} -> 1 | BS10: {=SUMPRODUCT(1*ISNUMBER(FIND("R",AM10:AS10)))} -> 0 | BT10: =SUM(BA10:BL10) -> 5 | BV10: 11
B11: T02776 | C11: 陳怡臻 | D11: 01午m | E11: 01午m | F11: 01午M | G11: 01午M | H11: R | I11: 01夜B2 | J11: 01夜B1 | P11: R | AE11: R | AF11: R | AG11: r' | AT11: =BV11+BW11 -> 11 | AU11: 3 | AV11: 2 | AW11: =COUNTIF(K11:AS11,"r'*") -> 1 | AX11: =COUNTIF(K11:AS11,"R") -> 3 | AY11: =8-AU11-AW11 -> 4 | AZ11: =8-AV11-AX11 -> 3 | BA11: =COUNTIF(J11:AN11,"*早*")-BB11 -> 0 | BB11: =COUNTIF(J11:AN11,"*早A") -> 0 | BC11: =COUNTIF(J11:AN11,"*中*") -> 0 | BD11: =COUNTIF(J11:AN11,"*午*")-BE11 -> 0 | BE11: =COUNTIF(J11:AN11,"*午F") -> 0 | BF11: =COUNTIF(J11:AN11,"*夜*") -> 1 | BG11: =COUNTIF(J11:AN11,"*T*") -> 0 | BH11: =COUNTIF(J11:AN11,"*日*") -> 0 | BI11: =COUNTIF(J11:AN11,"L") -> 0 | BJ11: {=SUMPRODUCT(1*ISNUMBER(FIND("R",J11:AN11)))} -> 3 | BK11: {=SUMPRODUCT(1*ISNUMBER(FIND("r",J11:AN11)))} -> 1 | BL11: {=SUMPRODUCT(1*ISNUMBER(FIND("P",J11:AN11)))-SUMPRODUCT(1*ISNUMBER(FIND("午P",G11:AK11)))} -> 0 | BM11: =SUM(BJ11:BL11) -> 4 | BN11: {=SUMPRODUCT(1*ISNUMBER(FIND("R",D11:J11)))} -> 1 | BO11: {=SUMPRODUCT(1*ISNUMBER(FIND("R",K11:Q11)))} -> 1 | BP11: {=SUMPRODUCT(1*ISNUMBER(FIND("R",R11:X11)))} -> 0 | BQ11: {=SUMPRODUCT(1*ISNUMBER(FIND("R",Y11:AE11)))} -> 1 | BR11: {=SUMPRODUCT(1*ISNUMBER(FIND("R",AF11:AL11)))} -> 1 | BS11: {=SUMPRODUCT(1*ISNUMBER(FIND("R",AM11:AS11)))} -> 0 | BT11: =SUM(BA11:BL11) -> 5 | BV11: 11 | BW11: {=SUMPRODUCT(1*ISNUMBER(FIND("P",K11:AL11)))-SUMPRODUCT(1*ISNUMBER(FIND("午P",K11:AL11)))} -> 0
B12: T02777 | C12: 彭裕涵 | D12: 01早M | E12: R | F12: 01早M | G12: 01夜B2 | H12: 01夜B1 | I12: r' | J12: r' | AG12: r' | AH12: R | AI12: P | AJ12: r' | AT12: =BV12+BW12 -> 12 | AU12: 3 | AV12: 2 | AW12: =COUNTIF(K12:AS12,"r'*") -> 2 | AX12: =COUNTIF(K12:AS12,"R") -> 1 | AY12: =8-AU12-AW12 -> 3 | AZ12: =8-AV12-AX12 -> 5 | BA12: =COUNTIF(J12:AN12,"*早*")-BB12 -> 0 | BB12: =COUNTIF(J12:AN12,"*早A") -> 0 | BC12: =COUNTIF(J12:AN12,"*中*") -> 0 | BD12: =COUNTIF(J12:AN12,"*午*")-BE12 -> 0 | BE12: =COUNTIF(J12:AN12,"*午F") -> 0 | BF12: =COUNTIF(J12:AN12,"*夜*") -> 0 | BG12: =COUNTIF(J12:AN12,"*T*") -> 0 | BH12: =COUNTIF(J12:AN12,"*日*") -> 0 | BI12: =COUNTIF(J12:AN12,"L") -> 0 | BJ12: {=SUMPRODUCT(1*ISNUMBER(FIND("R",J12:AN12)))} -> 1 | BK12: {=SUMPRODUCT(1*ISNUMBER(FIND("r",J12:AN12)))} -> 3 | BL12: {=SUMPRODUCT(1*ISNUMBER(FIND("P",J12:AN12)))-SUMPRODUCT(1*ISNUMBER(FIND("午P",G12:AK12)))} -> 1 | BM12: =SUM(BJ12:BL12) -> 5 | BN12: {=SUMPRODUCT(1*ISNUMBER(FIND("R",D12:J12)))} -> 1 | BO12: {=SUMPRODUCT(1*ISNUMBER(FIND("R",K12:Q12)))} -> 0 | BP12: {=SUMPRODUCT(1*ISNUMBER(FIND("R",R12:X12)))} -> 0 | BQ12: {=SUMPRODUCT(1*ISNUMBER(FIND("R",Y12:AE12)))} -> 0 | BR12: {=SUMPRODUCT(1*ISNUMBER(FIND("R",AF12:AL12)))} -> 1 | BS12: {=SUMPRODUCT(1*ISNUMBER(FIND("R",AM12:AS12)))} -> 0 | BT12: =SUM(BA12:BL12) -> 5 | BV12: 11 | BW12: {=SUMPRODUCT(1*ISNUMBER(FIND("P",K12:AL12)))-SUMPRODUCT(1*ISNUMBER(FIND("午P",K12:AL12)))} -> 1
B13: T00557 | C13: 陳志明 | D13: 03早 | E13: r' | F13: 01午B1 | G13: 01午B2 | H13: R | I13: 01午B1 | J13: 01午B2 | P13: L | Q13: R | AD13: r' | AE13: R | AT13: =BV13+BW13 -> 10 | AU13: 2 | AV13: 2 | AW13: =COUNTIF(K13:AS13,"r'*") -> 1 | AX13: =COUNTIF(K13:AS13,"R") -> 2 | AY13: =8-AU13-AW13 -> 5 | AZ13: =8-AV13-AX13 -> 4 | BA13: =COUNTIF(J13:AN13,"*早*")-BB13 -> 0 | BB13: =COUNTIF(J13:AN13,"*早A") -> 0 | BC13: =COUNTIF(J13:AN13,"*中*") -> 0 | BD13: =COUNTIF(J13:AN13,"*午*")-BE13 -> 1 | BE13: =COUNTIF(J13:AN13,"*午F") -> 0 | BF13: =COUNTIF(J13:AN13,"*夜*") -> 0 | BG13: =COUNTIF(J13:AN13,"*T*") -> 0 | BH13: =COUNTIF(J13:AN13,"*日*") -> 0 | BI13: =COUNTIF(J13:AN13,"L") -> 1 | BJ13: {=SUMPRODUCT(1*ISNUMBER(FIND("R",J13:AN13)))} -> 2 | BK13: {=SUMPRODUCT(1*ISNUMBER(FIND("r",J13:AN13)))} -> 1 | BL13: {=SUMPRODUCT(1*ISNUMBER(FIND("P",J13:AN13)))-SUMPRODUCT(1*ISNUMBER(FIND("午P",G13:AK13)))} -> 0 | BM13: =SUM(BJ13:BL13) -> 3 | BN13: {=SUMPRODUCT(1*ISNUMBER(FIND("R",D13:J13)))} -> 1 | BO13: {=SUMPRODUCT(1*ISNUMBER(FIND("R",K13:Q13)))} -> 1 | BP13: {=SUMPRODUCT(1*ISNUMBER(FIND("R",R13:X13)))} -> 0 | BQ13: {=SUMPRODUCT(1*ISNUMBER(FIND("R",Y13:AE13)))} -> 1 | BR13: {=SUMPRODUCT(1*ISNUMBER(FIND("R",AF13:AL13)))} -> 0 | BS13: {=SUMPRODUCT(1*ISNUMBER(FIND("R",AM13:AS13)))} -> 0 | BT13: =SUM(BA13:BL13) -> 5 | BV13: 10 | BW13: {=SUMPRODUCT(1*ISNUMBER(FIND("P",K13:AL13)))-SUMPRODUCT(1*ISNUMBER(FIND("午P",K13:AL13)))} -> 0
B14: T00929 | C14: 簡婉蓁 | D14: 01早B2 | E14: 01早B1 | F14: 01早B2 | G14: 01早B1(減壓課) | H14: 01早B2 | I14: R | J14: 01早B1 | N14: 01早B1 | Q14: 01早B2 | U14: 01早B1 | X14: 01早B2 | Y14: R | Z14: r' | AB14: 01早B1 | AI14: 01早B2 | AN14: R | AS14: r' | AT14: =BV14+BW14 -> 10 | AU14: 2 | AV14: 2 | AW14: =COUNTIF(K14:AS14,"r'*") -> 2 | AX14: =COUNTIF(K14:AS14,"R") -> 2 | AY14: =8-AU14-AW14 -> 4 | AZ14: =8-AV14-AX14 -> 4 | BA14: =COUNTIF(J14:AN14,"*早*")-BB14 -> 7 | BB14: =COUNTIF(J14:AN14,"*早A") -> 0 | BC14: =COUNTIF(J14:AN14,"*中*") -> 0 | BD14: =COUNTIF(J14:AN14,"*午*")-BE14 -> 0 | BE14: =COUNTIF(J14:AN14,"*午F") -> 0 | BF14: =COUNTIF(J14:AN14,"*夜*") -> 0 | BG14: =COUNTIF(J14:AN14,"*T*") -> 0 | BH14: =COUNTIF(J14:AN14,"*日*") -> 0 | BI14: =COUNTIF(J14:AN14,"L") -> 0 | BJ14: {=SUMPRODUCT(1*ISNUMBER(FIND("R",J14:AN14)))} -> 2 | BK14: {=SUMPRODUCT(1*ISNUMBER(FIND("r",J14:AN14)))} -> 1 | BL14: {=SUMPRODUCT(1*ISNUMBER(FIND("P",J14:AN14)))-SUMPRODUCT(1*ISNUMBER(FIND("午P",G14:AK14)))} -> 0 | BM14: =SUM(BJ14:BL14) -> 3 | BN14: {=SUMPRODUCT(1*ISNUMBER(FIND("R",D14:J14)))} -> 1 | BO14: {=SUMPRODUCT(1*ISNUMBER(FIND("R",K14:Q14)))} -> 0 | BP14: {=SUMPRODUCT(1*ISNUMBER(FIND("R",R14:X14)))} -> 0 | BQ14: {=SUMPRODUCT(1*ISNUMBER(FIND("R",Y14:AE14)))} -> 1 | BR14: {=SUMPRODUCT(1*ISNUMBER(FIND("R",AF14:AL14)))} -> 0 | BS14: {=SUMPRODUCT(1*ISNUMBER(FIND("R",AM14:AS14)))} -> 1 | BT14: =SUM(BA14:BL14) -> 10 | BV14: 10 | BW14: {=SUMPRODUCT(1*ISNUMBER(FIND("P",K14:AL14)))-SUMPRODUCT(1*ISNUMBER(FIND("午P",K14:AL14)))} -> 0
B15: T01459 | C15: 林禹丞 | D15: R | E15: L | F15: r' | G15: 01早B2(減壓課) | H15: 01早B1 | I15: 01早B2 | J15: 01早B2 | K15: r' | L15: R | R15: r' | S15: R | Y15: r' | Z15: R | AE15: L | AF15: L | AG15: R | AM15: r' | AN15: R | AT15: =BV15+BW15 -> 11 | AU15: 2 | AV15: 2 | AW15: =COUNTIF(K15:AS15,"r'*") -> 4 | AX15: =COUNTIF(K15:AS15,"R") -> 5 | AY15: =8-AU15-AW15 -> 2 | AZ15: =8-AV15-AX15 -> 1 | BA15: =COUNTIF(J15:AN15,"*早*")-BB15 -> 1 | BB15: =COUNTIF(J15:AN15,"*早A") -> 0 | BC15: =COUNTIF(J15:AN15,"*中*") -> 0 | BD15: =COUNTIF(J15:AN15,"*午*")-BE15 -> 0 | BE15: =COUNTIF(J15:AN15,"*午F") -> 0 | BF15: =COUNTIF(J15:AN15,"*夜*") -> 0 | BG15: =COUNTIF(J15:AN15,"*T*") -> 0 | BH15: =COUNTIF(J15:AN15,"*日*") -> 0 | BI15: =COUNTIF(J15:AN15,"L") -> 2 | BJ15: {=SUMPRODUCT(1*ISNUMBER(FIND("R",J15:AN15)))} -> 5 | BK15: {=SUMPRODUCT(1*ISNUMBER(FIND("r",J15:AN15)))} -> 4 | BL15: {=SUMPRODUCT(1*ISNUMBER(FIND("P",J15:AN15)))-SUMPRODUCT(1*ISNUMBER(FIND("午P",G15:AK15)))} -> 0 | BM15: =SUM(BJ15:BL15) -> 9 | BN15: {=SUMPRODUCT(1*ISNUMBER(FIND("R",D15:J15)))} -> 1 | BO15: {=SUMPRODUCT(1*ISNUMBER(FIND("R",K15:Q15)))} -> 1 | BP15: {=SUMPRODUCT(1*ISNUMBER(FIND("R",R15:X15)))} -> 1 | BQ15: {=SUMPRODUCT(1*ISNUMBER(FIND("R",Y15:AE15)))} -> 1 | BR15: {=SUMPRODUCT(1*ISNUMBER(FIND("R",AF15:AL15)))} -> 1 | BS15: {=SUMPRODUCT(1*ISNUMBER(FIND("R",AM15:AS15)))} -> 1 | BT15: =SUM(BA15:BL15) -> 12 | BV15: 11 | BW15: {=SUMPRODUCT(1*ISNUMBER(FIND("P",K15:AL15)))-SUMPRODUCT(1*ISNUMBER(FIND("午P",K15:AL15)))} -> 0
B16: T01600 | C16: 陳奎羽 | D16: L | E16: R | F16: 01早B1 | G16: 01早B1(減壓課) | H16: 01早B2 | I16: r' | J16: L | K16: r' | L16: R | W16: r' | X16: R | AT16: =BV16+BW16 -> 11 | AU16: 2 | AV16: 2 | AW16: =COUNTIF(K16:AS16,"r'*") -> 2 | AX16: =COUNTIF(K16:AS16,"R") -> 2 | AY16: =8-AU16-AW16 -> 4 | AZ16: =8-AV16-AX16 -> 4 | BA16: =COUNTIF(J16:AN16,"*早*")-BB16 -> 0 | BB16: =COUNTIF(J16:AN16,"*早A") -> 0 | BC16: =COUNTIF(J16:AN16,"*中*") -> 0 | BD16: =COUNTIF(J16:AN16,"*午*")-BE16 -> 0 | BE16: =COUNTIF(J16:AN16,"*午F") -> 0 | BF16: =COUNTIF(J16:AN16,"*夜*") -> 0 | BG16: =COUNTIF(J16:AN16,"*T*") -> 0 | BH16: =COUNTIF(J16:AN16,"*日*") -> 0 | BI16: =COUNTIF(J16:AN16,"L") -> 1 | BJ16: {=SUMPRODUCT(1*ISNUMBER(FIND("R",J16:AN16)))} -> 2 | BK16: {=SUMPRODUCT(1*ISNUMBER(FIND("r",J16:AN16)))} -> 2 | BL16: {=SUMPRODUCT(1*ISNUMBER(FIND("P",J16:AN16)))-SUMPRODUCT(1*ISNUMBER(FIND("午P",G16:AK16)))} -> 0 | BM16: =SUM(BJ16:BL16) -> 4 | BN16: {=SUMPRODUCT(1*ISNUMBER(FIND("R",D16:J16)))} -> 1 | BO16: {=SUMPRODUCT(1*ISNUMBER(FIND("R",K16:Q16)))} -> 1 | BP16: {=SUMPRODUCT(1*ISNUMBER(FIND("R",R16:X16)))} -> 1 | BQ16: {=SUMPRODUCT(1*ISNUMBER(FIND("R",Y16:AE16)))} -> 0 | BR16: {=SUMPRODUCT(1*ISNUMBER(FIND("R",AF16:AL16)))} -> 0 | BS16: {=SUMPRODUCT(1*ISNUMBER(FIND("R",AM16:AS16)))} -> 0 | BT16: =SUM(BA16:BL16) -> 5 | BV16: 11 | BW16: {=SUMPRODUCT(1*ISNUMBER(FIND("P",K16:AL16)))-SUMPRODUCT(1*ISNUMBER(FIND("午P",K16:AL16)))} -> 0
B17: T01795 | C17: 黃羿綾 | D17: 01午B2 | E17: 01午B1 | F17: P | G17: 01午B1 | H17: 01午B1 | I17: r' | J17: R | K17: r' | L17: R | M17: r' | Y17: R | Z17: 01午B2 | AR17: R | AS17: r' | AT17: =BV17+BW17 -> 11 | AU17: 2 | AV17: 2 | AW17: =COUNTIF(K17:AS17,"r'*") -> 3 | AX17: =COUNTIF(K17:AS17,"R") -> 3 | AY17: =8-AU17-AW17 -> 3 | AZ17: =8-AV17-AX17 -> 3 | BA17: =COUNTIF(J17:AN17,"*早*")-BB17 -> 0 | BB17: =COUNTIF(J17:AN17,"*早A") -> 0 | BC17: =COUNTIF(J17:AN17,"*中*") -> 0 | BD17: =COUNTIF(J17:AN17,"*午*")-BE17 -> 1 | BE17: =COUNTIF(J17:AN17,"*午F") -> 0 | BF17: =COUNTIF(J17:AN17,"*夜*") -> 0 | BG17: =COUNTIF(J17:AN17,"*T*") -> 0 | BH17: =COUNTIF(J17:AN17,"*日*") -> 0 | BI17: =COUNTIF(J17:AN17,"L") -> 0 | BJ17: {=SUMPRODUCT(1*ISNUMBER(FIND("R",J17:AN17)))} -> 3 | BK17: {=SUMPRODUCT(1*ISNUMBER(FIND("r",J17:AN17)))} -> 2 | BL17: {=SUMPRODUCT(1*ISNUMBER(FIND("P",J17:AN17)))-SUMPRODUCT(1*ISNUMBER(FIND("午P",G17:AK17)))} -> 0 | BM17: =SUM(BJ17:BL17) -> 5 | BN17: {=SUMPRODUCT(1*ISNUMBER(FIND("R",D17:J17)))} -> 1 | BO17: {=SUMPRODUCT(1*ISNUMBER(FIND("R",K17:Q17)))} -> 1 | BP17: {=SUMPRODUCT(1*ISNUMBER(FIND("R",R17:X17)))} -> 0 | BQ17: {=SUMPRODUCT(1*ISNUMBER(FIND("R",Y17:AE17)))} -> 1 | BR17: {=SUMPRODUCT(1*ISNUMBER(FIND("R",AF17:AL17)))} -> 0 | BS17: {=SUMPRODUCT(1*ISNUMBER(FIND("R",AM17:AS17)))} -> 1 | BT17: =SUM(BA17:BL17) -> 6 | BV17: 11 | BW17: {=SUMPRODUCT(1*ISNUMBER(FIND("P",K17:AL17)))-SUMPRODUCT(1*ISNUMBER(FIND("午P",K17:AL17)))} -> 0
B18: T02222 | C18: 𡍼文妤 | D18: R | E18: P | F18: 01早B1 | G18: 01早B2(減壓課) | H18: 01早B2 | I18: 01早B1 | J18: r' | R18: R | S18: r' | AK18: R | AL18: r' | AT18: =BV18+BW18 -> 11 | AU18: 2 | AV18: 2 | AW18: =COUNTIF(K18:AS18,"r'*") -> 2 | AX18: =COUNTIF(K18:AS18,"R") -> 2 | AY18: =8-AU18-AW18 -> 4 | AZ18: =8-AV18-AX18 -> 4 | BA18: =COUNTIF(J18:AN18,"*早*")-BB18 -> 0 | BB18: =COUNTIF(J18:AN18,"*早A") -> 0 | BC18: =COUNTIF(J18:AN18,"*中*") -> 0 | BD18: =COUNTIF(J18:AN18,"*午*")-BE18 -> 0 | BE18: =COUNTIF(J18:AN18,"*午F") -> 0 | BF18: =COUNTIF(J18:AN18,"*夜*") -> 0 | BG18: =COUNTIF(J18:AN18,"*T*") -> 0 | BH18: =COUNTIF(J18:AN18,"*日*") -> 0 | BI18: =COUNTIF(J18:AN18,"L") -> 0 | BJ18: {=SUMPRODUCT(1*ISNUMBER(FIND("R",J18:AN18)))} -> 2 | BK18: {=SUMPRODUCT(1*ISNUMBER(FIND("r",J18:AN18)))} -> 3 | BL18: {=SUMPRODUCT(1*ISNUMBER(FIND("P",J18:AN18)))-SUMPRODUCT(1*ISNUMBER(FIND("午P",G18:AK18)))} -> 0 | BM18: =SUM(BJ18:BL18) -> 5 | BN18: {=SUMPRODUCT(1*ISNUMBER(FIND("R",D18:J18)))} -> 1 | BO18: {=SUMPRODUCT(1*ISNUMBER(FIND("R",K18:Q18)))} -> 0 | BP18: {=SUMPRODUCT(1*ISNUMBER(FIND("R",R18:X18)))} -> 1 | BQ18: {=SUMPRODUCT(1*ISNUMBER(FIND("R",Y18:AE18)))} -> 0 | BR18: {=SUMPRODUCT(1*ISNUMBER(FIND("R",AF18:AL18)))} -> 1 | BS18: {=SUMPRODUCT(1*ISNUMBER(FIND("R",AM18:AS18)))} -> 0 | BT18: =SUM(BA18:BL18) -> 5 | BV18: 11 | BW18: {=SUMPRODUCT(1*ISNUMBER(FIND("P",K18:AL18)))-SUMPRODUCT(1*ISNUMBER(FIND("午P",K18:AL18)))} -> 0
B19: T02233 | C19: 簡悅如 | D19: 01早B1 | E19: 01早B2 | F19: P | G19: R | H19: r' | I19: r' | J19: 01早B2 | X19: R | Y19: R | AD19: L | AO19: R | AT19: =BV19+BW19 -> 11 | AU19: 2 | AV19: 2 | AW19: =COUNTIF(K19:AS19,"r'*") -> 0 | AX19: =COUNTIF(K19:AS19,"R") -> 3 | AY19: =8-AU19-AW19 -> 6 | AZ19: =8-AV19-AX19 -> 3 | BA19: =COUNTIF(J19:AN19,"*早*")-BB19 -> 1 | BB19: =COUNTIF(J19:AN19,"*早A") -> 0 | BC19: =COUNTIF(J19:AN19,"*中*") -> 0 | BD19: =COUNTIF(J19:AN19,"*午*")-BE19 -> 0 | BE19: =COUNTIF(J19:AN19,"*午F") -> 0 | BF19: =COUNTIF(J19:AN19,"*夜*") -> 0 | BG19: =COUNTIF(J19:AN19,"*T*") -> 0 | BH19: =COUNTIF(J19:AN19,"*日*") -> 0 | BI19: =COUNTIF(J19:AN19,"L") -> 1 | BJ19: {=SUMPRODUCT(1*ISNUMBER(FIND("R",J19:AN19)))} -> 2 | BK19: {=SUMPRODUCT(1*ISNUMBER(FIND("r",J19:AN19)))} -> 0 | BL19: {=SUMPRODUCT(1*ISNUMBER(FIND("P",J19:AN19)))-SUMPRODUCT(1*ISNUMBER(FIND("午P",G19:AK19)))} -> 0 | BM19: =SUM(BJ19:BL19) -> 2 | BN19: {=SUMPRODUCT(1*ISNUMBER(FIND("R",D19:J19)))} -> 1 | BO19: {=SUMPRODUCT(1*ISNUMBER(FIND("R",K19:Q19)))} -> 0 | BP19: {=SUMPRODUCT(1*ISNUMBER(FIND("R",R19:X19)))} -> 1 | BQ19: {=SUMPRODUCT(1*ISNUMBER(FIND("R",Y19:AE19)))} -> 1 | BR19: {=SUMPRODUCT(1*ISNUMBER(FIND("R",AF19:AL19)))} -> 0 | BS19: {=SUMPRODUCT(1*ISNUMBER(FIND("R",AM19:AS19)))} -> 1 | BT19: =SUM(BA19:BL19) -> 4 | BV19: 11 | BW19: {=SUMPRODUCT(1*ISNUMBER(FIND("P",K19:AL19)))-SUMPRODUCT(1*ISNUMBER(FIND("午P",K19:AL19)))} -> 0
B20: T02613 | C20: 張雅荃 | D20: R | E20: P | F20: 01午B1 | G20: 01午B2 | H20: 01午B1 | I20: r' | J20: 01午B2 | U20: R | AE20: R | AF20: R | AK20: r' | AT20: =BV20+BW20 -> 10 | AU20: 2 | AV20: 2 | AW20: =COUNTIF(K20:AS20,"r'*") -> 1 | AX20: =COUNTIF(K20:AS20,"R") -> 3 | AY20: =8-AU20-AW20 -> 5 | AZ20: =8-AV20-AX20 -> 3 | BA20: =COUNTIF(J20:AN20,"*早*")-BB20 -> 0 | BB20: =COUNTIF(J20:AN20,"*早A") -> 0 | BC20: =COUNTIF(J20:AN20,"*中*") -> 0 | BD20: =COUNTIF(J20:AN20,"*午*")-BE20 -> 1 | BE20: =COUNTIF(J20:AN20,"*午F") -> 0 | BF20: =COUNTIF(J20:AN20,"*夜*") -> 0 | BG20: =COUNTIF(J20:AN20,"*T*") -> 0 | BH20: =COUNTIF(J20:AN20,"*日*") -> 0 | BI20: =COUNTIF(J20:AN20,"L") -> 0 | BJ20: {=SUMPRODUCT(1*ISNUMBER(FIND("R",J20:AN20)))} -> 3 | BK20: {=SUMPRODUCT(1*ISNUMBER(FIND("r",J20:AN20)))} -> 1 | BL20: {=SUMPRODUCT(1*ISNUMBER(FIND("P",J20:AN20)))-SUMPRODUCT(1*ISNUMBER(FIND("午P",G20:AK20)))} -> 0 | BM20: =SUM(BJ20:BL20) -> 4 | BN20: {=SUMPRODUCT(1*ISNUMBER(FIND("R",D20:J20)))} -> 1 | BO20: {=SUMPRODUCT(1*ISNUMBER(FIND("R",K20:Q20)))} -> 0 | BP20: {=SUMPRODUCT(1*ISNUMBER(FIND("R",R20:X20)))} -> 1 | BQ20: {=SUMPRODUCT(1*ISNUMBER(FIND("R",Y20:AE20)))} -> 1 | BR20: {=SUMPRODUCT(1*ISNUMBER(FIND("R",AF20:AL20)))} -> 1 | BS20: {=SUMPRODUCT(1*ISNUMBER(FIND("R",AM20:AS20)))} -> 0 | BT20: =SUM(BA20:BL20) -> 5 | BV20: 10 | BW20: {=SUMPRODUCT(1*ISNUMBER(FIND("P",K20:AL20)))-SUMPRODUCT(1*ISNUMBER(FIND("午P",K20:AL20)))} -> 0
B21: T02758 | C21: 王映心 | D21: 01早B2 | E21: 01早B1 | F21: 01早B2 | G21: 01午B2 | H21: r' | I21: R | J21: 01午B1 | R21: r' | S21: r' | W21: R | X21: r' | AT21: =BV21+BW21 -> 11 | AU21: 2 | AV21: 2 | AW21: =COUNTIF(K21:AS21,"r'*") -> 3 | AX21: =COUNTIF(K21:AS21,"R") -> 1 | AY21: =8-AU21-AW21 -> 3 | AZ21: =8-AV21-AX21 -> 5 | BA21: =COUNTIF(J21:AN21,"*早*")-BB21 -> 0 | BB21: =COUNTIF(J21:AN21,"*早A") -> 0 | BC21: =COUNTIF(J21:AN21,"*中*") -> 0 | BD21: =COUNTIF(J21:AN21,"*午*")-BE21 -> 1 | BE21: =COUNTIF(J21:AN21,"*午F") -> 0 | BF21: =COUNTIF(J21:AN21,"*夜*") -> 0 | BG21: =COUNTIF(J21:AN21,"*T*") -> 0 | BH21: =COUNTIF(J21:AN21,"*日*") -> 0 | BI21: =COUNTIF(J21:AN21,"L") -> 0 | BJ21: {=SUMPRODUCT(1*ISNUMBER(FIND("R",J21:AN21)))} -> 1 | BK21: {=SUMPRODUCT(1*ISNUMBER(FIND("r",J21:AN21)))} -> 3 | BL21: {=SUMPRODUCT(1*ISNUMBER(FIND("P",J21:AN21)))-SUMPRODUCT(1*ISNUMBER(FIND("午P",G21:AK21)))} -> 0 | BM21: =SUM(BJ21:BL21) -> 4 | BN21: {=SUMPRODUCT(1*ISNUMBER(FIND("R",D21:J21)))} -> 1 | BO21: {=SUMPRODUCT(1*ISNUMBER(FIND("R",K21:Q21)))} -> 0 | BP21: {=SUMPRODUCT(1*ISNUMBER(FIND("R",R21:X21)))} -> 1 | BQ21: {=SUMPRODUCT(1*ISNUMBER(FIND("R",Y21:AE21)))} -> 0 | BR21: {=SUMPRODUCT(1*ISNUMBER(FIND("R",AF21:AL21)))} -> 0 | BS21: {=SUMPRODUCT(1*ISNUMBER(FIND("R",AM21:AS21)))} -> 0 | BT21: =SUM(BA21:BL21) -> 5 | BV21: 11 | BW21: {=SUMPRODUCT(1*ISNUMBER(FIND("P",K21:AL21)))-SUMPRODUCT(1*ISNUMBER(FIND("午P",K21:AL21)))} -> 0
B22: T02762 | C22: 周怡萍 | D22: R | E22: 01午B1 | F22: 01午B2 | G22: r' | H22: 01午B2 | I22: 01午B2 | J22: 01午B1 | Q22: R | R22: R | AB22: P | AC22: R | AD22: r' | AT22: =BV22+BW22 -> 11 | AU22: 2 | AV22: 2 | AW22: =COUNTIF(K22:AS22,"r'*") -> 1 | AX22: =COUNTIF(K22:AS22,"R") -> 3 | AY22: =8-AU22-AW22 -> 5 | AZ22: =8-AV22-AX22 -> 3 | BA22: =COUNTIF(J22:AN22,"*早*")-BB22 -> 0 | BB22: =COUNTIF(J22:AN22,"*早A") -> 0 | BC22: =COUNTIF(J22:AN22,"*中*") -> 0 | BD22: =COUNTIF(J22:AN22,"*午*")-BE22 -> 1 | BE22: =COUNTIF(J22:AN22,"*午F") -> 0 | BF22: =COUNTIF(J22:AN22,"*夜*") -> 0 | BG22: =COUNTIF(J22:AN22,"*T*") -> 0 | BH22: =COUNTIF(J22:AN22,"*日*") -> 0 | BI22: =COUNTIF(J22:AN22,"L") -> 0 | BJ22: {=SUMPRODUCT(1*ISNUMBER(FIND("R",J22:AN22)))} -> 3 | BK22: {=SUMPRODUCT(1*ISNUMBER(FIND("r",J22:AN22)))} -> 1 | BL22: {=SUMPRODUCT(1*ISNUMBER(FIND("P",J22:AN22)))-SUMPRODUCT(1*ISNUMBER(FIND("午P",G22:AK22)))} -> 1 | BM22: =SUM(BJ22:BL22) -> 5 | BN22: {=SUMPRODUCT(1*ISNUMBER(FIND("R",D22:J22)))} -> 1 | BO22: {=SUMPRODUCT(1*ISNUMBER(FIND("R",K22:Q22)))} -> 1 | BP22: {=SUMPRODUCT(1*ISNUMBER(FIND("R",R22:X22)))} -> 1 | BQ22: {=SUMPRODUCT(1*ISNUMBER(FIND("R",Y22:AE22)))} -> 1 | BR22: {=SUMPRODUCT(1*ISNUMBER(FIND("R",AF22:AL22)))} -> 0 | BS22: {=SUMPRODUCT(1*ISNUMBER(FIND("R",AM22:AS22)))} -> 0 | BT22: =SUM(BA22:BL22) -> 6 | BV22: 10 | BW22: {=SUMPRODUCT(1*ISNUMBER(FIND("P",K22:AL22)))-SUMPRODUCT(1*ISNUMBER(FIND("午P",K22:AL22)))} -> 1
B23: T02763 | C23: 陳佑融 | D23: 01早B1 | E23: 01早B2 | F23: r' | G23: R | H23: 01早B1 | I23: 01早B2 | J23: r' | K23: r' | L23: R | W23: R | X23: r' | AT23: =BV23+BW23 -> 11 | AU23: 2 | AV23: 2 | AW23: =COUNTIF(K23:AS23,"r'*") -> 2 | AX23: =COUNTIF(K23:AS23,"R") -> 2 | AY23: =8-AU23-AW23 -> 4 | AZ23: =8-AV23-AX23 -> 4 | BA23: =COUNTIF(J23:AN23,"*早*")-BB23 -> 0 | BB23: =COUNTIF(J23:AN23,"*早A") -> 0 | BC23: =COUNTIF(J23:AN23,"*中*") -> 0 | BD23: =COUNTIF(J23:AN23,"*午*")-BE23 -> 0 | BE23: =COUNTIF(J23:AN23,"*午F") -> 0 | BF23: =COUNTIF(J23:AN23,"*夜*") -> 0 | BG23: =COUNTIF(J23:AN23,"*T*") -> 0 | BH23: =COUNTIF(J23:AN23,"*日*") -> 0 | BI23: =COUNTIF(J23:AN23,"L") -> 0 | BJ23: {=SUMPRODUCT(1*ISNUMBER(FIND("R",J23:AN23)))} -> 2 | BK23: {=SUMPRODUCT(1*ISNUMBER(FIND("r",J23:AN23)))} -> 3 | BL23: {=SUMPRODUCT(1*ISNUMBER(FIND("P",J23:AN23)))-SUMPRODUCT(1*ISNUMBER(FIND("午P",G23:AK23)))} -> 0 | BM23: =SUM(BJ23:BL23) -> 5 | BN23: {=SUMPRODUCT(1*ISNUMBER(FIND("R",D23:J23)))} -> 1 | BO23: {=SUMPRODUCT(1*ISNUMBER(FIND("R",K23:Q23)))} -> 1 | BP23: {=SUMPRODUCT(1*ISNUMBER(FIND("R",R23:X23)))} -> 1 | BQ23: {=SUMPRODUCT(1*ISNUMBER(FIND("R",Y23:AE23)))} -> 0 | BR23: {=SUMPRODUCT(1*ISNUMBER(FIND("R",AF23:AL23)))} -> 0 | BS23: {=SUMPRODUCT(1*ISNUMBER(FIND("R",AM23:AS23)))} -> 0 | BT23: =SUM(BA23:BL23) -> 5 | BV23: 11 | BW23: {=SUMPRODUCT(1*ISNUMBER(FIND("P",K23:AL23)))-SUMPRODUCT(1*ISNUMBER(FIND("午P",K23:AL23)))} -> 0
B24: T02769 | C24: 吳東翰 | D24: 01午B1 | E24: r' | F24: R | G24: 01午B1 | H24: 01午B2 | I24: 01午B2 | J24: r' | R24: R | S24: r' | T24: r' | AL24: R | AT24: =BV24+BW24 -> 11 | AU24: 2 | AV24: 2 | AW24: =COUNTIF(K24:AS24,"r'*") -> 2 | AX24: =COUNTIF(K24:AS24,"R") -> 2 | AY24: =8-AU24-AW24 -> 4 | AZ24: =8-AV24-AX24 -> 4 | BA24: =COUNTIF(J24:AN24,"*早*")-BB24 -> 0 | BB24: =COUNTIF(J24:AN24,"*早A") -> 0 | BC24: =COUNTIF(J24:AN24,"*中*") -> 0 | BD24: =COUNTIF(J24:AN24,"*午*")-BE24 -> 0 | BE24: =COUNTIF(J24:AN24,"*午F") -> 0 | BF24: =COUNTIF(J24:AN24,"*夜*") -> 0 | BG24: =COUNTIF(J24:AN24,"*T*") -> 0 | BH24: =COUNTIF(J24:AN24,"*日*") -> 0 | BI24: =COUNTIF(J24:AN24,"L") -> 0 | BJ24: {=SUMPRODUCT(1*ISNUMBER(FIND("R",J24:AN24)))} -> 2 | BK24: {=SUMPRODUCT(1*ISNUMBER(FIND("r",J24:AN24)))} -> 3 | BL24: {=SUMPRODUCT(1*ISNUMBER(FIND("P",J24:AN24)))-SUMPRODUCT(1*ISNUMBER(FIND("午P",G24:AK24)))} -> 0 | BM24: =SUM(BJ24:BL24) -> 5 | BN24: {=SUMPRODUCT(1*ISNUMBER(FIND("R",D24:J24)))} -> 1 | BO24: {=SUMPRODUCT(1*ISNUMBER(FIND("R",K24:Q24)))} -> 0 | BP24: {=SUMPRODUCT(1*ISNUMBER(FIND("R",R24:X24)))} -> 1 | BQ24: {=SUMPRODUCT(1*ISNUMBER(FIND("R",Y24:AE24)))} -> 0 | BR24: {=SUMPRODUCT(1*ISNUMBER(FIND("R",AF24:AL24)))} -> 1 | BS24: {=SUMPRODUCT(1*ISNUMBER(FIND("R",AM24:AS24)))} -> 0 | BT24: =SUM(BA24:BL24) -> 5 | BV24: 11 | BW24: {=SUMPRODUCT(1*ISNUMBER(FIND("P",K24:AL24)))-SUMPRODUCT(1*ISNUMBER(FIND("午P",K24:AL24)))} -> 0
C25: 班別代號: OO早A：0620~1520(9hr) OO早：0630~1430(8hr) OO早G：0730~1530(8hr) OO早Q：0930~1730(8hr) OO中A：1100~1900(8hr) OO午P：1400~2200(8hr) OO午：1410~2210(8hr) OO午F：1500~2400(9hr) OO夜：2150~0650(9hr) OO代表車站、段辦(例如：A17早班，代碼17早。A17正常班，代碼17日。中心正常班，代碼日。北段段辦正常班，代號41日。中段段辦正常班，代號42日。南段段辦正常班，代號43日。) T：訓練 0830~1730 日：0830~1730 R：例假 L：其他休假 r：休假 P：國定假日
A26: 備註
B32: 員編 ID No. | C32: 日期 星期 姓名 | D32: =D1 -> 46229 | E32: =E1 -> 46230 | F32: =F1 -> 46231 | G32: =G1 -> 46232 | H32: =H1 -> 46233 | I32: =I1 -> 46234 | J32: =J1 -> 46235 | K32: =K1 -> 46236 | ... AS32: =AS1 -> 46270
D33: =D2 -> 日 | E33: =E2 -> 一 | F33: =F2 -> 二 | G33: =G2 -> 三 | H33: =H2 -> 四 | I33: =I2 -> 五 | J33: =J2 -> 六 | K33: =K2 -> 日 | ... AS33: =AS2 -> 六
C34: 41早 | D34: =COUNTIF(D$3:D$24,"41早") -> 0 | E34: =COUNTIF(E$3:E$24,"41早") -> 0 | F34: =COUNTIF(F$3:F$24,"41早") -> 0 | G34: =COUNTIF(G$3:G$24,"41早") -> 0 | H34: =COUNTIF(H$3:H$24,"41早") -> 0 | I34: =COUNTIF(I$3:I$24,"41早") -> 0 | J34: =COUNTIF(J$3:J$24,"41早") -> 0 | K34: =COUNTIF(K$3:K$24,"41早") -> 0 | ... P34: =COUNTIF(P$3:P$24,"41早") -> 0 | Q34: =COUNTIF(Q$3:Q$24,"41早*") -> 0 | R34: =COUNTIF(R$3:R$24,"41早") -> 0 | S34: =COUNTIF(S$3:S$24,"41早") -> 0 | T34: =COUNTIF(T$3:T$24,"41早") -> 0 | U34: =COUNTIF(U$3:U$24,"41早") -> 0 | V34: =COUNTIF(V$3:V$24,"41早") -> 0 | W34: =COUNTIF(W$3:W$24,"41早") -> 0 | X34: =COUNTIF(X$3:X$24,"41早") -> 0 | Y34: =COUNTIF(Y$3:Y$24,"41早") -> 0 | ... AS34: =COUNTIF(AS$3:AS$24,"41早") -> 0
C35: 41午 | D35: =COUNTIF(D$3:D$24,"41午") -> 0 | E35: =COUNTIF(E$3:E$24,"41午") -> 0 | F35: =COUNTIF(F$3:F$24,"41午") -> 0 | G35: =COUNTIF(G$3:G$24,"41午") -> 0 | H35: =COUNTIF(H$3:H$24,"41午") -> 0 | I35: =COUNTIF(I$3:I$24,"41午") -> 0 | J35: =COUNTIF(J$3:J$24,"41午") -> 0 | K35: =COUNTIF(K$3:K$24,"41午") -> 0 | L35: =COUNTIF(L$3:L$24,"41午*") -> 0 | M35: =COUNTIF(M$3:M$24,"41午") -> 0 | N35: =COUNTIF(N$3:N$24,"41午") -> 0 | O35: =COUNTIF(O$3:O$24,"41午") -> 0 | P35: =COUNTIF(P$3:P$24,"41午") -> 0 | Q35: =COUNTIF(Q$3:Q$24,"41午") -> 0 | R35: =COUNTIF(R$3:R$24,"41午") -> 0 | S35: =COUNTIF(S$3:S$24,"41午") -> 0 | T35: =COUNTIF(T$3:T$24,"41午") -> 0 | ... AS35: =COUNTIF(AS$3:AS$24,"41午") -> 0
C36: 41夜 | D36: =COUNTIF(D$3:D$24,"41夜*") -> 0 | E36: =COUNTIF(E$3:E$24,"41夜*") -> 0 | F36: =COUNTIF(F$3:F$24,"41夜*") -> 0 | G36: =COUNTIF(G$3:G$24,"41夜*") -> 0 | H36: =COUNTIF(H$3:H$24,"41夜*") -> 0 | I36: =COUNTIF(I$3:I$24,"41夜*") -> 0 | J36: =COUNTIF(J$3:J$24,"41夜*") -> 0 | K36: =COUNTIF(K$3:K$24,"41夜*") -> 0 | ... AS36: =COUNTIF(AS$3:AS$24,"41夜*") -> 0
C37: A1早 | D37: =COUNTIF(D$3:D$24,"01早*") -> 5 | E37: =COUNTIF(E$3:E$24,"01早*") -> 5 | F37: =COUNTIF(F$3:F$24,"01早*") -> 6 | G37: =COUNTIF(G$3:G$24,"01早*") -> 6 | H37: =COUNTIF(H$3:H$24,"01早*") -> 6 | I37: =COUNTIF(I$3:I$24,"01早*") -> 6 | J37: =COUNTIF(J$3:J$24,"01早*") -> 6 | K37: =COUNTIF(K$3:K$24,"01早*") -> 0 | ... AS37: =COUNTIF(AS$3:AS$24,"01早*") -> 0
C38: A1中A | D38: =COUNTIF(D$3:D$24,"01中A*") -> 0 | E38: =COUNTIF(E$3:E$24,"01中A*") -> 0 | F38: =COUNTIF(F$3:F$24,"01中A*") -> 0 | G38: =COUNTIF(G$3:G$24,"01中A*") -> 0 | H38: =COUNTIF(H$3:H$24,"01中A*") -> 0 | I38: =COUNTIF(I$3:I$24,"01中A*") -> 0 | J38: =COUNTIF(J$3:J$24,"01中A*") -> 0 | K38: =COUNTIF(K$3:K$24,"01中A*") -> 0 | ... AS38: =COUNTIF(AS$3:AS$24,"01中A*") -> 0
C39: A1午 | D39: =COUNTIF(D$3:D$24,"01午*") -> 4 | E39: =COUNTIF(E$3:E$24,"01午*") -> 4 | F39: =COUNTIF(F$3:F$24,"01午*") -> 5 | G39: =COUNTIF(G$3:G$24,"01午*") -> 6 | H39: =COUNTIF(H$3:H$24,"01午*") -> 5 | I39: =COUNTIF(I$3:I$24,"01午*") -> 5 | J39: =COUNTIF(J$3:J$24,"01午*") -> 6 | K39: =COUNTIF(K$3:K$24,"01午*") -> 0 | ... AS39: =COUNTIF(AS$3:AS$24,"01午*") -> 0
C40: A1夜 | D40: =COUNTIF(D$3:D$24,"01夜*") -> 2 | E40: =COUNTIF(E$3:E$24,"01夜*") -> 2 | F40: =COUNTIF(F$3:F$24,"01夜*") -> 2 | G40: =COUNTIF(G$3:G$24,"01夜*") -> 2 | H40: =COUNTIF(H$3:H$24,"01夜*") -> 2 | I40: =COUNTIF(I$3:I$24,"01夜*") -> 2 | J40: =COUNTIF(J$3:J$24,"01夜*") -> 2 | K40: =COUNTIF(K$3:K$24,"01夜*") -> 0 | ... AS40: =COUNTIF(AS$3:AS$24,"01夜*") -> 0

Sheet 北段 (人資版)
B1: 員編 ID No. | C1: 日期 星期 姓名 | D1: 46204 | E1: 46205 | F1: 46206 | G1: 46207 | H1: 46208 | I1: 46209 | J1: 46210 | K1: 46211 | L1: 46212 | M1: 46213 | N1: 46214 | O1: 46215 | P1: 46216 | Q1: 46217 | R1: 46218 | S1: 46219 | T1: 46220 | U1: 46221 | V1: 46222 | W1: 46223 | X1: 46224 | Y1: 46225 | Z1: 46226 | AA1: 46227 | AB1: 46228 | AC1: 46229 | AD1: 46230 | AE1: 46231 | AF1: 46232 | AG1: 46233 | AH1: 46234
D2: =IFERROR(IF(WEEKDAY(D1,2)=7,"日",WEEKDAY(D1,2)),"") -> 3 | E2: =IFERROR(IF(WEEKDAY(E1,2)=7,"日",WEEKDAY(E1,2)),"") -> 4 | F2: =IFERROR(IF(WEEKDAY(F1,2)=7,"日",WEEKDAY(F1,2)),"") -> 5 | G2: =IFERROR(IF(WEEKDAY(G1,2)=7,"日",WEEKDAY(G1,2)),"") -> 6 | H2: =IFERROR(IF(WEEKDAY(H1,2)=7,"日",WEEKDAY(H1,2)),"") -> 日 | I2: =IFERROR(IF(WEEKDAY(I1,2)=7,"日",WEEKDAY(I1,2)),"") -> 1 | J2: =IFERROR(IF(WEEKDAY(J1,2)=7,"日",WEEKDAY(J1,2)),"") -> 2 | K2: =IFERROR(IF(WEEKDAY(K1,2)=7,"日",WEEKDAY(K1,2)),"") -> 3 | ... AH2: =IFERROR(IF(WEEKDAY(AH1,2)=7,"日",WEEKDAY(AH1,2)),"") -> 5
B3: =LEFT(北段!#REF!,6) -> #REF! | C3: =VLOOKUP(B3,北段!B:C,2,FALSE) -> #REF! | D3: =LEFT(北段!#REF!,4) -> #REF! | E3: =LEFT(北段!#REF!,4) -> #REF! | F3: =LEFT(北段!#REF!,4) -> #REF! | G3: =LEFT(北段!#REF!,4) -> #REF! | H3: =LEFT(北段!#REF!,4) -> #REF! | I3: =LEFT(北段!#REF!,4) -> #REF! | J3: =LEFT(北段!#REF!,4) -> #REF! | K3: =LEFT(北段!#REF!,4) -> #REF! | ... AH3: =LEFT(北段!#REF!,4) -> #REF!
B4: =LEFT(北段!#REF!,6) -> #REF! | C4: =VLOOKUP(B4,北段!B:C,2,FALSE) -> #REF! | D4: =LEFT(北段!#REF!,4) -> #REF! | E4: =LEFT(北段!#REF!,4) -> #REF! | F4: =LEFT(北段!#REF!,4) -> #REF! | G4: =LEFT(北段!#REF!,4) -> #REF! | H4: =LEFT(北段!#REF!,4) -> #REF! | I4: =LEFT(北段!#REF!,4) -> #REF! | J4: =LEFT(北段!#REF!,4) -> #REF! | K4: =LEFT(北段!#REF!,4) -> #REF! | ... AH4: =LEFT(北段!#REF!,4) -> #REF!
B5: =LEFT(北段!#REF!,6) -> #REF! | C5: =VLOOKUP(B5,北段!B:C,2,FALSE) -> #REF! | D5: =LEFT(北段!#REF!,4) -> #REF! | E5: =LEFT(北段!#REF!,4) -> #REF! | F5: =LEFT(北段!#REF!,4) -> #REF! | G5: =LEFT(北段!#REF!,4) -> #REF! | H5: =LEFT(北段!#REF!,4) -> #REF! | I5: =LEFT(北段!#REF!,4) -> #REF! | J5: =LEFT(北段!#REF!,4) -> #REF! | K5: =LEFT(北段!#REF!,4) -> #REF! | ... AH5: =LEFT(北段!#REF!,4) -> #REF!
B6: =LEFT(北段!#REF!,6) -> #REF! | C6: =VLOOKUP(B6,北段!B:C,2,FALSE) -> #REF! | D6: =LEFT(北段!#REF!,4) -> #REF! | E6: =LEFT(北段!#REF!,4) -> #REF! | F6: =LEFT(北段!#REF!,4) -> #REF! | G6: =LEFT(北段!#REF!,4) -> #REF! | H6: =LEFT(北段!#REF!,4) -> #REF! | I6: =LEFT(北段!#REF!,4) -> #REF! | J6: =LEFT(北段!#REF!,4) -> #REF! | K6: =LEFT(北段!#REF!,4) -> #REF! | ... AH6: =LEFT(北段!#REF!,4) -> #REF!
B7: =LEFT(北段!#REF!,6) -> #REF! | C7: =VLOOKUP(B7,北段!B:C,2,FALSE) -> #REF! | D7: =LEFT(北段!#REF!,4) -> #REF! | E7: =LEFT(北段!#REF!,4) -> #REF! | F7: =LEFT(北段!#REF!,4) -> #REF! | G7: =LEFT(北段!#REF!,4) -> #REF! | H7: =LEFT(北段!#REF!,4) -> #REF! | I7: =LEFT(北段!#REF!,4) -> #REF! | J7: =LEFT(北段!#REF!,4) -> #REF! | K7: =LEFT(北段!#REF!,4) -> #REF! | ... AH7: =LEFT(北段!#REF!,4) -> #REF!
B8: =LEFT(北段!#REF!,6) -> #REF! | C8: =VLOOKUP(B8,北段!B:C,2,FALSE) -> #REF! | D8: =LEFT(北段!#REF!,4) -> #REF! | E8: =LEFT(北段!#REF!,4) -> #REF! | F8: =LEFT(北段!#REF!,4) -> #REF! | G8: =LEFT(北段!#REF!,4) -> #REF! | H8: =LEFT(北段!#REF!,4) -> #REF! | I8: =LEFT(北段!#REF!,4) -> #REF! | J8: =LEFT(北段!#REF!,4) -> #REF! | K8: =LEFT(北段!#REF!,4) -> #REF! | ... AH8: =LEFT(北段!#REF!,4) -> #REF!
B9: =LEFT(北段!#REF!,6) -> #REF! | C9: =VLOOKUP(B9,北段!B:C,2,FALSE) -> #REF! | D9: =LEFT(北段!#REF!,4) -> #REF! | E9: =LEFT(北段!#REF!,4) -> #REF! | F9: =LEFT(北段!#REF!,4) -> #REF! | G9: =LEFT(北段!#REF!,4) -> #REF! | H9: =LEFT(北段!#REF!,4) -> #REF! | I9: =LEFT(北段!#REF!,4) -> #REF! | J9: =LEFT(北段!#REF!,4) -> #REF! | K9: =LEFT(北段!#REF!,4) -> #REF! | ... AH9: =LEFT(北段!#REF!,4) -> #REF!
B10: =LEFT(北段!#REF!,6) -> #REF! | C10: =VLOOKUP(B10,北段!B:C,2,FALSE) -> #REF! | D10: =LEFT(北段!#REF!,4) -> #REF! | E10: =LEFT(北段!#REF!,4) -> #REF! | F10: =LEFT(北段!#REF!,4) -> #REF! | G10: =LEFT(北段!#REF!,4) -> #REF! | H10: =LEFT(北段!#REF!,4) -> #REF! | I10: =LEFT(北段!#REF!,4) -> #REF! | J10: =LEFT(北段!#REF!,4) -> #REF! | K10: =LEFT(北段!#REF!,4) -> #REF! | ... AH10: =LEFT(北段!#REF!,4) -> #REF!
B11: =LEFT(北段!#REF!,6) -> #REF! | C11: =VLOOKUP(B11,北段!B:C,2,FALSE) -> #REF! | D11: =LEFT(北段!#REF!,4) -> #REF! | E11: =LEFT(北段!#REF!,4) -> #REF! | F11: =LEFT(北段!#REF!,4) -> #REF! | G11: =LEFT(北段!#REF!,4) -> #REF! | H11: =LEFT(北段!#REF!,4) -> #REF! | I11: =LEFT(北段!#REF!,4) -> #REF! | J11: =LEFT(北段!#REF!,4) -> #REF! | K11: =LEFT(北段!#REF!,4) -> #REF! | ... AH11: =LEFT(北段!#REF!,4) -> #REF!
B12: =LEFT(北段!#REF!,6) -> #REF! | C12: =VLOOKUP(B12,北段!B:C,2,FALSE) -> #REF! | D12: =LEFT(北段!#REF!,4) -> #REF! | E12: =LEFT(北段!#REF!,4) -> #REF! | F12: =LEFT(北段!#REF!,4) -> #REF! | G12: =LEFT(北段!#REF!,4) -> #REF! | H12: =LEFT(北段!#REF!,4) -> #REF! | I12: =LEFT(北段!#REF!,4) -> #REF! | J12: =LEFT(北段!#REF!,4) -> #REF! | K12: =LEFT(北段!#REF!,4) -> #REF! | ... AH12: =LEFT(北段!#REF!,4) -> #REF!
B13: =LEFT(北段!B3,6) -> T01028 | C13: =VLOOKUP(B13,北段!B:C,2,FALSE) -> 林金緗 | D13: =LEFT(北段!J3,3) -> 01午 | E13: =LEFT(北段!K3,4) | F13: =LEFT(北段!L3,4) | G13: =LEFT(北段!M3,4) -> R | H13: =LEFT(北段!N3,4) | I13: =LEFT(北段!O3,4) | J13: =LEFT(北段!P3,4) | K13: =LEFT(北段!Q3,4) | L13: =LEFT(北段!R3,4) | ... AH13: =LEFT(北段!AN3,4)
B14: =LEFT(北段!B4,6) -> T00509 | C14: =VLOOKUP(B14,北段!B:C,2,FALSE) -> 郭秋儀 | D14: =LEFT(北段!J4,3) -> 01午 | E14: =LEFT(北段!K4,4) | F14: =LEFT(北段!L4,4) | G14: =LEFT(北段!M4,4) | H14: =LEFT(北段!N4,4) -> L | I14: =LEFT(北段!O4,4) | J14: =LEFT(北段!P4,4) | K14: =LEFT(北段!Q4,4) | L14: =LEFT(北段!R4,4) | ... AH14: =LEFT(北段!AN4,4)
B15: =LEFT(北段!B5,6) -> T01029 | C15: =VLOOKUP(B15,北段!B:C,2,FALSE) -> 林雯琳 | D15: =LEFT(北段!J5,3) -> 01夜 | E15: =LEFT(北段!K5,4) | F15: =LEFT(北段!L5,4) | G15: =LEFT(北段!M5,4) | H15: =LEFT(北段!N5,4) | I15: =LEFT(北段!O5,4) | J15: =LEFT(北段!P5,4) | K15: =LEFT(北段!Q5,4) | L15: =LEFT(北段!R5,4) | ... AH15: =LEFT(北段!AN5,4)
B16: =LEFT(北段!B6,6) -> T01734 | C16: =VLOOKUP(B16,北段!B:C,2,FALSE) -> 黃冠銘 | D16: =LEFT(北段!J6,3) -> 01早 | E16: =LEFT(北段!K6,4) | F16: =LEFT(北段!L6,4) | G16: =LEFT(北段!M6,4) | H16: =LEFT(北段!N6,4) | I16: =LEFT(北段!O6,4) | J16: =LEFT(北段!P6,4) | K16: =LEFT(北段!Q6,4) | L16: =LEFT(北段!R6,4) | ... AH16: =LEFT(北段!AN6,4)
B17: =LEFT(北段!B7,6) -> T02287 | C17: =VLOOKUP(B17,北段!B:C,2,FALSE) -> 林江玉 | D17: =LEFT(北段!J7,3) -> 01早 | E17: =LEFT(北段!K7,4) | F17: =LEFT(北段!L7,4) | G17: =LEFT(北段!M7,4) -> L | H17: =LEFT(北段!N7,4) -> L | I17: =LEFT(北段!O7,4) -> L | J17: =LEFT(北段!P7,4) -> L | K17: =LEFT(北段!Q7,4) -> R | L17: =LEFT(北段!R7,4) -> R | ... AH17: =LEFT(北段!AN7,4) -> r'
B18: =LEFT(北段!B8,6) -> T02359 | C18: =VLOOKUP(B18,北段!B:C,2,FALSE) -> 陳佳婷 | D18: =LEFT(北段!J8,3) -> 01早 | E18: =LEFT(北段!K8,4) | F18: =LEFT(北段!L8,4) | G18: =LEFT(北段!M8,4) | H18: =LEFT(北段!N8,4) | I18: =LEFT(北段!O8,4) | J18: =LEFT(北段!P8,4) | K18: =LEFT(北段!Q8,4) -> R | L18: =LEFT(北段!R8,4) -> R | ... AH18: =LEFT(北段!AN8,4)
B19: =LEFT(北段!B9,6) -> T02363 | C19: =VLOOKUP(B19,北段!B:C,2,FALSE) -> 林孟錡 | D19: =LEFT(北段!J9,3) -> R | E19: =LEFT(北段!K9,4) -> r' | F19: =LEFT(北段!L9,4) -> R | G19: =LEFT(北段!M9,4) -> L | H19: =LEFT(北段!N9,4) -> L | I19: =LEFT(北段!O9,4) -> L | J19: =LEFT(北段!P9,4) -> r' | K19: =LEFT(北段!Q9,4) -> 01夜B | L19: =LEFT(北段!R9,4) -> 01夜B | ... AH19: =LEFT(北段!AN9,4)
B20: =LEFT(北段!#REF!,6) -> #REF! | C20: =VLOOKUP(B20,北段!B:C,2,FALSE) -> #REF! | D20: =LEFT(北段!#REF!,3) -> #REF! | E20: =LEFT(北段!#REF!,4) -> #REF! | F20: =LEFT(北段!#REF!,4) -> #REF! | G20: =LEFT(北段!#REF!,4) -> #REF! | H20: =LEFT(北段!#REF!,4) -> #REF! | I20: =LEFT(北段!#REF!,4) -> #REF! | J20: =LEFT(北段!#REF!,4) -> #REF! | K20: =LEFT(北段!#REF!,4) -> #REF! | L20: =LEFT(北段!#REF!,4) -> #REF! | ... AH20: =LEFT(北段!#REF!,4) -> #REF!
B21: =LEFT(北段!B10,6) -> T02505 | C21: =VLOOKUP(B21,北段!B:C,2,FALSE) -> 李慧盺 | D21: =LEFT(北段!J10,3) -> R | E21: =LEFT(北段!K10,4) | F21: =LEFT(北段!L10,4) | G21: =LEFT(北段!M10,4) | H21: =LEFT(北段!N10,4) | I21: =LEFT(北段!O10,4) | J21: =LEFT(北段!P10,4) | K21: =LEFT(北段!Q10,4) | L21: =LEFT(北段!R10,4) | ... AH21: =LEFT(北段!AN10,4)
B22: =LEFT(北段!B11,6) -> T02776 | C22: =VLOOKUP(B22,北段!B:C,2,FALSE) -> 陳怡臻 | D22: =LEFT(北段!J11,3) -> 01夜 | E22: =LEFT(北段!K11,4) | F22: =LEFT(北段!L11,4) | G22: =LEFT(北段!M11,4) | H22: =LEFT(北段!N11,4) | I22: =LEFT(北段!O11,4) | J22: =LEFT(北段!P11,4) -> R | K22: =LEFT(北段!Q11,4) | L22: =LEFT(北段!R11,4) | ... AH22: =LEFT(北段!AN11,4)
B23: =LEFT(北段!B12,6) -> T02777 | C23: =VLOOKUP(B23,北段!B:C,2,FALSE) -> 彭裕涵 | D23: =LEFT(北段!J12,3) -> r' | E23: =LEFT(北段!K12,4) | F23: =LEFT(北段!L12,4) | G23: =LEFT(北段!M12,4) | H23: =LEFT(北段!N12,4) | I23: =LEFT(北段!O12,4) | J23: =LEFT(北段!P12,4) | K23: =LEFT(北段!Q12,4) | L23: =LEFT(北段!R12,4) | ... AH23: =LEFT(北段!AN12,4)
B24: =LEFT(北段!B13,6) -> T00557 | C24: =VLOOKUP(B24,北段!B:C,2,FALSE) -> 陳志明 | D24: =LEFT(北段!J13,3) -> 01午 | E24: =LEFT(北段!K13,4) | F24: =LEFT(北段!L13,4) | G24: =LEFT(北段!M13,4) | H24: =LEFT(北段!N13,4) | I24: =LEFT(北段!O13,4) | J24: =LEFT(北段!P13,4) -> L | K24: =LEFT(北段!Q13,4) -> R | L24: =LEFT(北段!R13,4) | ... AH24: =LEFT(北段!AN13,4)
B25: =LEFT(北段!B14,6) -> T00929 | C25: =VLOOKUP(B25,北段!B:C,2,FALSE) -> 簡婉蓁 | D25: =LEFT(北段!J14,3) -> 01早 | E25: =LEFT(北段!K14,4) | F25: =LEFT(北段!L14,4) | G25: =LEFT(北段!M14,4) | H25: =LEFT(北段!N14,4) -> 01早B | I25: =LEFT(北段!O14,4) | J25: =LEFT(北段!P14,4) | K25: =LEFT(北段!Q14,4) -> 01早B | L25: =LEFT(北段!R14,4) | ... AH25: =LEFT(北段!AN14,4) -> R
B26: =LEFT(北段!B15,6) -> T01459 | C26: =VLOOKUP(B26,北段!B:C,2,FALSE) -> 林禹丞 | D26: =LEFT(北段!J15,3) -> 01早 | E26: =LEFT(北段!K15,4) -> r' | F26: =LEFT(北段!L15,4) -> R | G26: =LEFT(北段!M15,4) | H26: =LEFT(北段!N15,4) | I26: =LEFT(北段!O15,4) | J26: =LEFT(北段!P15,4) | K26: =LEFT(北段!Q15,4) | L26: =LEFT(北段!R15,4) -> r' | ... AH26: =LEFT(北段!AN15,4) -> R
B27: =LEFT(北段!B16,6) -> T01600 | C27: =VLOOKUP(B27,北段!B:C,2,FALSE) -> 陳奎羽 | D27: =LEFT(北段!J16,3) -> L | E27: =LEFT(北段!K16,4) -> r' | F27: =LEFT(北段!L16,4) -> R | G27: =LEFT(北段!M16,4) | H27: =LEFT(北段!N16,4) | I27: =LEFT(北段!O16,4) | J27: =LEFT(北段!P16,4) | K27: =LEFT(北段!Q16,4) | L27: =LEFT(北段!R16,4) | ... AH27: =LEFT(北段!AN16,4)
B28: =LEFT(北段!B17,6) -> T01795 | C28: =VLOOKUP(B28,北段!B:C,2,FALSE) -> 黃羿綾 | D28: =LEFT(北段!J17,3) -> R | E28: =LEFT(北段!K17,4) -> r' | F28: =LEFT(北段!L17,4) -> R | G28: =LEFT(北段!M17,4) -> r' | H28: =LEFT(北段!N17,4) | I28: =LEFT(北段!O17,4) | J28: =LEFT(北段!P17,4) | K28: =LEFT(北段!Q17,4) | L28: =LEFT(北段!R17,4) | ... AH28: =LEFT(北段!AN17,4)
B29: =LEFT(北段!B18,6) -> T02222 | C29: =VLOOKUP(B29,北段!B:C,2,FALSE) -> 𡍼文妤 | D29: =LEFT(北段!J18,3) -> r' | E29: =LEFT(北段!K18,4) | F29: =LEFT(北段!L18,4) | G29: =LEFT(北段!M18,4) | H29: =LEFT(北段!N18,4) | I29: =LEFT(北段!O18,4) | J29: =LEFT(北段!P18,4) | K29: =LEFT(北段!Q18,4) | L29: =LEFT(北段!R18,4) -> R | ... AH29: =LEFT(北段!AN18,4)
B30: =LEFT(北段!B19,6) -> T02233 | C30: =VLOOKUP(B30,北段!B:C,2,FALSE) -> 簡悅如 | D30: =LEFT(北段!J19,3) -> 01早 | E30: =LEFT(北段!K19,4) | F30: =LEFT(北段!L19,4) | G30: =LEFT(北段!M19,4) | H30: =LEFT(北段!N19,4) | I30: =LEFT(北段!O19,4) | J30: =LEFT(北段!P19,4) | K30: =LEFT(北段!Q19,4) | L30: =LEFT(北段!R19,4) | ... AH30: =LEFT(北段!AN19,4)
B31: =LEFT(北段!B20,6) -> T02613 | C31: =VLOOKUP(B31,北段!B:C,2,FALSE) -> 張雅荃 | D31: =LEFT(北段!J20,3) -> 01午 | E31: =LEFT(北段!K20,4) | F31: =LEFT(北段!L20,4) | G31: =LEFT(北段!M20,4) | H31: =LEFT(北段!N20,4) | I31: =LEFT(北段!O20,4) | J31: =LEFT(北段!P20,4) | K31: =LEFT(北段!Q20,4) | L31: =LEFT(北段!R20,4) | ... AH31: =LEFT(北段!AN20,4)
B32: =LEFT(北段!B21,6) -> T02758 | C32: =VLOOKUP(B32,北段!B:C,2,FALSE) -> 王映心 | D32: =LEFT(北段!J21,3) -> 01午 | E32: =LEFT(北段!K21,4) | F32: =LEFT(北段!L21,4) | G32: =LEFT(北段!M21,4) | H32: =LEFT(北段!N21,4) | I32: =LEFT(北段!O21,4) | J32: =LEFT(北段!P21,4) | K32: =LEFT(北段!Q21,4) | L32: =LEFT(北段!R21,4) -> r' | ... AH32: =LEFT(北段!AN21,4)
... B35: =LEFT(北段!B24,6) -> T02769 | C35: =VLOOKUP(B35,北段!B:C,2,FALSE) -> 吳東翰 | D35: =LEFT(北段!J24,3) -> r' | E35: =LEFT(北段!K24,4) | F35: =LEFT(北段!L24,4) | G35: =LEFT(北段!M24,4) | H35: =LEFT(北段!N24,4) | I35: =LEFT(北段!O24,4) | J35: =LEFT(北段!P24,4) | K35: =LEFT(北段!Q24,4) | L35: =LEFT(北段!R24,4) -> R | ... AH35: =LEFT(北段!AN24,4)
B36: =LEFT(北段!#REF!,6) -> #REF! | C36: =VLOOKUP(B36,北段!B:C,2,FALSE) -> #REF! | D36: =LEFT(北段!#REF!,3) -> #REF! | E36: =LEFT(北段!#REF!,4) -> #REF! | F36: =LEFT(北段!#REF!,4) -> #REF! | G36: =LEFT(北段!#REF!,4) -> #REF! | H36: =LEFT(北段!#REF!,4) -> #REF! | I36: =LEFT(北段!#REF!,4) -> #REF! | J36: =LEFT(北段!#REF!,4) -> #REF! | K36: =LEFT(北段!#REF!,4) -> #REF! | L36: =LEFT(北段!#REF!,4) -> #REF! | ... AH36: =LEFT(北段!#REF!,4) -> #REF!
B37: =LEFT(北段!#REF!,6) -> #REF! | C37: =VLOOKUP(B37,北段!B:C,2,FALSE) -> #REF! | D37: =LEFT(北段!#REF!,3) -> #REF! | E37: =LEFT(北段!#REF!,4) -> #REF! | F37: =LEFT(北段!#REF!,4) -> #REF! | G37: =LEFT(北段!#REF!,4) -> #REF! | H37: =LEFT(北段!#REF!,4) -> #REF! | I37: =LEFT(北段!#REF!,4) -> #REF! | J37: =LEFT(北段!#REF!,4) -> #REF! | K37: =LEFT(北段!#REF!,4) -> #REF! | L37: =LEFT(北段!#REF!,4) -> #REF! | ... AH37: =LEFT(北段!#REF!,4) -> #REF!
B38: =LEFT(北段!#REF!,6) -> #REF! | C38: =VLOOKUP(B38,北段!B:C,2,FALSE) -> #REF! | D38: =LEFT(北段!#REF!,3) -> #REF! | E38: =LEFT(北段!#REF!,4) -> #REF! | F38: =LEFT(北段!#REF!,4) -> #REF! | G38: =LEFT(北段!#REF!,4) -> #REF! | H38: =LEFT(北段!#REF!,4) -> #REF! | I38: =LEFT(北段!#REF!,4) -> #REF! | J38: =LEFT(北段!#REF!,4) -> #REF! | K38: =LEFT(北段!#REF!,4) -> #REF! | L38: =LEFT(北段!#REF!,4) -> #REF! | ... AH38: =LEFT(北段!#REF!,4) -> #REF!
B39: =LEFT(北段!#REF!,6) -> #REF! | C39: =VLOOKUP(B39,北段!B:C,2,FALSE) -> #REF! | D39: =LEFT(北段!#REF!,4) -> #REF! | E39: =LEFT(北段!#REF!,4) -> #REF! | F39: =LEFT(北段!#REF!,4) -> #REF! | G39: =LEFT(北段!#REF!,4) -> #REF! | H39: =LEFT(北段!#REF!,4) -> #REF! | I39: =LEFT(北段!#REF!,4) -> #REF! | J39: =LEFT(北段!#REF!,4) -> #REF! | K39: =LEFT(北段!#REF!,4) -> #REF! | ... AH39: =LEFT(北段!#REF!,4) -> #REF!
B40: =LEFT(北段!#REF!,6) -> #REF! | C40: =VLOOKUP(B40,北段!B:C,2,FALSE) -> #REF! | D40: =LEFT(北段!#REF!,4) -> #REF! | E40: =LEFT(北段!#REF!,4) -> #REF! | F40: =LEFT(北段!#REF!,4) -> #REF! | G40: =LEFT(北段!#REF!,4) -> #REF! | H40: =LEFT(北段!#REF!,4) -> #REF! | I40: =LEFT(北段!#REF!,4) -> #REF! | J40: =LEFT(北段!#REF!,4) -> #REF! | K40: =LEFT(北段!#REF!,4) -> #REF! | ... AH40: =LEFT(北段!#REF!,4) -> #REF!
B41: =LEFT(北段!#REF!,6) -> #REF! | C41: =VLOOKUP(B41,北段!B:C,2,FALSE) -> #REF! | D41: =LEFT(北段!#REF!,4) -> #REF! | E41: =LEFT(北段!#REF!,4) -> #REF! | F41: =LEFT(北段!#REF!,4) -> #REF! | G41: =LEFT(北段!#REF!,4) -> #REF! | H41: =LEFT(北段!#REF!,4) -> #REF! | I41: =LEFT(北段!#REF!,4) -> #REF! | J41: =LEFT(北段!#REF!,4) -> #REF! | K41: =LEFT(北段!#REF!,4) -> #REF! | ... AH41: =LEFT(北段!#REF!,4) -> #REF!
B42: =LEFT(北段!#REF!,6) -> #REF! | C42: =VLOOKUP(B42,北段!B:C,2,FALSE) -> #REF! | D42: =LEFT(北段!#REF!,4) -> #REF! | E42: =LEFT(北段!#REF!,4) -> #REF! | F42: =LEFT(北段!#REF!,4) -> #REF! | G42: =LEFT(北段!#REF!,4) -> #REF! | H42: =LEFT(北段!#REF!,4) -> #REF! | I42: =LEFT(北段!#REF!,4) -> #REF! | J42: =LEFT(北段!#REF!,4) -> #REF! | K42: =LEFT(北段!#REF!,4) -> #REF! | ... AH42: =LEFT(北段!#REF!,4) -> #REF!
...

Sheet 北段(八周檢核代碼
B1: 員編 ID No. | C1: 日期 星期 姓名 | D1: ='北段 (人資版)'!D1 -> 46204 | E1: ='北段 (人資版)'!E1 -> 46205 | F1: ='北段 (人資版)'!F1 -> 46206 | G1: ='北段 (人資版)'!G1 -> 46207 | H1: ='北段 (人資版)'!H1 -> 46208 | I1: ='北段 (人資版)'!I1 -> 46209 | J1: ='北段 (人資版)'!J1 -> 46210 | K1: ='北段 (人資版)'!K1 -> 46211 | ... AH1: ='北段 (人資版)'!AH1 -> 46234 | AI1: ='北段 (人資版)'!#REF! -> #REF! | AJ1: ='北段 (人資版)'!#REF! -> #REF! | AK1: ='北段 (人資版)'!#REF! -> #REF! | AL1: ='北段 (人資版)'!#REF! -> #REF! | AM1: ='北段 (人資版)'!#REF! -> #REF! | AN1: ='北段 (人資版)'!AI1 -> 0 | AO1: ='北段 (人資版)'!AJ1 -> 0
D2: =IFERROR(IF(WEEKDAY(D1,2)=7,"日",WEEKDAY(D1,2)),"") -> 3 | E2: =IFERROR(IF(WEEKDAY(E1,2)=7,"日",WEEKDAY(E1,2)),"") -> 4 | F2: =IFERROR(IF(WEEKDAY(F1,2)=7,"日",WEEKDAY(F1,2)),"") -> 5 | G2: =IFERROR(IF(WEEKDAY(G1,2)=7,"日",WEEKDAY(G1,2)),"") -> 6 | H2: =IFERROR(IF(WEEKDAY(H1,2)=7,"日",WEEKDAY(H1,2)),"") -> 日 | I2: =IFERROR(IF(WEEKDAY(I1,2)=7,"日",WEEKDAY(I1,2)),"") -> 1 | J2: =IFERROR(IF(WEEKDAY(J1,2)=7,"日",WEEKDAY(J1,2)),"") -> 2 | K2: =IFERROR(IF(WEEKDAY(K1,2)=7,"日",WEEKDAY(K1,2)),"") -> 3 | ... AH2: =IFERROR(IF(WEEKDAY(AH1,2)=7,"日",WEEKDAY(AH1,2)),"") -> 5
A3: 北 段 辦 | B3: =北段!#REF! -> #REF! | C3: =VLOOKUP(B3,北段!B:C,2,FALSE) -> #REF! | D3: =VLOOKUP('北段 (人資版)'!D3,工作表1!$A$3:$B$78,2,FALSE) -> #REF! | E3: =VLOOKUP('北段 (人資版)'!E3,工作表1!$A$3:$B$78,2,FALSE) -> #REF! | F3: =VLOOKUP('北段 (人資版)'!F3,工作表1!$A$3:$B$78,2,FALSE) -> #REF! | G3: =VLOOKUP('北段 (人資版)'!G3,工作表1!$A$3:$B$78,2,FALSE) -> #REF! | H3: =VLOOKUP('北段 (人資版)'!H3,工作表1!$A$3:$B$78,2,FALSE) -> #REF! | I3: =VLOOKUP('北段 (人資版)'!I3,工作表1!$A$3:$B$78,2,FALSE) -> #REF! | J3: =VLOOKUP('北段 (人資版)'!J3,工作表1!$A$3:$B$78,2,FALSE) -> #REF! | K3: =VLOOKUP('北段 (人資版)'!K3,工作表1!$A$3:$B$78,2,FALSE) -> #REF! | ... AH3: =VLOOKUP('北段 (人資版)'!AH3,工作表1!$A$3:$B$78,2,FALSE) -> #REF!
B4: =北段!#REF! -> #REF! | C4: =VLOOKUP(B4,北段!B:C,2,FALSE) -> #REF! | D4: =VLOOKUP('北段 (人資版)'!D4,工作表1!$A$3:$B$78,2,FALSE) -> #REF! | E4: =VLOOKUP('北段 (人資版)'!E4,工作表1!$A$3:$B$78,2,FALSE) -> #REF! | F4: =VLOOKUP('北段 (人資版)'!F4,工作表1!$A$3:$B$78,2,FALSE) -> #REF! | G4: =VLOOKUP('北段 (人資版)'!G4,工作表1!$A$3:$B$78,2,FALSE) -> #REF! | H4: =VLOOKUP('北段 (人資版)'!H4,工作表1!$A$3:$B$78,2,FALSE) -> #REF! | I4: =VLOOKUP('北段 (人資版)'!I4,工作表1!$A$3:$B$78,2,FALSE) -> #REF! | J4: =VLOOKUP('北段 (人資版)'!J4,工作表1!$A$3:$B$78,2,FALSE) -> #REF! | K4: =VLOOKUP('北段 (人資版)'!K4,工作表1!$A$3:$B$78,2,FALSE) -> #REF! | ... AH4: =VLOOKUP('北段 (人資版)'!AH4,工作表1!$A$3:$B$78,2,FALSE) -> #REF!
B5: =北段!#REF! -> #REF! | C5: =VLOOKUP(B5,北段!B:C,2,FALSE) -> #REF! | D5: =VLOOKUP('北段 (人資版)'!D5,工作表1!$A$3:$B$78,2,FALSE) -> #REF! | E5: =VLOOKUP('北段 (人資版)'!E5,工作表1!$A$3:$B$78,2,FALSE) -> #REF! | F5: =VLOOKUP('北段 (人資版)'!F5,工作表1!$A$3:$B$78,2,FALSE) -> #REF! | G5: =VLOOKUP('北段 (人資版)'!G5,工作表1!$A$3:$B$78,2,FALSE) -> #REF! | H5: =VLOOKUP('北段 (人資版)'!H5,工作表1!$A$3:$B$78,2,FALSE) -> #REF! | I5: =VLOOKUP('北段 (人資版)'!I5,工作表1!$A$3:$B$78,2,FALSE) -> #REF! | J5: =VLOOKUP('北段 (人資版)'!J5,工作表1!$A$3:$B$78,2,FALSE) -> #REF! | K5: =VLOOKUP('北段 (人資版)'!K5,工作表1!$A$3:$B$78,2,FALSE) -> #REF! | ... AH5: =VLOOKUP('北段 (人資版)'!AH5,工作表1!$A$3:$B$78,2,FALSE) -> #REF!
B6: =北段!#REF! -> #REF! | C6: =VLOOKUP(B6,北段!B:C,2,FALSE) -> #REF! | D6: =VLOOKUP('北段 (人資版)'!D6,工作表1!$A$3:$B$78,2,FALSE) -> #REF! | E6: =VLOOKUP('北段 (人資版)'!E6,工作表1!$A$3:$B$78,2,FALSE) -> #REF! | F6: =VLOOKUP('北段 (人資版)'!F6,工作表1!$A$3:$B$78,2,FALSE) -> #REF! | G6: =VLOOKUP('北段 (人資版)'!G6,工作表1!$A$3:$B$78,2,FALSE) -> #REF! | H6: =VLOOKUP('北段 (人資版)'!H6,工作表1!$A$3:$B$78,2,FALSE) -> #REF! | I6: =VLOOKUP('北段 (人資版)'!I6,工作表1!$A$3:$B$78,2,FALSE) -> #REF! | J6: =VLOOKUP('北段 (人資版)'!J6,工作表1!$A$3:$B$78,2,FALSE) -> #REF! | K6: =VLOOKUP('北段 (人資版)'!K6,工作表1!$A$3:$B$78,2,FALSE) -> #REF! | ... AH6: =VLOOKUP('北段 (人資版)'!AH6,工作表1!$A$3:$B$78,2,FALSE) -> #REF!
B7: =北段!#REF! -> #REF! | C7: =VLOOKUP(B7,北段!B:C,2,FALSE) -> #REF! | D7: =VLOOKUP('北段 (人資版)'!D7,工作表1!$A$3:$B$78,2,FALSE) -> #REF! | E7: =VLOOKUP('北段 (人資版)'!E7,工作表1!$A$3:$B$78,2,FALSE) -> #REF! | F7: =VLOOKUP('北段 (人資版)'!F7,工作表1!$A$3:$B$78,2,FALSE) -> #REF! | G7: =VLOOKUP('北段 (人資版)'!G7,工作表1!$A$3:$B$78,2,FALSE) -> #REF! | H7: =VLOOKUP('北段 (人資版)'!H7,工作表1!$A$3:$B$78,2,FALSE) -> #REF! | I7: =VLOOKUP('北段 (人資版)'!I7,工作表1!$A$3:$B$78,2,FALSE) -> #REF! | J7: =VLOOKUP('北段 (人資版)'!J7,工作表1!$A$3:$B$78,2,FALSE) -> #REF! | K7: =VLOOKUP('北段 (人資版)'!K7,工作表1!$A$3:$B$78,2,FALSE) -> #REF! | ... AH7: =VLOOKUP('北段 (人資版)'!AH7,工作表1!$A$3:$B$78,2,FALSE) -> #REF!
B8: =北段!#REF! -> #REF! | C8: =VLOOKUP(B8,北段!B:C,2,FALSE) -> #REF! | D8: =VLOOKUP('北段 (人資版)'!D8,工作表1!$A$3:$B$78,2,FALSE) -> #REF! | E8: =VLOOKUP('北段 (人資版)'!E8,工作表1!$A$3:$B$78,2,FALSE) -> #REF! | F8: =VLOOKUP('北段 (人資版)'!F8,工作表1!$A$3:$B$78,2,FALSE) -> #REF! | G8: =VLOOKUP('北段 (人資版)'!G8,工作表1!$A$3:$B$78,2,FALSE) -> #REF! | H8: =VLOOKUP('北段 (人資版)'!H8,工作表1!$A$3:$B$78,2,FALSE) -> #REF! | I8: =VLOOKUP('北段 (人資版)'!I8,工作表1!$A$3:$B$78,2,FALSE) -> #REF! | J8: =VLOOKUP('北段 (人資版)'!J8,工作表1!$A$3:$B$78,2,FALSE) -> #REF! | K8: =VLOOKUP('北段 (人資版)'!K8,工作表1!$A$3:$B$78,2,FALSE) -> #REF! | ... AH8: =VLOOKUP('北段 (人資版)'!AH8,工作表1!$A$3:$B$78,2,FALSE) -> #REF!
B9: =北段!#REF! -> #REF! | C9: =VLOOKUP(B9,北段!B:C,2,FALSE) -> #REF! | D9: =VLOOKUP('北段 (人資版)'!D9,工作表1!$A$3:$B$78,2,FALSE) -> #REF! | E9: =VLOOKUP('北段 (人資版)'!E9,工作表1!$A$3:$B$78,2,FALSE) -> #REF! | F9: =VLOOKUP('北段 (人資版)'!F9,工作表1!$A$3:$B$78,2,FALSE) -> #REF! | G9: =VLOOKUP('北段 (人資版)'!G9,工作表1!$A$3:$B$78,2,FALSE) -> #REF! | H9: =VLOOKUP('北段 (人資版)'!H9,工作表1!$A$3:$B$78,2,FALSE) -> #REF! | I9: =VLOOKUP('北段 (人資版)'!I9,工作表1!$A$3:$B$78,2,FALSE) -> #REF! | J9: =VLOOKUP('北段 (人資版)'!J9,工作表1!$A$3:$B$78,2,FALSE) -> #REF! | K9: =VLOOKUP('北段 (人資版)'!K9,工作表1!$A$3:$B$78,2,FALSE) -> #REF! | ... AH9: =VLOOKUP('北段 (人資版)'!AH9,工作表1!$A$3:$B$78,2,FALSE) -> #REF!
B10: =北段!#REF! -> #REF! | C10: =VLOOKUP(B10,北段!B:C,2,FALSE) -> #REF! | D10: =VLOOKUP('北段 (人資版)'!D10,工作表1!$A$3:$B$78,2,FALSE) -> #REF! | E10: =VLOOKUP('北段 (人資版)'!E10,工作表1!$A$3:$B$78,2,FALSE) -> #REF! | F10: =VLOOKUP('北段 (人資版)'!F10,工作表1!$A$3:$B$78,2,FALSE) -> #REF! | G10: =VLOOKUP('北段 (人資版)'!G10,工作表1!$A$3:$B$78,2,FALSE) -> #REF! | H10: =VLOOKUP('北段 (人資版)'!H10,工作表1!$A$3:$B$78,2,FALSE) -> #REF! | I10: =VLOOKUP('北段 (人資版)'!I10,工作表1!$A$3:$B$78,2,FALSE) -> #REF! | J10: =VLOOKUP('北段 (人資版)'!J10,工作表1!$A$3:$B$78,2,FALSE) -> #REF! | K10: =VLOOKUP('北段 (人資版)'!K10,工作表1!$A$3:$B$78,2,FALSE) -> #REF! | ... AH10: =VLOOKUP('北段 (人資版)'!AH10,工作表1!$A$3:$B$78,2,FALSE) -> #REF!
B11: =北段!#REF! -> #REF! | C11: =VLOOKUP(B11,北段!B:C,2,FALSE) -> #REF! | D11: =VLOOKUP('北段 (人資版)'!D11,工作表1!$A$3:$B$78,2,FALSE) -> #REF! | E11: =VLOOKUP('北段 (人資版)'!E11,工作表1!$A$3:$B$78,2,FALSE) -> #REF! | F11: =VLOOKUP('北段 (人資版)'!F11,工作表1!$A$3:$B$78,2,FALSE) -> #REF! | G11: =VLOOKUP('北段 (人資版)'!G11,工作表1!$A$3:$B$78,2,FALSE) -> #REF! | H11: =VLOOKUP('北段 (人資版)'!H11,工作表1!$A$3:$B$78,2,FALSE) -> #REF! | I11: =VLOOKUP('北段 (人資版)'!I11,工作表1!$A$3:$B$78,2,FALSE) -> #REF! | J11: =VLOOKUP('北段 (人資版)'!J11,工作表1!$A$3:$B$78,2,FALSE) -> #REF! | K11: =VLOOKUP('北段 (人資版)'!K11,工作表1!$A$3:$B$78,2,FALSE) -> #REF! | ... AH11: =VLOOKUP('北段 (人資版)'!AH11,工作表1!$A$3:$B$78,2,FALSE) -> #REF!
B12: =北段!#REF! -> #REF! | C12: =VLOOKUP(B12,北段!B:C,2,FALSE) -> #REF! | D12: =VLOOKUP('北段 (人資版)'!D12,工作表1!$A$3:$B$78,2,FALSE) -> #REF! | E12: =VLOOKUP('北段 (人資版)'!E12,工作表1!$A$3:$B$78,2,FALSE) -> #REF! | F12: =VLOOKUP('北段 (人資版)'!F12,工作表1!$A$3:$B$78,2,FALSE) -> #REF! | G12: =VLOOKUP('北段 (人資版)'!G12,工作表1!$A$3:$B$78,2,FALSE) -> #REF! | H12: =VLOOKUP('北段 (人資版)'!H12,工作表1!$A$3:$B$78,2,FALSE) -> #REF! | I12: =VLOOKUP('北段 (人資版)'!I12,工作表1!$A$3:$B$78,2,FALSE) -> #REF! | J12: =VLOOKUP('北段 (人資版)'!J12,工作表1!$A$3:$B$78,2,FALSE) -> #REF! | K12: =VLOOKUP('北段 (人資版)'!K12,工作表1!$A$3:$B$78,2,FALSE) -> #REF! | ... AH12: =VLOOKUP('北段 (人資版)'!AH12,工作表1!$A$3:$B$78,2,FALSE) -> #REF!
A13: A1 | B13: =北段!B3 -> T01028 | C13: =VLOOKUP(B13,北段!B:C,2,FALSE) -> 林金緗 | D13: =VLOOKUP('北段 (人資版)'!D13,工作表1!$A$3:$B$78,2,FALSE) -> 66 | E13: =VLOOKUP('北段 (人資版)'!E13,工作表1!$A$3:$B$78,2,FALSE) -> #N/A | F13: =VLOOKUP('北段 (人資版)'!F13,工作表1!$A$3:$B$78,2,FALSE) -> #N/A | G13: =VLOOKUP('北段 (人資版)'!G13,工作表1!$A$3:$B$78,2,FALSE) -> 91 | H13: =VLOOKUP('北段 (人資版)'!H13,工作表1!$A$3:$B$78,2,FALSE) -> #N/A | I13: =VLOOKUP('北段 (人資版)'!I13,工作表1!$A$3:$B$78,2,FALSE) -> #N/A | J13: =VLOOKUP('北段 (人資版)'!J13,工作表1!$A$3:$B$78,2,FALSE) -> #N/A | K13: =VLOOKUP('北段 (人資版)'!K13,工作表1!$A$3:$B$78,2,FALSE) -> #N/A | ... AH13: =VLOOKUP('北段 (人資版)'!AH13,工作表1!$A$3:$B$78,2,FALSE) -> #N/A
B14: =北段!B4 -> T00509 | C14: =VLOOKUP(B14,北段!B:C,2,FALSE) -> 郭秋儀 | D14: =VLOOKUP('北段 (人資版)'!D14,工作表1!$A$3:$B$78,2,FALSE) -> 66 | E14: =VLOOKUP('北段 (人資版)'!E14,工作表1!$A$3:$B$78,2,FALSE) -> #N/A | F14: =VLOOKUP('北段 (人資版)'!F14,工作表1!$A$3:$B$78,2,FALSE) -> #N/A | G14: =VLOOKUP('北段 (人資版)'!G14,工作表1!$A$3:$B$78,2,FALSE) -> #N/A | H14: =VLOOKUP('北段 (人資版)'!H14,工作表1!$A$3:$B$78,2,FALSE) -> 07 | I14: =VLOOKUP('北段 (人資版)'!I14,工作表1!$A$3:$B$78,2,FALSE) -> #N/A | J14: =VLOOKUP('北段 (人資版)'!J14,工作表1!$A$3:$B$78,2,FALSE) -> #N/A | K14: =VLOOKUP('北段 (人資版)'!K14,工作表1!$A$3:$B$78,2,FALSE) -> #N/A | ... AH14: =VLOOKUP('北段 (人資版)'!AH14,工作表1!$A$3:$B$78,2,FALSE) -> #N/A
