Workbook

Sheet 北段
B1: 員編 ID No. | C1: 日期 星期 | D1: 46166 | E1: 46167 | F1: 46168 | G1: 46169 | H1: 46170 | I1: 46171 | J1: 46172 | K1: 46173 | L1: 46174 | M1: 46175 | N1: 46176 | O1: 46177 | P1: 46178 | Q1: 46179 | R1: 46180 | S1: 46181 | T1: 46182 | U1: 46183 | V1: 46184 | W1: 46185 | X1: 46186 | Y1: 46187 | Z1: 46188 | AA1: 46189 | AB1: 46190 | AC1: 46191 | AD1: 46192 | AE1: 46193 | AF1: 46194 | AG1: 46195 | AH1: 46196 | AI1: 46197 | AJ1: 46198 | AK1: 46199 | AL1: 46200 | AM1: 46201 | AN1: 46202 | AO1: 46203
C2: 姓名 | D2: =RIGHT(TEXT(D1,"[$-404]aaaa;@"),1) -> 日 | E2: =RIGHT(TEXT(E1,"[$-404]aaaa;@"),1) -> 一 | F2: =RIGHT(TEXT(F1,"[$-404]aaaa;@"),1) -> 二 | G2: =RIGHT(TEXT(G1,"[$-404]aaaa;@"),1) -> 三 | H2: =RIGHT(TEXT(H1,"[$-404]aaaa;@"),1) -> 四 | I2: =RIGHT(TEXT(I1,"[$-404]aaaa;@"),1) -> 五 | J2: =RIGHT(TEXT(J1,"[$-404]aaaa;@"),1) -> 六 | K2: =RIGHT(TEXT(K1,"[$-404]aaaa;@"),1) -> 日 | ... AO2: =RIGHT(TEXT(AO1,"[$-404]aaaa;@"),1) -> 二
A3: A1 | B3: T00509 | C3: 郭秋儀 | D3: P | E3: 01早M | F3: 01早M | G3: 01早m | H3: 01中A | I3: R | J3: 01夜B2 | K3: 01夜B1 | L3: r' | M3: R | N3: 01早M | O3: 01早m | P3: 01午M | Q3: r' | R3: 01夜 | S3: 01夜 | T3: 01夜 | U3: r' | V3: R | W3: 01早 | X3: 01早 | Y3: 01夜 | Z3: 01夜 | AA3: R | AB3: P | AC3: r' | AD3: r' | AE3: 01早 | AF3: 01早 | AG3: 01早 | AH3: 01午 | AI3: r' | AJ3: R | AK3: L | AL3: L | AM3: 01午 | AN3: 01午 | AO3: R
B4: T01028 | C4: 林金緗 | D4: R | E4: r' | F4: 01午m | G4: 01午M | H4: 01午m | I4: 01午M | J4: r' | K4: 01午M | L4: 01午m | M4: P | N4: R | O4: 01夜B1 | P4: 01夜B2 | Q4: 01夜B1 | R4: R | S4: r' | T4: L | U4: 01午 | V4: 01午 | W4: 01夜 | X4: 01夜 | Y4: 01夜 | Z4: r' | AA4: R | AB4: 01午 | AC4: 01午 | AD4: 01午 | AE4: 01午 | AF4: R | AG4: 01午 | AH4: 01午 | AI4: r' | AJ4: 01午 | AK4: 01午 | AL4: r' | AM4: 01早 | AN4: 01早 | AO4: 01午
B5: T01029 | C5: 林雯琳 | D5: R | E5: P | F5: P | G5: 01午m | H5: 01午M | I5: 01午m | J5: 01午m | K5: r' | L5: 01夜B1 | M5: 01夜B2 | N5: R | O5: P | P5: r' | Q5: 01午m | R5: 01午 | S5: R | T5: r' | U5: 01午 | V5: 01午 | W5: r' | X5: 01早 | Y5: 01午 | Z5: 01夜 | AA5: 01夜 | AB5: 01夜 | AC5: R | AD5: L | AE5: 01午 | AF5: 01午 | AG5: 01午 | AH5: r' | AI5: r' | AJ5: R | AK5: L | AL5: L | AM5: 01午 | AN5: 01午 | AO5: R
B6: T01734 | C6: 黃冠銘 | D6: 01早m | E6: R | F6: r' | G6: 01早M | H6: 01早m | I6: 01早M | J6: r' | K6: 01早m | L6: 01早M | M6: 01早m | N6: P | O6: R | P6: 01早M | Q6: 01早m | R6: R | S6: 01夜 | T6: 01夜 | U6: 01夜 | V6: 01夜 | W6: r' | X6: r' | Y6: R | Z6: 01午 | AA6: 01午 | AB6: r' | AC6: 01早 | AD6: 01早 | AE6: 01早 | AF6: 01早 | AG6: 01早 | AH6: R | AI6: r' | AJ6: 01早 | AK6: 01早 | AL6: 01早 | AM6: 01早 | AN6: R | AO6: 01早
B7: T02287 | C7: 林江玉 | D7: 01夜B2 | E7: 01夜B1 | F7: 01夜B2 | G7: R | H7: r' | I7: r' | J7: 01早m | K7: 01早M | L7: 01早m | M7: 01早M | N7: R | O7: 01早M | P7: 01早m | Q7: 01早M | R7: R | S7: 01早 | T7: 01早 | U7: 01早 | V7: 01早 | W7: r' | X7: r' | Y7: 01早 | Z7: 01早 | AA7: 01早 | AB7: 01早 | AC7: 01早 | AD7: R | AE7: L | AF7: R | AG7: r' | AH7: 01夜 | AI7: 01夜 | AJ7: 01夜 | AK7: 01夜 | AL7: 01夜 | AM7: R | AN7: P | AO7: 01中A
B8: T02359 | C8: 陳佳婷 | D8: 01早B1 | E8: 01早m | F8: R | G8: 01中A | H8: 01早M | I8: 01早m | J8: 01早M | K8: R | L8: 01夜B2 | M8: 01夜B1 | N8: 01夜B2 | O8: r' | P8: P | Q8: r' | R8: 01早 | S8: 01早 | T8: 01午 | U8: R | V8: r' | W8: 01午 | X8: 01午 | Y8: L | Z8: L | AA8: R | AB8: 01早 | AC8: 01早 | AD8: 01早 | AE8: 01早 | AF8: 01早 | AG8: r' | AH8: 01早 | AI8: 01早 | AJ8: 01夜 | AK8: 01夜 | AL8: R | AM8: R | AN8: r' | AO8: 01早
B9: T02363 | C9: 林孟錡 | D9: 01夜B1 | E9: 01夜B2 | F9: r' | G9: R | H9: 01夜B1 | I9: 01夜B2 | J9: 01夜B1 | K9: 01夜B2 | L9: r' | M9: R | N9: 01夜B1 | O9: 01夜B2 | P9: 01夜B1 | Q9: 01夜B2 | R9: 01夜 | S9: r' | T9: R | U9: 01夜 | V9: 01夜 | W9: 01夜 | X9: 01夜 | Y9: r' | Z9: r' | AA9: 01夜 | AB9: 01夜 | AC9: 01夜 | AD9: R | AE9: r' | AF9: 01夜 | AG9: 01夜 | AH9: 01夜 | AI9: 01夜 | AJ9: R | AK9: P | AL9: 01夜 | AM9: 01夜 | AN9: 01夜 | AO9: 01夜
B10: T02504 | C10: 潘元浩 | D10: 01午m | E10: 01午M | F10: 01夜B1 | G10: 01夜B2 | H10: R | I10: r' | J10: r' | K10: 01中A | L10: 01午M | M10: 01午m | N10: 01午M | O10: R | P10: 01午m | Q10: 01午M | R10: 01午 | S10: 01午 | T10: R | U10: r' | V10: L | W10: L | X10: L | Y10: L | Z10: P | AA10: R | AB10: 01午 | AC10: 01夜 | AD10: 01夜 | AE10: 01夜 | AF10: 01夜 | AG10: 01夜 | AH10: R | AI10: r' | AJ10: r' | AK10: 01午 | AL10: 01午 | AM10: 01午 | AN10: 01午 | AO10: 01午
B11: T02505 | C11: 李慧盺 | D11: 01午M | E11: 01午m | F11: 01午M | G11: r' | H11: R | I11: 01中A | J11: 01午M | K11: 01午m | L11: r' | M11: 01午M | N11: 01午m | O11: 01午M | P11: 01午B1 | Q11: R | R11: 01早 | S11: 01午 | T11: R | U11: r' | V11: L | W11: L | X11: L | Y11: L | Z11: P | AA11: R | AB11: 01午 | AC11: 01午 | AD11: 01夜 | AE11: 01夜 | AF11: R | AG11: r' | AH11: 01午 | AI11: 01午 | AJ11: 01午 | AK11: r' | AL11: 01午 | AM11: 01夜 | AN11: 01夜 | AO11: 01夜
B12: T00557 | C12: 陳志明 | D12: 01早B1 | E12: 01早B2 | F12: 01早B1 | G12: R | H12: r' | I12: r' | J12: 01中A | K12: 01午B2 | L12: 01午B1 | M12: P | N12: R | O12: 01早B2 | P12: 01早B1 | Q12: 01早B2 | R12: 01早 | S12: R | T12: 01早 | U12: 01早 | V12: 01早 | W12: L | X12: 01午 | Y12: 01午 | Z12: r' | AA12: 01午 | AB12: 01午 | AC12: 01午 | AD12: 01午 | AE12: R | AF12: R | AG12: 01午 | AH12: 01午 | AI12: r' | AJ12: 01早 | AK12: 01早 | AL12: 01早 | AM12: 01早 | AN12: r' | AO12: L
B13: T00929 | C13: 簡婉蓁 | D13: P | E13: R | F13: r' | G13: 01早B1 | H13: 01早B2 | I13: 01早B1 | J13: 01早B2 | K13: R | L13: 01早B1 | M13: 01早B2 | N13: 01早B1 | O13: 01午B2 | P13: r' | Q13: 01早B1 | R13: 01早 | S13: 01早 | T13: r' | U13: 01早 | V13: 01早 | W13: 01早 | X13: R | Y13: 01早 | Z13: 01早 | AA13: 01早 | AB13: R | AC13: 01早 | AD13: 01早 | AE13: r' | AF13: R | AG13: 01早 | AH13: 01早 | AI13: 01早 | AJ13: r' | AK13: 01午 | AL13: 01午 | AM13: 01午 | AN13: 01午 | AO13: R
B14: T01459 | C14: 林禹丞 | D14: R | E14: L | F14: 01午B1 | G14: 01午B1 | H14: 01午B2 | I14: 01午B1 | J14: r' | K14: R | L14: P | M14: 01中A | N14: 01早B2 | O14: 01早B1 | P14: 01早B1 | Q14: r' | R14: r' | S14: R | T14: 01早 | U14: 01早 | V14: 01午 | W14: 01午 | X14: 01午 | Y14: R | Z14: L | AA14: 01早 | AB14: 01早 | AC14: r' | AD14: 01早 | AE14: 01早 | AF14: R | AG14: r' | AH14: 01早 | AI14: 01午 | AJ14: 01午 | AK14: 01午 | AL14: 01中A | AM14: R | AN14: r' | AO14: 01午
B15: T01600 | C15: 陳奎羽 | D15: 01早B2 | E15: 01早B1 | F15: 01早B2 | G15: R | H15: r' | I15: 01早B2 | J15: 01早B1 | K15: 01早B2 | L15: 01早B1 | M15: R | N15: r' | O15: 01早B1 | P15: 01早B2 | Q15: 01早B1 | R15: 01早 | S15: R | T15: 01早 | U15: 01早 | V15: 01早 | W15: r' | X15: 01午 | Y15: 01午 | Z15: 01午 | AA15: 01午 | AB15: 01午 | AC15: r' | AD15: R | AE15: L | AF15: 01早 | AG15: 01早 | AH15: 01早 | AI15: 01早 | AJ15: R | AK15: 01早 | AL15: 01早 | AM15: R | AN15: P | AO15: r'
... B21: T02613 | C21: 張雅荃 | D21: P | E21: 01早B1 | F21: 01午B1 | G21: 01午B2 | H21: 01午B1 | I21: R | J21: 01午B1 | K21: r' | L21: r' | M21: 01午B2 | N21: 01午B1 | O21: r' | P21: R | Q21: 01午B1 | R21: 01午 | S21: 01午 | T21: 01午 | U21: r' | V21: 01午 | W21: 01午 | X21: R | Y21: P | Z21: 01午 | AA21: 01午 | AB21: R | AC21: 01午 | AD21: 01午 | AE21: 01午 | AF21: 01午 | AG21: R | AH21: r' | AI21: 01午 | AJ21: 01午 | AK21: r' | AL21: 01午 | AM21: 01午 | AN21: 01中A | AO21: R

Sheet 北段 (人資版)
B1: 員編 ID No. | C1: 日期 星期 姓名 | D1: =DATE(工作表1!C1,工作表1!H1,1) -> 45870 | E1: =D1+1 -> 45871 | F1: =E1+1 -> 45872 | G1: =F1+1 -> 45873 | H1: =G1+1 -> 45874 | I1: =H1+1 -> 45875 | J1: =I1+1 -> 45876 | K1: =J1+1 -> 45877 | L1: =K1+1 -> 45878 | ... AL1: =AK1+1 -> 45904
D2: =IFERROR(IF(WEEKDAY(D1,2)=7,"日",WEEKDAY(D1,2)),"") -> 5 | E2: =IFERROR(IF(WEEKDAY(E1,2)=7,"日",WEEKDAY(E1,2)),"") -> 6 | F2: =IFERROR(IF(WEEKDAY(F1,2)=7,"日",WEEKDAY(F1,2)),"") -> 日 | G2: =IFERROR(IF(WEEKDAY(G1,2)=7,"日",WEEKDAY(G1,2)),"") -> 1 | H2: =IFERROR(IF(WEEKDAY(H1,2)=7,"日",WEEKDAY(H1,2)),"") -> 2 | I2: =IFERROR(IF(WEEKDAY(I1,2)=7,"日",WEEKDAY(I1,2)),"") -> 3 | J2: =IFERROR(IF(WEEKDAY(J1,2)=7,"日",WEEKDAY(J1,2)),"") -> 4 | K2: =IFERROR(IF(WEEKDAY(K1,2)=7,"日",WEEKDAY(K1,2)),"") -> 5 | ... AL2: =IFERROR(IF(WEEKDAY(AL1,2)=7,"日",WEEKDAY(AL1,2)),"") -> 4
A3: 北 段 辦 | B3: =LEFT(北段!#REF!,6) -> #REF! | C3: =VLOOKUP(B3,北段!B:C,2,FALSE) -> #REF! | D3: =LEFT(北段!#REF!,4) -> #REF! | E3: =LEFT(北段!#REF!,4) -> #REF! | F3: =LEFT(北段!#REF!,4) -> #REF! | G3: =LEFT(北段!#REF!,4) -> #REF! | H3: =LEFT(北段!#REF!,4) -> #REF! | I3: =LEFT(北段!#REF!,4) -> #REF! | J3: =LEFT(北段!#REF!,4) -> #REF! | K3: =LEFT(北段!#REF!,4) -> #REF! | ... AL3: =LEFT(北段!#REF!,4) -> #REF!
B4: =LEFT(北段!#REF!,6) -> #REF! | C4: =VLOOKUP(B4,北段!B:C,2,FALSE) -> #REF! | D4: =LEFT(北段!#REF!,4) -> #REF! | E4: =LEFT(北段!#REF!,4) -> #REF! | F4: =LEFT(北段!#REF!,4) -> #REF! | G4: =LEFT(北段!#REF!,4) -> #REF! | H4: =LEFT(北段!#REF!,4) -> #REF! | I4: =LEFT(北段!#REF!,4) -> #REF! | J4: =LEFT(北段!#REF!,4) -> #REF! | K4: =LEFT(北段!#REF!,4) -> #REF! | ... AL4: =LEFT(北段!#REF!,4) -> #REF!
B5: =LEFT(北段!#REF!,6) -> #REF! | C5: =VLOOKUP(B5,北段!B:C,2,FALSE) -> #REF! | D5: =LEFT(北段!#REF!,4) -> #REF! | E5: =LEFT(北段!#REF!,4) -> #REF! | F5: =LEFT(北段!#REF!,4) -> #REF! | G5: =LEFT(北段!#REF!,4) -> #REF! | H5: =LEFT(北段!#REF!,4) -> #REF! | I5: =LEFT(北段!#REF!,4) -> #REF! | J5: =LEFT(北段!#REF!,4) -> #REF! | K5: =LEFT(北段!#REF!,4) -> #REF! | ... AL5: =LEFT(北段!#REF!,4) -> #REF!
B6: =LEFT(北段!#REF!,6) -> #REF! | C6: =VLOOKUP(B6,北段!B:C,2,FALSE) -> #REF! | D6: =LEFT(北段!#REF!,4) -> #REF! | E6: =LEFT(北段!#REF!,4) -> #REF! | F6: =LEFT(北段!#REF!,4) -> #REF! | G6: =LEFT(北段!#REF!,4) -> #REF! | H6: =LEFT(北段!#REF!,4) -> #REF! | I6: =LEFT(北段!#REF!,4) -> #REF! | J6: =LEFT(北段!#REF!,4) -> #REF! | K6: =LEFT(北段!#REF!,4) -> #REF! | ... Z6: =LEFT(北段!#REF!,4) -> #REF! | AA6: =LEFT(北段!#REF!,5) -> #REF! | AB6: =LEFT(北段!#REF!,4) -> #REF! | AC6: =LEFT(北段!#REF!,4) -> #REF! | AD6: =LEFT(北段!#REF!,4) -> #REF! | AE6: =LEFT(北段!#REF!,4) -> #REF! | AF6: =LEFT(北段!#REF!,4) -> #REF! | AG6: =LEFT(北段!#REF!,4) -> #REF! | AH6: =LEFT(北段!#REF!,4) -> #REF! | AI6: =LEFT(北段!#REF!,4) -> #REF! | ... AL6: =LEFT(北段!#REF!,4) -> #REF!
B7: =LEFT(北段!#REF!,6) -> #REF! | C7: =VLOOKUP(B7,北段!B:C,2,FALSE) -> #REF! | D7: =LEFT(北段!#REF!,4) -> #REF! | E7: =LEFT(北段!#REF!,4) -> #REF! | F7: =LEFT(北段!#REF!,4) -> #REF! | G7: =LEFT(北段!#REF!,4) -> #REF! | H7: =LEFT(北段!#REF!,4) -> #REF! | I7: =LEFT(北段!#REF!,4) -> #REF! | J7: =LEFT(北段!#REF!,4) -> #REF! | K7: =LEFT(北段!#REF!,4) -> #REF! | ... AL7: =LEFT(北段!#REF!,4) -> #REF!
B8: =LEFT(北段!#REF!,6) -> #REF! | C8: =VLOOKUP(B8,北段!B:C,2,FALSE) -> #REF! | D8: =LEFT(北段!#REF!,4) -> #REF! | E8: =LEFT(北段!#REF!,4) -> #REF! | F8: =LEFT(北段!#REF!,4) -> #REF! | G8: =LEFT(北段!#REF!,4) -> #REF! | H8: =LEFT(北段!#REF!,4) -> #REF! | I8: =LEFT(北段!#REF!,4) -> #REF! | J8: =LEFT(北段!#REF!,4) -> #REF! | K8: =LEFT(北段!#REF!,4) -> #REF! | ... AL8: =LEFT(北段!#REF!,4) -> #REF!
B9: =LEFT(北段!#REF!,6) -> #REF! | C9: =VLOOKUP(B9,北段!B:C,2,FALSE) -> #REF! | D9: =LEFT(北段!#REF!,4) -> #REF! | E9: =LEFT(北段!#REF!,4) -> #REF! | F9: =LEFT(北段!#REF!,4) -> #REF! | G9: =LEFT(北段!#REF!,4) -> #REF! | H9: =LEFT(北段!#REF!,4) -> #REF! | I9: =LEFT(北段!#REF!,4) -> #REF! | J9: =LEFT(北段!#REF!,4) -> #REF! | K9: =LEFT(北段!#REF!,4) -> #REF! | ... AL9: =LEFT(北段!#REF!,4) -> #REF!
B10: =LEFT(北段!#REF!,6) -> #REF! | C10: =VLOOKUP(B10,北段!B:C,2,FALSE) -> #REF! | D10: =LEFT(北段!#REF!,4) -> #REF! | E10: =LEFT(北段!#REF!,4) -> #REF! | F10: =LEFT(北段!#REF!,4) -> #REF! | G10: =LEFT(北段!#REF!,4) -> #REF! | H10: =LEFT(北段!#REF!,4) -> #REF! | I10: =LEFT(北段!#REF!,4) -> #REF! | J10: =LEFT(北段!#REF!,4) -> #REF! | K10: =LEFT(北段!#REF!,4) -> #REF! | ... AL10: =LEFT(北段!#REF!,4) -> #REF!
B11: =LEFT(北段!#REF!,6) -> #REF! | C11: =VLOOKUP(B11,北段!B:C,2,FALSE) -> #REF! | D11: =LEFT(北段!#REF!,4) -> #REF! | E11: =LEFT(北段!#REF!,4) -> #REF! | F11: =LEFT(北段!#REF!,4) -> #REF! | G11: =LEFT(北段!#REF!,4) -> #REF! | H11: =LEFT(北段!#REF!,4) -> #REF! | I11: =LEFT(北段!#REF!,4) -> #REF! | J11: =LEFT(北段!#REF!,4) -> #REF! | K11: =LEFT(北段!#REF!,4) -> #REF! | ... AL11: =LEFT(北段!#REF!,4) -> #REF!
B12: =LEFT(北段!#REF!,6) -> #REF! | C12: =VLOOKUP(B12,北段!B:C,2,FALSE) -> #REF! | D12: =LEFT(北段!#REF!,4) -> #REF! | E12: =LEFT(北段!#REF!,4) -> #REF! | F12: =LEFT(北段!#REF!,4) -> #REF! | G12: =LEFT(北段!#REF!,4) -> #REF! | H12: =LEFT(北段!#REF!,4) -> #REF! | I12: =LEFT(北段!#REF!,4) -> #REF! | J12: =LEFT(北段!#REF!,4) -> #REF! | K12: =LEFT(北段!#REF!,4) -> #REF! | ... AL12: =LEFT(北段!#REF!,4) -> #REF!
A13: A1 | B13: =LEFT(北段!B3,6) -> T00509 | C13: =VLOOKUP(B13,北段!B:C,2,FALSE) -> 郭秋儀 | D13: =LEFT(北段!Q3,4) -> r' | E13: =LEFT(北段!R3,4) -> 01夜 | F13: =LEFT(北段!S3,4) -> 01夜 | G13: =LEFT(北段!T3,4) -> 01夜 | H13: =LEFT(北段!U3,4) -> r' | I13: =LEFT(北段!Q3,4) -> r' | J13: =LEFT(北段!R3,4) -> 01夜 | K13: =LEFT(北段!S3,4) -> 01夜 | L13: =LEFT(北段!T3,4) -> 01夜 | M13: =LEFT(北段!U3,4) -> r' | N13: =LEFT(北段!V3,4) -> R | O13: =LEFT(北段!W3,4) -> 01早 | P13: =LEFT(北段!X3,4) -> 01早 | ... AG13: =LEFT(北段!AO3,4) -> R | AH13: =LEFT(北段!#REF!,4) -> #REF! | AI13: =LEFT(北段!#REF!,4) -> #REF! | AJ13: =LEFT(北段!#REF!,4) -> #REF! | AK13: =LEFT(北段!#REF!,4) -> #REF! | AL13: =LEFT(北段!#REF!,4) -> #REF!
B14: =LEFT(北段!B4,6) -> T01028 | C14: =VLOOKUP(B14,北段!B:C,2,FALSE) -> 林金緗 | D14: =LEFT(北段!Q4,4) -> 01夜B | E14: =LEFT(北段!R4,4) -> R | F14: =LEFT(北段!S4,4) -> r' | G14: =LEFT(北段!T4,4) -> L | H14: =LEFT(北段!U4,4) -> 01午 | I14: =LEFT(北段!Q4,4) -> 01夜B | J14: =LEFT(北段!R4,4) -> R | K14: =LEFT(北段!S4,4) -> r' | L14: =LEFT(北段!T4,4) -> L | M14: =LEFT(北段!U4,4) -> 01午 | N14: =LEFT(北段!V4,4) -> 01午 | O14: =LEFT(北段!W4,4) -> 01夜 | P14: =LEFT(北段!X4,4) -> 01夜 | ... V14: =LEFT(北段!AD4,4) -> 01午 | W14: =LEFT(北段!AE4,6) -> 01午 | X14: =LEFT(北段!AF4,4) -> R | Y14: =LEFT(北段!AG4,4) -> 01午 | Z14: =LEFT(北段!AH4,4) -> 01午 | AA14: =LEFT(北段!AI4,4) -> r' | AB14: =LEFT(北段!AJ4,4) -> 01午 | AC14: =LEFT(北段!AK4,4) -> 01午 | AD14: =LEFT(北段!AL4,4) -> r' | AE14: =LEFT(北段!AM4,4) -> 01早 | ... AG14: =LEFT(北段!AO4,4) -> 01午 | AH14: =LEFT(北段!#REF!,4) -> #REF! | AI14: =LEFT(北段!#REF!,4) -> #REF! | AJ14: =LEFT(北段!#REF!,4) -> #REF! | AK14: =LEFT(北段!#REF!,4) -> #REF! | AL14: =LEFT(北段!#REF!,4) -> #REF!
B15: =LEFT(北段!B6,6) -> T01734 | C15: =VLOOKUP(B15,北段!B:C,2,FALSE) -> 黃冠銘 | D15: =LEFT(北段!#REF!,4) -> #REF! | E15: =LEFT(北段!#REF!,4) -> #REF! | F15: =LEFT(北段!#REF!,4) -> #REF! | G15: =LEFT(北段!#REF!,4) -> #REF! | H15: =LEFT(北段!#REF!,4) -> #REF! | I15: =LEFT(北段!#REF!,4) -> #REF! | J15: =LEFT(北段!#REF!,4) -> #REF! | K15: =LEFT(北段!#REF!,4) -> #REF! | ... AL15: =LEFT(北段!#REF!,4) -> #REF!
B16: =LEFT(北段!B7,6) -> T02287 | C16: =VLOOKUP(B16,北段!B:C,2,FALSE) -> 林江玉 | D16: =LEFT(北段!Q6,4) -> 01早m | E16: =LEFT(北段!R6,4) -> R | F16: =LEFT(北段!S6,4) -> 01夜 | G16: =LEFT(北段!T6,4) -> 01夜 | H16: =LEFT(北段!U6,4) -> 01夜 | I16: =LEFT(北段!Q6,4) -> 01早m | J16: =LEFT(北段!R6,4) -> R | K16: =LEFT(北段!S6,4) -> 01夜 | L16: =LEFT(北段!T6,4) -> 01夜 | M16: =LEFT(北段!U6,4) -> 01夜 | N16: =LEFT(北段!V6,4) -> 01夜 | O16: =LEFT(北段!W6,4) -> r' | P16: =LEFT(北段!X6,4) -> r' | ... AG16: =LEFT(北段!AO6,4) -> 01早 | AH16: =LEFT(北段!#REF!,4) -> #REF! | AI16: =LEFT(北段!#REF!,4) -> #REF! | AJ16: =LEFT(北段!#REF!,4) -> #REF! | AK16: =LEFT(北段!#REF!,4) -> #REF! | AL16: =LEFT(北段!#REF!,4) -> #REF!
B17: =LEFT(北段!B8,6) -> T02359 | C17: =VLOOKUP(B17,北段!B:C,2,FALSE) -> 陳佳婷 | D17: =LEFT(北段!Q7,4) -> 01早M | E17: =LEFT(北段!R7,4) -> R | F17: =LEFT(北段!S7,4) -> 01早 | G17: =LEFT(北段!T7,4) -> 01早 | H17: =LEFT(北段!U7,4) -> 01早 | I17: =LEFT(北段!Q7,4) -> 01早M | J17: =LEFT(北段!R7,4) -> R | K17: =LEFT(北段!S7,4) -> 01早 | L17: =LEFT(北段!T7,4) -> 01早 | M17: =LEFT(北段!U7,4) -> 01早 | N17: =LEFT(北段!V7,4) -> 01早 | O17: =LEFT(北段!W7,4) -> r' | P17: =LEFT(北段!X7,4) -> r' | ... AG17: =LEFT(北段!AO7,4) -> 01中A | AH17: =LEFT(北段!#REF!,4) -> #REF! | AI17: =LEFT(北段!#REF!,4) -> #REF! | AJ17: =LEFT(北段!#REF!,4) -> #REF! | AK17: =LEFT(北段!#REF!,4) -> #REF! | AL17: =LEFT(北段!#REF!,4) -> #REF!
B18: =LEFT(北段!B9,6) -> T02363 | C18: =VLOOKUP(B18,北段!B:C,2,FALSE) -> 林孟錡 | D18: =LEFT(北段!Q8,4) -> r' | E18: =LEFT(北段!R8,4) -> 01早 | F18: =LEFT(北段!S8,4) -> 01早 | G18: =LEFT(北段!T8,4) -> 01午 | H18: =LEFT(北段!U8,4) -> R | I18: =LEFT(北段!Q8,4) -> r' | J18: =LEFT(北段!R8,4) -> 01早 | K18: =LEFT(北段!S8,4) -> 01早 | L18: =LEFT(北段!T8,4) -> 01午 | M18: =LEFT(北段!U8,4) -> R | N18: =LEFT(北段!V8,4) -> r' | O18: =LEFT(北段!W8,4) -> 01午 | P18: =LEFT(北段!X8,4) -> 01午 | ... AG18: =LEFT(北段!AO8,4) -> 01早 | AH18: =LEFT(北段!#REF!,4) -> #REF! | AI18: =LEFT(北段!#REF!,4) -> #REF! | AJ18: =LEFT(北段!#REF!,4) -> #REF! | AK18: =LEFT(北段!#REF!,4) -> #REF! | AL18: =LEFT(北段!#REF!,4) -> #REF!
B19: =LEFT(北段!#REF!,6) -> #REF! | C19: =VLOOKUP(B19,北段!B:C,2,FALSE) -> #REF! | D19: =LEFT(北段!Q9,4) -> 01夜B | E19: =LEFT(北段!R9,4) -> 01夜 | F19: =LEFT(北段!S9,4) -> r' | G19: =LEFT(北段!T9,4) -> R | H19: =LEFT(北段!U9,4) -> 01夜 | I19: =LEFT(北段!Q9,4) -> 01夜B | J19: =LEFT(北段!R9,4) -> 01夜 | K19: =LEFT(北段!S9,4) -> r' | L19: =LEFT(北段!T9,4) -> R | M19: =LEFT(北段!U9,4) -> 01夜 | N19: =LEFT(北段!V9,4) -> 01夜 | O19: =LEFT(北段!W9,4) -> 01夜 | P19: =LEFT(北段!X9,4) -> 01夜 | ... AG19: =LEFT(北段!AO9,4) -> 01夜 | AH19: =LEFT(北段!#REF!,4) -> #REF! | AI19: =LEFT(北段!#REF!,4) -> #REF! | AJ19: =LEFT(北段!#REF!,4) -> #REF! | AK19: =LEFT(北段!#REF!,4) -> #REF! | AL19: =LEFT(北段!#REF!,4) -> #REF!
B20: =LEFT(北段!B10,6) -> T02504 | C20: =VLOOKUP(B20,北段!B:C,2,FALSE) -> 潘元浩 | D20: =LEFT(北段!#REF!,4) -> #REF! | E20: =LEFT(北段!#REF!,4) -> #REF! | F20: =LEFT(北段!#REF!,4) -> #REF! | G20: =LEFT(北段!#REF!,4) -> #REF! | H20: =LEFT(北段!#REF!,4) -> #REF! | I20: =LEFT(北段!#REF!,4) -> #REF! | J20: =LEFT(北段!#REF!,4) -> #REF! | K20: =LEFT(北段!#REF!,4) -> #REF! | ... AL20: =LEFT(北段!#REF!,4) -> #REF!
B21: =LEFT(北段!B11,6) -> T02505 | C21: =VLOOKUP(B21,北段!B:C,2,FALSE) -> 李慧盺
B22: =LEFT(北段!B17,6) -> T02222 | C22: =VLOOKUP(B22,北段!B:C,2,FALSE) -> 𡍼文妤 | D22: =LEFT(北段!Q10,4) -> 01午M | E22: =LEFT(北段!R10,4) -> 01午 | F22: =LEFT(北段!S10,4) -> 01午 | G22: =LEFT(北段!T10,4) -> R | H22: =LEFT(北段!U10,4) -> r' | I22: =LEFT(北段!Q11,4) -> R | J22: =LEFT(北段!R11,4) -> 01早 | K22: =LEFT(北段!S11,4) -> 01午 | L22: =LEFT(北段!T11,4) -> R | M22: =LEFT(北段!U11,4) -> r' | N22: =LEFT(北段!V11,4) -> L | O22: =LEFT(北段!W11,4) -> L | P22: =LEFT(北段!X11,4) -> L | ... AG22: =LEFT(北段!AO11,4) -> 01夜 | AH22: =LEFT(北段!#REF!,4) -> #REF! | AI22: =LEFT(北段!#REF!,4) -> #REF! | AJ22: =LEFT(北段!#REF!,4) -> #REF! | AK22: =LEFT(北段!#REF!,4) -> #REF! | AL22: =LEFT(北段!#REF!,4) -> #REF!
B23: =LEFT(北段!B18,6) -> T02233 | C23: =VLOOKUP(B23,北段!B:C,2,FALSE) -> 簡悅如 | D23: =LEFT(北段!Q11,4) -> R | E23: =LEFT(北段!R11,4) -> 01早 | F23: =LEFT(北段!S11,4) -> 01午 | G23: =LEFT(北段!T11,4) -> R | H23: =LEFT(北段!U11,4) -> r' | I23: =LEFT(北段!Q17,4) -> R | J23: =LEFT(北段!R17,4) -> 01午 | K23: =LEFT(北段!S17,4) -> 01午 | L23: =LEFT(北段!T17,4) -> 01午 | M23: =LEFT(北段!U17,4) -> 01午 | N23: =LEFT(北段!V17,4) -> R | O23: =LEFT(北段!W17,4) -> 01早 | P23: =LEFT(北段!X17,4) -> 01早 | ... AG23: =LEFT(北段!AO17,4) -> 01早 | AH23: =LEFT(北段!#REF!,4) -> #REF! | AI23: =LEFT(北段!#REF!,4) -> #REF! | AJ23: =LEFT(北段!#REF!,4) -> #REF! | AK23: =LEFT(北段!#REF!,4) -> #REF! | AL23: =LEFT(北段!#REF!,4) -> #REF!
B24: =LEFT(北段!B19,6) -> T02498 | C24: =VLOOKUP(B24,北段!B:C,2,FALSE) -> 張芯瑜 | D24: =LEFT(北段!Q18,4) -> R | E24: =LEFT(北段!R18,4) -> R | F24: =LEFT(北段!S18,4) -> 01早 | G24: =LEFT(北段!T18,4) -> 01午 | H24: =LEFT(北段!U18,4) -> 01午 | I24: =LEFT(北段!Q18,4) -> R | J24: =LEFT(北段!R18,4) -> R | K24: =LEFT(北段!S18,4) -> 01早 | L24: =LEFT(北段!T18,4) -> 01午 | M24: =LEFT(北段!U18,4) -> 01午 | N24: =LEFT(北段!V18,4) -> r' | O24: =LEFT(北段!W18,4) -> 01早 | P24: =LEFT(北段!X18,4) -> 01早 | ... AG24: =LEFT(北段!AO18,4) -> 01早 | AH24: =LEFT(北段!#REF!,4) -> #REF! | AI24: =LEFT(北段!#REF!,4) -> #REF! | AJ24: =LEFT(北段!#REF!,4) -> #REF! | AK24: =LEFT(北段!#REF!,4) -> #REF! | AL24: =LEFT(北段!#REF!,4) -> #REF!
B25: =LEFT(北段!B20,6) -> T02612 | C25: =VLOOKUP(B25,北段!B:C,2,FALSE) -> 蕭曉琦 | D25: =LEFT(北段!Q19,4) -> 01午B | E25: =LEFT(北段!R19,4) -> 01午 | F25: =LEFT(北段!S19,4) -> 01午 | G25: =LEFT(北段!T19,4) -> r' | H25: =LEFT(北段!U19,4) -> P | I25: =LEFT(北段!Q19,4) -> 01午B | J25: =LEFT(北段!R19,4) -> 01午 | K25: =LEFT(北段!S19,4) -> 01午 | L25: =LEFT(北段!T19,4) -> r' | M25: =LEFT(北段!U19,4) -> P | N25: =LEFT(北段!V19,4) -> 01午 | O25: =LEFT(北段!W19,4) -> 01午 | P25: =LEFT(北段!X19,4) -> R | ... AG25: =LEFT(北段!AO19,4) -> 01午 | AH25: =LEFT(北段!#REF!,4) -> #REF! | AI25: =LEFT(北段!#REF!,4) -> #REF! | AJ25: =LEFT(北段!#REF!,4) -> #REF! | AK25: =LEFT(北段!#REF!,4) -> #REF! | AL25: =LEFT(北段!#REF!,4) -> #REF!
B26: =LEFT(北段!B21,6) -> T02613 | C26: =VLOOKUP(B26,北段!B:C,2,FALSE) -> 張雅荃 | D26: =LEFT(北段!Q20,4) -> 01午B | E26: =LEFT(北段!R20,4) -> R | F26: =LEFT(北段!S20,4) -> 01早 | G26: =LEFT(北段!T20,4) -> 01早 | H26: =LEFT(北段!U20,4) -> P | I26: =LEFT(北段!Q20,4) -> 01午B | J26: =LEFT(北段!R20,4) -> R | K26: =LEFT(北段!S20,4) -> 01早 | L26: =LEFT(北段!T20,4) -> 01早 | M26: =LEFT(北段!U20,4) -> P | N26: =LEFT(北段!V20,4) -> 01早 | O26: =LEFT(北段!W20,4) -> 01早 | P26: =LEFT(北段!X20,4) -> 01早 | ... AG26: =LEFT(北段!AO20,4) -> 01早 | AH26: =LEFT(北段!#REF!,4) -> #REF! | AI26: =LEFT(北段!#REF!,4) -> #REF! | AJ26: =LEFT(北段!#REF!,4) -> #REF! | AK26: =LEFT(北段!#REF!,4) -> #REF! | AL26: =LEFT(北段!#REF!,4) -> #REF!
B27: =LEFT(北段!#REF!,6) -> #REF! | C27: =VLOOKUP(B27,北段!B:C,2,FALSE) -> #REF! | D27: =LEFT(北段!Q21,4) -> 01午B | E27: =LEFT(北段!R21,4) -> 01午 | F27: =LEFT(北段!S21,4) -> 01午 | G27: =LEFT(北段!T21,4) -> 01午 | H27: =LEFT(北段!U21,4) -> r' | I27: =LEFT(北段!Q21,4) -> 01午B | J27: =LEFT(北段!R21,4) -> 01午 | K27: =LEFT(北段!S21,4) -> 01午 | L27: =LEFT(北段!T21,4) -> 01午 | M27: =LEFT(北段!U21,4) -> r' | N27: =LEFT(北段!V21,4) -> 01午 | O27: =LEFT(北段!W21,4) -> 01午 | P27: =LEFT(北段!X21,4) -> R | ... AG27: =LEFT(北段!AO21,4) -> R | AH27: =LEFT(北段!#REF!,4) -> #REF! | AI27: =LEFT(北段!#REF!,4) -> #REF! | AJ27: =LEFT(北段!#REF!,4) -> #REF! | AK27: =LEFT(北段!#REF!,4) -> #REF! | AL27: =LEFT(北段!#REF!,4) -> #REF!
B28: =LEFT(北段!#REF!,6) -> #REF! | C28: =VLOOKUP(B28,北段!B:C,2,FALSE) -> #REF! | D28: =LEFT(北段!#REF!,4) -> #REF! | E28: =LEFT(北段!#REF!,4) -> #REF! | F28: =LEFT(北段!#REF!,4) -> #REF! | G28: =LEFT(北段!#REF!,4) -> #REF! | H28: =LEFT(北段!#REF!,4) -> #REF! | I28: =LEFT(北段!#REF!,4) -> #REF! | J28: =LEFT(北段!#REF!,4) -> #REF! | K28: =LEFT(北段!#REF!,4) -> #REF! | ... Z28: =LEFT(北段!#REF!,4) -> #REF! | AA28: =LEFT(北段!#REF!,5) -> #REF! | AB28: =LEFT(北段!#REF!,4) -> #REF! | AC28: =LEFT(北段!#REF!,4) -> #REF! | AD28: =LEFT(北段!#REF!,4) -> #REF! | AE28: =LEFT(北段!#REF!,4) -> #REF! | AF28: =LEFT(北段!#REF!,4) -> #REF! | AG28: =LEFT(北段!#REF!,4) -> #REF! | AH28: =LEFT(北段!#REF!,4) -> #REF! | AI28: =LEFT(北段!#REF!,4) -> #REF! | ... AL28: =LEFT(北段!#REF!,4) -> #REF!
B29: =LEFT(北段!#REF!,6) -> #REF! | C29: =VLOOKUP(B29,北段!B:C,2,FALSE) -> #REF! | D29: =LEFT(北段!#REF!,4) -> #REF! | E29: =LEFT(北段!#REF!,4) -> #REF! | F29: =LEFT(北段!#REF!,4) -> #REF! | G29: =LEFT(北段!#REF!,4) -> #REF! | H29: =LEFT(北段!#REF!,4) -> #REF! | I29: =LEFT(北段!#REF!,4) -> #REF! | J29: =LEFT(北段!#REF!,4) -> #REF! | K29: =LEFT(北段!#REF!,4) -> #REF! | ... AL29: =LEFT(北段!#REF!,4) -> #REF!
B30: =LEFT(北段!#REF!,6) -> #REF! | C30: =VLOOKUP(B30,北段!B:C,2,FALSE) -> #REF! | D30: =LEFT(北段!#REF!,4) -> #REF! | E30: =LEFT(北段!#REF!,4) -> #REF! | F30: =LEFT(北段!#REF!,4) -> #REF! | G30: =LEFT(北段!#REF!,4) -> #REF! | H30: =LEFT(北段!#REF!,4) -> #REF! | I30: =LEFT(北段!#REF!,4) -> #REF! | J30: =LEFT(北段!#REF!,4) -> #REF! | K30: =LEFT(北段!#REF!,4) -> #REF! | ... AL30: =LEFT(北段!#REF!,4) -> #REF!
A31: A2 | B31: =LEFT(北段!#REF!,6) -> #REF! | C31: =VLOOKUP(B31,北段!B:C,2,FALSE) -> #REF! | D31: =LEFT(北段!#REF!,4) -> #REF! | E31: =LEFT(北段!#REF!,4) -> #REF! | F31: =LEFT(北段!#REF!,4) -> #REF! | G31: =LEFT(北段!#REF!,4) -> #REF! | H31: =LEFT(北段!#REF!,4) -> #REF! | I31: =LEFT(北段!#REF!,4) -> #REF! | J31: =LEFT(北段!#REF!,4) -> #REF! | K31: =LEFT(北段!#REF!,4) -> #REF! | ... AL31: =LEFT(北段!#REF!,4) -> #REF!
B32: =LEFT(北段!#REF!,6) -> #REF! | C32: =VLOOKUP(B32,北段!B:C,2,FALSE) -> #REF! | D32: =LEFT(北段!#REF!,4) -> #REF! | E32: =LEFT(北段!#REF!,4) -> #REF! | F32: =LEFT(北段!#REF!,4) -> #REF! | G32: =LEFT(北段!#REF!,4) -> #REF! | H32: =LEFT(北段!#REF!,4) -> #REF! | I32: =LEFT(北段!#REF!,4) -> #REF! | J32: =LEFT(北段!#REF!,4) -> #REF! | K32: =LEFT(北段!#REF!,4) -> #REF! | ... V32: =LEFT(北段!#REF!,4) -> #REF! | W32: =LEFT(北段!#REF!,6) -> #REF! | X32: =LEFT(北段!#REF!,4) -> #REF! | Y32: =LEFT(北段!#REF!,4) -> #REF! | Z32: =LEFT(北段!#REF!,4) -> #REF! | AA32: =LEFT(北段!#REF!,4) -> #REF! | AB32: =LEFT(北段!#REF!,4) -> #REF! | AC32: =LEFT(北段!#REF!,4) -> #REF! | AD32: =LEFT(北段!#REF!,4) -> #REF! | AE32: =LEFT(北段!#REF!,4) -> #REF! | ... AL32: =LEFT(北段!#REF!,4) -> #REF!
B33: =LEFT(北段!#REF!,6) -> #REF! | C33: =VLOOKUP(B33,北段!B:C,2,FALSE) -> #REF! | D33: =LEFT(北段!#REF!,4) -> #REF! | E33: =LEFT(北段!#REF!,4) -> #REF! | F33: =LEFT(北段!#REF!,4) -> #REF! | G33: =LEFT(北段!#REF!,4) -> #REF! | H33: =LEFT(北段!#REF!,4) -> #REF! | I33: =LEFT(北段!#REF!,4) -> #REF! | J33: =LEFT(北段!#REF!,4) -> #REF! | K33: =LEFT(北段!#REF!,4) -> #REF! | ... Z33: =LEFT(北段!#REF!,4) -> #REF! | AA33: =LEFT(北段!#REF!,5) -> #REF! | AB33: =LEFT(北段!#REF!,4) -> #REF! | AC33: =LEFT(北段!#REF!,4) -> #REF! | AD33: =LEFT(北段!#REF!,4) -> #REF! | AE33: =LEFT(北段!#REF!,4) -> #REF! | AF33: =LEFT(北段!#REF!,4) -> #REF! | AG33: =LEFT(北段!#REF!,4) -> #REF! | AH33: =LEFT(北段!#REF!,4) -> #REF! | AI33: =LEFT(北段!#REF!,4) -> #REF! | ... AL33: =LEFT(北段!#REF!,4) -> #REF!
B34: =LEFT(北段!#REF!,6) -> #REF! | C34: =VLOOKUP(B34,北段!B:C,2,FALSE) -> #REF! | D34: =LEFT(北段!#REF!,4) -> #REF! | E34: =LEFT(北段!#REF!,4) -> #REF! | F34: =LEFT(北段!#REF!,4) -> #REF! | G34: =LEFT(北段!#REF!,4) -> #REF! | H34: =LEFT(北段!#REF!,4) -> #REF! | I34: =LEFT(北段!#REF!,4) -> #REF! | J34: =LEFT(北段!#REF!,4) -> #REF! | K34: =LEFT(北段!#REF!,4) -> #REF! | ... AL34: =LEFT(北段!#REF!,4) -> #REF!
B35: =LEFT(北段!#REF!,6) -> #REF! | C35: =VLOOKUP(B35,北段!B:C,2,FALSE) -> #REF!
B36: =LEFT(北段!#REF!,6) -> #REF! | C36: =VLOOKUP(B36,北段!B:C,2,FALSE) -> #REF! | D36: =LEFT(北段!#REF!,4) -> #REF! | E36: =LEFT(北段!#REF!,4) -> #REF! | F36: =LEFT(北段!#REF!,4) -> #REF! | G36: =LEFT(北段!#REF!,4) -> #REF! | H36: =LEFT(北段!#REF!,4) -> #REF! | I36: =LEFT(北段!#REF!,4) -> #REF! | J36: =LEFT(北段!#REF!,4) -> #REF! | K36: =LEFT(北段!#REF!,4) -> #REF! | ... AL36: =LEFT(北段!#REF!,4) -> #REF!
B37: =LEFT(北段!#REF!,6) -> #REF! | C37: =VLOOKUP(B37,北段!B:C,2,FALSE) -> #REF! | D37: =LEFT(北段!#REF!,4) -> #REF! | E37: =LEFT(北段!#REF!,4) -> #REF! | F37: =LEFT(北段!#REF!,4) -> #REF! | G37: =LEFT(北段!#REF!,4) -> #REF! | H37: =LEFT(北段!#REF!,4) -> #REF! | I37: =LEFT(北段!#REF!,4) -> #REF! | J37: =LEFT(北段!#REF!,4) -> #REF! | K37: =LEFT(北段!#REF!,4) -> #REF! | ... AL37: =LEFT(北段!#REF!,4) -> #REF!
B38: =LEFT(北段!#REF!,6) -> #REF! | C38: =VLOOKUP(B38,北段!B:C,2,FALSE) -> #REF! | D38: =LEFT(北段!#REF!,4) -> #REF! | E38: =LEFT(北段!#REF!,4) -> #REF! | F38: =LEFT(北段!#REF!,4) -> #REF! | G38: =LEFT(北段!#REF!,4) -> #REF! | H38: =LEFT(北段!#REF!,4) -> #REF! | I38: =LEFT(北段!#REF!,4) -> #REF! | J38: =LEFT(北段!#REF!,4) -> #REF! | K38: =LEFT(北段!#REF!,4) -> #REF! | ... AL38: =LEFT(北段!#REF!,4) -> #REF!
B39: =LEFT(北段!#REF!,6) -> #REF! | C39: =VLOOKUP(B39,北段!B:C,2,FALSE) -> #REF! | D39: =LEFT(北段!#REF!,4) -> #REF! | E39: =LEFT(北段!#REF!,4) -> #REF! | F39: =LEFT(北段!#REF!,4) -> #REF! | G39: =LEFT(北段!#REF!,4) -> #REF! | H39: =LEFT(北段!#REF!,4) -> #REF! | I39: =LEFT(北段!#REF!,4) -> #REF! | J39: =LEFT(北段!#REF!,4) -> #REF! | K39: =LEFT(北段!#REF!,4) -> #REF! | ... AL39: =LEFT(北段!#REF!,4) -> #REF!
B40: =LEFT(北段!#REF!,6) -> #REF! | C40: =VLOOKUP(B40,北段!B:C,2,FALSE) -> #REF! | D40: =LEFT(北段!#REF!,4) -> #REF! | E40: =LEFT(北段!#REF!,4) -> #REF! | F40: =LEFT(北段!#REF!,4) -> #REF! | G40: =LEFT(北段!#REF!,4) -> #REF! | H40: =LEFT(北段!#REF!,4) -> #REF! | I40: =LEFT(北段!#REF!,4) -> #REF! | J40: =LEFT(北段!#REF!,4) -> #REF! | K40: =LEFT(北段!#REF!,4) -> #REF! | ... AL40: =LEFT(北段!#REF!,4) -> #REF!
...

Sheet 北段(八周檢核代碼
B1: 員編 ID No. | C1: 日期 星期 姓名 | D1: =DATE(工作表1!C1,工作表1!H1,1) -> 45870 | E1: =IFERROR(IF(MONTH(D1+1)=工作表1!$H$1,D1+1,""),"") -> 45871 | F1: =IFERROR(IF(MONTH(E1+1)=工作表1!$H$1,E1+1,""),"") -> 45872 | G1: =IFERROR(IF(MONTH(F1+1)=工作表1!$H$1,F1+1,""),"") -> 45873 | H1: =IFERROR(IF(MONTH(G1+1)=工作表1!$H$1,G1+1,""),"") -> 45874 | I1: =IFERROR(IF(MONTH(H1+1)=工作表1!$H$1,H1+1,""),"") -> 45875 | J1: =IFERROR(IF(MONTH(I1+1)=工作表1!$H$1,I1+1,""),"") -> 45876 | K1: =IFERROR(IF(MONTH(J1+1)=工作表1!$H$1,J1+1,""),"") -> 45877 | L1: =IFERROR(IF(MONTH(K1+1)=工作表1!$H$1,K1+1,""),"") -> 45878 | ... AG1: =IFERROR(IF(MONTH(AF1+1)=工作表1!$H$1,AF1+1,""),"") -> 45899 | AH1: 45566 | AI1: 45567 | AJ1: 45568 | AK1: 45569 | AL1: 45570
D2: =IFERROR(IF(WEEKDAY(D1,2)=7,"日",WEEKDAY(D1,2)),"") -> 5 | E2: =IFERROR(IF(WEEKDAY(E1,2)=7,"日",WEEKDAY(E1,2)),"") -> 6 | F2: =IFERROR(IF(WEEKDAY(F1,2)=7,"日",WEEKDAY(F1,2)),"") -> 日 | G2: =IFERROR(IF(WEEKDAY(G1,2)=7,"日",WEEKDAY(G1,2)),"") -> 1 | H2: =IFERROR(IF(WEEKDAY(H1,2)=7,"日",WEEKDAY(H1,2)),"") -> 2 | I2: =IFERROR(IF(WEEKDAY(I1,2)=7,"日",WEEKDAY(I1,2)),"") -> 3 | J2: =IFERROR(IF(WEEKDAY(J1,2)=7,"日",WEEKDAY(J1,2)),"") -> 4 | K2: =IFERROR(IF(WEEKDAY(K1,2)=7,"日",WEEKDAY(K1,2)),"") -> 5 | ... AL2: =IFERROR(IF(WEEKDAY(AL1,2)=7,"日",WEEKDAY(AL1,2)),"") -> 6
A3: 北 段 辦 | B3: =北段!#REF! -> #REF! | C3: =VLOOKUP(B3,北段!B:C,2,FALSE) -> #REF! | D3: =VLOOKUP('北段 (人資版)'!D3,工作表1!$A$3:$B$74,2,FALSE) -> #REF! | E3: =VLOOKUP('北段 (人資版)'!E3,工作表1!$A$3:$B$74,2,FALSE) -> #REF! | F3: =VLOOKUP('北段 (人資版)'!F3,工作表1!$A$3:$B$74,2,FALSE) -> #REF! | G3: =VLOOKUP('北段 (人資版)'!G3,工作表1!$A$3:$B$74,2,FALSE) -> #REF! | H3: =VLOOKUP('北段 (人資版)'!H3,工作表1!$A$3:$B$74,2,FALSE) -> #REF! | I3: =VLOOKUP('北段 (人資版)'!I3,工作表1!$A$3:$B$74,2,FALSE) -> #REF! | J3: =VLOOKUP('北段 (人資版)'!J3,工作表1!$A$3:$B$74,2,FALSE) -> #REF! | K3: =VLOOKUP('北段 (人資版)'!K3,工作表1!$A$3:$B$74,2,FALSE) -> #REF! | ... AL3: =VLOOKUP('北段 (人資版)'!AL3,工作表1!$A$3:$B$74,2,FALSE) -> #REF!
B4: =北段!#REF! -> #REF! | C4: =VLOOKUP(B4,北段!B:C,2,FALSE) -> #REF! | D4: =VLOOKUP('北段 (人資版)'!D4,工作表1!$A$3:$B$74,2,FALSE) -> #REF! | E4: =VLOOKUP('北段 (人資版)'!E4,工作表1!$A$3:$B$74,2,FALSE) -> #REF! | F4: =VLOOKUP('北段 (人資版)'!F4,工作表1!$A$3:$B$74,2,FALSE) -> #REF! | G4: =VLOOKUP('北段 (人資版)'!G4,工作表1!$A$3:$B$74,2,FALSE) -> #REF! | H4: =VLOOKUP('北段 (人資版)'!H4,工作表1!$A$3:$B$74,2,FALSE) -> #REF! | I4: =VLOOKUP('北段 (人資版)'!I4,工作表1!$A$3:$B$74,2,FALSE) -> #REF! | J4: =VLOOKUP('北段 (人資版)'!J4,工作表1!$A$3:$B$74,2,FALSE) -> #REF! | K4: =VLOOKUP('北段 (人資版)'!K4,工作表1!$A$3:$B$74,2,FALSE) -> #REF! | ... AL4: =VLOOKUP('北段 (人資版)'!AL4,工作表1!$A$3:$B$74,2,FALSE) -> #REF!
B5: =北段!#REF! -> #REF! | C5: =VLOOKUP(B5,北段!B:C,2,FALSE) -> #REF! | D5: =VLOOKUP('北段 (人資版)'!D5,工作表1!$A$3:$B$74,2,FALSE) -> #REF! | E5: =VLOOKUP('北段 (人資版)'!E5,工作表1!$A$3:$B$74,2,FALSE) -> #REF! | F5: =VLOOKUP('北段 (人資版)'!F5,工作表1!$A$3:$B$74,2,FALSE) -> #REF! | G5: =VLOOKUP('北段 (人資版)'!G5,工作表1!$A$3:$B$74,2,FALSE) -> #REF! | H5: =VLOOKUP('北段 (人資版)'!H5,工作表1!$A$3:$B$74,2,FALSE) -> #REF! | I5: =VLOOKUP('北段 (人資版)'!I5,工作表1!$A$3:$B$74,2,FALSE) -> #REF! | J5: =VLOOKUP('北段 (人資版)'!J5,工作表1!$A$3:$B$74,2,FALSE) -> #REF! | K5: =VLOOKUP('北段 (人資版)'!K5,工作表1!$A$3:$B$74,2,FALSE) -> #REF! | ... AL5: =VLOOKUP('北段 (人資版)'!AL5,工作表1!$A$3:$B$74,2,FALSE) -> #REF!
B6: =北段!#REF! -> #REF! | C6: =VLOOKUP(B6,北段!B:C,2,FALSE) -> #REF! | D6: =VLOOKUP('北段 (人資版)'!D6,工作表1!$A$3:$B$74,2,FALSE) -> #REF! | E6: =VLOOKUP('北段 (人資版)'!E6,工作表1!$A$3:$B$74,2,FALSE) -> #REF! | F6: =VLOOKUP('北段 (人資版)'!F6,工作表1!$A$3:$B$74,2,FALSE) -> #REF! | G6: =VLOOKUP('北段 (人資版)'!G6,工作表1!$A$3:$B$74,2,FALSE) -> #REF! | H6: =VLOOKUP('北段 (人資版)'!H6,工作表1!$A$3:$B$74,2,FALSE) -> #REF! | I6: =VLOOKUP('北段 (人資版)'!I6,工作表1!$A$3:$B$74,2,FALSE) -> #REF! | J6: =VLOOKUP('北段 (人資版)'!J6,工作表1!$A$3:$B$74,2,FALSE) -> #REF! | K6: =VLOOKUP('北段 (人資版)'!K6,工作表1!$A$3:$B$74,2,FALSE) -> #REF! | ... AL6: =VLOOKUP('北段 (人資版)'!AL6,工作表1!$A$3:$B$74,2,FALSE) -> #REF!
B7: =北段!#REF! -> #REF! | C7: =VLOOKUP(B7,北段!B:C,2,FALSE) -> #REF! | D7: =VLOOKUP('北段 (人資版)'!D7,工作表1!$A$3:$B$74,2,FALSE) -> #REF! | E7: =VLOOKUP('北段 (人資版)'!E7,工作表1!$A$3:$B$74,2,FALSE) -> #REF! | F7: =VLOOKUP('北段 (人資版)'!F7,工作表1!$A$3:$B$74,2,FALSE) -> #REF! | G7: =VLOOKUP('北段 (人資版)'!G7,工作表1!$A$3:$B$74,2,FALSE) -> #REF! | H7: =VLOOKUP('北段 (人資版)'!H7,工作表1!$A$3:$B$74,2,FALSE) -> #REF! | I7: =VLOOKUP('北段 (人資版)'!I7,工作表1!$A$3:$B$74,2,FALSE) -> #REF! | J7: =VLOOKUP('北段 (人資版)'!J7,工作表1!$A$3:$B$74,2,FALSE) -> #REF! | K7: =VLOOKUP('北段 (人資版)'!K7,工作表1!$A$3:$B$74,2,FALSE) -> #REF! | ... AL7: =VLOOKUP('北段 (人資版)'!AL7,工作表1!$A$3:$B$74,2,FALSE) -> #REF!
B8: =北段!#REF! -> #REF! | C8: =VLOOKUP(B8,北段!B:C,2,FALSE) -> #REF! | D8: =VLOOKUP('北段 (人資版)'!D8,工作表1!$A$3:$B$74,2,FALSE) -> #REF! | E8: =VLOOKUP('北段 (人資版)'!E8,工作表1!$A$3:$B$74,2,FALSE) -> #REF! | F8: =VLOOKUP('北段 (人資版)'!F8,工作表1!$A$3:$B$74,2,FALSE) -> #REF! | G8: =VLOOKUP('北段 (人資版)'!G8,工作表1!$A$3:$B$74,2,FALSE) -> #REF! | H8: =VLOOKUP('北段 (人資版)'!H8,工作表1!$A$3:$B$74,2,FALSE) -> #REF! | I8: =VLOOKUP('北段 (人資版)'!I8,工作表1!$A$3:$B$74,2,FALSE) -> #REF! | J8: =VLOOKUP('北段 (人資版)'!J8,工作表1!$A$3:$B$74,2,FALSE) -> #REF! | K8: =VLOOKUP('北段 (人資版)'!K8,工作表1!$A$3:$B$74,2,FALSE) -> #REF! | ... AL8: =VLOOKUP('北段 (人資版)'!AL8,工作表1!$A$3:$B$74,2,FALSE) -> #REF!
B9: =北段!#REF! -> #REF! | C9: =VLOOKUP(B9,北段!B:C,2,FALSE) -> #REF! | D9: =VLOOKUP('北段 (人資版)'!D9,工作表1!$A$3:$B$74,2,FALSE) -> #REF! | E9: =VLOOKUP('北段 (人資版)'!E9,工作表1!$A$3:$B$74,2,FALSE) -> #REF! | F9: =VLOOKUP('北段 (人資版)'!F9,工作表1!$A$3:$B$74,2,FALSE) -> #REF! | G9: =VLOOKUP('北段 (人資版)'!G9,工作表1!$A$3:$B$74,2,FALSE) -> #REF! | H9: =VLOOKUP('北段 (人資版)'!H9,工作表1!$A$3:$B$74,2,FALSE) -> #REF! | I9: =VLOOKUP('北段 (人資版)'!I9,工作表1!$A$3:$B$74,2,FALSE) -> #REF! | J9: =VLOOKUP('北段 (人資版)'!J9,工作表1!$A$3:$B$74,2,FALSE) -> #REF! | K9: =VLOOKUP('北段 (人資版)'!K9,工作表1!$A$3:$B$74,2,FALSE) -> #REF! | ... AL9: =VLOOKUP('北段 (人資版)'!AL9,工作表1!$A$3:$B$74,2,FALSE) -> #REF!
B10: =北段!#REF! -> #REF! | C10: =VLOOKUP(B10,北段!B:C,2,FALSE) -> #REF! | D10: =VLOOKUP('北段 (人資版)'!D10,工作表1!$A$3:$B$74,2,FALSE) -> #REF! | E10: =VLOOKUP('北段 (人資版)'!E10,工作表1!$A$3:$B$74,2,FALSE) -> #REF! | F10: =VLOOKUP('北段 (人資版)'!F10,工作表1!$A$3:$B$74,2,FALSE) -> #REF! | G10: =VLOOKUP('北段 (人資版)'!G10,工作表1!$A$3:$B$74,2,FALSE) -> #REF! | H10: =VLOOKUP('北段 (人資版)'!H10,工作表1!$A$3:$B$74,2,FALSE) -> #REF! | I10: =VLOOKUP('北段 (人資版)'!I10,工作表1!$A$3:$B$74,2,FALSE) -> #REF! | J10: =VLOOKUP('北段 (人資版)'!J10,工作表1!$A$3:$B$74,2,FALSE) -> #REF! | K10: =VLOOKUP('北段 (人資版)'!K10,工作表1!$A$3:$B$74,2,FALSE) -> #REF! | ... AL10: =VLOOKUP('北段 (人資版)'!AL10,工作表1!$A$3:$B$74,2,FALSE) -> #REF!
B11: =北段!#REF! -> #REF! | C11: =VLOOKUP(B11,北段!B:C,2,FALSE) -> #REF! | D11: =VLOOKUP('北段 (人資版)'!D11,工作表1!$A$3:$B$74,2,FALSE) -> #REF! | E11: =VLOOKUP('北段 (人資版)'!E11,工作表1!$A$3:$B$74,2,FALSE) -> #REF! | F11: =VLOOKUP('北段 (人資版)'!F11,工作表1!$A$3:$B$74,2,FALSE) -> #REF! | G11: =VLOOKUP('北段 (人資版)'!G11,工作表1!$A$3:$B$74,2,FALSE) -> #REF! | H11: =VLOOKUP('北段 (人資版)'!H11,工作表1!$A$3:$B$74,2,FALSE) -> #REF! | I11: =VLOOKUP('北段 (人資版)'!I11,工作表1!$A$3:$B$74,2,FALSE) -> #REF! | J11: =VLOOKUP('北段 (人資版)'!J11,工作表1!$A$3:$B$74,2,FALSE) -> #REF! | K11: =VLOOKUP('北段 (人資版)'!K11,工作表1!$A$3:$B$74,2,FALSE) -> #REF! | ... AL11: =VLOOKUP('北段 (人資版)'!AL11,工作表1!$A$3:$B$74,2,FALSE) -> #REF!
B12: =北段!#REF! -> #REF! | C12: =VLOOKUP(B12,北段!B:C,2,FALSE) -> #REF! | D12: =VLOOKUP('北段 (人資版)'!D12,工作表1!$A$3:$B$74,2,FALSE) -> #REF! | E12: =VLOOKUP('北段 (人資版)'!E12,工作表1!$A$3:$B$74,2,FALSE) -> #REF! | F12: =VLOOKUP('北段 (人資版)'!F12,工作表1!$A$3:$B$74,2,FALSE) -> #REF! | G12: =VLOOKUP('北段 (人資版)'!G12,工作表1!$A$3:$B$74,2,FALSE) -> #REF! | H12: =VLOOKUP('北段 (人資版)'!H12,工作表1!$A$3:$B$74,2,FALSE) -> #REF! | I12: =VLOOKUP('北段 (人資版)'!I12,工作表1!$A$3:$B$74,2,FALSE) -> #REF! | J12: =VLOOKUP('北段 (人資版)'!J12,工作表1!$A$3:$B$74,2,FALSE) -> #REF! | K12: =VLOOKUP('北段 (人資版)'!K12,工作表1!$A$3:$B$74,2,FALSE) -> #REF! | ... AL12: =VLOOKUP('北段 (人資版)'!AL12,工作表1!$A$3:$B$74,2,FALSE) -> #REF!
A13: A1 | B13: =北段!B3 -> T00509 | C13: =VLOOKUP(B13,北段!B:C,2,FALSE) -> 郭秋儀 | D13: =VLOOKUP('北段 (人資版)'!D13,工作表1!$A$3:$B$74,2,FALSE) -> 92 | E13: =VLOOKUP('北段 (人資版)'!E13,工作表1!$A$3:$B$74,2,FALSE) -> 70 | F13: =VLOOKUP('北段 (人資版)'!F13,工作表1!$A$3:$B$74,2,FALSE) -> 70 | G13: =VLOOKUP('北段 (人資版)'!G13,工作表1!$A$3:$B$74,2,FALSE) -> 70 | H13: =VLOOKUP('北段 (人資版)'!H13,工作表1!$A$3:$B$74,2,FALSE) -> 92 | I13: =VLOOKUP('北段 (人資版)'!I13,工作表1!$A$3:$B$74,2,FALSE) -> 92 | J13: =VLOOKUP('北段 (人資版)'!J13,工作表1!$A$3:$B$74,2,FALSE) -> 70 | K13: =VLOOKUP('北段 (人資版)'!K13,工作表1!$A$3:$B$74,2,FALSE) -> 70 | ... AL13: =VLOOKUP('北段 (人資版)'!AL13,工作表1!$A$3:$B$74,2,FALSE) -> #REF!
B14: =北段!B4 -> T01028 | C14: =VLOOKUP(B14,北段!B:C,2,FALSE) -> 林金緗 | D14: =VLOOKUP('北段 (人資版)'!D14,工作表1!$A$3:$B$74,2,FALSE) -> #N/A | E14: =VLOOKUP('北段 (人資版)'!E14,工作表1!$A$3:$B$74,2,FALSE) -> 91 | F14: =VLOOKUP('北段 (人資版)'!F14,工作表1!$A$3:$B$74,2,FALSE) -> 92 | G14: =VLOOKUP('北段 (人資版)'!G14,工作表1!$A$3:$B$74,2,FALSE) -> 07 | H14: =VLOOKUP('北段 (人資版)'!H14,工作表1!$A$3:$B$74,2,FALSE) -> 66 | I14: =VLOOKUP('北段 (人資版)'!I14,工作表1!$A$3:$B$74,2,FALSE) -> #N/A | J14: =VLOOKUP('北段 (人資版)'!J14,工作表1!$A$3:$B$74,2,FALSE) -> 91 | K14: =VLOOKUP('北段 (人資版)'!K14,工作表1!$A$3:$B$74,2,FALSE) -> 92 | ... AL14: =VLOOKUP('北段 (人資版)'!AL14,工作表1!$A$3:$B$74,2,FALSE) -> #REF!
B15: =北段!#REF! -> #REF! | C15: =VLOOKUP(B15,北段!B:C,2,FALSE) -> #REF! | D15: =VLOOKUP('北段 (人資版)'!D15,工作表1!$A$3:$B$74,2,FALSE) -> #REF! | E15: =VLOOKUP('北段 (人資版)'!E15,工作表1!$A$3:$B$74,2,FALSE) -> #REF! | F15: =VLOOKUP('北段 (人資版)'!F15,工作表1!$A$3:$B$74,2,FALSE) -> #REF! | G15: =VLOOKUP('北段 (人資版)'!G15,工作表1!$A$3:$B$74,2,FALSE) -> #REF! | H15: =VLOOKUP('北段 (人資版)'!H15,工作表1!$A$3:$B$74,2,FALSE) -> #REF! | I15: =VLOOKUP('北段 (人資版)'!I15,工作表1!$A$3:$B$74,2,FALSE) -> #REF! | J15: =VLOOKUP('北段 (人資版)'!J15,工作表1!$A$3:$B$74,2,FALSE) -> #REF! | K15: =VLOOKUP('北段 (人資版)'!K15,工作表1!$A$3:$B$74,2,FALSE) -> #REF! | ... AL15: =VLOOKUP('北段 (人資版)'!AL15,工作表1!$A$3:$B$74,2,FALSE) -> #REF!
B16: =北段!B6 -> T01734 | C16: =VLOOKUP(B16,北段!B:C,2,FALSE) -> 黃冠銘 | D16: =VLOOKUP('北段 (人資版)'!D16,工作表1!$A$3:$B$74,2,FALSE) -> #N/A | E16: =VLOOKUP('北段 (人資版)'!E16,工作表1!$A$3:$B$74,2,FALSE) -> 91 | F16: =VLOOKUP('北段 (人資版)'!F16,工作表1!$A$3:$B$74,2,FALSE) -> 70 | G16: =VLOOKUP('北段 (人資版)'!G16,工作表1!$A$3:$B$74,2,FALSE) -> 70 | H16: =VLOOKUP('北段 (人資版)'!H16,工作表1!$A$3:$B$74,2,FALSE) -> 70 | I16: =VLOOKUP('北段 (人資版)'!I16,工作表1!$A$3:$B$74,2,FALSE) -> #N/A | J16: =VLOOKUP('北段 (人資版)'!J16,工作表1!$A$3:$B$74,2,FALSE) -> 91 | K16: =VLOOKUP('北段 (人資版)'!K16,工作表1!$A$3:$B$74,2,FALSE) -> 70 | ... AL16: =VLOOKUP('北段 (人資版)'!AL16,工作表1!$A$3:$B$74,2,FALSE) -> #REF!
B17: =北段!B7 -> T02287 | C17: =VLOOKUP(B17,北段!B:C,2,FALSE) -> 林江玉 | D17: =VLOOKUP('北段 (人資版)'!D17,工作表1!$A$3:$B$74,2,FALSE) -> #N/A | E17: =VLOOKUP('北段 (人資版)'!E17,工作表1!$A$3:$B$74,2,FALSE) -> 91 | F17: =VLOOKUP('北段 (人資版)'!F17,工作表1!$A$3:$B$74,2,FALSE) -> 38 | G17: =VLOOKUP('北段 (人資版)'!G17,工作表1!$A$3:$B$74,2,FALSE) -> 38 | H17: =VLOOKUP('北段 (人資版)'!H17,工作表1!$A$3:$B$74,2,FALSE) -> 38 | I17: =VLOOKUP('北段 (人資版)'!I17,工作表1!$A$3:$B$74,2,FALSE) -> #N/A | J17: =VLOOKUP('北段 (人資版)'!J17,工作表1!$A$3:$B$74,2,FALSE) -> 91 | K17: =VLOOKUP('北段 (人資版)'!K17,工作表1!$A$3:$B$74,2,FALSE) -> 38 | ... AL17: =VLOOKUP('北段 (人資版)'!AL17,工作表1!$A$3:$B$74,2,FALSE) -> #REF!
B18: =北段!B8 -> T02359 | C18: =VLOOKUP(B18,北段!B:C,2,FALSE) -> 陳佳婷 | D18: =VLOOKUP('北段 (人資版)'!D18,工作表1!$A$3:$B$74,2,FALSE) -> 92 | E18: =VLOOKUP('北段 (人資版)'!E18,工作表1!$A$3:$B$74,2,FALSE) -> 38 | F18: =VLOOKUP('北段 (人資版)'!F18,工作表1!$A$3:$B$74,2,FALSE) -> 38 | G18: =VLOOKUP('北段 (人資版)'!G18,工作表1!$A$3:$B$74,2,FALSE) -> 66 | H18: =VLOOKUP('北段 (人資版)'!H18,工作表1!$A$3:$B$74,2,FALSE) -> 91 | I18: =VLOOKUP('北段 (人資版)'!I18,工作表1!$A$3:$B$74,2,FALSE) -> 92 | J18: =VLOOKUP('北段 (人資版)'!J18,工作表1!$A$3:$B$74,2,FALSE) -> 38 | K18: =VLOOKUP('北段 (人資版)'!K18,工作表1!$A$3:$B$74,2,FALSE) -> 38 | ... AL18: =VLOOKUP('北段 (人資版)'!AL18,工作表1!$A$3:$B$74,2,FALSE) -> #REF!
B19: =北段!B9 -> T02363 | C19: =VLOOKUP(B19,北段!B:C,2,FALSE) -> 林孟錡 | D19: =VLOOKUP('北段 (人資版)'!D19,工作表1!$A$3:$B$74,2,FALSE) -> #N/A | E19: =VLOOKUP('北段 (人資版)'!E19,工作表1!$A$3:$B$74,2,FALSE) -> 70 | F19: =VLOOKUP('北段 (人資版)'!F19,工作表1!$A$3:$B$74,2,FALSE) -> 92 | G19: =VLOOKUP('北段 (人資版)'!G19,工作表1!$A$3:$B$74,2,FALSE) -> 91 | H19: =VLOOKUP('北段 (人資版)'!H19,工作表1!$A$3:$B$74,2,FALSE) -> 70 | I19: =VLOOKUP('北段 (人資版)'!I19,工作表1!$A$3:$B$74,2,FALSE) -> #N/A | J19: =VLOOKUP('北段 (人資版)'!J19,工作表1!$A$3:$B$74,2,FALSE) -> 70 | K19: =VLOOKUP('北段 (人資版)'!K19,工作表1!$A$3:$B$74,2,FALSE) -> 92 | ... AL19: =VLOOKUP('北段 (人資版)'!AL19,工作表1!$A$3:$B$74,2,FALSE) -> #REF!
B20: =北段!#REF! -> #REF! | C20: =VLOOKUP(B20,北段!B:C,2,FALSE) -> #REF! | D20: =VLOOKUP('北段 (人資版)'!D20,工作表1!$A$3:$B$74,2,FALSE) -> #REF! | E20: =VLOOKUP('北段 (人資版)'!E20,工作表1!$A$3:$B$74,2,FALSE) -> #REF! | F20: =VLOOKUP('北段 (人資版)'!F20,工作表1!$A$3:$B$74,2,FALSE) -> #REF! | G20: =VLOOKUP('北段 (人資版)'!G20,工作表1!$A$3:$B$74,2,FALSE) -> #REF! | H20: =VLOOKUP('北段 (人資版)'!H20,工作表1!$A$3:$B$74,2,FALSE) -> #REF! | I20: =VLOOKUP('北段 (人資版)'!I20,工作表1!$A$3:$B$74,2,FALSE) -> #REF! | J20: =VLOOKUP('北段 (人資版)'!J20,工作表1!$A$3:$B$74,2,FALSE) -> #REF! | K20: =VLOOKUP('北段 (人資版)'!K20,工作表1!$A$3:$B$74,2,FALSE) -> #REF! | ... AL20: =VLOOKUP('北段 (人資版)'!AL20,工作表1!$A$3:$B$74,2,FALSE) -> #REF!
B21: =北段!B11 -> T02505 | C21: =VLOOKUP(B21,北段!B:C,2,FALSE) -> 李慧盺 | D21: =VLOOKUP('北段 (人資版)'!D22,工作表1!$A$3:$B$74,2,FALSE) -> #N/A | E21: =VLOOKUP('北段 (人資版)'!E22,工作表1!$A$3:$B$74,2,FALSE) -> 66 | F21: =VLOOKUP('北段 (人資版)'!F22,工作表1!$A$3:$B$74,2,FALSE) -> 66 | G21: =VLOOKUP('北段 (人資版)'!G22,工作表1!$A$3:$B$74,2,FALSE) -> 91 | H21: =VLOOKUP('北段 (人資版)'!H22,工作表1!$A$3:$B$74,2,FALSE) -> 92 | I21: =VLOOKUP('北段 (人資版)'!I22,工作表1!$A$3:$B$74,2,FALSE) -> 91 | J21: =VLOOKUP('北段 (人資版)'!J22,工作表1!$A$3:$B$74,2,FALSE) -> 38 | K21: =VLOOKUP('北段 (人資版)'!K22,工作表1!$A$3:$B$74,2,FALSE) -> 66 | ... AL21: =VLOOKUP('北段 (人資版)'!AL22,工作表1!$A$3:$B$74,2,FALSE) -> #REF!
B22: =北段!B17 -> T02222 | C22: =VLOOKUP(B22,北段!B:C,2,FALSE) -> 𡍼文妤 | D22: =VLOOKUP('北段 (人資版)'!D23,工作表1!$A$3:$B$74,2,FALSE) -> 91 | E22: =VLOOKUP('北段 (人資版)'!E23,工作表1!$A$3:$B$74,2,FALSE) -> 38 | F22: =VLOOKUP('北段 (人資版)'!F23,工作表1!$A$3:$B$74,2,FALSE) -> 66 | G22: =VLOOKUP('北段 (人資版)'!G23,工作表1!$A$3:$B$74,2,FALSE) -> 91 | H22: =VLOOKUP('北段 (人資版)'!H23,工作表1!$A$3:$B$74,2,FALSE) -> 92 | I22: =VLOOKUP('北段 (人資版)'!I23,工作表1!$A$3:$B$74,2,FALSE) -> 91 | J22: =VLOOKUP('北段 (人資版)'!J23,工作表1!$A$3:$B$74,2,FALSE) -> 66 | K22: =VLOOKUP('北段 (人資版)'!K23,工作表1!$A$3:$B$74,2,FALSE) -> 66 | ... AL22: =VLOOKUP('北段 (人資版)'!AL23,工作表1!$A$3:$B$74,2,FALSE) -> #REF!
B23: =北段!#REF! -> #REF! | C23: =VLOOKUP(B23,北段!B:C,2,FALSE) -> #REF! | D23: =VLOOKUP('北段 (人資版)'!#REF!,工作表1!$A$3:$B$74,2,FALSE) -> #REF! | E23: =VLOOKUP('北段 (人資版)'!#REF!,工作表1!$A$3:$B$74,2,FALSE) -> #REF! | F23: =VLOOKUP('北段 (人資版)'!#REF!,工作表1!$A$3:$B$74,2,FALSE) -> #REF! | G23: =VLOOKUP('北段 (人資版)'!#REF!,工作表1!$A$3:$B$74,2,FALSE) -> #REF! | H23: =VLOOKUP('北段 (人資版)'!#REF!,工作表1!$A$3:$B$74,2,FALSE) -> #REF! | I23: =VLOOKUP('北段 (人資版)'!#REF!,工作表1!$A$3:$B$74,2,FALSE) -> #REF! | J23: =VLOOKUP('北段 (人資版)'!#REF!,工作表1!$A$3:$B$74,2,FALSE) -> #REF! | K23: =VLOOKUP('北段 (人資版)'!#REF!,工作表1!$A$3:$B$74,2,FALSE) -> #REF! | ... AL23: =VLOOKUP('北段 (人資版)'!#REF!,工作表1!$A$3:$B$74,2,FALSE) -> #REF!
B24: =北段!B18 -> T02233 | C24: =VLOOKUP(B24,北段!B:C,2,FALSE) -> 簡悅如 | D24: =VLOOKUP('北段 (人資版)'!D24,工作表1!$A$3:$B$74,2,FALSE) -> 91 | E24: =VLOOKUP('北段 (人資版)'!E24,工作表1!$A$3:$B$74,2,FALSE) -> 91 | F24: =VLOOKUP('北段 (人資版)'!F24,工作表1!$A$3:$B$74,2,FALSE) -> 38 | G24: =VLOOKUP('北段 (人資版)'!G24,工作表1!$A$3:$B$74,2,FALSE) -> 66 | H24: =VLOOKUP('北段 (人資版)'!H24,工作表1!$A$3:$B$74,2,FALSE) -> 66 | I24: =VLOOKUP('北段 (人資版)'!I24,工作表1!$A$3:$B$74,2,FALSE) -> 91 | J24: =VLOOKUP('北段 (人資版)'!J24,工作表1!$A$3:$B$74,2,FALSE) -> 91 | K24: =VLOOKUP('北段 (人資版)'!K24,工作表1!$A$3:$B$74,2,FALSE) -> 38 | ... AL24: =VLOOKUP('北段 (人資版)'!AL24,工作表1!$A$3:$B$74,2,FALSE) -> #REF!
B25: =北段!B19 -> T02498 | C25: =VLOOKUP(B25,北段!B:C,2,FALSE) -> 張芯瑜 | D25: =VLOOKUP('北段 (人資版)'!D25,工作表1!$A$3:$B$74,2,FALSE) -> #N/A | E25: =VLOOKUP('北段 (人資版)'!E25,工作表1!$A$3:$B$74,2,FALSE) -> 66 | F25: =VLOOKUP('北段 (人資版)'!F25,工作表1!$A$3:$B$74,2,FALSE) -> 66 | G25: =VLOOKUP('北段 (人資版)'!G25,工作表1!$A$3:$B$74,2,FALSE) -> 92 | H25: =VLOOKUP('北段 (人資版)'!H25,工作表1!$A$3:$B$74,2,FALSE) -> 90 | I25: =VLOOKUP('北段 (人資版)'!I25,工作表1!$A$3:$B$74,2,FALSE) -> #N/A | J25: =VLOOKUP('北段 (人資版)'!J25,工作表1!$A$3:$B$74,2,FALSE) -> 66 | K25: =VLOOKUP('北段 (人資版)'!K25,工作表1!$A$3:$B$74,2,FALSE) -> 66 | ... AL25: =VLOOKUP('北段 (人資版)'!AL25,工作表1!$A$3:$B$74,2,FALSE) -> #REF!
B26: =北段!B20 -> T02612 | C26: =VLOOKUP(B26,北段!B:C,2,FALSE) -> 蕭曉琦 | D26: =VLOOKUP('北段 (人資版)'!D26,工作表1!$A$3:$B$74,2,FALSE) -> #N/A | E26: =VLOOKUP('北段 (人資版)'!E26,工作表1!$A$3:$B$74,2,FALSE) -> 91 | F26: =VLOOKUP('北段 (人資版)'!F26,工作表1!$A$3:$B$74,2,FALSE) -> 38 | G26: =VLOOKUP('北段 (人資版)'!G26,工作表1!$A$3:$B$74,2,FALSE) -> 38 | H26: =VLOOKUP('北段 (人資版)'!H26,工作表1!$A$3:$B$74,2,FALSE) -> 90 | I26: =VLOOKUP('北段 (人資版)'!I26,工作表1!$A$3:$B$74,2,FALSE) -> #N/A | J26: =VLOOKUP('北段 (人資版)'!J26,工作表1!$A$3:$B$74,2,FALSE) -> 91 | K26: =VLOOKUP('北段 (人資版)'!K26,工作表1!$A$3:$B$74,2,FALSE) -> 38 | ... AL26: =VLOOKUP('北段 (人資版)'!AL26,工作表1!$A$3:$B$74,2,FALSE) -> #REF!
B27: =北段!B21 -> T02613 | C27: =VLOOKUP(B27,北段!B:C,2,FALSE) -> 張雅荃 | D27: =VLOOKUP('北段 (人資版)'!D27,工作表1!$A$3:$B$74,2,FALSE) -> #N/A | E27: =VLOOKUP('北段 (人資版)'!E27,工作表1!$A$3:$B$74,2,FALSE) -> 66 | F27: =VLOOKUP('北段 (人資版)'!F27,工作表1!$A$3:$B$74,2,FALSE) -> 66 | G27: =VLOOKUP('北段 (人資版)'!G27,工作表1!$A$3:$B$74,2,FALSE) -> 66 | H27: =VLOOKUP('北段 (人資版)'!H27,工作表1!$A$3:$B$74,2,FALSE) -> 92 | I27: =VLOOKUP('北段 (人資版)'!I27,工作表1!$A$3:$B$74,2,FALSE) -> #N/A | J27: =VLOOKUP('北段 (人資版)'!J27,工作表1!$A$3:$B$74,2,FALSE) -> 66 | K27: =VLOOKUP('北段 (人資版)'!K27,工作表1!$A$3:$B$74,2,FALSE) -> 66 | ... AL27: =VLOOKUP('北段 (人資版)'!AL27,工作表1!$A$3:$B$74,2,FALSE) -> #REF!
B28: =北段!#REF! -> #REF! | C28: =VLOOKUP(B28,北段!B:C,2,FALSE) -> #REF! | D28: =VLOOKUP('北段 (人資版)'!D28,工作表1!$A$3:$B$74,2,FALSE) -> #REF! | E28: =VLOOKUP('北段 (人資版)'!E28,工作表1!$A$3:$B$74,2,FALSE) -> #REF! | F28: =VLOOKUP('北段 (人資版)'!F28,工作表1!$A$3:$B$74,2,FALSE) -> #REF! | G28: =VLOOKUP('北段 (人資版)'!G28,工作表1!$A$3:$B$74,2,FALSE) -> #REF! | H28: =VLOOKUP('北段 (人資版)'!H28,工作表1!$A$3:$B$74,2,FALSE) -> #REF! | I28: =VLOOKUP('北段 (人資版)'!I28,工作表1!$A$3:$B$74,2,FALSE) -> #REF! | J28: =VLOOKUP('北段 (人資版)'!J28,工作表1!$A$3:$B$74,2,FALSE) -> #REF! | K28: =VLOOKUP('北段 (人資版)'!K28,工作表1!$A$3:$B$74,2,FALSE) -> #REF! | ... AL28: =VLOOKUP('北段 (人資版)'!AL28,工作表1!$A$3:$B$74,2,FALSE) -> #REF!
B29: =北段!#REF! -> #REF! | C29: =VLOOKUP(B29,北段!B:C,2,FALSE) -> #REF! | D29: =VLOOKUP('北段 (人資版)'!D29,工作表1!$A$3:$B$74,2,FALSE) -> #REF! | E29: =VLOOKUP('北段 (人資版)'!E29,工作表1!$A$3:$B$74,2,FALSE) -> #REF! | F29: =VLOOKUP('北段 (人資版)'!F29,工作表1!$A$3:$B$74,2,FALSE) -> #REF! | G29: =VLOOKUP('北段 (人資版)'!G29,工作表1!$A$3:$B$74,2,FALSE) -> #REF! | H29: =VLOOKUP('北段 (人資版)'!H29,工作表1!$A$3:$B$74,2,FALSE) -> #REF! | I29: =VLOOKUP('北段 (人資版)'!I29,工作表1!$A$3:$B$74,2,FALSE) -> #REF! | J29: =VLOOKUP('北段 (人資版)'!J29,工作表1!$A$3:$B$74,2,FALSE) -> #REF! | K29: =VLOOKUP('北段 (人資版)'!K29,工作表1!$A$3:$B$74,2,FALSE) -> #REF! | ... AL29: =VLOOKUP('北段 (人資版)'!AL29,工作表1!$A$3:$B$74,2,FALSE) -> #REF!
B30: =北段!#REF! -> #REF! | C30: =VLOOKUP(B30,北段!B:C,2,FALSE) -> #REF! | D30: =VLOOKUP('北段 (人資版)'!D30,工作表1!$A$3:$B$74,2,FALSE) -> #REF! | E30: =VLOOKUP('北段 (人資版)'!E30,工作表1!$A$3:$B$74,2,FALSE) -> #REF! | F30: =VLOOKUP('北段 (人資版)'!F30,工作表1!$A$3:$B$74,2,FALSE) -> #REF! | G30: =VLOOKUP('北段 (人資版)'!G30,工作表1!$A$3:$B$74,2,FALSE) -> #REF! | H30: =VLOOKUP('北段 (人資版)'!H30,工作表1!$A$3:$B$74,2,FALSE) -> #REF! | I30: =VLOOKUP('北段 (人資版)'!I30,工作表1!$A$3:$B$74,2,FALSE) -> #REF! | J30: =VLOOKUP('北段 (人資版)'!J30,工作表1!$A$3:$B$74,2,FALSE) -> #REF! | K30: =VLOOKUP('北段 (人資版)'!K30,工作表1!$A$3:$B$74,2,FALSE) -> #REF! | ... AL30: =VLOOKUP('北段 (人資版)'!AL30,工作表1!$A$3:$B$74,2,FALSE) -> #REF!
B31: =北段!#REF! -> #REF! | C31: =VLOOKUP(B31,北段!B:C,2,FALSE) -> #REF! | D31: =VLOOKUP('北段 (人資版)'!D31,工作表1!$A$3:$B$74,2,FALSE) -> #REF! | E31: =VLOOKUP('北段 (人資版)'!E31,工作表1!$A$3:$B$74,2,FALSE) -> #REF! | F31: =VLOOKUP('北段 (人資版)'!F31,工作表1!$A$3:$B$74,2,FALSE) -> #REF! | G31: =VLOOKUP('北段 (人資版)'!G31,工作表1!$A$3:$B$74,2,FALSE) -> #REF! | H31: =VLOOKUP('北段 (人資版)'!H31,工作表1!$A$3:$B$74,2,FALSE) -> #REF! | I31: =VLOOKUP('北段 (人資版)'!I31,工作表1!$A$3:$B$74,2,FALSE) -> #REF! | J31: =VLOOKUP('北段 (人資版)'!J31,工作表1!$A$3:$B$74,2,FALSE) -> #REF! | K31: =VLOOKUP('北段 (人資版)'!K31,工作表1!$A$3:$B$74,2,FALSE) -> #REF! | ... AL31: =VLOOKUP('北段 (人資版)'!AL31,工作表1!$A$3:$B$74,2,FALSE) -> #REF!
A32: A2 | B32: =北段!#REF! -> #REF! | C32: =VLOOKUP(B32,北段!B:C,2,FALSE) -> #REF! | D32: =VLOOKUP('北段 (人資版)'!D32,工作表1!$A$3:$B$74,2,FALSE) -> #REF! | E32: =VLOOKUP('北段 (人資版)'!E32,工作表1!$A$3:$B$74,2,FALSE) -> #REF! | F32: =VLOOKUP('北段 (人資版)'!F32,工作表1!$A$3:$B$74,2,FALSE) -> #REF! | G32: =VLOOKUP('北段 (人資版)'!G32,工作表1!$A$3:$B$74,2,FALSE) -> #REF! | H32: =VLOOKUP('北段 (人資版)'!H32,工作表1!$A$3:$B$74,2,FALSE) -> #REF! | I32: =VLOOKUP('北段 (人資版)'!I32,工作表1!$A$3:$B$74,2,FALSE) -> #REF! | J32: =VLOOKUP('北段 (人資版)'!J32,工作表1!$A$3:$B$74,2,FALSE) -> #REF! | K32: =VLOOKUP('北段 (人資版)'!K32,工作表1!$A$3:$B$74,2,FALSE) -> #REF! | ... AL32: =VLOOKUP('北段 (人資版)'!AL32,工作表1!$A$3:$B$74,2,FALSE) -> #REF!
B33: =北段!#REF! -> #REF! | C33: =VLOOKUP(B33,北段!B:C,2,FALSE) -> #REF! | D33: =VLOOKUP('北段 (人資版)'!D33,工作表1!$A$3:$B$74,2,FALSE) -> #REF! | E33: =VLOOKUP('北段 (人資版)'!E33,工作表1!$A$3:$B$74,2,FALSE) -> #REF! | F33: =VLOOKUP('北段 (人資版)'!F33,工作表1!$A$3:$B$74,2,FALSE) -> #REF! | G33: =VLOOKUP('北段 (人資版)'!G33,工作表1!$A$3:$B$74,2,FALSE) -> #REF! | H33: =VLOOKUP('北段 (人資版)'!H33,工作表1!$A$3:$B$74,2,FALSE) -> #REF! | I33: =VLOOKUP('北段 (人資版)'!I33,工作表1!$A$3:$B$74,2,FALSE) -> #REF! | J33: =VLOOKUP('北段 (人資版)'!J33,工作表1!$A$3:$B$74,2,FALSE) -> #REF! | K33: =VLOOKUP('北段 (人資版)'!K33,工作表1!$A$3:$B$74,2,FALSE) -> #REF! | ... AL33: =VLOOKUP('北段 (人資版)'!AL33,工作表1!$A$3:$B$74,2,FALSE) -> #REF!
B34: =北段!#REF! -> #REF! | C34: =VLOOKUP(B34,北段!B:C,2,FALSE) -> #REF! | D34: =VLOOKUP('北段 (人資版)'!D34,工作表1!$A$3:$B$74,2,FALSE) -> #REF! | E34: =VLOOKUP('北段 (人資版)'!E34,工作表1!$A$3:$B$74,2,FALSE) -> #REF! | F34: =VLOOKUP('北段 (人資版)'!F34,工作表1!$A$3:$B$74,2,FALSE) -> #REF! | G34: =VLOOKUP('北段 (人資版)'!G34,工作表1!$A$3:$B$74,2,FALSE) -> #REF! | H34: =VLOOKUP('北段 (人資版)'!H34,工作表1!$A$3:$B$74,2,FALSE) -> #REF! | I34: =VLOOKUP('北段 (人資版)'!I34,工作表1!$A$3:$B$74,2,FALSE) -> #REF! | J34: =VLOOKUP('北段 (人資版)'!J34,工作表1!$A$3:$B$74,2,FALSE) -> #REF! | K34: =VLOOKUP('北段 (人資版)'!K34,工作表1!$A$3:$B$74,2,FALSE) -> #REF! | ... AL34: =VLOOKUP('北段 (人資版)'!AL34,工作表1!$A$3:$B$74,2,FALSE) -> #REF!
B35: =北段!#REF! -> #REF! | C35: =VLOOKUP(B35,北段!B:C,2,FALSE) -> #REF! | D35: =VLOOKUP('北段 (人資版)'!D36,工作表1!$A$3:$B$74,2,FALSE) -> #REF! | E35: =VLOOKUP('北段 (人資版)'!E36,工作表1!$A$3:$B$74,2,FALSE) -> #REF! | F35: =VLOOKUP('北段 (人資版)'!F36,工作表1!$A$3:$B$74,2,FALSE) -> #REF! | G35: =VLOOKUP('北段 (人資版)'!G36,工作表1!$A$3:$B$74,2,FALSE) -> #REF! | H35: =VLOOKUP('北段 (人資版)'!H36,工作表1!$A$3:$B$74,2,FALSE) -> #REF! | I35: =VLOOKUP('北段 (人資版)'!I36,工作表1!$A$3:$B$74,2,FALSE) -> #REF! | J35: =VLOOKUP('北段 (人資版)'!J36,工作表1!$A$3:$B$74,2,FALSE) -> #REF! | K35: =VLOOKUP('北段 (人資版)'!K36,工作表1!$A$3:$B$74,2,FALSE) -> #REF! | ... AL35: =VLOOKUP('北段 (人資版)'!AL36,工作表1!$A$3:$B$74,2,FALSE) -> #REF!
B36: =北段!#REF! -> #REF! | C36: =VLOOKUP(B36,北段!B:C,2,FALSE) -> #REF! | D36: =VLOOKUP('北段 (人資版)'!D37,工作表1!$A$3:$B$74,2,FALSE) -> #REF! | E36: =VLOOKUP('北段 (人資版)'!E37,工作表1!$A$3:$B$74,2,FALSE) -> #REF! | F36: =VLOOKUP('北段 (人資版)'!F37,工作表1!$A$3:$B$74,2,FALSE) -> #REF! | G36: =VLOOKUP('北段 (人資版)'!G37,工作表1!$A$3:$B$74,2,FALSE) -> #REF! | H36: =VLOOKUP('北段 (人資版)'!H37,工作表1!$A$3:$B$74,2,FALSE) -> #REF! | I36: =VLOOKUP('北段 (人資版)'!I37,工作表1!$A$3:$B$74,2,FALSE) -> #REF! | J36: =VLOOKUP('北段 (人資版)'!J37,工作表1!$A$3:$B$74,2,FALSE) -> #REF! | K36: =VLOOKUP('北段 (人資版)'!K37,工作表1!$A$3:$B$74,2,FALSE) -> #REF! | ... AL36: =VLOOKUP('北段 (人資版)'!AL37,工作表1!$A$3:$B$74,2,FALSE) -> #REF!
B37: =北段!#REF! -> #REF! | C37: =VLOOKUP(B37,北段!B:C,2,FALSE) -> #REF! | D37: =VLOOKUP('北段 (人資版)'!D38,工作表1!$A$3:$B$74,2,FALSE) -> #REF! | E37: =VLOOKUP('北段 (人資版)'!E38,工作表1!$A$3:$B$74,2,FALSE) -> #REF! | F37: =VLOOKUP('北段 (人資版)'!F38,工作表1!$A$3:$B$74,2,FALSE) -> #REF! | G37: =VLOOKUP('北段 (人資版)'!G38,工作表1!$A$3:$B$74,2,FALSE) -> #REF! | H37: =VLOOKUP('北段 (人資版)'!H38,工作表1!$A$3:$B$74,2,FALSE) -> #REF! | I37: =VLOOKUP('北段 (人資版)'!I38,工作表1!$A$3:$B$74,2,FALSE) -> #REF! | J37: =VLOOKUP('北段 (人資版)'!J38,工作表1!$A$3:$B$74,2,FALSE) -> #REF! | K37: =VLOOKUP('北段 (人資版)'!K38,工作表1!$A$3:$B$74,2,FALSE) -> #REF! | ... AL37: =VLOOKUP('北段 (人資版)'!AL38,工作表1!$A$3:$B$74,2,FALSE) -> #REF!
B38: =北段!#REF! -> #REF! | C38: =VLOOKUP(B38,北段!B:C,2,FALSE) -> #REF! | D38: =VLOOKUP('北段 (人資版)'!D39,工作表1!$A$3:$B$74,2,FALSE) -> #REF! | E38: =VLOOKUP('北段 (人資版)'!E39,工作表1!$A$3:$B$74,2,FALSE) -> #REF! | F38: =VLOOKUP('北段 (人資版)'!F39,工作表1!$A$3:$B$74,2,FALSE) -> #REF! | G38: =VLOOKUP('北段 (人資版)'!G39,工作表1!$A$3:$B$74,2,FALSE) -> #REF! | H38: =VLOOKUP('北段 (人資版)'!H39,工作表1!$A$3:$B$74,2,FALSE) -> #REF! | I38: =VLOOKUP('北段 (人資版)'!I39,工作表1!$A$3:$B$74,2,FALSE) -> #REF! | J38: =VLOOKUP('北段 (人資版)'!J39,工作表1!$A$3:$B$74,2,FALSE) -> #REF! | K38: =VLOOKUP('北段 (人資版)'!K39,工作表1!$A$3:$B$74,2,FALSE) -> #REF! | ... AL38: =VLOOKUP('北段 (人資版)'!AL39,工作表1!$A$3:$B$74,2,FALSE) -> #REF!
B39: =北段!#REF! -> #REF! | C39: =VLOOKUP(B39,北段!B:C,2,FALSE) -> #REF! | D39: =VLOOKUP('北段 (人資版)'!D40,工作表1!$A$3:$B$74,2,FALSE) -> #REF! | E39: =VLOOKUP('北段 (人資版)'!E40,工作表1!$A$3:$B$74,2,FALSE) -> #REF! | F39: =VLOOKUP('北段 (人資版)'!F40,工作表1!$A$3:$B$74,2,FALSE) -> #REF! | G39: =VLOOKUP('北段 (人資版)'!G40,工作表1!$A$3:$B$74,2,FALSE) -> #REF! | H39: =VLOOKUP('北段 (人資版)'!H40,工作表1!$A$3:$B$74,2,FALSE) -> #REF! | I39: =VLOOKUP('北段 (人資版)'!I40,工作表1!$A$3:$B$74,2,FALSE) -> #REF! | J39: =VLOOKUP('北段 (人資版)'!J40,工作表1!$A$3:$B$74,2,FALSE) -> #REF! | K39: =VLOOKUP('北段 (人資版)'!K40,工作表1!$A$3:$B$74,2,FALSE) -> #REF! | ... AL39: =VLOOKUP('北段 (人資版)'!AL40,工作表1!$A$3:$B$74,2,FALSE) -> #REF!
B40: =北段!#REF! -> #REF! | C40: =VLOOKUP(B40,北段!B:C,2,FALSE) -> #REF! | D40: =VLOOKUP('北段 (人資版)'!D42,工作表1!$A$3:$B$74,2,FALSE) -> #REF! | E40: =VLOOKUP('北段 (人資版)'!E42,工作表1!$A$3:$B$74,2,FALSE) -> #REF! | F40: =VLOOKUP('北段 (人資版)'!F42,工作表1!$A$3:$B$74,2,FALSE) -> #REF! | G40: =VLOOKUP('北段 (人資版)'!G42,工作表1!$A$3:$B$74,2,FALSE) -> #REF! | H40: =VLOOKUP('北段 (人資版)'!H42,工作表1!$A$3:$B$74,2,FALSE) -> #REF! | I40: =VLOOKUP('北段 (人資版)'!I42,工作表1!$A$3:$B$74,2,FALSE) -> #REF! | J40: =VLOOKUP('北段 (人資版)'!J42,工作表1!$A$3:$B$74,2,FALSE) -> #REF! | K40: =VLOOKUP('北段 (人資版)'!K42,工作表1!$A$3:$B$74,2,FALSE) -> #REF! | ... AL40: =VLOOKUP('北段 (人資版)'!AL42,工作表1!$A$3:$B$74,2,FALSE) -> #REF!
...

Sheet 工作表1
B1: 請輸入年度 | C1: 2025 | E1: 請輸入月份 | F1: 2 | H1: 8
A3: 41日 | B3: 05
A4: 01日 | B4: 05
A5: 06日 | B5: 05
A6: 01日. | B6: 03
A7: T | B7: 05
A8: 01中A | B8: 07
A9: 02中A | B9: 07
A10: 03中A | B10: 07
A11: 04中A | B11: 07
A12: 05中A | B12: 07
A13: 06中A | B13: 07
A14: 41中A | B14: 07
A15: 早Q | B15: 43
A16: 41早K | B16: 31
A17: 41早G | B17: 11
A18: 01早 | B18: 38
A19: 02早 | B19: 38
A20: 03早 | B20: 38
A21: 04早 | B21: 38
A22: 05早 | B22: 38
A23: 06早 | B23: 38
A24: 07早 | B24: 38
A25: 21早 | B25: 38
A26: 41早 | B26: 38
... A48: 41夜. | B48: 67
A49: 03早A | B49: 23d
A50: 03午F | B50: 34d
A51: L | B51: 07
A52: P | B52: 90
A53: R | B53: 91
A54: r' | B54: 92
A55: r'(04早) | B55: 92
A56: r'(01早) | B56: 92
A57: r'(02早) | B57: 92
A58: r'(06早) | B58: 92
A59: r'(03早A) | B59: 92
A60: r'(01中A) | B60: 92
A61: r'(04中A) | B61: 92
A62: r'(05中A) | B62: 92
...
